Workbook

Sheet Jan
A1: PHILIPPINE INVESTMENT FUNDS ASSOCIATION, INC.
A2: MUTUAL FUNDS STATISTICAL REPORT
A3: Month of January 2022
A4: (Amounts in Peso)
I5: F O R - T H E - M O N T H | L5: Y E A R - T O - D A T E
A6: Fund Category | C6: Fund Name | D6: ASSETS | E6: LIABILITIES | F6: NET ASSETS | G6: EQUITY INV. | H6: NO. OF A/C | I6: SALES | J6: REDEMPTIONS | K6: NET SALES | L6: TOTAL SALES | M6: TOTAL REDEMPTIONS | N6: TOTAL NET SALES
A7: Stock Funds
A8: Primarily invested in Peso Securities (shares)
B9: 1 | C9: ALFM Growth Fund, Inc. | D9: 5.5179892e+09 | E9: 17386841 | F9: =D9-E9 -> 5500602324 | G9: 5221517716 | H9: 7670 | I9: 16578719 | J9: 59527096 | K9: =I9-J9 -> -42948377 | L9: =I9 -> 16578719 | M9: =J9 -> 59527096 | N9: =L9-M9 -> -42948377
B10: 2 | C10: ATRAM Alpha Opportunity Fund, Inc. (formerly, ATRKE Alpha Opportunity Fund, Inc.) | D10: 8.3966205e+08 | E10: 14606381 | F10: =D10-E10 -> 8.2505567e+08 | G10: 7.7282253e+08 | H10: 4318 | I10: 26363298 | J10: 12448817 | K10: =I10-J10 -> 13914480 | L10: =I10 -> 26363298 | M10: =J10 -> 12448817 | N10: =L10-M10 -> 13914480
B11: 3 | C11: ATRAM Phil. Equity Opportunity Fund, Inc. (formerly, ATRKE Equity Opportunity Fund, Inc.) | D11: 1.181147e+09 | E11: 3602939.4 | F11: =D11-E11 -> 1177544093 | G11: 1.1169147e+09 | H11: 2920 | I11: 19336344 | J11: 20237651 | K11: =I11-J11 -> -901307.42 | L11: =I11 -> 19336344 | M11: =J11 -> 20237651 | N11: =L11-M11 -> -901307.42
B12: 4 | C12: Climbs Share Capital Equity Investment Fund Corp. | D12: 3.6089249e+08 | E12: 8768078.7 | F12: =D12-E12 -> 3.5212441e+08 | G12: 1.1124367e+08 | H12: 1621 | I12: 1239934.8 | J12: 5155350.7 | K12: =I12-J12 -> -3915415.9 | L12: =I12 -> 1239934.8 | M12: =J12 -> 5155350.7 | N12: =L12-M12 -> -3915415.9
B13: 5 | C13: First Metro Consumer Fund on MSCI Phils. IMI, Inc. | D13: 6.0724955e+08 | E13: 22638785 | F13: =D13-E13 -> 5.8461076e+08 | G13: 5.3069916e+08 | H13: 1536 | I13: 1506512.2 | J13: 6275249.8 | K13: =I13-J13 -> -4768737.6 | L13: =I13 -> 1506512.2 | M13: =J13 -> 6275249.8 | N13: =L13-M13 -> -4768737.6
B14: 6 | C14: First Metro Save and Learn Equity Fund, Inc. | D14: 4.5966022e+09 | E14: 2.1260095e+08 | F14: =D14-E14 -> 4384001270 | G14: 3.9845724e+09 | H14: 16626 | I14: 42273854 | J14: 1.2164963e+08 | K14: =I14-J14 -> -79375779 | L14: =I14 -> 42273854 | M14: =J14 -> 1.2164963e+08 | N14: =L14-M14 -> -79375779
B15: 7 | C15: First Metro Save and Learn Phil. Index Fund, Inc. (formerly, One Wealthy Nation Fund, Inc.) | D15: 95793097 | E15: 627634.54 | F15: =D15-E15 -> 95165462 | G15: 92036632 | H15: 522 | I15: 1179498.6 | J15: 427978 | K15: =I15-J15 -> 751520.59 | L15: =I15 -> 1179498.6 | M15: =J15 -> 427978 | N15: =L15-M15 -> 751520.59
B16: 8 | C16: MBG Equity Investment Fund, Inc. | D16: 1.5160231e+08 | E16: 748143.77 | F16: =D16-E16 -> 1.5085417e+08 | G16: 1.4266239e+08 | H16: 50 | I16: 0 | J16: 0 | K16: =I16-J16 -> 0 | L16: =I16 -> 0 | M16: =J16 -> 0 | N16: =L16-M16 -> 0
B17: 9 | C17: PAMI Equity Index Fund, Inc. | D17: 1.7617541e+10 | E17: 1.08597e+08 | F17: =D17-E17 -> 17508943754 | G17: 1.7421561e+10 | H17: 12906 | I17: 2.306412e+08 | J17: 20341527 | K17: =I17-J17 -> 2.1029967e+08 | L17: =I17 -> 2.306412e+08 | M17: =J17 -> 20341527 | N17: =L17-M17 -> 2.1029967e+08
B18: 10 | C18: Philam Strategic Growth Fund, Inc. | D18: 3.6417171e+10 | E18: 1.3766723e+08 | F18: =D18-E18 -> 36279503946 | G18: 3.437328e+10 | H18: 12741 | I18: 90692795 | J18: 43775263 | K18: =I18-J18 -> 46917531 | L18: =I18 -> 90692795 | M18: =J18 -> 43775263 | N18: =L18-M18 -> 46917531
B19: 11 | C19: Philequity Dividend Yield Fund, Inc. | D19: 2.5451253e+09 | E19: 5184306.3 | F19: =D19-E19 -> 2539941020 | G19: 2.3826987e+09 | H19: 4697 | I19: 14697247 | J19: 60946454 | K19: =I19-J19 -> -46249207 | L19: =I19 -> 14697247 | M19: =J19 -> 60946454 | N19: =L19-M19 -> -46249207
B20: 12 | C20: Philequity Fund, Inc. | D20: 1.1195866e+10 | E20: 93886822 | F20: =D20-E20 -> 11101978939 | G20: 1.0336527e+10 | H20: 37263 | I20: 37032105 | J20: 34967192 | K20: =I20-J20 -> 2064913 | L20: =I20 -> 37032105 | M20: =J20 -> 34967192 | N20: =L20-M20 -> 2064913
... B27: 19 | C27: United Fund, Inc. | D27: 6.5910108e+08 | E27: 6989710.8 | F27: =D27-E27 -> 652111369 | G27: 5.8379131e+08 | H27: 1300 | I27: 976063.74 | J27: 477744.54 | K27: =I27-J27 -> 498319.2 | L27: =I27 -> 976063.74 | M27: =J27 -> 477744.54 | N27: =L27-M27 -> 498319.2
A28: Primarily invested in Peso Securities (units)
B29: 20 | C29: Philequity Alpha One Fund, Inc. | D29: 3.4147679e+08 | E29: 999989.53 | F29: =D29-E29 -> 3.404768e+08 | G29: 3.1221962e+08 | H29: 1042 | I29: 8239126.5 | J29: 4679932.7 | K29: =I29-J29 -> 3559193.8 | L29: =I29 -> 8239126.5 | M29: =J29 -> 4679932.7 | N29: =L29-M29 -> 3559193.8
B30: 21 | C30: Philippine Stock Index Fund Corp. | D30: 1.5393858e+08 | E30: 7577262.4 | F30: =D30-E30 -> 1.4636132e+08 | G30: 146293913 | H30: 120934 | I30: 1.6089645e+08 | J30: 13339551 | K30: =I30-J30 -> 1.475569e+08 | L30: =I30 -> 1.6089645e+08 | M30: =J30 -> 13339551 | N30: =L30-M30 -> 1.475569e+08
A31: Exchange Traded Fund
B32: 22 | C32: First Metro Phil. Equity Exchange Traded Fund, Inc. | D32: 2.2732739e+09 | E32: 6053519.2 | F32: =D32-E32 -> 2267220339 | G32: 2.2600147e+09 | H32: 3043 | I32: 10880756 | J32: 3331959 | K32: =I32-J32 -> 7548797 | L32: =I32 -> 10880756 | M32: =J32 -> 3331959 | N32: =L32-M32 -> 7548797
A33: Sub total - Peso Currency | D33: =SUM(D9:D32) -> 123021176865 | E33: =SUM(E9:E32) -> 8.1280275e+08 | F33: =SUM(F9:F32) -> 122208374115 | G33: =SUM(G9:G32) -> 117484683786 | H33: =SUM(H9:H32) -> 405474 | I33: =SUM(I9:I32) -> 948068606 | J33: =SUM(J9:J32) -> 8.1973635e+08 | K33: =SUM(K9:K32) -> 128332254 | ... N33: =SUM(N9:N32) -> 128332254
A34: Primarily invested in foreign currency securities (shares)
B35: 23 | C35: ATRAM AsiaPlus Equity Fund, Inc. (formerly, ATR KimEng AsiaPlus Recovery Fund, Inc.) | D35: 50202171 | E35: 1011746.4 | F35: =D35-E35 -> 49190425 | G35: 0 | H35: 57 | I35: 99.77 | J35: 3932.8 | K35: =I35-J35 -> -3833.03 | L35: =I35 -> 99.77 | M35: =J35 -> 3932.8 | N35: =L35-M35 -> -3833.03
B36: 24 | C36: Sun Life Prosperity World Voyager Fund, Inc. | D36: =50.95*38310707.15 -> 1951930529 | E36: =50.95*962842.17 -> 49056809 | F36: =D36-E36 -> 1902873721 | G36: 0 | H36: 2718 | I36: =50.95*517309.67 -> 26356928 | J36: =50.95*2016259.18 -> 1.0272841e+08 | K36: =I36-J36 -> -76371478 | L36: =I36 -> 26356928 | M36: =J36 -> 1.0272841e+08 | N36: =L36-M36 -> -76371478
A37: Sub total - US Currency | D37: =SUM(D35:D36) -> 2002132700 | E37: =SUM(E35:E36) -> 50068555 | F37: =SUM(F35:F36) -> 1952064145 | G37: =SUM(G35:G36) -> 0 | H37: =SUM(H35:H36) -> 2775 | I37: =SUM(I35:I36) -> 26357027 | J37: =SUM(J35:J36) -> 102732338 | K37: =SUM(K35:K36) -> -76375311 | ... N37: =SUM(N35:N36) -> -76375311
A38: Sub total - stock funds | D38: =D33+D37 -> 125023309566 | E38: =E33+E37 -> 8.6287131e+08 | F38: =F33+F37 -> 124160438260 | G38: =G33+G37 -> 117484683786 | H38: =H33+H37 -> 408249 | I38: =I33+I37 -> 9.7442563e+08 | J38: =J33+J37 -> 9.2246869e+08 | K38: =K33+K37 -> 51956943 | ... N38: =N33+N37 -> 51956943
A39: Balanced Funds
A40: Primarily invested in Peso Securities (shares)
B41: 25 | C41: ATRAM Dynamic Allocation Fund, Inc. (formerly, Optima Balanced Fund, Inc.) | D41: 1.3206969e+08 | E41: 3492791.5 | F41: =D41-E41 -> 1.285769e+08 | G41: 51581471 | H41: 747 | I41: 4280453.3 | J41: 651534.23 | K41: =I41-J41 -> 3628919.1 | L41: =I41 -> 4280453.3 | M41: =J41 -> 651534.23 | N41: =L41-M41 -> 3628919.1
B42: 26 | C42: ATRAM Philippine Balanced Fund, Inc. (formerly, ATRKE Philippine Balanced Fund, Inc.) | D42: 7.2513203e+08 | E42: 24440745 | F42: =D42-E42 -> 7.0069128e+08 | G42: 4.4385314e+08 | H42: 2502 | I42: 1461165.2 | J42: 5139792.9 | K42: =I42-J42 -> -3678627.7 | L42: =I42 -> 1461165.2 | M42: =J42 -> 5139792.9 | N42: =L42-M42 -> -3678627.7
B43: 27 | C43: First Metro Save and Learn Balanced Fund, Inc. | D43: 1.380406e+09 | E43: 63202847 | F43: =D43-E43 -> 1317203199 | G43: 8.0577773e+08 | H43: 4939 | I43: 2329359.7 | J43: 2786616.8 | K43: =I43-J43 -> -457257.08 | L43: =I43 -> 2329359.7 | M43: =J43 -> 2786616.8 | N43: =L43-M43 -> -457257.08
B44: 28 | C44: First Metro Save and Learn F.O.C.C.U.S. Dynamic Fund, Inc. | D44: 1.3671436e+08 | E44: 8732703.8 | F44: =D44-E44 -> 1.2798165e+08 | G44: 2.2600147e+09 | H44: 70 | I44: 98260869 | J44: 0 | K44: =I44-J44 -> 98260869 | L44: =I44 -> 98260869 | M44: =J44 -> 0 | N44: =L44-M44 -> 98260869
B45: 29 | C45: NCM Mutual Fund of the Phils., Inc. | D45: 3.6303231e+08 | E45: 1312853.8 | F45: =D45-E45 -> 361719457 | G45: 1.7603567e+08 | H45: 57 | I45: 0 | J45: 0 | K45: =I45-J45 -> 0 | L45: =I45 -> 0 | M45: =J45 -> 0 | N45: =L45-M45 -> 0
B46: 30 | C46: PAMI Horizon Fund, Inc. | D46: 6.5565586e+08 | E46: 16576585 | F46: =D46-E46 -> 6.3907927e+08 | G46: 3.5663041e+08 | H46: 10279 | I46: 253166.07 | J46: 8386100.3 | K46: =I46-J46 -> -8132934.2 | L46: =I46 -> 253166.07 | M46: =J46 -> 8386100.3 | N46: =L46-M46 -> -8132934.2
...

Sheet Feb
A1: PHILIPPINE INVESTMENT FUNDS ASSOCIATION, INC.
A2: MUTUAL FUNDS STATISTICAL REPORT
A3: Month of February 2022
A4: (Amounts in Peso)
I5: F O R - T H E - M O N T H | L5: Y E A R - T O - D A T E
A6: Fund Category | C6: Fund Name | D6: ASSETS | E6: LIABILITIES | F6: NET ASSETS | G6: EQUITY INV. | H6: NO. OF A/C | I6: SALES | J6: REDEMPTIONS | K6: NET SALES | L6: TOTAL SALES | M6: TOTAL REDEMPTIONS | N6: TOTAL NET SALES
A7: Stock Funds
A8: Primarily invested in Peso Securities (shares)
B9: 1 | C9: ALFM Growth Fund, Inc. | D9: 5.5023457e+09 | E9: 41795235 | F9: =D9-E9 -> 5460550495 | G9: 5.1599286e+09 | H9: 7601 | I9: 16600435 | J9: 44507421 | K9: =I9-J9 -> -27906986 | L9: =I9+Jan!L9 -> 33179154 | M9: =J9+Jan!M9 -> 104034517 | N9: =L9-M9 -> -70855363
B10: 2 | C10: ATRAM Alpha Opportunity Fund, Inc. (formerly, ATRKE Alpha Opportunity Fund, Inc.) | D10: 9.0302162e+08 | E10: 46247536 | F10: =D10-E10 -> 8.5677408e+08 | G10: 7.5178026e+08 | H10: 4346 | I10: 98900298 | J10: 45823349 | K10: =I10-J10 -> 53076949 | L10: =I10+Jan!L10 -> 1.252636e+08 | M10: =J10+Jan!M10 -> 58272166 | N10: =L10-M10 -> 66991429
B11: 3 | C11: ATRAM Phil. Equity Opportunity Fund, Inc. (formerly, ATRKE Equity Opportunity Fund, Inc.) | D11: 1.2057533e+09 | E11: 20249179 | F11: =D11-E11 -> 1185504155 | G11: 1.125418e+09 | H11: 2934 | I11: 13774681 | J11: 5637747.8 | K11: =I11-J11 -> 8136932.8 | L11: =I11+Jan!L11 -> 33111025 | M11: =J11+Jan!M11 -> 25875399 | N11: =L11-M11 -> 7235625.4
B12: 4 | C12: Climbs Share Capital Equity Investment Fund Corp. | D12: 3.5901243e+08 | E12: 6112033.5 | F12: =D12-E12 -> 3.5290039e+08 | G12: 1.1949881e+08 | H12: 1645 | I12: 1434327.4 | J12: 303337.57 | K12: =I12-J12 -> 1130989.9 | L12: =I12+Jan!L12 -> 2674262.2 | M12: =J12+Jan!M12 -> 5458688.3 | N12: =L12-M12 -> -2784426.1
B13: 5 | C13: First Metro Consumer Fund on MSCI Phils. IMI, Inc. | D13: 5.7876478e+08 | E13: 1066443.3 | F13: =D13-E13 -> 5.7769833e+08 | G13: 4.4216959e+08 | H13: 1528 | I13: 13064894 | J13: 2483026.1 | K13: =I13-J13 -> 10581868 | L13: =I13+Jan!L13 -> 14571406 | M13: =J13+Jan!M13 -> 8758275.9 | N13: =L13-M13 -> 5813130
B14: 6 | C14: First Metro Save and Learn Equity Fund, Inc. | D14: 4.398399e+09 | E14: 65528050 | F14: =D14-E14 -> 4332870927 | G14: 4.0242637e+09 | H14: 16569 | I14: 42563072 | J14: 99409339 | K14: =I14-J14 -> -56846267 | L14: =I14+Jan!L14 -> 84836926 | M14: =J14+Jan!M14 -> 2.2105897e+08 | N14: =L14-M14 -> -1.3622205e+08
B15: 7 | C15: First Metro Save and Learn Phil. Index Fund, Inc. (formerly, One Wealthy Nation Fund, Inc.) | D15: 95296341 | E15: 1085574.4 | F15: =D15-E15 -> 94210767 | G15: 91097740 | H15: 525 | I15: 2260130.8 | J15: 2664832.1 | K15: =I15-J15 -> -404701.26 | L15: =I15+Jan!L15 -> 3439629.4 | M15: =J15+Jan!M15 -> 3092810.1 | N15: =L15-M15 -> 346819.33
B16: 8 | C16: MBG Equity Investment Fund, Inc. | D16: 1.5231995e+08 | E16: 788522.83 | F16: =D16-E16 -> 151531431 | G16: 1.4341738e+08 | H16: 50 | I16: 1500000 | J16: 950000 | K16: =I16-J16 -> 550000 | L16: =I16+Jan!L16 -> 1500000 | M16: =J16+Jan!M16 -> 950000 | N16: =L16-M16 -> 550000
B17: 9 | C17: PAMI Equity Index Fund, Inc. | D17: 1.7611372e+10 | E17: 38875099 | F17: =D17-E17 -> 17572497138 | G17: 1.7441594e+10 | H17: 12841 | I17: 2.1841968e+08 | J17: 12600102 | K17: =I17-J17 -> 2.0581958e+08 | L17: =I17+Jan!L17 -> 4.4906088e+08 | M17: =J17+Jan!M17 -> 32941629 | N17: =L17-M17 -> 4.1611925e+08
B18: 10 | C18: Philam Strategic Growth Fund, Inc. | D18: 3.6258664e+10 | E18: 2.3708773e+08 | F18: =D18-E18 -> 36021576552 | G18: 3.3963108e+10 | H18: 12681 | I18: 1.195454e+08 | J18: 2.807745e+08 | K18: =I18-J18 -> -1.612291e+08 | L18: =I18+Jan!L18 -> 2.1023819e+08 | M18: =J18+Jan!M18 -> 3.2454976e+08 | N18: =L18-M18 -> -1.1431157e+08
B19: 11 | C19: Philequity Dividend Yield Fund, Inc. | D19: 2.5453655e+09 | E19: 10292568 | F19: =D19-E19 -> 2535072969 | G19: 2.3363814e+09 | H19: 5127 | I19: 42284892 | J19: 13422890 | K19: =I19-J19 -> 28862002 | L19: =I19+Jan!L19 -> 56982138 | M19: =J19+Jan!M19 -> 74369343 | N19: =L19-M19 -> -17387205
B20: 12 | C20: Philequity Fund, Inc. | D20: 1.1071211e+10 | E20: 80060697 | F20: =D20-E20 -> 10991150660 | G20: 1.0167479e+10 | H20: 37169 | I20: 19886753 | J20: 52198284 | K20: =I20-J20 -> -32311531 | L20: =I20+Jan!L20 -> 56918857 | M20: =J20+Jan!M20 -> 87165476 | N20: =L20-M20 -> -30246618
... B27: 19 | C27: United Fund, Inc. | D27: 6.6871624e+08 | E27: 5676745.1 | F27: =D27-E27 -> 6.6303949e+08 | G27: 5.9165654e+08 | H27: 1303 | I27: 7901800.6 | J27: 307375.51 | K27: =I27-J27 -> 7594425.1 | L27: =I27+Jan!L27 -> 8877864.4 | M27: =J27+Jan!M27 -> 785120.05 | N27: =L27-M27 -> 8092744.3
A28: Primarily invested in Peso Securities (units)
B29: 20 | C29: Philequity Alpha One Fund, Inc. | D29: 3.6784988e+08 | E29: 6639840.3 | F29: =D29-E29 -> 3.6121004e+08 | G29: 3.1323153e+08 | H29: 1189 | I29: 18892860 | J29: 3320308.6 | K29: =I29-J29 -> 15572552 | L29: =I29+Jan!L29 -> 27131987 | M29: =J29+Jan!M29 -> 8000241.3 | N29: =L29-M29 -> 19131745
B30: 21 | C30: Philippine Stock Index Fund Corp. | D30: 2.0859375e+08 | E30: 17685844 | F30: =D30-E30 -> 1.9090791e+08 | G30: 190309510 | H30: 223356.55 | I30: 54985282 | J30: 8160245.7 | K30: =I30-J30 -> 46825036 | L30: =I30+Jan!L30 -> 2.1588173e+08 | M30: =J30+Jan!M30 -> 21499797 | N30: =L30-M30 -> 1.9438194e+08
A31: Exchange Traded Fund
B32: 22 | C32: First Metro Phil. Equity Exchange Traded Fund, Inc. | D32: 2.2703183e+09 | E32: 4918758.2 | F32: =D32-E32 -> 2265399587 | G32: 2.2435504e+09 | H32: 3087 | I32: 13570706 | J32: 0 | K32: =I32-J32 -> 13570706 | L32: =I32+Jan!L32 -> 24451462 | M32: =J32+Jan!M32 -> 3331959 | N32: =L32-M32 -> 21119503
A33: Sub total - Peso Currency | D33: =SUM(D9:D32) -> 122538486394 | E33: =SUM(E9:E32) -> 873652877 | F33: =SUM(F9:F32) -> 121664833517 | G33: =SUM(G9:G32) -> 116728959129 | H33: =SUM(H9:H32) -> 503500.55 | I33: =SUM(I9:I32) -> 1333415858 | J33: =SUM(J9:J32) -> 1240231063 | K33: =SUM(K9:K32) -> 93184795 | ... N33: =SUM(N9:N32) -> 2.2151705e+08
A34: Primarily invested in foreign currency securities (shares)
B35: 23 | C35: ATRAM AsiaPlus Equity Fund, Inc. (formerly, ATR KimEng AsiaPlus Recovery Fund, Inc.) | D35: 48507171 | E35: 870845.56 | F35: =D35-E35 -> 47636326 | G35: 0 | H35: 57 | I35: 66487.45 | J35: 0 | K35: =I35-J35 -> 66487.45 | L35: =I35+Jan!L35 -> 66587.22 | M35: =J35+Jan!M35 -> 3932.8 | N35: =L35-M35 -> 62654.42
B36: 24 | C36: Sun Life Prosperity World Voyager Fund, Inc. | D36: =51.27*38407946.19 -> 1969175401 | E36: =51.27*456910.44 -> 23425798 | F36: =D36-E36 -> 1945749603 | G36: 0 | H36: 2737 | I36: =51.27*1708172.56 -> 87578007 | J36: =51.27*827089.28 -> 42404867 | K36: =I36-J36 -> 45173140 | L36: =I36+Jan!L36 -> 1.1393493e+08 | M36: =J36+Jan!M36 -> 1.4513327e+08 | N36: =L36-M36 -> -31198338
A37: Sub total - US Currency | D37: =SUM(D35:D36) -> 2017682573 | E37: =SUM(E35:E36) -> 24296644 | F37: =SUM(F35:F36) -> 1993385929 | G37: =SUM(G35:G36) -> 0 | H37: =SUM(H35:H36) -> 2794 | I37: =SUM(I35:I36) -> 87644495 | J37: =SUM(J35:J36) -> 42404867 | K37: =SUM(K35:K36) -> 45239627 | ... N37: =SUM(N35:N36) -> -31135683
A38: Sub total - stock funds | D38: =D33+D37 -> 124556168967 | E38: =E33+E37 -> 8.9794952e+08 | F38: =F33+F37 -> 123658219446 | G38: =G33+G37 -> 116728959129 | H38: =H33+H37 -> 506294.55 | I38: =I33+I37 -> 1421060353 | J38: =J33+J37 -> 1282635931 | K38: =K33+K37 -> 1.3842442e+08 | ... N38: =N33+N37 -> 1.9038137e+08
A39: Balanced Funds
A40: Primarily invested in Peso Securities (shares)
B41: 25 | C41: ATRAM Dynamic Allocation Fund, Inc. (formerly, Optima Balanced Fund, Inc.) | D41: 1.3571173e+08 | E41: 7767502.2 | F41: =D41-E41 -> 1.2794423e+08 | G41: 44100274 | H41: 737 | I41: 640001.5 | J41: 408396.7 | K41: =I41-J41 -> 231604.8 | L41: =I41+Jan!L41 -> 4920454.8 | M41: =J41+Jan!M41 -> 1059930.9 | N41: =L41-M41 -> 3860523.9
B42: 26 | C42: ATRAM Philippine Balanced Fund, Inc. (formerly, ATRKE Philippine Balanced Fund, Inc.) | D42: 766179756 | E42: 77996203 | F42: =D42-E42 -> 6.8818355e+08 | G42: 3.6708896e+08 | H42: 2496 | I42: 2834082 | J42: 6744427.5 | K42: =I42-J42 -> -3910345.5 | L42: =I42+Jan!L42 -> 4295247.2 | M42: =J42+Jan!M42 -> 11884220 | N42: =L42-M42 -> -7588973.2
B43: 27 | C43: First Metro Save and Learn Balanced Fund, Inc. | D43: 1.2214972e+09 | E43: 15082503 | F43: =D43-E43 -> 1206414713 | G43: 7.5770798e+08 | H43: 4915 | I43: 2980749.5 | J43: 1.1344169e+08 | K43: =I43-J43 -> -1.1046094e+08 | L43: =I43+Jan!L43 -> 5310109.2 | M43: =J43+Jan!M43 -> 1.1622831e+08 | N43: =L43-M43 -> -1.109182e+08
B44: 28 | C44: First Metro Save and Learn F.O.C.C.U.S. Dynamic Fund, Inc. | D44: 2.0210034e+08 | E44: 2656225.7 | F44: =D44-E44 -> 1.9944412e+08 | G44: 1.5564739e+08 | H44: 117 | I44: 72806828 | J44: 9966.8754 | K44: =I44-J44 -> 72796861 | L44: =I44+Jan!L44 -> 1.710677e+08 | M44: =J44+Jan!M44 -> 9966.8754 | N44: =L44-M44 -> 1.7105773e+08
B45: 29 | C45: NCM Mutual Fund of the Phils., Inc. | D45: 3.6011492e+08 | E45: 1580349.6 | F45: =D45-E45 -> 3.5853457e+08 | G45: 1.7487343e+08 | H45: 57 | I45: 0 | J45: 1017100 | K45: =I45-J45 -> -1017100 | L45: =I45+Jan!L45 -> 0 | M45: =J45+Jan!M45 -> 1017100 | N45: =L45-M45 -> -1017100
B46: 30 | C46: PAMI Horizon Fund, Inc. | D46: 6.6010759e+08 | E46: 27068236 | F46: =D46-E46 -> 6.3303935e+08 | G46: 3.6444768e+08 | H46: 10272 | I46: 857580.44 | J46: 6899852.4 | K46: =I46-J46 -> -6042272 | L46: =I46+Jan!L46 -> 1110746.5 | M46: =J46+Jan!M46 -> 15285953 | N46: =L46-M46 -> -14175206
...

Sheet Mar
A1: PHILIPPINE INVESTMENT FUNDS ASSOCIATION, INC.
A2: MUTUAL FUNDS STATISTICAL REPORT
A3: Month of March 2022
A4: (Amounts in Peso)
I5: F O R - T H E - M O N T H | L5: Y E A R - T O - D A T E
A6: Fund Category | C6: Fund Name | D6: ASSETS | E6: LIABILITIES | F6: NET ASSETS | G6: EQUITY INV. | H6: NO. OF A/C | I6: SALES | J6: REDEMPTIONS | K6: NET SALES | L6: TOTAL SALES | M6: TOTAL REDEMPTIONS | N6: TOTAL NET SALES
A7: Stock Funds
A8: Primarily invested in Peso Securities (shares)
B9: 1 | C9: ALFM Growth Fund, Inc. | D9: 5.4255175e+09 | E9: 28682990 | F9: =D9-E9 -> 5396834531 | G9: 5102527402 | H9: 7552 | I9: 20452327 | J9: 46191957 | K9: =I9-J9 -> -25739631 | L9: =I9+Feb!L9 -> 53631481 | M9: =J9+Feb!M9 -> 1.5022647e+08 | N9: =L9-M9 -> -96594994
B10: 2 | C10: ATRAM Alpha Opportunity Fund, Inc. (formerly, ATRKE Alpha Opportunity Fund, Inc.) | D10: 8.3970022e+08 | E10: 2668826.9 | F10: =D10-E10 -> 837031397 | G10: 7.6814084e+08 | H10: 4365 | I10: 20098937 | J10: 15697829 | K10: =I10-J10 -> 4401107.6 | L10: =I10+Feb!L10 -> 1.4536253e+08 | M10: =J10+Feb!M10 -> 73969996 | N10: =L10-M10 -> 71392537
B11: 3 | C11: ATRAM Phil. Equity Opportunity Fund, Inc. (formerly, ATRKE Equity Opportunity Fund, Inc.) | D11: 1.1818333e+09 | E11: 4636608 | F11: =D11-E11 -> 1177196657 | G11: 1.1173972e+09 | H11: 2926 | I11: 13437584 | J11: 7523678.8 | K11: =I11-J11 -> 5913904.8 | L11: =I11+Feb!L11 -> 46548608 | M11: =J11+Feb!M11 -> 33399078 | N11: =L11-M11 -> 13149530
B12: 4 | C12: Climbs Share Capital Equity Investment Fund Corp. | D12: 3.5764422e+08 | E12: 6277681.5 | F12: =D12-E12 -> 3.5136654e+08 | G12: 1.3690588e+08 | H12: 1637 | I12: 2392431.6 | J12: 828815.08 | K12: =I12-J12 -> 1563616.6 | L12: =I12+Feb!L12 -> 5066693.8 | M12: =J12+Feb!M12 -> 6287503.3 | N12: =L12-M12 -> -1220809.5
B13: 5 | C13: First Metro Consumer Fund on MSCI Phils. IMI, Inc. | D13: 5.4189985e+08 | E13: 2088591.7 | F13: =D13-E13 -> 5.3981126e+08 | G13: 3.2308374e+08 | H13: 1516 | I13: 3394080.8 | J13: 1336116.5 | K13: =I13-J13 -> 2057964.3 | L13: =I13+Feb!L13 -> 17965487 | M13: =J13+Feb!M13 -> 10094392 | N13: =L13-M13 -> 7871094.3
B14: 6 | C14: First Metro Save and Learn Equity Fund, Inc. | D14: 4.5297684e+09 | E14: 90400916 | F14: =D14-E14 -> 4439367518 | G14: 4.16045e+09 | H14: 16549 | I14: 1.589971e+08 | J14: 26955818 | K14: =I14-J14 -> 1.3204129e+08 | L14: =I14+Feb!L14 -> 2.4383403e+08 | M14: =J14+Feb!M14 -> 2.4801479e+08 | N14: =L14-M14 -> -4180760.9
B15: 7 | C15: First Metro Save and Learn Phil. Index Fund, Inc. (formerly, One Wealthy Nation Fund, Inc.) | D15: 95537171 | E15: 673071.94 | F15: =D15-E15 -> 94864099 | G15: 92658060 | H15: 528 | I15: 2452560.8 | J15: 1045150.3 | K15: =I15-J15 -> 1407410.5 | L15: =I15+Feb!L15 -> 5892190.2 | M15: =J15+Feb!M15 -> 4137960.4 | N15: =L15-M15 -> 1754229.8
B16: 8 | C16: MBG Equity Investment Fund, Inc. | D16: 1.4503946e+08 | E16: 1321641.8 | F16: =D16-E16 -> 1.4371782e+08 | G16: 1.3588403e+08 | H16: 51 | I16: 100000 | J16: 0 | K16: =I16-J16 -> 100000 | L16: =I16+Feb!L16 -> 1600000 | M16: =J16+Feb!M16 -> 950000 | N16: =L16-M16 -> 650000
B17: 9 | C17: PAMI Equity Index Fund, Inc. | D17: 1.7734575e+10 | E17: 1.1436651e+08 | F17: =D17-E17 -> 17620208196 | G17: 1.7409542e+10 | H17: 12653 | I17: 2.0349806e+08 | J17: 19417689 | K17: =I17-J17 -> 1.8408037e+08 | L17: =I17+Feb!L17 -> 6.5255894e+08 | M17: =J17+Feb!M17 -> 52359318 | N17: =L17-M17 -> 6.0019962e+08
B18: 10 | C18: Philam Strategic Growth Fund, Inc. | D18: 3.6072818e+10 | E18: 2.3966711e+08 | F18: =D18-E18 -> 35833150750 | G18: 3.3811235e+10 | H18: 12509 | I18: 1.0984326e+08 | J18: 49551411 | K18: =I18-J18 -> 60291849 | L18: =I18+Feb!L18 -> 3.2008145e+08 | M18: =J18+Feb!M18 -> 3.7410117e+08 | N18: =L18-M18 -> -54019718
B19: 11 | C19: Philequity Dividend Yield Fund, Inc. | D19: 2.4315306e+09 | E19: 8614573.5 | F19: =D19-E19 -> 2422915983 | G19: 2.2154061e+09 | H19: 5440 | I19: 7939366 | J19: 1.3200375e+08 | K19: =I19-J19 -> -1.2406438e+08 | L19: =I19+Feb!L19 -> 64921504 | M19: =J19+Feb!M19 -> 2.0637309e+08 | N19: =L19-M19 -> -1.4145159e+08
B20: 12 | C20: Philequity Fund, Inc. | D20: 1.0987251e+10 | E20: 55251287 | F20: =D20-E20 -> 10932000014 | G20: 1.0234858e+10 | H20: 37125 | I20: 43254081 | J20: 97810271 | K20: =I20-J20 -> -54556190 | L20: =I20+Feb!L20 -> 100172938 | M20: =J20+Feb!M20 -> 1.8497575e+08 | N20: =L20-M20 -> -84802809
... B27: 19 | C27: United Fund, Inc. | D27: 6.5564841e+08 | E27: 2533259.3 | F27: =D27-E27 -> 6.5311515e+08 | G27: 5.8535425e+08 | H27: 1305 | I27: 856512.45 | J27: 2625310 | K27: =I27-J27 -> -1768797.5 | L27: =I27+Feb!L27 -> 9734376.8 | M27: =J27+Feb!M27 -> 3410430 | N27: =L27-M27 -> 6323946.8
A28: Primarily invested in Peso Securities (units)
B29: 20 | C29: Philequity Alpha One Fund, Inc. | D29: 3.8454509e+08 | E29: 1490616 | F29: =D29-E29 -> 3.8305447e+08 | G29: 3.2953919e+08 | H29: 1381 | I29: 23361793 | J29: 1374530.4 | K29: =I29-J29 -> 21987262 | L29: =I29+Feb!L29 -> 50493779 | M29: =J29+Feb!M29 -> 9374771.7 | N29: =L29-M29 -> 41119008
B30: 21 | C30: Philippine Stock Index Fund Corp. | D30: 2.6831137e+08 | E30: 8129778.2 | F30: =D30-E30 -> 2.6018159e+08 | G30: 257930952 | H30: 262090 | I30: 76075942 | J30: 5716365.5 | K30: =I30-J30 -> 70359576 | L30: =I30+Feb!L30 -> 2.9195767e+08 | M30: =J30+Feb!M30 -> 27216162 | N30: =L30-M30 -> 2.6474151e+08
A31: Exchange Traded Fund
B32: 22 | C32: First Metro Phil. Equity Exchange Traded Fund, Inc. | D32: 2.2667763e+09 | E32: 4989457.7 | F32: =D32-E32 -> 2261786813 | G32: 2.2396655e+09 | H32: 3147 | I32: 12829924 | J32: 1110966 | K32: =I32-J32 -> 11718958 | L32: =I32+Feb!L32 -> 37281386 | M32: =J32+Feb!M32 -> 4442925 | N32: =L32-M32 -> 32838461
A33: Sub total - Peso Currency | D33: =SUM(D9:D32) -> 121832814330 | E33: =SUM(E9:E32) -> 8.6269359e+08 | F33: =SUM(F9:F32) -> 120970120741 | G33: =SUM(G9:G32) -> 115973117152 | H33: =SUM(H9:H32) -> 548400 | I33: =SUM(I9:I32) -> 1182359131 | J33: =SUM(J9:J32) -> 9.8425006e+08 | K33: =SUM(K9:K32) -> 1.9810907e+08 | ... N33: =SUM(N9:N32) -> 4.1962612e+08
A34: Primarily invested in foreign currency securities (shares)
B35: 23 | C35: ATRAM AsiaPlus Equity Fund, Inc. (formerly, ATR KimEng AsiaPlus Recovery Fund, Inc.) | D35: 46768822 | E35: 6166296.6 | F35: =D35-E35 -> 40602526 | G35: 0 | H35: 55 | I35: 265868.06 | J35: 5524304.1 | K35: =I35-J35 -> -5258436.1 | L35: =I35+Feb!L35 -> 332455.28 | M35: =J35+Feb!M35 -> 5528236.9 | N35: =L35-M35 -> -5195781.6
B36: 24 | C36: Sun Life Prosperity World Voyager Fund, Inc. | D36: =51.74*40944318.38 -> 2118459033 | E36: =51.74*166192.94 -> 8598822.7 | F36: =D36-E36 -> 2109860210 | G36: 0 | H36: 2764 | I36: =51.74*1960281.65 -> 1.0142497e+08 | J36: =51.74*543941.09 -> 28143512 | K36: =I36-J36 -> 73281461 | L36: =I36+Feb!L36 -> 2.1535991e+08 | M36: =J36+Feb!M36 -> 1.7327678e+08 | N36: =L36-M36 -> 42083123
A37: Sub total - US Currency | D37: =SUM(D35:D36) -> 2165227855 | E37: =SUM(E35:E36) -> 14765119 | F37: =SUM(F35:F36) -> 2150462736 | G37: =SUM(G35:G36) -> 0 | H37: =SUM(H35:H36) -> 2819 | I37: =SUM(I35:I36) -> 1.0169084e+08 | J37: =SUM(J35:J36) -> 33667816 | K37: =SUM(K35:K36) -> 68023025 | ... N37: =SUM(N35:N36) -> 36887341
A38: Sub total - stock funds | D38: =D33+D37 -> 123998042185 | E38: =E33+E37 -> 8.7745871e+08 | F38: =F33+F37 -> 123120583477 | G38: =G33+G37 -> 115973117152 | H38: =H33+H37 -> 551219 | I38: =I33+I37 -> 1284049972 | J38: =J33+J37 -> 1017917877 | K38: =K33+K37 -> 2.6613209e+08 | ... N38: =N33+N37 -> 4.5651346e+08
A39: Balanced Funds
A40: Primarily invested in Peso Securities (shares)
B41: 25 | C41: ATRAM Dynamic Allocation Fund, Inc. (formerly, Optima Balanced Fund, Inc.) | D41: 1.2696265e+08 | E41: 1383198.2 | F41: =D41-E41 -> 1.2557945e+08 | G41: 26371510 | H41: 732 | I41: 651643.41 | J41: 1441232.7 | K41: =I41-J41 -> -789589.26 | L41: =I41+Feb!L41 -> 5572098.2 | M41: =J41+Feb!M41 -> 2501163.6 | N41: =L41-M41 -> 3070934.6
B42: 26 | C42: ATRAM Philippine Balanced Fund, Inc. (formerly, ATRKE Philippine Balanced Fund, Inc.) | D42: 6.7250306e+08 | E42: 7174557.7 | F42: =D42-E42 -> 6.653285e+08 | G42: 2.8338959e+08 | H42: 2495 | I42: 1747521.9 | J42: 13626132 | K42: =I42-J42 -> -11878610 | L42: =I42+Feb!L42 -> 6042769.1 | M42: =J42+Feb!M42 -> 25510352 | N42: =L42-M42 -> -19467583
B43: 27 | C43: First Metro Save and Learn Balanced Fund, Inc. | D43: 1.2182981e+09 | E43: 19534120 | F43: =D43-E43 -> 1198763973 | G43: 7.6569518e+08 | H43: 4893 | I43: 4957005.9 | J43: 7163798.2 | K43: =I43-J43 -> -2206792.3 | L43: =I43+Feb!L43 -> 10267115 | M43: =J43+Feb!M43 -> 123392105 | N43: =L43-M43 -> -1.1312499e+08
B44: 28 | C44: First Metro Save and Learn F.O.C.C.U.S. Dynamic Fund, Inc. | D44: 2.5287461e+08 | E44: 7299630.1 | F44: =D44-E44 -> 2.4557498e+08 | G44: 1.8250664e+08 | H44: 149 | I44: 59037067 | J44: 11371674 | K44: =I44-J44 -> 47665393 | L44: =I44+Feb!L44 -> 2.3010476e+08 | M44: =J44+Feb!M44 -> 11381641 | N44: =L44-M44 -> 2.1872312e+08
B45: 29 | C45: NCM Mutual Fund of the Phils., Inc. | D45: 3.5850689e+08 | E45: 1627177.6 | F45: =D45-E45 -> 3.5687971e+08 | G45: 1.7236078e+08 | H45: 57 | I45: 0 | J45: 0 | K45: =I45-J45 -> 0 | L45: =I45+Feb!L45 -> 0 | M45: =J45+Feb!M45 -> 1017100 | N45: =L45-M45 -> -1017100
B46: 30 | C46: PAMI Horizon Fund, Inc. | D46: 6.3515457e+08 | E46: 11829793 | F46: =D46-E46 -> 6.2332478e+08 | G46: 361984395 | H46: 10165 | I46: 360586.55 | J46: 6995274.6 | K46: =I46-J46 -> -6634688.1 | L46: =I46+Feb!L46 -> 1471333.1 | M46: =J46+Feb!M46 -> 22281227 | N46: =L46-M46 -> -20809894
...

Sheet Q1
A1: PHILIPPINE INVESTMENT FUNDS ASSOCIATION, INC.
A2: MUTUAL FUNDS STATISTICAL REPORT
A3: As of the First Quarter of 2022
A4: (Amounts in Peso)
A6: Fund Category | C6: Fund Name | D6: NET ASSETS | E6: TOTAL SALES | F6: TOTAL REDEMPTIONS | G6: NET SALES
A7: Stock Funds
A8: Primarily invested in Peso Securities (shares)
B9: 1 | C9: ALFM Growth Fund, Inc. | D9: =Mar!F9 -> 5396834531 | E9: =Jan!I9+Feb!I9+Mar!I9 -> 53631481 | F9: =Jan!J9+Feb!J9+Mar!J9 -> 1.5022647e+08 | G9: =E9-F9 -> -96594994
B10: 2 | C10: ATRAM Alpha Opportunity Fund, Inc. (formerly, ATRKE Alpha Opportunity Fund, Inc.) | D10: =Mar!F10 -> 837031397 | E10: =Jan!I10+Feb!I10+Mar!I10 -> 1.4536253e+08 | F10: =Jan!J10+Feb!J10+Mar!J10 -> 73969996 | G10: =E10-F10 -> 71392537
B11: 3 | C11: ATRAM Phil. Equity Opportunity Fund, Inc. (formerly, ATRKE Equity Opportunity Fund, Inc.) | D11: =Mar!F11 -> 1177196657 | E11: =Jan!I11+Feb!I11+Mar!I11 -> 46548608 | F11: =Jan!J11+Feb!J11+Mar!J11 -> 33399078 | G11: =E11-F11 -> 13149530
B12: 4 | C12: Climbs Share Capital Equity Investment Fund Corp. | D12: =Mar!F12 -> 3.5136654e+08 | E12: =Jan!I12+Feb!I12+Mar!I12 -> 5066693.8 | F12: =Jan!J12+Feb!J12+Mar!J12 -> 6287503.3 | G12: =E12-F12 -> -1220809.5
B13: 5 | C13: First Metro Consumer Fund on MSCI Phils. IMI, Inc. | D13: =Mar!F13 -> 5.3981126e+08 | E13: =Jan!I13+Feb!I13+Mar!I13 -> 17965487 | F13: =Jan!J13+Feb!J13+Mar!J13 -> 10094392 | G13: =E13-F13 -> 7871094.3
B14: 6 | C14: First Metro Save and Learn Equity Fund, Inc. | D14: =Mar!F14 -> 4439367518 | E14: =Jan!I14+Feb!I14+Mar!I14 -> 2.4383403e+08 | F14: =Jan!J14+Feb!J14+Mar!J14 -> 2.4801479e+08 | G14: =E14-F14 -> -4180760.9
B15: 7 | C15: First Metro Save and Learn Phil. Index Fund, Inc. (formerly, One Wealthy Nation Fund, Inc.) | D15: =Mar!F15 -> 94864099 | E15: =Jan!I15+Feb!I15+Mar!I15 -> 5892190.2 | F15: =Jan!J15+Feb!J15+Mar!J15 -> 4137960.4 | G15: =E15-F15 -> 1754229.8
B16: 8 | C16: MBG Equity Investment Fund, Inc. | D16: =Mar!F16 -> 1.4371782e+08 | E16: =Jan!I16+Feb!I16+Mar!I16 -> 1600000 | F16: =Jan!J16+Feb!J16+Mar!J16 -> 950000 | G16: =E16-F16 -> 650000
B17: 9 | C17: PAMI Equity Index Fund, Inc. | D17: =Mar!F17 -> 17620208196 | E17: =Jan!I17+Feb!I17+Mar!I17 -> 6.5255894e+08 | F17: =Jan!J17+Feb!J17+Mar!J17 -> 52359318 | G17: =E17-F17 -> 6.0019962e+08
B18: 10 | C18: Philam Strategic Growth Fund, Inc. | D18: =Mar!F18 -> 35833150750 | E18: =Jan!I18+Feb!I18+Mar!I18 -> 3.2008145e+08 | F18: =Jan!J18+Feb!J18+Mar!J18 -> 3.7410117e+08 | G18: =E18-F18 -> -54019718
B19: 11 | C19: Philequity Dividend Yield Fund, Inc. | D19: =Mar!F19 -> 2422915983 | E19: =Jan!I19+Feb!I19+Mar!I19 -> 64921504 | F19: =Jan!J19+Feb!J19+Mar!J19 -> 2.0637309e+08 | G19: =E19-F19 -> -1.4145159e+08
B20: 12 | C20: Philequity Fund, Inc. | D20: =Mar!F20 -> 10932000014 | E20: =Jan!I20+Feb!I20+Mar!I20 -> 100172938 | F20: =Jan!J20+Feb!J20+Mar!J20 -> 1.8497575e+08 | G20: =E20-F20 -> -84802809
... B27: 19 | C27: United Fund, Inc. | D27: =Mar!F27 -> 6.5311515e+08 | E27: =Jan!I27+Feb!I27+Mar!I27 -> 9734376.8 | F27: =Jan!J27+Feb!J27+Mar!J27 -> 3410430 | G27: =E27-F27 -> 6323946.8
A28: Primarily invested in Peso Securities (units)
B29: 20 | C29: Philequity Alpha One Fund, Inc. | D29: =Mar!F29 -> 3.8305447e+08 | E29: =Jan!I29+Feb!I29+Mar!I29 -> 50493779 | F29: =Jan!J29+Feb!J29+Mar!J29 -> 9374771.7 | G29: =E29-F29 -> 41119008
B30: 21 | C30: Philippine Stock Index Fund Corp. | D30: =Mar!F30 -> 2.6018159e+08 | E30: =Jan!I30+Feb!I30+Mar!I30 -> 2.9195767e+08 | F30: =Jan!J30+Feb!J30+Mar!J30 -> 27216162 | G30: =E30-F30 -> 2.6474151e+08
A31: Exchange Traded Fund
B32: 22 | C32: First Metro Phil. Equity Exchange Traded Fund, Inc. | D32: =Mar!F32 -> 2261786813 | E32: =Jan!I32+Feb!I32+Mar!I32 -> 37281386 | F32: =Jan!J32+Feb!J32+Mar!J32 -> 4442925 | G32: =E32-F32 -> 32838461
A33: Sub total - Peso Currency | D33: =SUM(D9:D32) -> 120970120741 | E33: =SUM(E9:E32) -> 3463843595 | F33: =SUM(F9:F32) -> 3044217476 | G33: =SUM(G9:G32) -> 4.1962612e+08
A34: Primarily invested in foreign currency securities (shares)
B35: 23 | C35: ATRAM AsiaPlus Equity Fund, Inc. (formerly, ATR KimEng AsiaPlus Recovery Fund, Inc.) | D35: =Mar!F35 -> 40602526 | E35: =Jan!I35+Feb!I35+Mar!I35 -> 332455.28 | F35: =Jan!J35+Feb!J35+Mar!J35 -> 5528236.9 | G35: =E35-F35 -> -5195781.6
B36: 24 | C36: Sun Life Prosperity World Voyager Fund, Inc. | D36: =Mar!F36 -> 2109860210 | E36: =Jan!I36+Feb!I36+Mar!I36 -> 2.1535991e+08 | F36: =Jan!J36+Feb!J36+Mar!J36 -> 1.7327678e+08 | G36: =E36-F36 -> 42083123
A37: Sub total - US Currency | D37: =SUM(D35:D36) -> 2150462736 | E37: =SUM(E35:E36) -> 2.1569236e+08 | F37: =SUM(F35:F36) -> 1.7880502e+08 | G37: =SUM(G35:G36) -> 36887341
A38: Sub total - stock funds | D38: =D33+D37 -> 123120583477 | E38: =E33+E37 -> 3679535958 | F38: =F33+F37 -> 3223022498 | G38: =G33+G37 -> 4.5651346e+08
A39: Balanced Funds
A40: Primarily invested in Peso Securities (shares)
B41: 25 | C41: ATRAM Dynamic Allocation Fund, Inc. (formerly, Optima Balanced Fund, Inc.) | D41: =Mar!F41 -> 1.2557945e+08 | E41: =Jan!I41+Feb!I41+Mar!I41 -> 5572098.2 | F41: =Jan!J41+Feb!J41+Mar!J41 -> 2501163.6 | G41: =E41-F41 -> 3070934.6
B42: 26 | C42: ATRAM Philippine Balanced Fund, Inc. (formerly, ATRKE Philippine Balanced Fund, Inc.) | D42: =Mar!F42 -> 6.653285e+08 | E42: =Jan!I42+Feb!I42+Mar!I42 -> 6042769.1 | F42: =Jan!J42+Feb!J42+Mar!J42 -> 25510352 | G42: =E42-F42 -> -19467583
B43: 27 | C43: First Metro Save and Learn Balanced Fund, Inc. | D43: =Mar!F43 -> 1198763973 | E43: =Jan!I43+Feb!I43+Mar!I43 -> 10267115 | F43: =Jan!J43+Feb!J43+Mar!J43 -> 123392105 | G43: =E43-F43 -> -1.1312499e+08
B44: 28 | C44: First Metro Save and Learn F.O.C.C.U.S. Dynamic Fund, Inc. | D44: =Mar!F44 -> 2.4557498e+08 | E44: =Jan!I44+Feb!I44+Mar!I44 -> 2.3010476e+08 | F44: =Jan!J44+Feb!J44+Mar!J44 -> 11381641 | G44: =E44-F44 -> 2.1872312e+08
B45: 29 | C45: NCM Mutual Fund of the Phils., Inc. | D45: =Mar!F45 -> 3.5687971e+08 | E45: =Jan!I45+Feb!I45+Mar!I45 -> 0 | F45: =Jan!J45+Feb!J45+Mar!J45 -> 1017100 | G45: =E45-F45 -> -1017100
B46: 30 | C46: PAMI Horizon Fund, Inc. | D46: =Mar!F46 -> 6.2332478e+08 | E46: =Jan!I46+Feb!I46+Mar!I46 -> 1471333.1 | F46: =Jan!J46+Feb!J46+Mar!J46 -> 22281227 | G46: =E46-F46 -> -20809894
B47: 31 | C47: Philam Fund, Inc. | D47: =Mar!F47 -> 11255547324 | E47: =Jan!I47+Feb!I47+Mar!I47 -> 98735442 | F47: =Jan!J47+Feb!J47+Mar!J47 -> 53922592 | G47: =E47-F47 -> 44812850
...

Sheet Apr
A1: PHILIPPINE INVESTMENT FUNDS ASSOCIATION, INC.
A2: MUTUAL FUNDS STATISTICAL REPORT
A3: Month of April 2022
A4: (Amounts in Peso)
I5: F O R - T H E - M O N T H | L5: Y E A R - T O - D A T E
A6: Fund Category | C6: Fund Name | D6: ASSETS | E6: LIABILITIES | F6: NET ASSETS | G6: EQUITY INV. | H6: NO. OF A/C | I6: SALES | J6: REDEMPTIONS | K6: NET SALES | L6: TOTAL SALES | M6: TOTAL REDEMPTIONS | N6: TOTAL NET SALES
A7: Stock Funds
A8: Primarily invested in Peso Securities (shares)
B9: 1 | C9: ALFM Growth Fund, Inc. | D9: 5.0665058e+09 | E9: 48029314 | F9: =D9-E9 -> 5018476476 | G9: 4538049056 | H9: 7521 | I9: 12419129 | J9: 35604983 | K9: =I9-J9 -> -23185854 | L9: =I9+Mar!L9 -> 66050609 | M9: =J9+Mar!M9 -> 1.8583146e+08 | N9: =L9-M9 -> -1.1978085e+08
B10: 2 | C10: ATRAM Alpha Opportunity Fund, Inc. (formerly, ATRKE Alpha Opportunity Fund, Inc.) | D10: 7.9023011e+08 | E10: 3471619.1 | F10: =D10-E10 -> 7.8675849e+08 | G10: 7.1142735e+08 | H10: 4302 | I10: 18285444 | J10: 30400784 | K10: =I10-J10 -> -12115341 | L10: =I10+Mar!L10 -> 1.6364798e+08 | M10: =J10+Mar!M10 -> 104370780 | N10: =L10-M10 -> 59277196
B11: 3 | C11: ATRAM Phil. Equity Opportunity Fund, Inc. (formerly, ATRKE Equity Opportunity Fund, Inc.) | D11: 1.0514034e+09 | E11: 2896197.8 | F11: =D11-E11 -> 1048507204 | G11: 9.9227865e+08 | H11: 2790 | I11: 9371667.6 | J11: 62776067 | K11: =I11-J11 -> -53404400 | L11: =I11+Mar!L11 -> 55920276 | M11: =J11+Mar!M11 -> 96175146 | N11: =L11-M11 -> -40254870
B12: 4 | C12: Climbs Share Capital Equity Investment Fund Corp. | D12: 3.5728097e+08 | E12: 10503458 | F12: =D12-E12 -> 3.4677751e+08 | G12: 1.61718e+08 | H12: 1647 | I12: 5929188.2 | J12: 327919.81 | K12: =I12-J12 -> 5601268.4 | L12: =I12+Mar!L12 -> 10995882 | M12: =J12+Mar!M12 -> 6615423.2 | N12: =L12-M12 -> 4380458.9
B13: 5 | C13: First Metro Consumer Fund on MSCI Phils. IMI, Inc. | D13: 5.421278e+08 | E13: 13646273 | F13: =D13-E13 -> 5.2848153e+08 | G13: 285219813 | H13: 1509 | I13: 2466414.5 | J13: 657838.7 | K13: =I13-J13 -> 1808575.8 | L13: =I13+Mar!L13 -> 20431901 | M13: =J13+Mar!M13 -> 10752231 | N13: =L13-M13 -> 9679670.1
B14: 6 | C14: First Metro Save and Learn Equity Fund, Inc. | D14: 4.3204525e+09 | E14: 1.140337e+08 | F14: =D14-E14 -> 4206418803 | G14: 3.6076096e+09 | H14: 16521 | I14: 68128268 | J14: 38996181 | K14: =I14-J14 -> 29132086 | L14: =I14+Mar!L14 -> 3.119623e+08 | M14: =J14+Mar!M14 -> 2.8701097e+08 | N14: =L14-M14 -> 24951326
B15: 7 | C15: First Metro Save and Learn Phil. Index Fund, Inc. (formerly, One Wealthy Nation Fund, Inc.) | D15: 92403107 | E15: 2330194.4 | F15: =D15-E15 -> 90072912 | G15: 88213491 | H15: 533 | I15: 1995715.7 | J15: 475006.28 | K15: =I15-J15 -> 1520709.4 | L15: =I15+Mar!L15 -> 7887905.8 | M15: =J15+Mar!M15 -> 4612966.7 | N15: =L15-M15 -> 3274939.2
B16: 8 | C16: MBG Equity Investment Fund, Inc. | D16: 1.3908794e+08 | E16: 1368397.5 | F16: =D16-E16 -> 137719545 | G16: 1.2918488e+08 | H16: 51 | I16: 0 | J16: 0 | K16: =I16-J16 -> 0 | L16: =I16+Mar!L16 -> 1600000 | M16: =J16+Mar!M16 -> 950000 | N16: =L16-M16 -> 650000
B17: 9 | C17: PAMI Equity Index Fund, Inc. | D17: 1.6712619e+10 | E17: 1.053246e+08 | F17: =D17-E17 -> 16607294092 | G17: 1.6500662e+10 | H17: 12720 | I17: 1.6300182e+08 | J17: 6331981.9 | K17: =I17-J17 -> 1.5666984e+08 | L17: =I17+Mar!L17 -> 8.1556076e+08 | M17: =J17+Mar!M17 -> 58691300 | N17: =L17-M17 -> 7.5686946e+08
B18: 10 | C18: Philam Strategic Growth Fund, Inc. | D18: 3.3686368e+10 | E18: 2.1088593e+08 | F18: =D18-E18 -> 33475482285 | G18: 3.0849602e+10 | H18: 12574 | I18: 80647561 | J18: 55872262 | K18: =I18-J18 -> 24775299 | L18: =I18+Mar!L18 -> 4.0072901e+08 | M18: =J18+Mar!M18 -> 4.2997343e+08 | N18: =L18-M18 -> -29244419
B19: 11 | C19: Philequity Dividend Yield Fund, Inc. | D19: 2.3330496e+09 | E19: 36031659 | F19: =D19-E19 -> 2297017959 | G19: 2.0670896e+09 | H19: 5674 | I19: 9033937.2 | J19: 23684862 | K19: =I19-J19 -> -14650925 | L19: =I19+Mar!L19 -> 73955442 | M19: =J19+Mar!M19 -> 2.3005795e+08 | N19: =L19-M19 -> -1.5610251e+08
B20: 12 | C20: Philequity Fund, Inc. | D20: 1.0232577e+10 | E20: 36345336 | F20: =D20-E20 -> 10196231269 | G20: 9.5202036e+09 | H20: 37059 | I20: 16398998 | J20: 58978880 | K20: =I20-J20 -> -42579882 | L20: =I20+Mar!L20 -> 1.1657194e+08 | M20: =J20+Mar!M20 -> 2.4395463e+08 | N20: =L20-M20 -> -1.2738269e+08
... B27: 19 | C27: United Fund, Inc. | D27: 6.1629966e+08 | E27: 1827281 | F27: =D27-E27 -> 6.1447238e+08 | G27: 5.5029376e+08 | H27: 1307 | I27: 831472.44 | J27: 321301.97 | K27: =I27-J27 -> 510170.47 | L27: =I27+Mar!L27 -> 10565849 | M27: =J27+Mar!M27 -> 3731732 | N27: =L27-M27 -> 6834117.3
A28: Primarily invested in Peso Securities (units)
B29: 20 | C29: Philequity Alpha One Fund, Inc. | D29: 3.7018298e+08 | E29: 786131.53 | F29: =D29-E29 -> 3.6939684e+08 | G29: 3.1405409e+08 | H29: 1475 | I29: 6278896.7 | J29: 512339.96 | K29: =I29-J29 -> 5766556.7 | L29: =I29+Mar!L29 -> 56772676 | M29: =J29+Mar!M29 -> 9887111.7 | N29: =L29-M29 -> 46885564
B30: 21 | C30: Philippine Stock Index Fund Corp. | D30: 2.8775254e+08 | E30: 1290731.9 | F30: =D30-E30 -> 2.8646181e+08 | G30: 281220153 | H30: 269922 | I30: 51346167 | J30: 6338777.3 | K30: =I30-J30 -> 45007390 | L30: =I30+Mar!L30 -> 343303841 | M30: =J30+Mar!M30 -> 33554940 | N30: =L30-M30 -> 3.097489e+08
A31: Exchange Traded Fund
B32: 22 | C32: First Metro Phil. Equity Exchange Traded Fund, Inc. | D32: 2.139491e+09 | E32: 6323546.1 | F32: =D32-E32 -> 2133167442 | G32: 2.1094449e+09 | H32: 3162 | I32: 19322915 | J32: 0 | K32: =I32-J32 -> 19322915 | L32: =I32+Mar!L32 -> 56604301 | M32: =J32+Mar!M32 -> 4442925 | N32: =L32-M32 -> 52161376
A33: Sub total - Peso Currency | D33: =SUM(D9:D32) -> 114191281501 | E33: =SUM(E9:E32) -> 9.3974639e+08 | F33: =SUM(F9:F32) -> 113251535113 | G33: =SUM(G9:G32) -> 107371982344 | H33: =SUM(H9:H32) -> 556666 | I33: =SUM(I9:I32) -> 1012469250 | J33: =SUM(J9:J32) -> 8.5423638e+08 | K33: =SUM(K9:K32) -> 158232870 | ... N33: =SUM(N9:N32) -> 5.7785899e+08
A34: Primarily invested in foreign currency securities (shares)
B35: 23 | C35: ATRAM AsiaPlus Equity Fund, Inc. (formerly, ATR KimEng AsiaPlus Recovery Fund, Inc.) | D35: 39840171 | E35: 940783.16 | F35: =D35-E35 -> 38899388 | G35: 0 | H35: 56 | I35: 234923.86 | J35: 0 | K35: =I35-J35 -> 234923.86 | L35: =I35+Mar!L35 -> 567379.14 | M35: =J35+Mar!M35 -> 5528236.9 | N35: =L35-M35 -> -4960857.8
B36: 24 | C36: Sun Life Prosperity World Voyager Fund, Inc. | D36: =52.19*37783866.49 -> 1971939992 | E36: =52.19*319576.01 -> 16678672 | F36: =D36-E36 -> 1955261320 | G36: 0 | H36: 2776 | I36: =52.19*292433.69 -> 15262114 | J36: =52.19*329735.99 -> 17208921 | K36: =I36-J36 -> -1946807 | L36: =I36+Mar!L36 -> 2.3062202e+08 | M36: =J36+Mar!M36 -> 1.9048571e+08 | N36: =L36-M36 -> 40136316
A37: Sub total - US Currency | D37: =SUM(D35:D36) -> 2011780163 | E37: =SUM(E35:E36) -> 17619455 | F37: =SUM(F35:F36) -> 1994160708 | G37: =SUM(G35:G36) -> 0 | H37: =SUM(H35:H36) -> 2832 | I37: =SUM(I35:I36) -> 15497038 | J37: =SUM(J35:J36) -> 17208921 | K37: =SUM(K35:K36) -> -1711883.2 | ... N37: =SUM(N35:N36) -> 35175458
A38: Sub total - stock funds | D38: =D33+D37 -> 116203061664 | E38: =E33+E37 -> 9.5736584e+08 | F38: =F33+F37 -> 115245695821 | G38: =G33+G37 -> 107371982344 | H38: =H33+H37 -> 559498 | I38: =I33+I37 -> 1027966288 | J38: =J33+J37 -> 8.714453e+08 | K38: =K33+K37 -> 1.5652099e+08 | ... N38: =N33+N37 -> 6.1303445e+08
A39: Balanced Funds
A40: Primarily invested in Peso Securities (shares)
B41: 25 | C41: ATRAM Dynamic Allocation Fund, Inc. (formerly, Optima Balanced Fund, Inc.) | D41: 1.0349471e+08 | E41: 819797.76 | F41: =D41-E41 -> 1.0267491e+08 | G41: 24025361 | H41: 735 | I41: 2418966.7 | J41: 378590.13 | K41: =I41-J41 -> 2040376.5 | L41: =I41+Mar!L41 -> 7991064.9 | M41: =J41+Mar!M41 -> 2879753.7 | N41: =L41-M41 -> 5111311.2
B42: 26 | C42: ATRAM Philippine Balanced Fund, Inc. (formerly, ATRKE Philippine Balanced Fund, Inc.) | D42: 6.4902713e+08 | E42: 4804901.5 | F42: =D42-E42 -> 6.4422223e+08 | G42: 2.3800128e+08 | H42: 2488 | I42: 958800.7 | J42: 2889665.5 | K42: =I42-J42 -> -1930864.8 | L42: =I42+Mar!L42 -> 7001569.8 | M42: =J42+Mar!M42 -> 28400018 | N42: =L42-M42 -> -21398448
B43: 27 | C43: First Metro Save and Learn Balanced Fund, Inc. | D43: 1.1449038e+09 | E43: 23394482 | F43: =D43-E43 -> 1121509363 | G43: 5.6427714e+08 | H43: 4866 | I43: 2862232.2 | J43: 34256866 | K43: =I43-J43 -> -31394634 | L43: =I43+Mar!L43 -> 13129347 | M43: =J43+Mar!M43 -> 1.5764897e+08 | N43: =L43-M43 -> -1.4451962e+08
B44: 28 | C44: First Metro Save and Learn F.O.C.C.U.S. Dynamic Fund, Inc. | D44: 2.7813192e+08 | E44: 7874836 | F44: =D44-E44 -> 2.7025708e+08 | G44: 1.6114661e+08 | H44: 170 | I44: 35227627 | J44: 202855.27 | K44: =I44-J44 -> 35024772 | L44: =I44+Mar!L44 -> 265332390 | M44: =J44+Mar!M44 -> 11584496 | N44: =L44-M44 -> 2.5374789e+08
B45: 29 | C45: NCM Mutual Fund of the Phils., Inc. | D45: 3.4656339e+08 | E45: 1437574.4 | F45: =D45-E45 -> 3.4512581e+08 | G45: 1.619019e+08 | H45: 57 | I45: 0 | J45: 0 | K45: =I45-J45 -> 0 | L45: =I45+Mar!L45 -> 0 | M45: =J45+Mar!M45 -> 1017100 | N45: =L45-M45 -> -1017100
B46: 30 | C46: PAMI Horizon Fund, Inc. | D46: 6.0552407e+08 | E46: 12363241 | F46: =D46-E46 -> 5.9316083e+08 | G46: 3.2958554e+08 | H46: 10239 | I46: 231515.65 | J46: 3766449.7 | K46: =I46-J46 -> -3534934 | L46: =I46+Mar!L46 -> 1702848.7 | M46: =J46+Mar!M46 -> 26047677 | N46: =L46-M46 -> -24344828
...

Sheet May
A1: PHILIPPINE INVESTMENT FUNDS ASSOCIATION, INC.
A2: MUTUAL FUNDS STATISTICAL REPORT
A3: Month of May 2022
A4: (Amounts in Peso)
I5: F O R - T H E - M O N T H | L5: Y E A R - T O - D A T E
A6: Fund Category | C6: Fund Name | D6: ASSETS | E6: LIABILITIES | F6: NET ASSETS | G6: EQUITY INV. | H6: NO. OF A/C | I6: SALES | J6: REDEMPTIONS | K6: NET SALES | L6: TOTAL SALES | M6: TOTAL REDEMPTIONS | N6: TOTAL NET SALES
A7: Stock Funds
A8: Primarily invested in Peso Securities (shares)
B9: 1 | C9: ALFM Growth Fund, Inc. | D9: 5.0663093e+09 | E9: 20667545 | F9: =D9-E9 -> 5045641707 | G9: 4569765363 | H9: 7467 | I9: 21536666 | J9: 45324980 | K9: =I9-J9 -> -23788314 | L9: =I9+Apr!L9 -> 87587275 | M9: =J9+Apr!M9 -> 2.3115644e+08 | N9: =L9-M9 -> -1.4356916e+08
B10: 2 | C10: ATRAM Alpha Opportunity Fund, Inc. (formerly, ATRKE Alpha Opportunity Fund, Inc.) | D10: 7.6089647e+08 | E10: 1923291.4 | F10: =D10-E10 -> 7.5897318e+08 | G10: 6.7521392e+08 | H10: 4295 | I10: 7952178.5 | J10: 11459317 | K10: =I10-J10 -> -3507138.1 | L10: =I10+Apr!L10 -> 1.7160015e+08 | M10: =J10+Apr!M10 -> 1.158301e+08 | N10: =L10-M10 -> 55770058
B11: 3 | C11: ATRAM Phil. Equity Opportunity Fund, Inc. (formerly, ATRKE Equity Opportunity Fund, Inc.) | D11: 1.0575983e+09 | E11: 2841553.6 | F11: =D11-E11 -> 1054756745 | G11: 9.9142116e+08 | H11: 2776 | I11: 6538160.7 | J11: 5612004 | K11: =I11-J11 -> 926156.64 | L11: =I11+Apr!L11 -> 62458437 | M11: =J11+Apr!M11 -> 1.0178715e+08 | N11: =L11-M11 -> -39328713
B12: 4 | C12: Climbs Share Capital Equity Investment Fund Corp. | D12: 3.612235e+08 | E12: 11549675 | F12: =D12-E12 -> 3.4967382e+08 | G12: 1.9944071e+08 | H12: 1668 | I12: 6045012.9 | J12: 1488209 | K12: =I12-J12 -> 4556803.9 | L12: =I12+Apr!L12 -> 17040895 | M12: =J12+Apr!M12 -> 8103632.2 | N12: =L12-M12 -> 8937262.8
B13: 5 | C13: First Metro Consumer Fund on MSCI Phils. IMI, Inc. | D13: 5.3358044e+08 | E13: 10444506 | F13: =D13-E13 -> 5.2313593e+08 | G13: 2.8813241e+08 | H13: 1501 | I13: 945891.77 | J13: 875055.7 | K13: =I13-J13 -> 70836.07 | L13: =I13+Apr!L13 -> 21377793 | M13: =J13+Apr!M13 -> 11627287 | N13: =L13-M13 -> 9750506.2
B14: 6 | C14: First Metro Save and Learn Equity Fund, Inc. | D14: 4.4352128e+09 | E14: 1.0911912e+08 | F14: =D14-E14 -> 4326093705 | G14: 3.7587172e+09 | H14: 16518 | I14: 1.2071828e+08 | J14: 14902248 | K14: =I14-J14 -> 1.0581603e+08 | L14: =I14+Apr!L14 -> 4.3268058e+08 | M14: =J14+Apr!M14 -> 3.0191322e+08 | N14: =L14-M14 -> 130767357
B15: 7 | C15: First Metro Save and Learn Phil. Index Fund, Inc. (formerly, One Wealthy Nation Fund, Inc.) | D15: 92739581 | E15: 681524.52 | F15: =D15-E15 -> 92058056 | G15: 89717218 | H15: 537 | I15: 3040101.7 | J15: 1690864.3 | K15: =I15-J15 -> 1349237.5 | L15: =I15+Apr!L15 -> 10928008 | M15: =J15+Apr!M15 -> 6303830.9 | N15: =L15-M15 -> 4624176.6
B16: 8 | C16: MBG Equity Investment Fund, Inc. | D16: 1.2960905e+08 | E16: 1031234 | F16: =D16-E16 -> 1.2857782e+08 | G16: 1.1991046e+08 | H16: 51 | I16: 0 | J16: 0 | K16: =I16-J16 -> 0 | L16: =I16+Apr!L16 -> 1600000 | M16: =J16+Apr!M16 -> 950000 | N16: =L16-M16 -> 650000
B17: 9 | C17: PAMI Equity Index Fund, Inc. | D17: 1.7147595e+10 | E17: 1.967699e+08 | F17: =D17-E17 -> 16950824816 | G17: 1.6848975e+10 | H17: 12428 | I17: 1.8792179e+08 | J17: 16741785 | K17: =I17-J17 -> 1.7118001e+08 | L17: =I17+Apr!L17 -> 1003482556 | M17: =J17+Apr!M17 -> 75433085 | N17: =L17-M17 -> 9.2804947e+08
B18: 10 | C18: Philam Strategic Growth Fund, Inc. | D18: 3.4071644e+10 | E18: 2.2642636e+08 | F18: =D18-E18 -> 33845217621 | G18: 3.0120423e+10 | H18: 12424 | I18: 1.0363244e+08 | J18: 36657818 | K18: =I18-J18 -> 66974618 | L18: =I18+Apr!L18 -> 5.0436145e+08 | M18: =J18+Apr!M18 -> 4.6663125e+08 | N18: =L18-M18 -> 37730199
B19: 11 | C19: Philequity Dividend Yield Fund, Inc. | D19: 2.3126048e+09 | E19: 16508957 | F19: =D19-E19 -> 2296095795 | G19: 2.0179858e+09 | H19: 5693 | I19: 17351207 | J19: 27041524 | K19: =I19-J19 -> -9690317.4 | L19: =I19+Apr!L19 -> 91306649 | M19: =J19+Apr!M19 -> 2.5709948e+08 | N19: =L19-M19 -> -1.6579283e+08
B20: 12 | C20: Philequity Fund, Inc. | D20: 1.0288366e+10 | E20: 65290340 | F20: =D20-E20 -> 10223075867 | G20: 9.6511799e+09 | H20: 36942 | I20: 47705834 | J20: 56509683 | K20: =I20-J20 -> -8803848.1 | L20: =I20+Apr!L20 -> 1.6427777e+08 | M20: =J20+Apr!M20 -> 3.0046431e+08 | N20: =L20-M20 -> -1.3618654e+08
... B27: 19 | C27: United Fund, Inc. | D27: 6.1555765e+08 | E27: 2711557.9 | F27: =D27-E27 -> 6.1284609e+08 | G27: 5.5541166e+08 | H27: 1306 | I27: 666991.43 | J27: 3234532.1 | K27: =I27-J27 -> -2567540.6 | L27: =I27+Apr!L27 -> 11232841 | M27: =J27+Apr!M27 -> 6966264.1 | N27: =L27-M27 -> 4266576.6
A28: Primarily invested in Peso Securities (units)
B29: 20 | C29: Philequity Alpha One Fund, Inc. | D29: 3.7799177e+08 | E29: 6640875.4 | F29: =D29-E29 -> 3.7135089e+08 | G29: 3.1764789e+08 | H29: 1479 | I29: 11023362 | J29: 3495515 | K29: =I29-J29 -> 7527846.5 | L29: =I29+Apr!L29 -> 67796038 | M29: =J29+Apr!M29 -> 13382627 | N29: =L29-M29 -> 54413411
B30: 21 | C30: Philippine Stock Index Fund Corp. | D30: 3.3700795e+08 | E30: 16779625 | F30: =D30-E30 -> 320228328 | G30: 3.1822412e+08 | H30: 275893 | I30: 65114204 | J30: 34277166 | K30: =I30-J30 -> 30837039 | L30: =I30+Apr!L30 -> 4.0841805e+08 | M30: =J30+Apr!M30 -> 67832105 | N30: =L30-M30 -> 3.4058594e+08
A31: Exchange Traded Fund
B32: 22 | C32: First Metro Phil. Equity Exchange Traded Fund, Inc. | D32: 2.1685273e+09 | E32: 4962134.9 | F32: =D32-E32 -> 2163565138 | G32: 2.1597662e+09 | H32: 3142 | I32: 19098124 | J32: 9240460 | K32: =I32-J32 -> 9857664 | L32: =I32+Apr!L32 -> 75702425 | M32: =J32+Apr!M32 -> 13683385 | N32: =L32-M32 -> 62019040
A33: Sub total - Peso Currency | D33: =SUM(D9:D32) -> 115879772249 | E33: =SUM(E9:E32) -> 9.0144768e+08 | F33: =SUM(F9:F32) -> 114978324568 | G33: =SUM(G9:G32) -> 108087231027 | H33: =SUM(H9:H32) -> 556529 | I33: =SUM(I9:I32) -> 1416307827 | J33: =SUM(J9:J32) -> 5.6954732e+08 | K33: =SUM(K9:K32) -> 8.4676051e+08 | ... N33: =SUM(N9:N32) -> 1424619500
A34: Primarily invested in foreign currency securities (shares)
B35: 23 | C35: ATRAM AsiaPlus Equity Fund, Inc. (formerly, ATR KimEng AsiaPlus Recovery Fund, Inc.) | D35: 40439759 | E35: 943443.46 | F35: =D35-E35 -> 39496316 | G35: 0 | H35: 57 | I35: 292627.85 | J35: 4725.87 | K35: =I35-J35 -> 287901.98 | L35: =I35+Apr!L35 -> 860006.99 | M35: =J35+Apr!M35 -> 5532962.8 | N35: =L35-M35 -> -4672955.8
B36: 24 | C36: Sun Life Prosperity World Voyager Fund, Inc. | D36: =52.37*37237603.84 -> 1950133313 | E36: =52.37*251879.39 -> 13190924 | F36: =D36-E36 -> 1936942389 | G36: 0 | H36: 2797 | I36: =52.37*270477.02 -> 14164882 | J36: =52.37*439889.89 -> 23037034 | K36: =I36-J36 -> -8872152 | L36: =I36+Apr!L36 -> 2.447869e+08 | M36: =J36+Apr!M36 -> 2.1352274e+08 | N36: =L36-M36 -> 31264164
A37: Sub total - US Currency | D37: =SUM(D35:D36) -> 1990573073 | E37: =SUM(E35:E36) -> 14134367 | F37: =SUM(F35:F36) -> 1976438705 | G37: =SUM(G35:G36) -> 0 | H37: =SUM(H35:H36) -> 2854 | I37: =SUM(I35:I36) -> 14457509 | J37: =SUM(J35:J36) -> 23041759 | K37: =SUM(K35:K36) -> -8584250 | ... N37: =SUM(N35:N36) -> 26591208
A38: Sub total - stock funds | D38: =D33+D37 -> 117870345322 | E38: =E33+E37 -> 9.1558205e+08 | F38: =F33+F37 -> 116954763273 | G38: =G33+G37 -> 108087231027 | H38: =H33+H37 -> 559383 | I38: =I33+I37 -> 1430765336 | J38: =J33+J37 -> 592589075 | K38: =K33+K37 -> 8.3817626e+08 | ... N38: =N33+N37 -> 1451210708
A39: Balanced Funds
A40: Primarily invested in Peso Securities (shares)
B41: 25 | C41: ATRAM Dynamic Allocation Fund, Inc. (formerly, Optima Balanced Fund, Inc.) | D41: 1.2351406e+08 | E41: 377187.72 | F41: =D41-E41 -> 1.2313687e+08 | G41: 26599529 | H41: 736 | I41: 645791.3 | J41: 259818.16 | K41: =I41-J41 -> 385973.14 | L41: =I41+Apr!L41 -> 8636856.2 | M41: =J41+Apr!M41 -> 3139571.9 | N41: =L41-M41 -> 5497284.3
B42: 26 | C42: ATRAM Philippine Balanced Fund, Inc. (formerly, ATRKE Philippine Balanced Fund, Inc.) | D42: 6.3766838e+08 | E42: 1923693.4 | F42: =D42-E42 -> 6.3574468e+08 | G42: 2.3499689e+08 | H42: 2479 | I42: 759091.28 | J42: 5529011.7 | K42: =I42-J42 -> -4769920.4 | L42: =I42+Apr!L42 -> 7760661.1 | M42: =J42+Apr!M42 -> 33929029 | N42: =L42-M42 -> -26168368
B43: 27 | C43: First Metro Save and Learn Balanced Fund, Inc. | D43: 1.1369879e+09 | E43: 16832001 | F43: =D43-E43 -> 1120155925 | G43: 5.7741168e+08 | H43: 4847 | I43: 1686071.3 | J43: 4333048.1 | K43: =I43-J43 -> -2646976.7 | L43: =I43+Apr!L43 -> 14815419 | M43: =J43+Apr!M43 -> 1.6198202e+08 | N43: =L43-M43 -> -1.471666e+08
B44: 28 | C44: First Metro Save and Learn F.O.C.C.U.S. Dynamic Fund, Inc. | D44: 2.8401796e+08 | E44: 4440600.1 | F44: =D44-E44 -> 2.7957736e+08 | G44: 1.6743062e+08 | H44: 186 | I44: 9359995.1 | J44: 61205.31 | K44: =I44-J44 -> 9298789.8 | L44: =I44+Apr!L44 -> 2.7469239e+08 | M44: =J44+Apr!M44 -> 11645701 | N44: =L44-M44 -> 263046684
B45: 29 | C45: NCM Mutual Fund of the Phils., Inc. | D45: 3.4718152e+08 | E45: 1751900.6 | F45: =D45-E45 -> 3.4542962e+08 | G45: 1.6310316e+08 | H45: 57 | I45: 0 | J45: 0 | K45: =I45-J45 -> 0 | L45: =I45+Apr!L45 -> 0 | M45: =J45+Apr!M45 -> 1017100 | N45: =L45-M45 -> -1017100
B46: 30 | C46: PAMI Horizon Fund, Inc. | D46: 6.0467418e+08 | E46: 12584014 | F46: =D46-E46 -> 5.9209016e+08 | G46: 3.1221278e+08 | H46: 10005 | I46: 2236451.9 | J46: 3894280.6 | K46: =I46-J46 -> -1657828.7 | L46: =I46+Apr!L46 -> 3939300.6 | M46: =J46+Apr!M46 -> 29941958 | N46: =L46-M46 -> -26002657
...

Sheet June
A1: PHILIPPINE INVESTMENT FUNDS ASSOCIATION, INC.
A2: MUTUAL FUNDS STATISTICAL REPORT
A3: Month of June 2022
A4: (Amounts in Peso)
I5: F O R - T H E - M O N T H | L5: Y E A R - T O - D A T E
A6: Fund Category | C6: Fund Name | D6: ASSETS | E6: LIABILITIES | F6: NET ASSETS | G6: EQUITY INV. | H6: NO. OF A/C | I6: SALES | J6: REDEMPTIONS | K6: NET SALES | L6: TOTAL SALES | M6: TOTAL REDEMPTIONS | N6: TOTAL NET SALES
A7: Stock Funds
A8: Primarily invested in Peso Securities (shares)
B9: 1 | C9: ALFM Growth Fund, Inc. | D9: 4.5803566e+09 | E9: 23785456 | F9: =D9-E9 -> 4556571107 | G9: 4.0897858e+09 | H9: 7497 | I9: 14802824 | J9: 26848823 | K9: =I9-J9 -> -12045999 | L9: =I9+May!L9 -> 1.023901e+08 | M9: =J9+May!M9 -> 258005260 | N9: =L9-M9 -> -1.5561516e+08
B10: 2 | C10: ATRAM Alpha Opportunity Fund, Inc. (formerly, ATRKE Alpha Opportunity Fund, Inc.) | D10: 7.0908328e+08 | E10: 2072831.4 | F10: =D10-E10 -> 7.0701045e+08 | G10: 6.048486e+08 | H10: 4285 | I10: 9288046.8 | J10: 7843672.4 | K10: =I10-J10 -> 1444374.4 | L10: =I10+May!L10 -> 1.808882e+08 | M10: =J10+May!M10 -> 123673769 | N10: =L10-M10 -> 57214432
B11: 3 | C11: ATRAM Phil. Equity Opportunity Fund, Inc. (formerly, ATRKE Equity Opportunity Fund, Inc.) | D11: 9.5218227e+08 | E11: 2599216.7 | F11: =D11-E11 -> 9.4958306e+08 | G11: 8.5539511e+08 | H11: 2771 | I11: 11847676 | J11: 12853522 | K11: =I11-J11 -> -1005846.2 | L11: =I11+May!L11 -> 74306113 | M11: =J11+May!M11 -> 114640672 | N11: =L11-M11 -> -40334559
B12: 4 | C12: Climbs Share Capital Equity Investment Fund Corp. | D12: 3.3719981e+08 | E12: 4004739.3 | F12: =D12-E12 -> 3.3319507e+08 | G12: 2.0678089e+08 | H12: 1652 | I12: 3410015.8 | J12: 2008534.6 | K12: =I12-J12 -> 1401481.2 | L12: =I12+May!L12 -> 20450911 | M12: =J12+May!M12 -> 10112167 | N12: =L12-M12 -> 10338744
B13: 5 | C13: First Metro Consumer Fund on MSCI Phils. IMI, Inc. | D13: 5.039934e+08 | E13: 1736315.9 | F13: =D13-E13 -> 5.0225709e+08 | G13: 2.3069467e+08 | H13: 1492 | I13: 866737.92 | J13: 2381109.7 | K13: =I13-J13 -> -1514371.8 | L13: =I13+May!L13 -> 22244531 | M13: =J13+May!M13 -> 14008396 | N13: =L13-M13 -> 8236134.4
B14: 6 | C14: First Metro Save and Learn Equity Fund, Inc. | D14: 4.110085e+09 | E14: 99953188 | F14: =D14-E14 -> 4010131781 | G14: 2.9668759e+09 | H14: 16497 | I14: 66089718 | J14: 15666842 | K14: =I14-J14 -> 50422877 | L14: =I14+May!L14 -> 4.9877029e+08 | M14: =J14+May!M14 -> 317580061 | N14: =L14-M14 -> 1.8119023e+08
B15: 7 | C15: First Metro Save and Learn Phil. Index Fund, Inc. (formerly, One Wealthy Nation Fund, Inc.) | D15: 87880005 | E15: 676406.51 | F15: =D15-E15 -> 87203598 | G15: 81511975 | H15: 554 | I15: 3748480.9 | J15: 125576 | K15: =I15-J15 -> 3622904.9 | L15: =I15+May!L15 -> 14676488 | M15: =J15+May!M15 -> 6429406.9 | N15: =L15-M15 -> 8247081.6
B16: 8 | C16: MBG Equity Investment Fund, Inc. | D16: 1.2681866e+08 | E16: 8244887.2 | F16: =D16-E16 -> 1.1857377e+08 | G16: 112058432 | H16: 51 | I16: 0 | J16: 6470778.8 | K16: =I16-J16 -> -6470778.8 | L16: =I16+May!L16 -> 1600000 | M16: =J16+May!M16 -> 7420778.8 | N16: =L16-M16 -> -5820778.8
B17: 9 | C17: PAMI Equity Index Fund, Inc. | D17: 1.5697676e+10 | E17: 1.3185222e+08 | F17: =D17-E17 -> 15565823898 | G17: 1.5484781e+10 | H17: 12626 | I17: 1.9043018e+08 | J17: 7081494.4 | K17: =I17-J17 -> 1.8334869e+08 | L17: =I17+May!L17 -> 1193912738 | M17: =J17+May!M17 -> 82514579 | N17: =L17-M17 -> 1111398159
B18: 10 | C18: Philam Strategic Growth Fund, Inc. | D18: 3.0999083e+10 | E18: 2.3316964e+08 | F18: =D18-E18 -> 30765913816 | G18: 2.7016509e+10 | H18: 12524 | I18: 1.1106147e+08 | J18: 29231977 | K18: =I18-J18 -> 81829490 | L18: =I18+May!L18 -> 6.1542292e+08 | M18: =J18+May!M18 -> 4.9586323e+08 | N18: =L18-M18 -> 1.1955969e+08
B19: 11 | C19: Philequity Dividend Yield Fund, Inc. | D19: 2.1078107e+09 | E19: 3294491 | F19: =D19-E19 -> 2104516217 | G19: 1.8761679e+09 | H19: 5694 | I19: 6681157.8 | J19: 7895348.7 | K19: =I19-J19 -> -1214190.9 | L19: =I19+May!L19 -> 97987806 | M19: =J19+May!M19 -> 2.6499483e+08 | N19: =L19-M19 -> -1.6700702e+08
B20: 12 | C20: Philequity Fund, Inc. | D20: 9.2939301e+09 | E20: 58678028 | F20: =D20-E20 -> 9235252023 | G20: 8.5040068e+09 | H20: 36879 | I20: 21557154 | J20: 27119110 | K20: =I20-J20 -> -5561955.6 | L20: =I20+May!L20 -> 1.8583492e+08 | M20: =J20+May!M20 -> 3.2758342e+08 | N20: =L20-M20 -> -1.4174849e+08
... B27: 19 | C27: United Fund, Inc. | D27: 5.684599e+08 | E27: 2614322.1 | F27: =D27-E27 -> 5.6584558e+08 | G27: 5.0873575e+08 | H27: 1307 | I27: 1530588.9 | J27: 220703.76 | K27: =I27-J27 -> 1309885.1 | L27: =I27+May!L27 -> 12763430 | M27: =J27+May!M27 -> 7186967.8 | N27: =L27-M27 -> 5576461.7
A28: Primarily invested in Peso Securities (units)
B29: 20 | C29: Philequity Alpha One Fund, Inc. | D29: 3.2903298e+08 | E29: 1748543.4 | F29: =D29-E29 -> 3.2728444e+08 | G29: 2.7560446e+08 | H29: 1462 | I29: 5745438.6 | J29: 12522358 | K29: =I29-J29 -> -6776919 | L29: =I29+May!L29 -> 73541476 | M29: =J29+May!M29 -> 25904984 | N29: =L29-M29 -> 47636492
B30: 21 | C30: Philippine Stock Index Fund Corp. | D30: 3.5968187e+08 | E30: 15259664 | F30: =D30-E30 -> 3.444222e+08 | G30: 3.4051191e+08 | H30: 284367 | I30: 64935543 | J30: 8915103.1 | K30: =I30-J30 -> 56020440 | L30: =I30+May!L30 -> 4.7335359e+08 | M30: =J30+May!M30 -> 76747208 | N30: =L30-M30 -> 3.9660638e+08
A31: Exchange Traded Fund
B32: 22 | C32: First Metro Phil. Equity Exchange Traded Fund, Inc. | D32: 2.0012374e+09 | E32: 6100193.7 | F32: =D32-E32 -> 1995137252 | G32: 1.9929227e+09 | H32: 3213 | I32: 31371140 | J32: 0 | K32: =I32-J32 -> 31371140 | L32: =I32+May!L32 -> 107073565 | M32: =J32+May!M32 -> 13683385 | N32: =L32-M32 -> 93390180
A33: Sub total - Peso Currency | D33: =SUM(D9:D32) -> 105648247107 | E33: =SUM(E9:E32) -> 7.4056906e+08 | F33: =SUM(F9:F32) -> 104907678044 | G33: =SUM(G9:G32) -> 97282688780 | H33: =SUM(H9:H32) -> 573714 | I33: =SUM(I9:I32) -> 9.3544514e+08 | J33: =SUM(J9:J32) -> 3.9812045e+08 | K33: =SUM(K9:K32) -> 5.3732469e+08 | ... N33: =SUM(N9:N32) -> 1961944194
A34: Primarily invested in foreign currency securities (shares)
B35: 23 | C35: ATRAM AsiaPlus Equity Fund, Inc. (formerly, ATR KimEng AsiaPlus Recovery Fund, Inc.) | D35: 41164913 | E35: 927726.76 | F35: =D35-E35 -> 40237187 | G35: 0 | H35: 57 | I35: 68596.71 | J35: 7245.16 | K35: =I35-J35 -> 61351.55 | L35: =I35+May!L35 -> 928603.7 | M35: =J35+May!M35 -> 5540208 | N35: =L35-M35 -> -4611604.2
