Workbook

Sheet Jan
A1: PHILIPPINE INVESTMENT FUNDS ASSOCIATION, INC.
A2: MUTUAL FUNDS STATISTICAL REPORT
A3: Month of January 2023
A4: (Amounts in Peso)
I5: F O R - T H E - M O N T H | L5: Y E A R - T O - D A T E
A6: Fund Category | C6: Fund Name | D6: ASSETS | E6: LIABILITIES | F6: NET ASSETS | G6: EQUITY INV. | H6: NO. OF A/C | I6: SALES | J6: REDEMPTIONS | K6: NET SALES | L6: TOTAL SALES | M6: TOTAL REDEMPTIONS | N6: TOTAL NET SALES
A7: Stock Funds
A8: Primarily invested in Peso Securities (shares)
B9: 1 | C9: ALFM Growth Fund, Inc. | D9: 4.7822898e+09 | E9: 22866144 | F9: =D9-E9 -> 4759423672 | G9: 4444566800 | H9: 7266 | I9: 6706839.1 | J9: 75206133 | K9: =I9-J9 -> -68499294 | L9: =I9 -> 6706839.1 | M9: =J9 -> 75206133 | N9: =L9-M9 -> -68499294
B10: 2 | C10: ATRAM Alpha Opportunity Fund, Inc. | D10: 7.9233593e+08 | E10: 15870067 | F10: =D10-E10 -> 776465859 | G10: 7.2170991e+08 | H10: 4230 | I10: 4499756.3 | J10: 16217191 | K10: =I10-J10 -> -11717435 | L10: =I10 -> 4499756.2 | M10: =J10 -> 16217191 | N10: =L10-M10 -> -11717435
B11: 3 | C11: ATRAM Phil. Equity Opportunity Fund, Inc. | D11: 1.5556866e+09 | E11: 11754287 | F11: =D11-E11 -> 1543932337 | G11: 1.4656305e+09 | H11: 2882 | I11: 1.8795634e+08 | J11: 10251679 | K11: =I11-J11 -> 1.7770466e+08 | L11: =I11 -> 1.8795634e+08 | M11: =J11 -> 10251679 | N11: =L11-M11 -> 1.7770466e+08
B12: 4 | C12: Climbs Share Capital Equity Investment Fund Corp. | D12: 3.5654467e+08 | E12: 10854564 | F12: =D12-E12 -> 3.4569011e+08 | G12: 1.729918e+08 | H12: 1719 | I12: 541004.5 | J12: 108166.61 | K12: =I12-J12 -> 432837.89 | L12: =I12 -> 541004.5 | M12: =J12 -> 108166.61 | N12: =L12-M12 -> 432837.89
B13: 5 | C13: First Metro Consumer Fund, Inc. | D13: 5.4004161e+08 | E13: 1254131.9 | F13: =D13-E13 -> 5.3878748e+08 | G13: 5.2880601e+08 | H13: 1434 | I13: 763858.11 | J13: 3298867.6 | K13: =I13-J13 -> -2535009.5 | L13: =I13 -> 763858.11 | M13: =J13 -> 3298867.6 | N13: =L13-M13 -> -2535009.5
B14: 6 | C14: First Metro Save and Learn Equity Fund, Inc. | D14: 4.3893954e+09 | E14: 56878998 | F14: =D14-E14 -> 4332516360 | G14: 4.2483787e+09 | H14: 16239 | I14: 19313813 | J14: 54006004 | K14: =I14-J14 -> -34692191 | L14: =I14 -> 19313813 | M14: =J14 -> 54006004 | N14: =L14-M14 -> -34692191
B15: 7 | C15: First Metro Save and Learn Phil. Index Fund, Inc. | D15: 1.0356468e+08 | E15: 1636633.3 | F15: =D15-E15 -> 1.0192804e+08 | G15: 1.0169772e+08 | H15: 556 | I15: 760936.48 | J15: 3170318.6 | K15: =I15-J15 -> -2409382.1 | L15: =I15 -> 760936.48 | M15: =J15 -> 3170318.6 | N15: =L15-M15 -> -2409382.1
B16: 8 | C16: MBG Equity Investment Fund, Inc. | D16: 1.2257233e+08 | E16: 1973258.4 | F16: =D16-E16 -> 1.2059907e+08 | G16: 93684327 | H16: 51 | I16: 0 | J16: 0 | K16: =I16-J16 -> 0 | L16: =I16 -> 0 | M16: =J16 -> 0 | N16: =L16-M16 -> 0
B17: 9 | C17: PAMI Equity Index Fund, Inc. | D17: 1.4143032e+09 | E17: 77183575 | F17: =D17-E17 -> 1337119599 | G17: 1.3559362e+09 | H17: 12264 | I17: 0 | J17: 22214781 | K17: =I17-J17 -> -22214781 | L17: =I17 -> 0 | M17: =J17 -> 22214781 | N17: =L17-M17 -> -22214781
B18: 10 | C18: Philam Strategic Growth Fund, Inc. | D18: 4.0324245e+09 | E18: 1.6336035e+08 | F18: =D18-E18 -> 3869064193 | G18: 3.5538122e+09 | H18: 12231 | I18: 4691707 | J18: 23242525 | K18: =I18-J18 -> -18550818 | L18: =I18 -> 4691707 | M18: =J18 -> 23242525 | N18: =L18-M18 -> -18550818
B19: 11 | C19: Philequity Dividend Yield Fund, Inc. | D19: 2.2049397e+09 | E19: 36620940 | F19: =D19-E19 -> 2168318719 | G19: 1.8965229e+09 | H19: 5629 | I19: 71593884 | J19: 4276017.4 | K19: =I19-J19 -> 67317866 | L19: =I19 -> 71593884 | M19: =J19 -> 4276017.4 | N19: =L19-M19 -> 67317866
B20: 12 | C20: Philequity Fund, Inc. | D20: 1.0039293e+10 | E20: 34899213 | F20: =D20-E20 -> 10004393473 | G20: 9.2304504e+09 | H20: 36180 | I20: 10633658 | J20: 45139938 | K20: =I20-J20 -> -34506280 | L20: =I20 -> 10633658 | M20: =J20 -> 45139938 | N20: =L20-M20 -> -34506280
... B27: 19 | C27: United Fund, Inc. | D27: 6.0788571e+08 | E27: 2758899.5 | F27: =D27-E27 -> 6.0512681e+08 | G27: 5.2895313e+08 | H27: 1304 | I27: 297833.86 | J27: 3606632.7 | K27: =I27-J27 -> -3308798.8 | L27: =I27 -> 297833.86 | M27: =J27 -> 3606632.7 | N27: =L27-M27 -> -3308798.8
A28: Primarily invested in Peso Securities (units)
B29: 20 | C29: COL Equity Index Unitized Mutual Fund, Inc. | D29: 1.334247e+08 | E29: 1368336.6 | F29: =D29-E29 -> 1.3205637e+08 | G29: 1.2990052e+08 | H29: 1222 | I29: 18662319 | J29: 1531528.5 | K29: =I29-J29 -> 17130791 | L29: =I29 -> 18662319 | M29: =J29 -> 1531528.5 | N29: =L29-M29 -> 17130791
B30: 21 | C30: Philequity Alpha One Fund, Inc. | D30: 3.4194384e+08 | E30: 1226623.2 | F30: =D30-E30 -> 3.4071722e+08 | G30: 3.1886116e+08 | H30: 1425 | I30: 1357758.3 | J30: 9542216.7 | K30: =I30-J30 -> -8184458.3 | L30: =I30 -> 1357758.3 | M30: =J30 -> 9542216.7 | N30: =L30-M30 -> -8184458.3
B31: 22 | C31: Philippine Stock Index Fund Corp. | D31: 4.8721803e+08 | E31: 15335630 | F31: =D31-E31 -> 4.718824e+08 | G31: 4.8025628e+08 | H31: 328363 | I31: 33306036 | J31: 54543447 | K31: =I31-J31 -> -21237411 | L31: =I31 -> 33306036 | M31: =J31 -> 54543447 | N31: =L31-M31 -> -21237411
A32: Exchange Traded Fund
B33: 23 | C33: First Metro Phil. Equity Exchange Traded Fund, Inc. | D33: 2.210282e+09 | E33: 1638636.6 | F33: =D33-E33 -> 2208643351 | G33: 2.2049191e+09 | H33: 3231 | I33: 1034532 | J33: 73813261 | K33: =I33-J33 -> -72778729 | L33: =I33 -> 1034532 | M33: =J33 -> 73813261 | N33: =L33-M33 -> -72778729
A34: Sub total - Peso Currency | D34: =SUM(D9:D33) -> 70670056765 | E34: =SUM(E9:E33) -> 9.0150261e+08 | F34: =SUM(F9:F33) -> 69768554152 | G34: =SUM(G9:G33) -> 66981970552 | H34: =SUM(H9:H33) -> 614666 | I34: =SUM(I9:I33) -> 9.5589796e+08 | J34: =SUM(J9:J33) -> 1386801971 | K34: =SUM(K9:K33) -> -4.3090401e+08 | ... N34: =SUM(N9:N33) -> -4.3090401e+08
A35: Primarily invested in foreign currency securities (shares)
B36: 24 | C36: ATRAM AsiaPlus Equity Fund, Inc. | D36: 38273149 | E36: 879713.29 | F36: =D36-E36 -> 37393436 | G36: 0 | H36: 55 | I36: 199.54 | J36: 0 | K36: =I36-J36 -> 199.54 | L36: =I36 -> 199.54 | M36: =J36 -> 0 | N36: =L36-M36 -> 199.54
B37: 25 | C37: Sun Life Prosperity World Voyager Fund, Inc. | D37: =54.64*34312196.64 -> 1874818424 | E37: =54.64*440448.86 -> 24066126 | F37: =D37-E37 -> 1850752299 | G37: 0 | H37: 2871 | I37: =54.64*240117.89 -> 13120042 | J37: =54.64*555198.89 -> 30336067 | K37: =I37-J37 -> -17216026 | L37: =I37 -> 13120042 | M37: =J37 -> 30336067 | N37: =L37-M37 -> -17216026
A38: Sub total - US Currency | D38: =SUM(D36:D37) -> 1913091573 | E38: =SUM(E36:E37) -> 24945839 | F38: =SUM(F36:F37) -> 1888145734 | G38: =SUM(G36:G37) -> 0 | H38: =SUM(H36:H37) -> 2926 | I38: =SUM(I36:I37) -> 13120241 | J38: =SUM(J36:J37) -> 30336067 | K38: =SUM(K36:K37) -> -17215826 | ... N38: =SUM(N36:N37) -> -17215826
A39: Sub total - stock funds | D39: =D34+D38 -> 72583148338 | E39: =E34+E38 -> 9.2644845e+08 | F39: =F34+F38 -> 71656699887 | G39: =G34+G38 -> 66981970552 | H39: =H34+H38 -> 617592 | I39: =I34+I38 -> 969018201 | J39: =J34+J38 -> 1417138038 | K39: =K34+K38 -> -4.4811984e+08 | ... N39: =N34+N38 -> -4.4811984e+08
A40: Balanced Funds
A41: Primarily invested in Peso Securities (shares)
B42: 26 | C42: ATRAM Dynamic Allocation Fund, Inc. | D42: 1.2619964e+08 | E42: 9166770.6 | F42: =D42-E42 -> 1.1703287e+08 | G42: 27577738 | H42: 722 | I42: 318249.68 | J42: 266687.3 | K42: =I42-J42 -> 51562.38 | L42: =I42 -> 318249.68 | M42: =J42 -> 266687.3 | N42: =L42-M42 -> 51562.38
B43: 27 | C43: ATRAM Philippine Balanced Fund, Inc. | D43: 6.677692e+08 | E43: 83820160 | F43: =D43-E43 -> 5.8394904e+08 | G43: 2.137249e+08 | H43: 2440 | I43: 1047414.5 | J43: 1930071.6 | K43: =I43-J43 -> -882657.13 | L43: =I43 -> 1047414.5 | M43: =J43 -> 1930071.6 | N43: =L43-M43 -> -882657.13
B44: 28 | C44: First Metro Save and Learn Balanced Fund, Inc. | D44: 1.0923571e+09 | E44: 11264935 | F44: =D44-E44 -> 1081092202 | G44: 6.8939087e+08 | H44: 4704 | I44: 1335330.8 | J44: 5135919.7 | K44: =I44-J44 -> -3800588.8 | L44: =I44 -> 1335330.8 | M44: =J44 -> 5135919.7 | N44: =L44-M44 -> -3800588.8
B45: 29 | C45: First Metro Save and Learn F.O.C.C.U.S. Dynamic Fund, Inc. | D45: 3.0862544e+08 | E45: 10753626 | F45: =D45-E45 -> 2.9787182e+08 | G45: 2.4309859e+08 | H45: 237 | I45: 4604623.3 | J45: 11846152 | K45: =I45-J45 -> -7241529 | L45: =I45 -> 4604623.3 | M45: =J45 -> 11846152 | N45: =L45-M45 -> -7241529
B46: 30 | C46: NCM Mutual Fund of the Phils., Inc. | D46: 3.5711594e+08 | E46: 4143976.5 | F46: =D46-E46 -> 3.5297197e+08 | G46: 1.619854e+08 | H46: 56 | I46: 0 | J46: 0 | K46: =I46-J46 -> 0 | L46: =I46 -> 0 | M46: =J46 -> 0 | N46: =L46-M46 -> 0
...

Sheet Feb
A1: PHILIPPINE INVESTMENT FUNDS ASSOCIATION, INC.
A2: MUTUAL FUNDS STATISTICAL REPORT
A3: Month of February 2023
A4: (Amounts in Peso)
I5: F O R - T H E - M O N T H | L5: Y E A R - T O - D A T E
A6: Fund Category | C6: Fund Name | D6: ASSETS | E6: LIABILITIES | F6: NET ASSETS | G6: EQUITY INV. | H6: NO. OF A/C | I6: SALES | J6: REDEMPTIONS | K6: NET SALES | L6: TOTAL SALES | M6: TOTAL REDEMPTIONS | N6: TOTAL NET SALES
A7: Stock Funds
A8: Primarily invested in Peso Securities (shares)
B9: 1 | C9: ALFM Growth Fund, Inc. | D9: 4593872904 | E9: 12038727 | F9: =D9-E9 -> 4581834177 | G9: 4291574273 | H9: 7236 | I9: 5275082 | J9: 24704237 | K9: =I9-J9 -> -19429155 | L9: =I9+Jan!L9 -> 11981921 | M9: =J9+Jan!M9 -> 99910370 | N9: =L9-M9 -> -87928449
B10: 2 | C10: ATRAM Alpha Opportunity Fund, Inc. | D10: 7.8551118e+08 | E10: 21049873 | F10: =D10-E10 -> 7.6446131e+08 | G10: 7.1177413e+08 | H10: 4221 | I10: 5560274.9 | J10: 12336999 | K10: =I10-J10 -> -6776724.6 | L10: =I10+Jan!L10 -> 10060031 | M10: =J10+Jan!M10 -> 28554190 | N10: =L10-M10 -> -18494159
B11: 3 | C11: ATRAM Phil. Equity Opportunity Fund, Inc. | D11: 1.6316838e+09 | E11: 1.0575227e+08 | F11: =D11-E11 -> 1525931484 | G11: 1.4548882e+09 | H11: 2874 | I11: 1.8514609e+08 | J11: 1.2266104e+08 | K11: =I11-J11 -> 62485054 | L11: =I11+Jan!L11 -> 3.7310243e+08 | M11: =J11+Jan!M11 -> 1.3291271e+08 | N11: =L11-M11 -> 2.4018971e+08
B12: 4 | C12: Climbs Share Capital Equity Investment Fund Corp. | D12: 3.6020278e+08 | E12: 17762394 | F12: =D12-E12 -> 3.4244039e+08 | G12: 2.0451595e+08 | H12: 1743 | I12: 588897.45 | J12: 71172.65 | K12: =I12-J12 -> 517724.8 | L12: =I12+Jan!L12 -> 1129901.9 | M12: =J12+Jan!M12 -> 179339.26 | N12: =L12-M12 -> 950562.69
B13: 5 | C13: First Metro Consumer Fund, Inc. | D13: 5.3822817e+08 | E13: 1229091.1 | F13: =D13-E13 -> 5.3699908e+08 | G13: 4.2599787e+08 | H13: 1428 | I13: 539284.43 | J13: 284725.86 | K13: =I13-J13 -> 254558.57 | L13: =I13+Jan!L13 -> 1303142.5 | M13: =J13+Jan!M13 -> 3583593.4 | N13: =L13-M13 -> -2280450.9
B14: 6 | C14: First Metro Save and Learn Equity Fund, Inc. | D14: 4.2099549e+09 | E14: 21850252 | F14: =D14-E14 -> 4188104604 | G14: 3.4415412e+09 | H14: 16190 | I14: 13071496 | J14: 17052745 | K14: =I14-J14 -> -3981249.8 | L14: =I14+Jan!L14 -> 32385308 | M14: =J14+Jan!M14 -> 71058749 | N14: =L14-M14 -> -38673441
B15: 7 | C15: First Metro Save and Learn Phil. Index Fund, Inc. | D15: 99621798 | E15: 1254140.8 | F15: =D15-E15 -> 98367658 | G15: 96925675 | H15: 554 | I15: 728740.25 | J15: 676891.31 | K15: =I15-J15 -> 51848.94 | L15: =I15+Jan!L15 -> 1489676.7 | M15: =J15+Jan!M15 -> 3847209.9 | N15: =L15-M15 -> -2357533.2
B16: 8 | C16: MBG Equity Investment Fund, Inc. | D16: 119846366 | E16: 2353974 | F16: =D16-E16 -> 117492392 | G16: 106689337 | H16: 50 | I16: 0 | J16: 496031 | K16: =I16-J16 -> -496031 | L16: =I16+Jan!L16 -> 0 | M16: =J16+Jan!M16 -> 496031 | N16: =L16-M16 -> -496031
B17: 9 | C17: PAMI Equity Index Fund, Inc. | D17: 1356343217 | E17: 74584016 | F17: =D17-E17 -> 1281759201 | G17: 1301656259 | H17: 12224 | I17: 0 | J17: 6972690 | K17: =I17-J17 -> -6972690 | L17: =I17+Jan!L17 -> 0 | M17: =J17+Jan!M17 -> 29187471 | N17: =L17-M17 -> -29187471
B18: 10 | C18: Philam Strategic Growth Fund, Inc. | D18: 3876027145 | E18: 161955174 | F18: =D18-E18 -> 3714071971 | G18: 3424225386 | H18: 12187 | I18: 3137498 | J18: 24799237 | K18: =I18-J18 -> -21661739 | L18: =I18+Jan!L18 -> 7829205 | M18: =J18+Jan!M18 -> 48041762 | N18: =L18-M18 -> -40212557
B19: 11 | C19: Philequity Dividend Yield Fund, Inc. | D19: 2.2240016e+09 | E19: 16490897 | F19: =D19-E19 -> 2207510676 | G19: 1.8905677e+09 | H19: 5618 | I19: 62015147 | J19: 3355607.8 | K19: =I19-J19 -> 58659539 | L19: =I19+Jan!L19 -> 1.3360903e+08 | M19: =J19+Jan!M19 -> 7631625.2 | N19: =L19-M19 -> 1.259774e+08
B20: 12 | C20: Philequity Fund, Inc. | D20: 9.9096779e+09 | E20: 1.7157781e+08 | F20: =D20-E20 -> 9738100086 | G20: 9.0494972e+09 | H20: 36023 | I20: 9950257.6 | J20: 21788683 | K20: =I20-J20 -> -11838425 | L20: =I20+Jan!L20 -> 20583916 | M20: =J20+Jan!M20 -> 66928621 | N20: =L20-M20 -> -46344705
... B27: 19 | C27: United Fund, Inc. | D27: 5.9229189e+08 | E27: 1560024.1 | F27: =D27-E27 -> 5.9073187e+08 | G27: 5.2026323e+08 | H27: 1303 | I27: 263765.73 | J27: 314979.52 | K27: =I27-J27 -> -51213.79 | L27: =I27+Jan!L27 -> 561599.59 | M27: =J27+Jan!M27 -> 3921612.2 | N27: =L27-M27 -> -3360012.6
A28: Primarily invested in Peso Securities (units)
B29: 20 | C29: COL Equity Index Unitized Mutual Fund, Inc. | D29: 1.7671353e+08 | E29: 2246958.8 | F29: =D29-E29 -> 1.7446658e+08 | G29: 1.7137742e+08 | H29: 1465 | I29: 45551836 | J29: 557412.75 | K29: =I29-J29 -> 44994424 | L29: =I29+Jan!L29 -> 64214155 | M29: =J29+Jan!M29 -> 2088941.2 | N29: =L29-M29 -> 62125214
B30: 21 | C30: Philequity Alpha One Fund, Inc. | D30: 3.4782165e+08 | E30: 10344952 | F30: =D30-E30 -> 3.3747669e+08 | G30: 3.1460403e+08 | H30: 1429 | I30: 3264446.1 | J30: 2521190.8 | K30: =I30-J30 -> 743255.36 | L30: =I30+Jan!L30 -> 4622204.5 | M30: =J30+Jan!M30 -> 12063407 | N30: =L30-M30 -> -7441203
B31: 22 | C31: Philippine Stock Index Fund Corp. | D31: 4.6996851e+08 | E31: 7064764.4 | F31: =D31-E31 -> 4.6290375e+08 | G31: 4.5824565e+08 | H31: 434548 | I31: 25170461 | J31: 17366285 | K31: =I31-J31 -> 7804176.4 | L31: =I31+Jan!L31 -> 58476497 | M31: =J31+Jan!M31 -> 71909731 | N31: =L31-M31 -> -13433235
A32: Exchange Traded Fund
B33: 23 | C33: First Metro Phil. Equity Exchange Traded Fund, Inc. | D33: 2.1365612e+09 | E33: 3745023.1 | F33: =D33-E33 -> 2132816191 | G33: 2.1297303e+09 | H33: 3245 | I33: 2057862 | J33: 0 | K33: =I33-J33 -> 2057862 | L33: =I33+Jan!L33 -> 3092394 | M33: =J33+Jan!M33 -> 73813261 | N33: =L33-M33 -> -70720867
A34: Sub total - Peso Currency | D34: =SUM(D9:D33) -> 68675584847 | E34: =SUM(E9:E33) -> 8.7031038e+08 | F34: =SUM(F9:F33) -> 67805274464 | G34: =SUM(G9:G33) -> 64436560313 | H34: =SUM(H9:H33) -> 721047 | I34: =SUM(I9:I33) -> 9.74199e+08 | J34: =SUM(J9:J33) -> 6.4554395e+08 | K34: =SUM(K9:K33) -> 3.2865505e+08 | ... N34: =SUM(N9:N33) -> -1.0224896e+08
A35: Primarily invested in foreign currency securities (shares)
B36: 24 | C36: ATRAM AsiaPlus Equity Fund, Inc. | D36: 36002947 | E36: 910124.83 | F36: =D36-E36 -> 35092822 | G36: 0 | H36: 54 | I36: 67873.86 | J36: 0 | K36: =I36-J36 -> 67873.86 | L36: =I36+Jan!L36 -> 68073.4 | M36: =J36+Jan!M36 -> 0 | N36: =L36-M36 -> 68073.4
B37: 25 | C37: Sun Life Prosperity World Voyager Fund, Inc. | D37: 1.8279623e+09 | E37: 8697686.8 | F37: =D37-E37 -> 1819264644 | G37: 0 | H37: 2879 | I37: 3800636 | J37: 19577478 | K37: =I37-J37 -> -15776842 | L37: =I37+Jan!L37 -> 16920677 | M37: =J37+Jan!M37 -> 49913545 | N37: =L37-M37 -> -32992868
A38: Sub total - US Currency | D38: =SUM(D36:D37) -> 1863965278 | E38: =SUM(E36:E37) -> 9607811.6 | F38: =SUM(F36:F37) -> 1854357466 | G38: =SUM(G36:G37) -> 0 | H38: =SUM(H36:H37) -> 2933 | I38: =SUM(I36:I37) -> 3868509.8 | J38: =SUM(J36:J37) -> 19577478 | K38: =SUM(K36:K37) -> -15708968 | ... N38: =SUM(N36:N37) -> -32924795
A39: Sub total - stock funds | D39: =D34+D38 -> 70539550125 | E39: =E34+E38 -> 879918195 | F39: =F34+F38 -> 69659631930 | G39: =G34+G38 -> 64436560313 | H39: =H34+H38 -> 723980 | I39: =I34+I38 -> 9.7806751e+08 | J39: =J34+J38 -> 665121432 | K39: =K34+K38 -> 3.1294608e+08 | ... N39: =N34+N38 -> -1.3517376e+08
A40: Balanced Funds
A41: Primarily invested in Peso Securities (shares)
B42: 26 | C42: ATRAM Dynamic Allocation Fund, Inc. | D42: 1.1782494e+08 | E42: 2052775 | F42: =D42-E42 -> 1.1577217e+08 | G42: 29155169 | H42: 722 | I42: 294604.87 | J42: 165504.09 | K42: =I42-J42 -> 129100.78 | L42: =I42+Jan!L42 -> 612854.55 | M42: =J42+Jan!M42 -> 432191.39 | N42: =L42-M42 -> 180663.16
B43: 27 | C43: ATRAM Philippine Balanced Fund, Inc. | D43: 5.8733469e+08 | E43: 11120079 | F43: =D43-E43 -> 5.7621461e+08 | G43: 2.3992904e+08 | H43: 2429 | I43: 1058123.5 | J43: 10518807 | K43: =I43-J43 -> -9460683.7 | L43: =I43+Jan!L43 -> 2105538 | M43: =J43+Jan!M43 -> 12448879 | N43: =L43-M43 -> -10343341
B44: 28 | C44: First Metro Save and Learn Balanced Fund, Inc. | D44: 1.0609576e+09 | E44: 6332406.8 | F44: =D44-E44 -> 1054625155 | G44: 5.5201376e+08 | H44: 4688 | I44: 1163040.7 | J44: 4113169.4 | K44: =I44-J44 -> -2950128.7 | L44: =I44+Jan!L44 -> 2498371.5 | M44: =J44+Jan!M44 -> 9249089.1 | N44: =L44-M44 -> -6750717.5
B45: 29 | C45: First Metro Save and Learn F.O.C.C.U.S. Dynamic Fund, Inc. | D45: 2.8443675e+08 | E45: 1055455.5 | F45: =D45-E45 -> 283381291 | G45: 1.7929856e+08 | H45: 237 | I45: 4505725.9 | J45: 16492535 | K45: =I45-J45 -> -11986809 | L45: =I45+Jan!L45 -> 9110349.3 | M45: =J45+Jan!M45 -> 28338687 | N45: =L45-M45 -> -19228338
B46: 30 | C46: NCM Mutual Fund of the Phils., Inc. | D46: 3.5178492e+08 | E46: 4220203.5 | F46: =D46-E46 -> 3.4756472e+08 | G46: 1.5637283e+08 | H46: 55 | I46: 0 | J46: 168529 | K46: =I46-J46 -> -168529 | L46: =I46+Jan!L46 -> 0 | M46: =J46+Jan!M46 -> 168529 | N46: =L46-M46 -> -168529
...

Sheet Feb UPDATED
A1: PHILIPPINE INVESTMENT FUNDS ASSOCIATION, INC.
A2: MUTUAL FUNDS STATISTICAL REPORT
A3: Month of February 2023
A4: (Amounts in Peso)
I5: F O R - T H E - M O N T H | L5: Y E A R - T O - D A T E
A6: Fund Category | C6: Fund Name | D6: ASSETS | E6: LIABILITIES | F6: NET ASSETS | G6: EQUITY INV. | H6: NO. OF A/C | I6: SALES | J6: REDEMPTIONS | K6: NET SALES | L6: TOTAL SALES | M6: TOTAL REDEMPTIONS | N6: TOTAL NET SALES
A7: Stock Funds
A8: Primarily invested in Peso Securities (shares)
B9: 1 | C9: ALFM Growth Fund, Inc. | D9: 4593872904 | E9: 12038727 | F9: =D9-E9 -> 4581834177 | G9: 4291574273 | H9: 7236 | I9: 5275082 | J9: 24704237 | K9: =I9-J9 -> -19429155 | L9: =I9+Jan!L9 -> 11981921 | M9: =J9+Jan!M9 -> 99910370 | N9: =L9-M9 -> -87928449
B10: 2 | C10: ATRAM Alpha Opportunity Fund, Inc. | D10: 7.8551118e+08 | E10: 21049873 | F10: =D10-E10 -> 7.6446131e+08 | G10: 7.1177413e+08 | H10: 4221 | I10: 5560274.9 | J10: 12336999 | K10: =I10-J10 -> -6776724.6 | L10: =I10+Jan!L10 -> 10060031 | M10: =J10+Jan!M10 -> 28554190 | N10: =L10-M10 -> -18494159
B11: 3 | C11: ATRAM Phil. Equity Opportunity Fund, Inc. | D11: 1.6316838e+09 | E11: 1.0575227e+08 | F11: =D11-E11 -> 1525931484 | G11: 1.4548882e+09 | H11: 2874 | I11: 1.8514609e+08 | J11: 1.2266104e+08 | K11: =I11-J11 -> 62485054 | L11: =I11+Jan!L11 -> 3.7310243e+08 | M11: =J11+Jan!M11 -> 1.3291271e+08 | N11: =L11-M11 -> 2.4018971e+08
B12: 4 | C12: Climbs Share Capital Equity Investment Fund Corp. | D12: 3.6020278e+08 | E12: 17762394 | F12: =D12-E12 -> 3.4244039e+08 | G12: 2.0451595e+08 | H12: 1743 | I12: 588897.45 | J12: 71172.65 | K12: =I12-J12 -> 517724.8 | L12: =I12+Jan!L12 -> 1129901.9 | M12: =J12+Jan!M12 -> 179339.26 | N12: =L12-M12 -> 950562.69
B13: 5 | C13: First Metro Consumer Fund, Inc. | D13: 5.3822817e+08 | E13: 1229091.1 | F13: =D13-E13 -> 5.3699908e+08 | G13: 4.2599787e+08 | H13: 1428 | I13: 539284.43 | J13: 284725.86 | K13: =I13-J13 -> 254558.57 | L13: =I13+Jan!L13 -> 1303142.5 | M13: =J13+Jan!M13 -> 3583593.4 | N13: =L13-M13 -> -2280450.9
B14: 6 | C14: First Metro Save and Learn Equity Fund, Inc. | D14: 4.2099549e+09 | E14: 21850252 | F14: =D14-E14 -> 4188104604 | G14: 3.4415412e+09 | H14: 16190 | I14: 13071496 | J14: 17052745 | K14: =I14-J14 -> -3981249.8 | L14: =I14+Jan!L14 -> 32385308 | M14: =J14+Jan!M14 -> 71058749 | N14: =L14-M14 -> -38673441
B15: 7 | C15: First Metro Save and Learn Phil. Index Fund, Inc. | D15: 99621798 | E15: 1254140.8 | F15: =D15-E15 -> 98367658 | G15: 96925675 | H15: 554 | I15: 728740.25 | J15: 676891.31 | K15: =I15-J15 -> 51848.94 | L15: =I15+Jan!L15 -> 1489676.7 | M15: =J15+Jan!M15 -> 3847209.9 | N15: =L15-M15 -> -2357533.2
B16: 8 | C16: MBG Equity Investment Fund, Inc. | D16: 119846366 | E16: 2353974 | F16: =D16-E16 -> 117492392 | G16: 106689337 | H16: 50 | I16: 0 | J16: 496031 | K16: =I16-J16 -> -496031 | L16: =I16+Jan!L16 -> 0 | M16: =J16+Jan!M16 -> 496031 | N16: =L16-M16 -> -496031
B17: 9 | C17: PAMI Equity Index Fund, Inc. | D17: 1356343217 | E17: 74584016 | F17: =D17-E17 -> 1281759201 | G17: 1301656259 | H17: 12224 | I17: 0 | J17: 6972690 | K17: =I17-J17 -> -6972690 | L17: =I17+Jan!L17 -> 0 | M17: =J17+Jan!M17 -> 29187471 | N17: =L17-M17 -> -29187471
B18: 10 | C18: Philam Strategic Growth Fund, Inc. | D18: 3876027145 | E18: 161955174 | F18: =D18-E18 -> 3714071971 | G18: 3424225386 | H18: 12187 | I18: 3137498 | J18: 24799237 | K18: =I18-J18 -> -21661739 | L18: =I18+Jan!L18 -> 7829205 | M18: =J18+Jan!M18 -> 48041762 | N18: =L18-M18 -> -40212557
B19: 11 | C19: Philequity Dividend Yield Fund, Inc. | D19: 2.2240016e+09 | E19: 16490897 | F19: =D19-E19 -> 2207510676 | G19: 1.8905677e+09 | H19: 5618 | I19: 62015147 | J19: 3355607.8 | K19: =I19-J19 -> 58659539 | L19: =I19+Jan!L19 -> 1.3360903e+08 | M19: =J19+Jan!M19 -> 7631625.2 | N19: =L19-M19 -> 1.259774e+08
B20: 12 | C20: Philequity Fund, Inc. | D20: 9.9096779e+09 | E20: 1.7157781e+08 | F20: =D20-E20 -> 9738100086 | G20: 9.0494972e+09 | H20: 36023 | I20: 9950257.6 | J20: 21788683 | K20: =I20-J20 -> -11838425 | L20: =I20+Jan!L20 -> 20583916 | M20: =J20+Jan!M20 -> 66928621 | N20: =L20-M20 -> -46344705
... B27: 19 | C27: United Fund, Inc. | D27: 5.9229189e+08 | E27: 1560024.1 | F27: =D27-E27 -> 5.9073187e+08 | G27: 5.2026323e+08 | H27: 1303 | I27: 263765.73 | J27: 314979.52 | K27: =I27-J27 -> -51213.79 | L27: =I27+Jan!L27 -> 561599.59 | M27: =J27+Jan!M27 -> 3921612.2 | N27: =L27-M27 -> -3360012.6
A28: Primarily invested in Peso Securities (units)
B29: 20 | C29: COL Equity Index Unitized Mutual Fund, Inc. * | D29: 1.7671353e+08 | E29: 2246958.8 | F29: =D29-E29 -> 1.7446658e+08 | G29: 1.7137742e+08 | H29: 1465 | I29: 49591258 | J29: 608149.37 | K29: =I29-J29 -> 48983109 | L29: =I29+Jan!L29 -> 68253577 | M29: =J29+Jan!M29 -> 2139677.8 | N29: =L29-M29 -> 66113899
B30: 21 | C30: Philequity Alpha One Fund, Inc. | D30: 3.4782165e+08 | E30: 10344952 | F30: =D30-E30 -> 3.3747669e+08 | G30: 3.1460403e+08 | H30: 1429 | I30: 3264446.1 | J30: 2521190.8 | K30: =I30-J30 -> 743255.36 | L30: =I30+Jan!L30 -> 4622204.5 | M30: =J30+Jan!M30 -> 12063407 | N30: =L30-M30 -> -7441203
B31: 22 | C31: Philippine Stock Index Fund Corp. | D31: 4.6996851e+08 | E31: 7064764.4 | F31: =D31-E31 -> 4.6290375e+08 | G31: 4.5824565e+08 | H31: 434548 | I31: 25170461 | J31: 17366285 | K31: =I31-J31 -> 7804176.4 | L31: =I31+Jan!L31 -> 58476497 | M31: =J31+Jan!M31 -> 71909731 | N31: =L31-M31 -> -13433235
A32: Exchange Traded Fund
B33: 23 | C33: First Metro Phil. Equity Exchange Traded Fund, Inc. | D33: 2.1365612e+09 | E33: 3745023.1 | F33: =D33-E33 -> 2132816191 | G33: 2.1297303e+09 | H33: 3245 | I33: 2057862 | J33: 0 | K33: =I33-J33 -> 2057862 | L33: =I33+Jan!L33 -> 3092394 | M33: =J33+Jan!M33 -> 73813261 | N33: =L33-M33 -> -70720867
A34: Sub total - Peso Currency | D34: =SUM(D9:D33) -> 68675584847 | E34: =SUM(E9:E33) -> 8.7031038e+08 | F34: =SUM(F9:F33) -> 67805274464 | G34: =SUM(G9:G33) -> 64436560313 | H34: =SUM(H9:H33) -> 721047 | I34: =SUM(I9:I33) -> 9.7823842e+08 | J34: =SUM(J9:J33) -> 6.4559469e+08 | K34: =SUM(K9:K33) -> 332643732 | ... N34: =SUM(N9:N33) -> -98260279
A35: Primarily invested in foreign currency securities (shares)
B36: 24 | C36: ATRAM AsiaPlus Equity Fund, Inc. | D36: 36002947 | E36: 910124.83 | F36: =D36-E36 -> 35092822 | G36: 0 | H36: 54 | I36: 67873.86 | J36: 0 | K36: =I36-J36 -> 67873.86 | L36: =I36+Jan!L36 -> 68073.4 | M36: =J36+Jan!M36 -> 0 | N36: =L36-M36 -> 68073.4
B37: 25 | C37: Sun Life Prosperity World Voyager Fund, Inc. | D37: 1.8279623e+09 | E37: 8697686.8 | F37: =D37-E37 -> 1819264644 | G37: 0 | H37: 2879 | I37: 3800636 | J37: 19577478 | K37: =I37-J37 -> -15776842 | L37: =I37+Jan!L37 -> 16920677 | M37: =J37+Jan!M37 -> 49913545 | N37: =L37-M37 -> -32992868
A38: Sub total - US Currency | D38: =SUM(D36:D37) -> 1863965278 | E38: =SUM(E36:E37) -> 9607811.6 | F38: =SUM(F36:F37) -> 1854357466 | G38: =SUM(G36:G37) -> 0 | H38: =SUM(H36:H37) -> 2933 | I38: =SUM(I36:I37) -> 3868509.8 | J38: =SUM(J36:J37) -> 19577478 | K38: =SUM(K36:K37) -> -15708968 | ... N38: =SUM(N36:N37) -> -32924795
A39: Sub total - stock funds | D39: =D34+D38 -> 70539550125 | E39: =E34+E38 -> 879918195 | F39: =F34+F38 -> 69659631930 | G39: =G34+G38 -> 64436560313 | H39: =H34+H38 -> 723980 | I39: =I34+I38 -> 9.8210693e+08 | J39: =J34+J38 -> 6.6517217e+08 | K39: =K34+K38 -> 3.1693476e+08 | ... N39: =N34+N38 -> -1.3118507e+08
A40: Balanced Funds
A41: Primarily invested in Peso Securities (shares)
B42: 26 | C42: ATRAM Dynamic Allocation Fund, Inc. | D42: 1.1782494e+08 | E42: 2052775 | F42: =D42-E42 -> 1.1577217e+08 | G42: 29155169 | H42: 722 | I42: 294604.87 | J42: 165504.09 | K42: =I42-J42 -> 129100.78 | L42: =I42+Jan!L42 -> 612854.55 | M42: =J42+Jan!M42 -> 432191.39 | N42: =L42-M42 -> 180663.16
B43: 27 | C43: ATRAM Philippine Balanced Fund, Inc. | D43: 5.8733469e+08 | E43: 11120079 | F43: =D43-E43 -> 5.7621461e+08 | G43: 2.3992904e+08 | H43: 2429 | I43: 1058123.5 | J43: 10518807 | K43: =I43-J43 -> -9460683.7 | L43: =I43+Jan!L43 -> 2105538 | M43: =J43+Jan!M43 -> 12448879 | N43: =L43-M43 -> -10343341
B44: 28 | C44: First Metro Save and Learn Balanced Fund, Inc. | D44: 1.0609576e+09 | E44: 6332406.8 | F44: =D44-E44 -> 1054625155 | G44: 5.5201376e+08 | H44: 4688 | I44: 1163040.7 | J44: 4113169.4 | K44: =I44-J44 -> -2950128.7 | L44: =I44+Jan!L44 -> 2498371.5 | M44: =J44+Jan!M44 -> 9249089.1 | N44: =L44-M44 -> -6750717.5
B45: 29 | C45: First Metro Save and Learn F.O.C.C.U.S. Dynamic Fund, Inc. | D45: 2.8443675e+08 | E45: 1055455.5 | F45: =D45-E45 -> 283381291 | G45: 1.7929856e+08 | H45: 237 | I45: 4505725.9 | J45: 16492535 | K45: =I45-J45 -> -11986809 | L45: =I45+Jan!L45 -> 9110349.3 | M45: =J45+Jan!M45 -> 28338687 | N45: =L45-M45 -> -19228338
B46: 30 | C46: NCM Mutual Fund of the Phils., Inc. | D46: 3.5178492e+08 | E46: 4220203.5 | F46: =D46-E46 -> 3.4756472e+08 | G46: 1.5637283e+08 | H46: 55 | I46: 0 | J46: 168529 | K46: =I46-J46 -> -168529 | L46: =I46+Jan!L46 -> 0 | M46: =J46+Jan!M46 -> 168529 | N46: =L46-M46 -> -168529
...

Sheet Mar
A1: PHILIPPINE INVESTMENT FUNDS ASSOCIATION, INC.
A2: MUTUAL FUNDS STATISTICAL REPORT
A3: Month of March 2023
A4: (Amounts in Peso)
I5: F O R - T H E - M O N T H | L5: Y E A R - T O - D A T E
A6: Fund Category | C6: Fund Name | D6: ASSETS | E6: LIABILITIES | F6: NET ASSETS | G6: EQUITY INV. | H6: NO. OF A/C | I6: SALES | J6: REDEMPTIONS | K6: NET SALES | L6: TOTAL SALES | M6: TOTAL REDEMPTIONS | N6: TOTAL NET SALES
A7: Stock Funds
A8: Primarily invested in Peso Securities (shares)
B9: 1 | C9: ALFM Growth Fund, Inc. | D9: 4.5930377e+09 | E9: 13267230 | F9: =D9-E9 -> 4579770512 | G9: 4.1517953e+09 | H9: 7209 | I9: 7212185.2 | J9: 51464462 | K9: =I9-J9 -> -44252276 | L9: =I9+'Feb UPDATED'!L9 -> 19194106 | M9: =J9+'Feb UPDATED'!M9 -> 151374832 | N9: =L9-M9 -> -1.3218073e+08
B10: 2 | C10: ATRAM Alpha Opportunity Fund, Inc. | D10: 7.6055047e+08 | E10: 2013776.8 | F10: =D10-E10 -> 7.5853669e+08 | G10: 7.1270159e+08 | H10: 4236 | I10: 5649888.2 | J10: 7842522.9 | K10: =I10-J10 -> -2192634.8 | L10: =I10+'Feb UPDATED'!L10 -> 15709919 | M10: =J10+'Feb UPDATED'!M10 -> 36396713 | N10: =L10-M10 -> -20686794
B11: 3 | C11: ATRAM Phil. Equity Opportunity Fund, Inc. | D11: 1.5343198e+09 | E11: 10438363 | F11: =D11-E11 -> 1523881453 | G11: 1.4512293e+09 | H11: 2853 | I11: 13436930 | J11: 30540757 | K11: =I11-J11 -> -17103827 | L11: =I11+'Feb UPDATED'!L11 -> 3.8653936e+08 | M11: =J11+'Feb UPDATED'!M11 -> 1.6345347e+08 | N11: =L11-M11 -> 223085885
B12: 4 | C12: Climbs Share Capital Equity Investment Fund Corp. | D12: 348883651 | E12: 8791778 | F12: =D12-E12 -> 340091873 | G12: 220716415 | H12: 1764 | I12: 536436 | J12: 1007506 | K12: =I12-J12 -> -471070 | L12: =I12+'Feb UPDATED'!L12 -> 1666337.9 | M12: =J12+'Feb UPDATED'!M12 -> 1186845.3 | N12: =L12-M12 -> 479492.69
B13: 5 | C13: First Metro Consumer Fund, Inc. | D13: 541654128 | E13: 16316480 | F13: =D13-E13 -> 525337648 | G13: 406134465 | H13: 1417 | I13: 704602 | J13: 1284122 | K13: =I13-J13 -> -579520 | L13: =I13+'Feb UPDATED'!L13 -> 2007744.5 | M13: =J13+'Feb UPDATED'!M13 -> 4867715.4 | N13: =L13-M13 -> -2859970.9
B14: 6 | C14: First Metro Save and Learn Equity Fund, Inc. | D14: 4294125331 | E14: 54589409 | F14: =D14-E14 -> 4239535922 | G14: 3446659166 | H14: 16139 | I14: 53938628 | J14: 17662981 | K14: =I14-J14 -> 36275647 | L14: =I14+'Feb UPDATED'!L14 -> 86323936 | M14: =J14+'Feb UPDATED'!M14 -> 88721730 | N14: =L14-M14 -> -2397794
B15: 7 | C15: First Metro Save and Learn Phil. Index Fund, Inc. | D15: 102660882 | E15: 1124945 | F15: =D15-E15 -> 101535937 | G15: 98641450 | H15: 549 | I15: 3956298 | J15: 959993 | K15: =I15-J15 -> 2996305 | L15: =I15+'Feb UPDATED'!L15 -> 5445974.7 | M15: =J15+'Feb UPDATED'!M15 -> 4807202.9 | N15: =L15-M15 -> 638771.8
B16: 8 | C16: MBG Equity Investment Fund, Inc. | D16: 1.2168999e+08 | E16: 1062505 | F16: =D16-E16 -> 1.2062748e+08 | G16: 105391640 | H16: 51 | I16: 241.49 | J16: 268193.93 | K16: =I16-J16 -> -267952.44 | L16: =I16+'Feb UPDATED'!L16 -> 241.49 | M16: =J16+'Feb UPDATED'!M16 -> 764224.93 | N16: =L16-M16 -> -763983.44
B17: 9 | C17: PAMI Equity Index Fund, Inc. | D17: 1.3464719e+09 | E17: 79787345 | F17: =D17-E17 -> 1266684572 | G17: 1.281623e+09 | H17: 12183 | I17: 0 | J17: 20483067 | K17: =I17-J17 -> -20483067 | L17: =I17+'Feb UPDATED'!L17 -> 0 | M17: =J17+'Feb UPDATED'!M17 -> 49670539 | N17: =L17-M17 -> -49670539
B18: 10 | C18: Philam Strategic Growth Fund, Inc. | D18: 3.8702801e+09 | E18: 1.6238491e+08 | F18: =D18-E18 -> 3707895226 | G18: 3.3366802e+09 | H18: 12130 | I18: 2454163.6 | J18: 39361027 | K18: =I18-J18 -> -36906863 | L18: =I18+'Feb UPDATED'!L18 -> 10283369 | M18: =J18+'Feb UPDATED'!M18 -> 87402788 | N18: =L18-M18 -> -77119420
B19: 11 | C19: Philequity Dividend Yield Fund, Inc. | D19: 2324690919 | E19: 67392048 | F19: =D19-E19 -> 2257298871 | G19: 2002288623 | H19: 5565 | I19: 1859089 | J19: 3785416 | K19: =I19-J19 -> -1926327 | L19: =I19+'Feb UPDATED'!L19 -> 1.3546812e+08 | M19: =J19+'Feb UPDATED'!M19 -> 11417041 | N19: =L19-M19 -> 1.2405108e+08
B20: 12 | C20: Philequity Fund, Inc. | D20: 9851454792 | E20: 48552221 | F20: =D20-E20 -> 9802902571 | G20: 9048438933 | H20: 35874 | I20: 43035302 | J20: 88408991 | K20: =I20-J20 -> -45373689 | L20: =I20+'Feb UPDATED'!L20 -> 63619218 | M20: =J20+'Feb UPDATED'!M20 -> 1.5533761e+08 | N20: =L20-M20 -> -91718394
... B27: 19 | C27: United Fund, Inc. | D27: 593533972 | E27: 1520125 | F27: =D27-E27 -> 592013847 | G27: 520375775 | H27: 1302 | I27: 3393106 | J27: 219792 | K27: =I27-J27 -> 3173314 | L27: =I27+'Feb UPDATED'!L27 -> 3954705.6 | M27: =J27+'Feb UPDATED'!M27 -> 4141404.2 | N27: =L27-M27 -> -186698.59
A28: Primarily invested in Peso Securities (units)
B29: 20 | C29: COL Equity Index Unitized Mutual Fund, Inc. | D29: 188703003 | E29: 1910155 | F29: =D29-E29 -> 186792848 | G29: 182350549 | H29: 1715 | I29: 14561464 | J29: 1720354 | K29: =I29-J29 -> 12841110 | L29: =I29+'Feb UPDATED'!L29 -> 82815041 | M29: =J29+'Feb UPDATED'!M29 -> 3860031.8 | N29: =L29-M29 -> 78955009
B30: 21 | C30: Philequity Alpha One Fund, Inc. | D30: 344864889 | E30: 915563 | F30: =D30-E30 -> 343949326 | G30: 309407557 | H30: 1423 | I30: 3497496 | J30: 778190 | K30: =I30-J30 -> 2719306 | L30: =I30+'Feb UPDATED'!L30 -> 8119700.5 | M30: =J30+'Feb UPDATED'!M30 -> 12841597 | N30: =L30-M30 -> -4721897
B31: 22 | C31: Philippine Stock Index Fund Corp. | D31: 4.9618635e+08 | E31: 7396072.5 | F31: =D31-E31 -> 4.8879028e+08 | G31: 4.8592705e+08 | H31: 370846 | I31: 39144887 | J31: 15349031 | K31: =I31-J31 -> 23795856 | L31: =I31+'Feb UPDATED'!L31 -> 97621384 | M31: =J31+'Feb UPDATED'!M31 -> 87258762 | N31: =L31-M31 -> 10362622
A32: Exchange Traded Fund
B33: 23 | C33: First Metro Phil. Equity Exchange Traded Fund, Inc. | D33: 2163447240 | E33: 1898036 | F33: =D33-E33 -> 2161549204 | G33: 2129490212 | H33: 3275 | I33: 21164197 | J33: 3087328 | K33: =I33-J33 -> 18076869 | L33: =I33+'Feb UPDATED'!L33 -> 24256591 | M33: =J33+'Feb UPDATED'!M33 -> 76900589 | N33: =L33-M33 -> -52643998
A34: Sub total - Peso Currency | D34: =SUM(D9:D33) -> 68839892558 | E34: =SUM(E9:E33) -> 7.4316658e+08 | F34: =SUM(F9:F33) -> 68096725981 | G34: =SUM(G9:G33) -> 64102287028 | H34: =SUM(H9:H33) -> 657161 | I34: =SUM(I9:I33) -> 4.5161649e+08 | J34: =SUM(J9:J33) -> 5.8120572e+08 | K34: =SUM(K9:K33) -> -1.2958923e+08 | ... N34: =SUM(N9:N33) -> -2.278495e+08
A35: Primarily invested in foreign currency securities (shares)
B36: 24 | C36: ATRAM AsiaPlus Equity Fund, Inc. | D36: 35712481 | E36: 1261270.5 | F36: =D36-E36 -> 34451210 | G36: 0 | H36: 54 | I36: 10806.22 | J36: 19382.09 | K36: =I36-J36 -> -8575.87 | L36: =I36+'Feb UPDATED'!L36 -> 78879.62 | M36: =J36+'Feb UPDATED'!M36 -> 19382.09 | N36: =L36-M36 -> 59497.53
B37: 25 | C37: Sun Life Prosperity World Voyager Fund, Inc. | D37: 1796930439 | E37: 27142106 | F37: =D37-E37 -> 1769788333 | G37: 0 | H37: 2880 | I37: 1554385 | J37: 27846024 | K37: =I37-J37 -> -26291639 | L37: =I37+'Feb UPDATED'!L37 -> 18475062 | M37: =J37+'Feb UPDATED'!M37 -> 77759569 | N37: =L37-M37 -> -59284507
A38: Sub total - US Currency | D38: =SUM(D36:D37) -> 1832642920 | E38: =SUM(E36:E37) -> 28403376 | F38: =SUM(F36:F37) -> 1804239543 | G38: =SUM(G36:G37) -> 0 | H38: =SUM(H36:H37) -> 2934 | I38: =SUM(I36:I37) -> 1565191.2 | J38: =SUM(J36:J37) -> 27865406 | K38: =SUM(K36:K37) -> -26300215 | ... N38: =SUM(N36:N37) -> -59225009
A39: Sub total - stock funds | D39: =D34+D38 -> 70672535478 | E39: =E34+E38 -> 7.7156995e+08 | F39: =F34+F38 -> 69900965524 | G39: =G34+G38 -> 64102287028 | H39: =H34+H38 -> 660095 | I39: =I34+I38 -> 4.5318168e+08 | J39: =J34+J38 -> 6.0907112e+08 | K39: =K34+K38 -> -1.5588944e+08 | ... N39: =N34+N38 -> -2.8707451e+08
A40: Balanced Funds
A41: Primarily invested in Peso Securities (shares)
B42: 26 | C42: ATRAM Dynamic Allocation Fund, Inc. | D42: 1.2098976e+08 | E42: 4620873.4 | F42: =D42-E42 -> 116368890 | G42: 38906616 | H42: 721 | I42: 477641.51 | J42: 307049.61 | K42: =I42-J42 -> 170591.9 | L42: =I42+'Feb UPDATED'!L42 -> 1090496.1 | M42: =J42+'Feb UPDATED'!M42 -> 739241 | N42: =L42-M42 -> 351255.06
B43: 27 | C43: ATRAM Philippine Balanced Fund, Inc. | D43: 6.1051091e+08 | E43: 29223817 | F43: =D43-E43 -> 5.812871e+08 | G43: 3.0887455e+08 | H43: 2421 | I43: 1018084.1 | J43: 3716688.6 | K43: =I43-J43 -> -2698604.5 | L43: =I43+'Feb UPDATED'!L43 -> 3123622.1 | M43: =J43+'Feb UPDATED'!M43 -> 16165567 | N43: =L43-M43 -> -13041945
B44: 28 | C44: First Metro Save and Learn Balanced Fund, Inc. | D44: 1066573414 | E44: 10403781 | F44: =D44-E44 -> 1056169633 | G44: 491266510 | H44: 4666 | I44: 3988943 | J44: 5214011 | K44: =I44-J44 -> -1225068 | L44: =I44+'Feb UPDATED'!L44 -> 6487314.5 | M44: =J44+'Feb UPDATED'!M44 -> 14463100 | N44: =L44-M44 -> -7975785.5
B45: 29 | C45: First Metro Save and Learn F.O.C.C.U.S. Dynamic Fund, Inc. | D45: 275364511 | E45: 5099873 | F45: =D45-E45 -> 270264638 | G45: 127721725 | H45: 242 | I45: 561245 | J45: 14197748 | K45: =I45-J45 -> -13636503 | L45: =I45+'Feb UPDATED'!L45 -> 9671594.3 | M45: =J45+'Feb UPDATED'!M45 -> 42536435 | N45: =L45-M45 -> -32864841
B46: 30 | C46: NCM Mutual Fund of the Phils., Inc. | D46: 348826992 | E46: 4210140 | F46: =D46-E46 -> 344616852 | G46: 154934365 | H46: 54 | I46: 0 | J46: 1339656 | K46: =I46-J46 -> -1339656 | L46: =I46+'Feb UPDATED'!L46 -> 0 | M46: =J46+'Feb UPDATED'!M46 -> 1508185 | N46: =L46-M46 -> -1508185
...

Sheet Q1
A1: PHILIPPINE INVESTMENT FUNDS ASSOCIATION, INC.
A2: MUTUAL FUNDS STATISTICAL REPORT
A3: As of the First Quarter of 2023
A4: (Amounts in Peso)
A6: Fund Category | C6: Fund Name | D6: NET ASSETS | E6: TOTAL SALES | F6: TOTAL REDEMPTIONS | G6: NET SALES
A7: Stock Funds
A8: Primarily invested in Peso Securities (shares)
B9: 1 | C9: ALFM Growth Fund, Inc. | D9: =Mar!F9 -> 4579770512 | E9: =Jan!I9+'Feb UPDATED'!I9+Mar!I9 -> 19194106 | F9: =Jan!J9+'Feb UPDATED'!J9+Mar!J9 -> 151374832 | G9: =E9-F9 -> -1.3218073e+08
B10: 2 | C10: ATRAM Alpha Opportunity Fund, Inc. | D10: =Mar!F10 -> 7.5853669e+08 | E10: =Jan!I10+'Feb UPDATED'!I10+Mar!I10 -> 15709919 | F10: =Jan!J10+'Feb UPDATED'!J10+Mar!J10 -> 36396713 | G10: =E10-F10 -> -20686794
B11: 3 | C11: ATRAM Phil. Equity Opportunity Fund, Inc. | D11: =Mar!F11 -> 1523881453 | E11: =Jan!I11+'Feb UPDATED'!I11+Mar!I11 -> 3.8653936e+08 | F11: =Jan!J11+'Feb UPDATED'!J11+Mar!J11 -> 1.6345347e+08 | G11: =E11-F11 -> 223085885
B12: 4 | C12: Climbs Share Capital Equity Investment Fund Corp. | D12: =Mar!F12 -> 340091873 | E12: =Jan!I12+'Feb UPDATED'!I12+Mar!I12 -> 1666337.9 | F12: =Jan!J12+'Feb UPDATED'!J12+Mar!J12 -> 1186845.3 | G12: =E12-F12 -> 479492.69
B13: 5 | C13: First Metro Consumer Fund on MSCI Phils. IMI, Inc. | D13: =Mar!F13 -> 525337648 | E13: =Jan!I13+'Feb UPDATED'!I13+Mar!I13 -> 2007744.5 | F13: =Jan!J13+'Feb UPDATED'!J13+Mar!J13 -> 4867715.4 | G13: =E13-F13 -> -2859970.9
B14: 6 | C14: First Metro Save and Learn Equity Fund, Inc. | D14: =Mar!F14 -> 4239535922 | E14: =Jan!I14+'Feb UPDATED'!I14+Mar!I14 -> 86323936 | F14: =Jan!J14+'Feb UPDATED'!J14+Mar!J14 -> 88721730 | G14: =E14-F14 -> -2397794
B15: 7 | C15: First Metro Save and Learn Phil. Index Fund, Inc. | D15: =Mar!F15 -> 101535937 | E15: =Jan!I15+'Feb UPDATED'!I15+Mar!I15 -> 5445974.7 | F15: =Jan!J15+'Feb UPDATED'!J15+Mar!J15 -> 4807202.9 | G15: =E15-F15 -> 638771.8
B16: 8 | C16: MBG Equity Investment Fund, Inc. | D16: =Mar!F16 -> 1.2062748e+08 | E16: =Jan!I16+'Feb UPDATED'!I16+Mar!I16 -> 241.49 | F16: =Jan!J16+'Feb UPDATED'!J16+Mar!J16 -> 764224.93 | G16: =E16-F16 -> -763983.44
B17: 9 | C17: PAMI Equity Index Fund, Inc. | D17: =Mar!F17 -> 1266684572 | E17: =Jan!I17+'Feb UPDATED'!I17+Mar!I17 -> 0 | F17: =Jan!J17+'Feb UPDATED'!J17+Mar!J17 -> 49670539 | G17: =E17-F17 -> -49670539
B18: 10 | C18: Philam Strategic Growth Fund, Inc. | D18: =Mar!F18 -> 3707895226 | E18: =Jan!I18+'Feb UPDATED'!I18+Mar!I18 -> 10283369 | F18: =Jan!J18+'Feb UPDATED'!J18+Mar!J18 -> 87402788 | G18: =E18-F18 -> -77119420
B19: 11 | C19: Philequity Dividend Yield Fund, Inc. | D19: =Mar!F19 -> 2257298871 | E19: =Jan!I19+'Feb UPDATED'!I19+Mar!I19 -> 1.3546812e+08 | F19: =Jan!J19+'Feb UPDATED'!J19+Mar!J19 -> 11417041 | G19: =E19-F19 -> 1.2405108e+08
B20: 12 | C20: Philequity Fund, Inc. | D20: =Mar!F20 -> 9802902571 | E20: =Jan!I20+'Feb UPDATED'!I20+Mar!I20 -> 63619218 | F20: =Jan!J20+'Feb UPDATED'!J20+Mar!J20 -> 1.5533761e+08 | G20: =E20-F20 -> -91718394
... B27: 19 | C27: United Fund, Inc. | D27: =Mar!F27 -> 592013847 | E27: =Jan!I27+'Feb UPDATED'!I27+Mar!I27 -> 3954705.6 | F27: =Jan!J27+'Feb UPDATED'!J27+Mar!J27 -> 4141404.2 | G27: =E27-F27 -> -186698.59
A28: Primarily invested in Peso Securities (units)
B29: 20 | C29: COL Equity Index Unitized Mutual Fund, Inc. | D29: =Mar!F29 -> 186792848 | E29: =Jan!I29+'Feb UPDATED'!I29+Mar!I29 -> 82815041 | F29: =Jan!J29+'Feb UPDATED'!J29+Mar!J29 -> 3860031.8 | G29: =E29-F29 -> 78955009
B30: 21 | C30: Philequity Alpha One Fund, Inc. | D30: =Mar!F30 -> 343949326 | E30: =Jan!I30+'Feb UPDATED'!I30+Mar!I30 -> 8119700.5 | F30: =Jan!J30+'Feb UPDATED'!J30+Mar!J30 -> 12841597 | G30: =E30-F30 -> -4721897
B31: 22 | C31: Philippine Stock Index Fund Corp. | D31: =Mar!F31 -> 4.8879028e+08 | E31: =Jan!I31+'Feb UPDATED'!I31+Mar!I31 -> 97621384 | F31: =Jan!J31+'Feb UPDATED'!J31+Mar!J31 -> 87258762 | G31: =E31-F31 -> 10362622
A32: Exchange Traded Fund
B33: 23 | C33: First Metro Phil. Equity Exchange Traded Fund, Inc. | D33: =Mar!F33 -> 2161549204 | E33: =Jan!I33+'Feb UPDATED'!I33+Mar!I33 -> 24256591 | F33: =Jan!J33+'Feb UPDATED'!J33+Mar!J33 -> 76900589 | G33: =E33-F33 -> -52643998
A34: Sub total - Peso Currency | D34: =SUM(D9:D33) -> 68096725981 | E34: =SUM(E9:E33) -> 2385752875 | F34: =SUM(F9:F33) -> 2613602379 | G34: =SUM(G9:G33) -> -2.278495e+08
A35: Primarily invested in foreign currency securities (shares)
B36: 24 | C36: ATRAM AsiaPlus Equity Fund, Inc. | D36: =Mar!F36 -> 34451210 | E36: =Jan!I36+'Feb UPDATED'!I36+Mar!I36 -> 78879.62 | F36: =Jan!J36+'Feb UPDATED'!J36+Mar!J36 -> 19382.09 | G36: =E36-F36 -> 59497.53
B37: 25 | C37: Sun Life Prosperity World Voyager Fund, Inc. | D37: =Mar!F37 -> 1769788333 | E37: =Jan!I37+'Feb UPDATED'!I37+Mar!I37 -> 18475062 | F37: =Jan!J37+'Feb UPDATED'!J37+Mar!J37 -> 77759569 | G37: =E37-F37 -> -59284507
A38: Sub total - US Currency | D38: =SUM(D36:D37) -> 1804239543 | E38: =SUM(E36:E37) -> 18553942 | F38: =SUM(F36:F37) -> 77778952 | G38: =SUM(G36:G37) -> -59225009
A39: Sub total - stock funds | D39: =D34+D38 -> 69900965524 | E39: =E34+E38 -> 2404306817 | F39: =F34+F38 -> 2691381331 | G39: =G34+G38 -> -2.8707451e+08
A40: Balanced Funds
A41: Primarily invested in Peso Securities (shares)
B42: 26 | C42: ATRAM Dynamic Allocation Fund, Inc. | D42: =Mar!F42 -> 116368890 | E42: =Jan!I42+'Feb UPDATED'!I42+Mar!I42 -> 1090496.1 | F42: =Jan!J42+'Feb UPDATED'!J42+Mar!J42 -> 739241 | G42: =E42-F42 -> 351255.06
B43: 27 | C43: ATRAM Philippine Balanced Fund, Inc. | D43: =Mar!F43 -> 5.812871e+08 | E43: =Jan!I43+'Feb UPDATED'!I43+Mar!I43 -> 3123622.1 | F43: =Jan!J43+'Feb UPDATED'!J43+Mar!J43 -> 16165567 | G43: =E43-F43 -> -13041945
B44: 28 | C44: First Metro Save and Learn Balanced Fund, Inc. | D44: =Mar!F44 -> 1056169633 | E44: =Jan!I44+'Feb UPDATED'!I44+Mar!I44 -> 6487314.5 | F44: =Jan!J44+'Feb UPDATED'!J44+Mar!J44 -> 14463100 | G44: =E44-F44 -> -7975785.5
B45: 29 | C45: First Metro Save and Learn F.O.C.C.U.S. Dynamic Fund, Inc. | D45: =Mar!F45 -> 270264638 | E45: =Jan!I45+'Feb UPDATED'!I45+Mar!I45 -> 9671594.3 | F45: =Jan!J45+'Feb UPDATED'!J45+Mar!J45 -> 42536435 | G45: =E45-F45 -> -32864841
B46: 30 | C46: NCM Mutual Fund of the Phils., Inc. | D46: =Mar!F46 -> 344616852 | E46: =Jan!I46+'Feb UPDATED'!I46+Mar!I46 -> 0 | F46: =Jan!J46+'Feb UPDATED'!J46+Mar!J46 -> 1508185 | G46: =E46-F46 -> -1508185
B47: 31 | C47: PAMI Horizon Fund, Inc. | D47: =Mar!F47 -> 5.4365285e+08 | E47: =Jan!I47+'Feb UPDATED'!I47+Mar!I47 -> 1928994.3 | F47: =Jan!J47+'Feb UPDATED'!J47+Mar!J47 -> 12123095 | G47: =E47-F47 -> -10194101
...

Sheet Apr
A1: PHILIPPINE INVESTMENT FUNDS ASSOCIATION, INC.
A2: MUTUAL FUNDS STATISTICAL REPORT
A3: Month of April 2023
A4: (Amounts in Peso)
I5: F O R - T H E - M O N T H | L5: Y E A R - T O - D A T E
A6: Fund Category | C6: Fund Name | D6: ASSETS | E6: LIABILITIES | F6: NET ASSETS | G6: EQUITY INV. | H6: NO. OF A/C | I6: SALES | J6: REDEMPTIONS | K6: NET SALES | L6: TOTAL SALES | M6: TOTAL REDEMPTIONS | N6: TOTAL NET SALES
A7: Stock Funds
A8: Primarily invested in Peso Securities (shares)
B9: 1 | C9: ALFM Growth Fund, Inc. | D9: 4.667551e+09 | E9: 11980470 | F9: =D9-E9 -> 4655570510 | G9: 4.1886425e+09 | H9: 7172 | I9: 7189190.9 | J9: 20503747 | K9: =I9-J9 -> -13314556 | L9: =I9+Mar!L9 -> 26383297 | M9: =J9+Mar!M9 -> 1.7187858e+08 | N9: =L9-M9 -> -1.4549528e+08
B10: 2 | C10: ATRAM Alpha Opportunity Fund, Inc. | D10: 774351672 | E10: 3180125 | F10: =D10-E10 -> 771171547 | G10: 731386659 | H10: 4222 | I10: 3101557 | J10: 2532451 | K10: =I10-J10 -> 569106 | L10: =I10+Mar!L10 -> 18811476 | M10: =J10+Mar!M10 -> 38929164 | N10: =L10-M10 -> -20117688
B11: 3 | C11: ATRAM Phil. Equity Opportunity Fund, Inc. | D11: 1528840217 | E11: 92591666 | F11: =D11-E11 -> 1436248551 | G11: 1320522430 | H11: 2841 | I11: 11561939 | J11: 112504436 | K11: =I11-J11 -> -100942497 | L11: =I11+Mar!L11 -> 3.981013e+08 | M11: =J11+Mar!M11 -> 2.7595791e+08 | N11: =L11-M11 -> 122143388
B12: 4 | C12: Climbs Share Capital Equity Investment Fund Corp. | D12: 3.4791205e+08 | E12: 10358152 | F12: =D12-E12 -> 3.375539e+08 | G12: 2.2799623e+08 | H12: 1764 | I12: 356196.5 | J12: 90033.22 | K12: =I12-J12 -> 266163.28 | L12: =I12+Mar!L12 -> 2022534.4 | M12: =J12+Mar!M12 -> 1276878.5 | N12: =L12-M12 -> 745655.97
B13: 5 | C13: First Metro Consumer Fund, Inc. | D13: 527205896 | E13: 4272347 | F13: =D13-E13 -> 522933549 | G13: 404537326 | H13: 1402 | I13: 324817 | J13: 623219 | K13: =I13-J13 -> -298402 | L13: =I13+Mar!L13 -> 2332561.5 | M13: =J13+Mar!M13 -> 5490934.4 | N13: =L13-M13 -> -3158372.9
B14: 6 | C14: First Metro Save and Learn Equity Fund, Inc. | D14: 4411079875 | E14: 74465389 | F14: =D14-E14 -> 4336614486 | G14: 3698284832 | H14: 16086 | I14: 19127887 | J14: 12992516 | K14: =I14-J14 -> 6135371 | L14: =I14+Mar!L14 -> 1.0545182e+08 | M14: =J14+Mar!M14 -> 1.0171425e+08 | N14: =L14-M14 -> 3737577
B15: 7 | C15: First Metro Save and Learn Phil. Index Fund, Inc. | D15: 104697431 | E15: 799966 | F15: =D15-E15 -> 103897465 | G15: 101962097 | H15: 546 | I15: 662770 | J15: 320731 | K15: =I15-J15 -> 342039 | L15: =I15+Mar!L15 -> 6108744.7 | M15: =J15+Mar!M15 -> 5127933.9 | N15: =L15-M15 -> 980810.8
B16: 8 | C16: MBG Equity Investment Fund, Inc. | D16: 131712890 | E16: 3997860 | F16: =D16-E16 -> 127715030 | G16: 112676941 | H16: 50 | I16: 0 | J16: 1621658 | K16: =I16-J16 -> -1621658 | L16: =I16+Mar!L16 -> 241.49 | M16: =J16+Mar!M16 -> 2385882.9 | N16: =L16-M16 -> -2385641.4
B17: 9 | C17: PAMI Equity Index Fund, Inc. | D17: 1.3619197e+09 | E17: 74392111 | F17: =D17-E17 -> 1287527639 | G17: 1.306339e+09 | H17: 12146 | I17: 0 | J17: 6486076 | K17: =I17-J17 -> -6486076 | L17: =I17+Mar!L17 -> 0 | M17: =J17+Mar!M17 -> 56156615 | N17: =L17-M17 -> -56156615
B18: 10 | C18: Philam Strategic Growth Fund, Inc. | D18: 3.9284951e+09 | E18: 1.6284258e+08 | F18: =D18-E18 -> 3765652473 | G18: 3.3630699e+09 | H18: 12093 | I18: 2872849.1 | J18: 16902753 | K18: =I18-J18 -> -14029904 | L18: =I18+Mar!L18 -> 13156218 | M18: =J18+Mar!M18 -> 1.0430554e+08 | N18: =L18-M18 -> -91149324
B19: 11 | C19: Philequity Dividend Yield Fund, Inc. | D19: 2250008121 | E19: 5450875 | F19: =D19-E19 -> 2244557246 | G19: 1952954572 | H19: 5522 | I19: 1521685 | J19: 2874317 | K19: =I19-J19 -> -1352632 | L19: =I19+Mar!L19 -> 1.369898e+08 | M19: =J19+Mar!M19 -> 14291358 | N19: =L19-M19 -> 1.2269845e+08
B20: 12 | C20: Philequity Fund, Inc. | D20: 10026638780 | E20: 48501629 | F20: =D20-E20 -> 9978137151 | G20: 9069995771 | H20: 35719 | I20: 7969619 | J20: 38388163 | K20: =I20-J20 -> -30418544 | L20: =I20+Mar!L20 -> 71588837 | M20: =J20+Mar!M20 -> 1.9372577e+08 | N20: =L20-M20 -> -1.2213694e+08
... B27: 19 | C27: United Fund, Inc. | D27: 602158905 | E27: 1634154 | F27: =D27-E27 -> 600524751 | G27: 519188141 | H27: 1299 | I27: 226182 | J27: 424100 | K27: =I27-J27 -> -197918 | L27: =I27+Mar!L27 -> 4180887.6 | M27: =J27+Mar!M27 -> 4565504.2 | N27: =L27-M27 -> -384616.59
A28: Primarily invested in Peso Securities (units)
B29: 20 | C29: COL Equity Index Unitized Mutual Fund, Inc. | D29: 196433580 | E29: 907906 | F29: =D29-E29 -> 195525674 | G29: 190585636 | H29: 1831 | I29: 5141519 | J29: 607224 | K29: =I29-J29 -> 4534295 | L29: =I29+Mar!L29 -> 87956560 | M29: =J29+Mar!M29 -> 4467255.8 | N29: =L29-M29 -> 83489304
B30: 21 | C30: Philequity Alpha One Fund, Inc. | D30: 350754219 | E30: 5543884 | F30: =D30-E30 -> 345210335 | G30: 302350718 | H30: 1403 | I30: 2887511 | J30: 2537938 | K30: =I30-J30 -> 349573 | L30: =I30+Mar!L30 -> 11007211 | M30: =J30+Mar!M30 -> 15379535 | N30: =L30-M30 -> -4372324
B31: 22 | C31: Philippine Stock Index Fund Corp. | D31: 5.0876378e+08 | E31: 1899177.5 | F31: =D31-E31 -> 5.068646e+08 | G31: 5.0244325e+08 | H31: 370876 | I31: 20438722 | J31: 13223196 | K31: =I31-J31 -> 7215525.4 | L31: =I31+Mar!L31 -> 1.1806011e+08 | M31: =J31+Mar!M31 -> 1.0048196e+08 | N31: =L31-M31 -> 17578147
A32: Exchange Traded Fund
B33: 23 | C33: First Metro Phil. Equity Exchange Traded Fund, Inc. | D33: 2212522760 | E33: 5746902 | F33: =D33-E33 -> 2206775858 | G33: 2183005778 | H33: 3262 | I33: 2027560 | J33: 4091292 | K33: =I33-J33 -> -2063732 | L33: =I33+Mar!L33 -> 26284151 | M33: =J33+Mar!M33 -> 80991881 | N33: =L33-M33 -> -54707730
A34: Sub total - Peso Currency | D34: =SUM(D9:D33) -> 69821583845 | E34: =SUM(E9:E33) -> 6.8537759e+08 | F34: =SUM(F9:F33) -> 69136206251 | G34: =SUM(G9:G33) -> 65190195279 | H34: =SUM(H9:H33) -> 655135 | I34: =SUM(I9:I33) -> 1.7136161e+08 | J34: =SUM(J9:J33) -> 4.2413855e+08 | K34: =SUM(K9:K33) -> -2.5277693e+08 | ... N34: =SUM(N9:N33) -> -4.8062644e+08
A35: Primarily invested in foreign currency securities (shares)
B36: 24 | C36: ATRAM AsiaPlus Equity Fund, Inc. | D36: =55.38*632270.24 -> 35015126 | E36: =55.38*13124.47 -> 726833.15 | F36: =D36-E36 -> 34288293 | G36: =55.38*561556.6 -> 31099005 | H36: 54 | I36: =55.38*189.86 -> 10514.447 | J36: =55.38*919.93 -> 50945.723 | K36: =I36-J36 -> -40431.277 | L36: =I36+Mar!L36 -> 89394.067 | M36: =J36+Mar!M36 -> 70327.813 | N36: =L36-M36 -> 19066.253
B37: 25 | C37: Sun Life Prosperity World Voyager Fund, Inc. | D37: 1831047393 | E37: 8458856 | F37: =D37-E37 -> 1822588537 | G37: 0 | H37: 2881 | I37: 1608433 | J37: 4852919 | K37: =I37-J37 -> -3244486 | L37: =I37+Mar!L37 -> 20083495 | M37: =J37+Mar!M37 -> 82612488 | N37: =L37-M37 -> -62528993
A38: Sub total - US Currency | D38: =SUM(D36:D37) -> 1866062519 | E38: =SUM(E36:E37) -> 9185689.1 | F38: =SUM(F36:F37) -> 1856876830 | G38: =SUM(G36:G37) -> 31099005 | H38: =SUM(H36:H37) -> 2935 | I38: =SUM(I36:I37) -> 1618947.4 | J38: =SUM(J36:J37) -> 4903864.7 | K38: =SUM(K36:K37) -> -3284917.3 | ... N38: =SUM(N36:N37) -> -62509927
A39: Sub total - stock funds | D39: =D34+D38 -> 71687646364 | E39: =E34+E38 -> 6.9456328e+08 | F39: =F34+F38 -> 70993083080 | G39: =G34+G38 -> 65221294283 | H39: =H34+H38 -> 658070 | I39: =I34+I38 -> 1.7298056e+08 | J39: =J34+J38 -> 4.2904241e+08 | K39: =K34+K38 -> -2.5606185e+08 | ... N39: =N34+N38 -> -5.4313637e+08
A40: Balanced Funds
A41: Primarily invested in Peso Securities (shares)
B42: 26 | C42: ATRAM Dynamic Allocation Fund, Inc. | D42: 128087667 | E42: 9040364 | F42: =D42-E42 -> 119047303 | G42: 34591450 | H42: 724 | I42: 214713 | J42: 111893 | K42: =I42-J42 -> 102820 | L42: =I42+Mar!L42 -> 1305209.1 | M42: =J42+Mar!M42 -> 851134 | N42: =L42-M42 -> 454075.06
B43: 27 | C43: ATRAM Philippine Balanced Fund, Inc. | D43: 604211941 | E43: 12563354 | F43: =D43-E43 -> 591648587 | G43: 266804912 | H43: 2415 | I43: 417818 | J43: 1591707 | K43: =I43-J43 -> -1173889 | L43: =I43+Mar!L43 -> 3541440.1 | M43: =J43+Mar!M43 -> 17757274 | N43: =L43-M43 -> -14215834
B44: 28 | C44: First Metro Save and Learn Balanced Fund, Inc. | D44: 1078420636 | E44: 16022947 | F44: =D44-E44 -> 1062397689 | G44: 509526700 | H44: 4635 | I44: 671902 | J44: 7277210 | K44: =I44-J44 -> -6605308 | L44: =I44+Mar!L44 -> 7159216.5 | M44: =J44+Mar!M44 -> 21740310 | N44: =L44-M44 -> -14581094
B45: 29 | C45: First Metro Save and Learn F.O.C.C.U.S. Dynamic Fund, Inc. | D45: 290596193 | E45: 4956355 | F45: =D45-E45 -> 285639838 | G45: 133315522 | H45: 245 | I45: 13086295 | J45: 10084 | K45: =I45-J45 -> 13076211 | L45: =I45+Mar!L45 -> 22757889 | M45: =J45+Mar!M45 -> 42546519 | N45: =L45-M45 -> -19788630
B46: 30 | C46: NCM Mutual Fund of the Phils., Inc. | D46: 352168980 | E46: 3988742 | F46: =D46-E46 -> 348180238 | G46: 157797583 | H46: 54 | I46: 0 | K46: =I46-J46 -> 0 | L46: =I46+Mar!L46 -> 0 | M46: =J46+Mar!M46 -> 1508185 | N46: =L46-M46 -> -1508185
...

Sheet May
A1: PHILIPPINE INVESTMENT FUNDS ASSOCIATION, INC.
A2: MUTUAL FUNDS STATISTICAL REPORT
A3: Month of May 2023
A4: (Amounts in Peso)
I5: F O R - T H E - M O N T H | L5: Y E A R - T O - D A T E
A6: Fund Category | C6: Fund Name | D6: ASSETS | E6: LIABILITIES | F6: NET ASSETS | G6: EQUITY INV. | H6: NO. OF A/C | I6: SALES | J6: REDEMPTIONS | K6: NET SALES | L6: TOTAL SALES | M6: TOTAL REDEMPTIONS | N6: TOTAL NET SALES
A7: Stock Funds
A8: Primarily invested in Peso Securities (shares)
B9: 1 | C9: ALFM Growth Fund, Inc. | D9: 4580283054 | E9: 41708631 | F9: =D9-E9 -> 4538574423 | G9: 4088428812 | H9: 7113 | I9: 21300859 | J9: 59179975 | K9: =I9-J9 -> -37879116 | L9: =I9+Apr!L9 -> 47684156 | M9: =J9+Apr!M9 -> 2.3105855e+08 | N9: =L9-M9 -> -1.833744e+08
B10: 2 | C10: ATRAM Alpha Opportunity Fund, Inc. | D10: 807006136 | E10: 36975838 | F10: =D10-E10 -> 770030298 | G10: 727559256 | H10: 4210 | I10: 10786118 | J10: 5902468 | K10: =I10-J10 -> 4883650 | L10: =I10+Apr!L10 -> 29597594 | M10: =J10+Apr!M10 -> 44831632 | N10: =L10-M10 -> -15234038
B11: 3 | C11: ATRAM Phil. Equity Opportunity Fund, Inc. | D11: 1338790122 | E11: 17473630 | F11: =D11-E11 -> 1321316492 | G11: 1262531747 | H11: 2822 | I11: 5539370 | J11: 102641009 | K11: =I11-J11 -> -97101639 | L11: =I11+Apr!L11 -> 4.0364067e+08 | M11: =J11+Apr!M11 -> 3.7859892e+08 | N11: =L11-M11 -> 25041749
B12: 4 | C12: Climbs Share Capital Equity Investment Fund Corp. | D12: 345494042 | E12: 7536978 | F12: =D12-E12 -> 337957064 | G12: 231995040 | H12: 1775 | I12: 559688 | J12: 64773 | K12: =I12-J12 -> 494915 | L12: =I12+Apr!L12 -> 2582222.5 | M12: =J12+Apr!M12 -> 1341651.5 | N12: =L12-M12 -> 1240571
B13: 5 | C13: First Metro Consumer Fund, Inc. | D13: 514887101 | E13: 8495304 | F13: =D13-E13 -> 506391797 | G13: 444226187 | H13: 1393 | I13: 509137 | J13: 1535932 | K13: =I13-J13 -> -1026795 | L13: =I13+Apr!L13 -> 2841698.5 | M13: =J13+Apr!M13 -> 7026866.4 | N13: =L13-M13 -> -4185167.9
B14: 6 | C14: First Metro Save and Learn Equity Fund, Inc. | D14: 4107114137 | E14: 42256803 | F14: =D14-E14 -> 4064857334 | G14: 3764677328 | H14: 15997 | I14: 13906297 | J14: 191260478 | K14: =I14-J14 -> -177354181 | L14: =I14+Apr!L14 -> 1.1935812e+08 | M14: =J14+Apr!M14 -> 2.9297472e+08 | N14: =L14-M14 -> -173616604
B15: 7 | C15: First Metro Save and Learn Phil. Index Fund, Inc. | D15: 102335589 | E15: 790199 | F15: =D15-E15 -> 101545390 | G15: 99688379 | H15: 541 | I15: 741530 | J15: 944418 | K15: =I15-J15 -> -202888 | L15: =I15+Apr!L15 -> 6850274.7 | M15: =J15+Apr!M15 -> 6072351.9 | N15: =L15-M15 -> 777922.8
B16: 8 | C16: MBG Equity Investment Fund, Inc. | D16: 132203274 | E16: 2397846 | F16: =D16-E16 -> 129805428 | G16: 118915632 | H16: 50 | I16: 0 | J16: 75475 | K16: =I16-J16 -> -75475 | L16: =I16+Apr!L16 -> 241.49 | M16: =J16+Apr!M16 -> 2461357.9 | N16: =L16-M16 -> -2461116.4
B17: 9 | C17: PAMI Equity Index Fund, Inc. | D17: 1330130478 | E17: 74573444 | F17: =D17-E17 -> 1255557034 | G17: 1272397363 | H17: 12086 | I17: 0 | J17: 5781563 | K17: =I17-J17 -> -5781563 | L17: =I17+Apr!L17 -> 0 | M17: =J17+Apr!M17 -> 61938178 | N17: =L17-M17 -> -61938178
B18: 10 | C18: Philam Strategic Growth Fund, Inc. | D18: 3872439462 | E18: 202508627 | F18: =D18-E18 -> 3669930835 | G18: 3297074710 | H18: 12041 | I18: 1977642 | J18: 33389100 | K18: =I18-J18 -> -31411458 | L18: =I18+Apr!L18 -> 15133860 | M18: =J18+Apr!M18 -> 1.3769464e+08 | N18: =L18-M18 -> -1.2256078e+08
B19: 11 | C19: Philequity Dividend Yield Fund, Inc. | D19: 2.2017712e+09 | E19: 11092900 | F19: =D19-E19 -> 2190678272 | G19: =VLOOKUP(C19,'[1]May 2023'!$A:$E,5,FALSE) -> #REF! | H19: 5438 | I19: 1797727.2 | J19: 7003587.1 | K19: =I19-J19 -> -5205859.9 | L19: =I19+Apr!L19 -> 1.3878753e+08 | M19: =J19+Apr!M19 -> 21294945 | N19: =L19-M19 -> 117492586
B20: 12 | C20: Philequity Fund, Inc. | D20: 9.8166714e+09 | E20: 83043570 | F20: =D20-E20 -> 9733627855 | G20: =VLOOKUP(C20,'[1]May 2023'!$A:$E,5,FALSE) -> #REF! | H20: 35498 | I20: 16169798 | J20: 67042576 | K20: =I20-J20 -> -50872778 | L20: =I20+Apr!L20 -> 87758635 | M20: =J20+Apr!M20 -> 2.6076835e+08 | N20: =L20-M20 -> -1.7300972e+08
B21: 13 | C21: Philequity MSCI Phil. Index Fund, Inc. | D21: 3.2865136e+08 | E21: 19138827 | F21: =D21-E21 -> 3.0951253e+08 | G21: =VLOOKUP(C21,'[1]May 2023'!$A:$E,5,FALSE) -> #REF! | H21: 998 | I21: 211920.79 | J21: 536416.84 | K21: =I21-J21 -> -324496.05 | L21: =I21+Apr!L21 -> 1624149.1 | M21: =J21+Apr!M21 -> 4097591.6 | N21: =L21-M21 -> -2473442.6
B22: 14 | C22: Philequity PSE Index Fund, Inc. | D22: 3.8580665e+09 | E22: 13561922 | F22: =D22-E22 -> 3844504596 | G22: =VLOOKUP(C22,'[1]May 2023'!$A:$E,5,FALSE) -> #REF! | H22: 26552 | I22: 8896361.5 | J22: 14227740 | K22: =I22-J22 -> -5331378.1 | L22: =I22+Apr!L22 -> 2.6753906e+08 | M22: =J22+Apr!M22 -> 1.999281e+08 | N22: =L22-M22 -> 67610955
B23: 15 | C23: Philippine Stock Index Fund Corp. | D23: 8683492437 | E23: 12709656 | F23: =D23-E23 -> 8670782781 | G23: 8621744003 | H23: 14009 | I23: 1084781 | J23: 68954130 | K23: =I23-J23 -> -67869349 | L23: =I23+Apr!L23 -> 9007613 | M23: =J23+Apr!M23 -> 4.7099363e+08 | N23: =L23-M23 -> -4.6198601e+08
B24: 16 | C24: Soldivo Strategic Growth Fund, Inc. | D24: 3266404923 | E24: 20535171 | F24: =D24-E24 -> 3245869752 | G24: 3079277001 | H24: 4432 | I24: 52238108 | J24: 3095006 | K24: =I24-J24 -> 49143102 | L24: =I24+Apr!L24 -> 2.0354128e+08 | M24: =J24+Apr!M24 -> 15875726 | N24: =L24-M24 -> 1.8766556e+08
B25: 17 | C25: Sun Life Prosperity Philippine Equity Fund, Inc. | D25: 7060451708 | E25: 119829389 | F25: =D25-E25 -> 6940622319 | G25: 6783849788 | H25: 66621 | I25: 77429144 | J25: 116325853 | K25: =I25-J25 -> -38896709 | L25: =I25+Apr!L25 -> 1.8910185e+08 | M25: =J25+Apr!M25 -> 4.7641023e+08 | N25: =L25-M25 -> -2.8730838e+08
B26: 18 | C26: Sun Life Prosperity Phil. Stock Index Fund, Inc. | D26: 11945694172 | E26: 100045704 | F26: =D26-E26 -> 11845648468 | G26: 11794114479 | H26: 57340 | I26: 73810926 | J26: 173117339 | K26: =I26-J26 -> -99306413 | L26: =I26+Apr!L26 -> 1071536026 | M26: =J26+Apr!M26 -> 1069565183 | N26: =L26-M26 -> 1970842.2
B27: 19 | C27: United Fund, Inc. | D27: 591099456 | E27: 2837752 | F27: =D27-E27 -> 588261704 | G27: 513442594 | H27: 1290 | I27: 317554 | J27: 1653648 | K27: =I27-J27 -> -1336094 | L27: =I27+Apr!L27 -> 4498441.6 | M27: =J27+Apr!M27 -> 6219152.2 | N27: =L27-M27 -> -1720710.6
A28: Primarily invested in Peso Securities (units)
B29: 20 | C29: COL Equity Index Unitized Mutual Fund, Inc. | D29: 197733142 | E29: 1637615 | F29: =D29-E29 -> 196095527 | G29: 190411528 | H29: 1973 | I29: 5567706 | J29: 1011621 | K29: =I29-J29 -> 4556085 | L29: =I29+Apr!L29 -> 93524266 | M29: =J29+Apr!M29 -> 5478876.8 | N29: =L29-M29 -> 88045389
B30: 21 | C30: Philequity Alpha One Fund, Inc. | D30: 3.3427097e+08 | E30: 6658410.8 | F30: =D30-E30 -> 3.2761256e+08 | G30: 3.0089513e+08 | H30: 1393 | I30: 1677415.5 | J30: 4637868.5 | K30: =I30-J30 -> -2960453 | L30: =I30+Apr!L30 -> 12684627 | M30: =J30+Apr!M30 -> 20017404 | N30: =L30-M30 -> -7332777
B31: 22 | C31: Philippine Stock Index Fund Corp. | D31: 501758357 | E31: 2296560 | F31: =D31-E31 -> 499461797 | G31: 495648024 | H31: 504922 | I31: 17776509 | J31: 14758957 | K31: =I31-J31 -> 3017552 | L31: =I31+Apr!L31 -> 1.3583661e+08 | M31: =J31+Apr!M31 -> 1.1524092e+08 | N31: =L31-M31 -> 20595699
A32: Exchange Traded Fund
B33: 23 | C33: First Metro Phil. Equity Exchange Traded Fund, Inc. | D33: 2143737388 | E33: 1645707 | F33: =D33-E33 -> 2142091681 | G33: 2121367148 | H33: 3254 | I33: 0 | J33: 22934110 | K33: =I33-J33 -> -22934110 | L33: =I33+Apr!L33 -> 26284151 | M33: =J33+Apr!M33 -> 103925991 | N33: =L33-M33 -> -77641840
A34: Sub total - Peso Currency | D34: =SUM(D9:D33) -> 68060486421 | E34: =SUM(E9:E33) -> 8.2975048e+08 | F34: =SUM(F9:F33) -> 67230735937 | G34: =SUM(G9:G33) -> #REF! | H34: =SUM(H9:H33) -> 781748 | I34: =SUM(I9:I33) -> 3.1229859e+08 | J34: =SUM(J9:J33) -> 896074043 | K34: =SUM(K9:K33) -> -5.8377545e+08 | ... N34: =SUM(N9:N33) -> -1064401890
A35: Primarily invested in foreign currency securities (shares)
B36: 24 | C36: ATRAM AsiaPlus Equity Fund, Inc. | D36: 34293712 | E36: 1181708.8 | F36: =D36-E36 -> 33112004 | G36: 0 | H36: 54 | I36: 58657.1 | J36: 258449.47 | K36: =I36-J36 -> -199792.37 | L36: =I36+Apr!L36 -> 148051.17 | M36: =J36+Apr!M36 -> 328777.28 | N36: =L36-M36 -> -180726.11
