Workbook

Sheet Jan
A1: PHILIPPINE INVESTMENT FUNDS ASSOCIATION, INC.
A2: MUTUAL FUNDS STATISTICAL REPORT
A3: Month of January 2024
A4: (Amounts in Peso)
I5: F O R - T H E - M O N T H | L5: Y E A R - T O - D A T E
A6: Fund Category | C6: Fund Name | D6: ASSETS | E6: LIABILITIES | F6: NET ASSETS | G6: EQUITY INV. | H6: NO. OF A/C | I6: SALES | J6: REDEMPTIONS | K6: NET SALES | L6: TOTAL SALES | M6: TOTAL REDEMPTIONS | N6: TOTAL NET SALES
A7: Stock Funds
A8: Primarily invested in Peso Securities (shares)
B9: 1 | C9: ALFM Growth Fund, Inc. | D9: 15852448 | E9: 493145 | F9: =D9-E9 -> 15359303 | G9: 4170172547 | H9: 6647 | I9: 5246522 | J9: 59052402 | K9: =I9-J9 -> -53805880 | L9: =I9 -> 5246522 | M9: =J9 -> 59052402 | N9: =L9-M9 -> -53805880
B10: =1+B9 -> 2 | C10: ATRAM Alpha Opportunity Fund, Inc. | D10: 7.7679695e+08 | E10: 4549367 | F10: =D10-E10 -> 772247588 | G10: 7.2461709e+08 | H10: 4097 | I10: 2767579.5 | J10: 18155947 | K10: =I10-J10 -> -15388367 | L10: =I10 -> 2767579.5 | M10: =J10 -> 18155947 | N10: =L10-M10 -> -15388367
B11: =1+B10 -> 3 | C11: ATRAM Phil. Equity Opportunity Fund, Inc. | D11: 1.3863369e+09 | E11: 20532353 | F11: =D11-E11 -> 1365804545 | G11: 1.2929364e+09 | H11: 2694 | I11: 18300741 | J11: 10969605 | K11: =I11-J11 -> 7331135.8 | L11: =I11 -> 18300741 | M11: =J11 -> 10969605 | N11: =L11-M11 -> 7331135.8
B12: =1+B11 -> 4 | C12: Climbs Share Capital Equity Investment Fund Corp. | D12: 3.5333195e+08 | E12: 4843605.6 | F12: =D12-E12 -> 3.4848835e+08 | G12: 2.1089339e+08 | H12: 1773 | I12: 527670.76 | J12: 7339206.8 | K12: =I12-J12 -> -6811536 | L12: =I12 -> 527670.76 | M12: =J12 -> 7339206.8 | N12: =L12-M12 -> -6811536
B13: =1+B12 -> 5 | C13: First Metro Consumer Fund, Inc. | D13: 470095998 | E13: 10696373 | F13: =D13-E13 -> 459399625 | G13: 383056795 | H13: 1322 | I13: 1482636 | J13: 4852537 | K13: =I13-J13 -> -3369901 | L13: =I13 -> 1482636 | M13: =J13 -> 4852537 | N13: =L13-M13 -> -3369901
B14: =1+B13 -> 6 | C14: First Metro Save and Learn Equity Fund, Inc. | D14: 4387782585 | E14: 149266345 | F14: =D14-E14 -> 4238516240 | G14: 4039857719 | H14: 15399 | I14: 4098336 | J14: 214609288 | K14: =I14-J14 -> -210510952 | L14: =I14 -> 4098336 | M14: =J14 -> 214609288 | N14: =L14-M14 -> -210510952
B15: =1+B14 -> 7 | C15: First Metro Save and Learn Phil. Index Fund, Inc. | D15: 101862188 | E15: 439965 | F15: =D15-E15 -> 101422223 | G15: 99758532 | H15: 512 | I15: 263908 | J15: 2310554 | K15: =I15-J15 -> -2046646 | L15: =I15 -> 263908 | M15: =J15 -> 2310554 | N15: =L15-M15 -> -2046646
B16: =1+B15 -> 8 | C16: MBG Equity Investment Fund, Inc. | D16: 126198350 | E16: 887102 | F16: =D16-E16 -> 125311248 | G16: 119327669 | H16: 49 | I16: 0 | J16: 1946420 | K16: =I16-J16 -> -1946420 | L16: =I16 -> 0 | M16: =J16 -> 1946420 | N16: =L16-M16 -> -1946420
B17: =1+B16 -> 9 | C17: PAMI Equity Index Fund, Inc. | D17: 1226771013 | E17: 39110074 | F17: =D17-E17 -> 1187660939 | G17: 1206090296 | H17: 11637 | I17: 0 | J17: 23899895 | K17: =I17-J17 -> -23899895 | L17: =I17 -> 0 | M17: =J17 -> 23899895 | N17: =L17-M17 -> -23899895
B18: =1+B17 -> 10 | C18: Philam Strategic Growth Fund, Inc. | D18: 3567912442 | E18: 37673568 | F18: =D18-E18 -> 3530238874 | G18: 3377488242 | H18: 11557 | I18: 5622689 | J18: 26906601 | K18: =I18-J18 -> -21283912 | L18: =I18 -> 5622689 | M18: =J18 -> 26906601 | N18: =L18-M18 -> -21283912
B19: =1+B18 -> 11 | C19: Philequity Dividend Yield Fund, Inc. | D19: 2.2366069e+09 | E19: 3269549.4 | F19: =D19-E19 -> 2233337400 | G19: 2.1104744e+09 | H19: 5014 | I19: 1455818.5 | J19: 5231460.5 | K19: =I19-J19 -> -3775642 | L19: =I19 -> 1455818.5 | M19: =J19 -> 5231460.5 | N19: =L19-M19 -> -3775642
B20: =1+B19 -> 12 | C20: Philequity Fund, Inc. | D20: 9.5676448e+09 | E20: 45360648 | F20: =D20-E20 -> 9522284162 | G20: 8.9689223e+09 | H20: 34177 | I20: 11795600 | J20: 63364290 | K20: =I20-J20 -> -51568690 | L20: =I20 -> 11795600 | M20: =J20 -> 63364290 | N20: =L20-M20 -> -51568690
B21: =1+B20 -> 13 | C21: Philequity MSCI Phil. Index Fund, Inc. | D21: 3.2164396e+08 | E21: 1024021.8 | F21: =D21-E21 -> 3.2061994e+08 | G21: 3.1891805e+08 | H21: 950 | I21: 670425.85 | J21: 504660.13 | K21: =I21-J21 -> 165765.72 | L21: =I21 -> 670425.85 | M21: =J21 -> 504660.13 | N21: =L21-M21 -> 165765.72
... B27: =1+B26 -> 19 | C27: United Fund, Inc. | D27: 6.0499976e+08 | E27: 2313657.1 | F27: =D27-E27 -> 6.0268611e+08 | G27: 5.2266307e+08 | H27: 1246 | I27: 69775.75 | J27: 1178611.1 | K27: =I27-J27 -> -1108835.3 | L27: =I27 -> 69775.75 | M27: =J27 -> 1178611.1 | N27: =L27-M27 -> -1108835.3
A28: Primarily invested in Peso Securities (units)
B29: =1+B27 -> 20 | C29: COL Equity Index Unitized Mutual Fund, Inc. | D29: 2.358269e+08 | E29: 5529640.7 | F29: =D29-E29 -> 230297255 | G29: 2.2761921e+08 | H29: 2971 | I29: 6397829.8 | J29: 11528172 | K29: =I29-J29 -> -5130341.8 | L29: =I29 -> 6397829.8 | M29: =J29 -> 11528172 | N29: =L29-M29 -> -5130341.8
B30: =1+B29 -> 21 | C30: COL Strategic Growth Equity Unitized Mutual Fund, Inc. | D30: 1.3320932e+08 | E30: 643619.95 | F30: =D30-E30 -> 1.325657e+08 | G30: 66740681 | H30: 1928 | I30: 28375881 | J30: 6871653.6 | K30: =I30-J30 -> 21504227 | L30: =I30 -> 28375881 | M30: =J30 -> 6871653.6 | N30: =L30-M30 -> 21504227
B31: =1+B30 -> 22 | C31: Philequity Alpha One Fund, Inc. | D31: 3.1721867e+08 | E31: 5821552.2 | F31: =D31-E31 -> 3.1139712e+08 | G31: 292544795 | H31: 1284 | I31: 808356.87 | J31: 5488814.9 | K31: =I31-J31 -> -4680458 | L31: =I31 -> 808356.87 | M31: =J31 -> 5488814.9 | N31: =L31-M31 -> -4680458
B32: =1+B31 -> 23 | C32: Philippine Stock Index Fund Corp. | D32: 622283336 | E32: 1895742 | F32: =D32-E32 -> 620387594 | G32: 615642340 | H32: 580880 | I32: 12415949 | J32: 26551720 | K32: =I32-J32 -> -14135771 | L32: =I32 -> 12415949 | M32: =J32 -> 26551720 | N32: =L32-M32 -> -14135771
A33: Exchange Traded Fund
B34: =1+B32 -> 24 | C34: First Metro Phil. Equity Exchange Traded Fund, Inc. | D34: 2202380827 | E34: 1752195 | F34: =D34-E34 -> 2200628632 | G34: 2197606516 | H34: 3266 | I34: 6181440 | J34: 8442016 | K34: =I34-J34 -> -2260576 | L34: =I34 -> 6181440 | M34: =J34 -> 8442016 | N34: =L34-M34 -> -2260576
A35: Sub total - Peso Currency | D35: =SUM(D9:D34) -> 62080064976 | E35: =SUM(E9:E34) -> 5.1109707e+08 | F35: =SUM(F9:F34) -> 61568967908 | G35: =SUM(G9:G34) -> 63733764266 | H35: =SUM(H9:H34) -> 863311 | I35: =SUM(I9:I34) -> 2.064859e+08 | J35: =SUM(J9:J34) -> 1166313041 | K35: =SUM(K9:K34) -> -9.5982714e+08 | ... N35: =SUM(N9:N34) -> -9.5982714e+08
A36: Primarily invested in foreign currency securities (shares)
B37: =1+B34 -> 25 | C37: ATRAM AsiaPlus Equity Fund, Inc. | D37: 24541947 | E37: 60919.38 | F37: =D37-E37 -> 24481027 | G37: 22780589 | H37: 52 | I37: 92758.65 | J37: 11209.42 | K37: =I37-J37 -> 81549.23 | L37: =I37 -> 92758.65 | M37: =J37 -> 11209.42 | N37: =L37-M37 -> 81549.23
B38: =1+B37 -> 26 | C38: Sun Life Prosperity World Voyager Fund, Inc. | D38: 1992280284 | E38: 13992408 | F38: =D38-E38 -> 1978287876 | G38: 0 | H38: 2948 | I38: 17601442 | J38: 71992871 | K38: =I38-J38 -> -54391429 | L38: =I38 -> 17601442 | M38: =J38 -> 71992871 | N38: =L38-M38 -> -54391429
A39: Sub total - US Currency | D39: =SUM(D37:D38) -> 2016822231 | E39: =SUM(E37:E38) -> 14053327 | F39: =SUM(F37:F38) -> 2002768903 | G39: =SUM(G37:G38) -> 22780589 | H39: =SUM(H37:H38) -> 3000 | I39: =SUM(I37:I38) -> 17694201 | J39: =SUM(J37:J38) -> 72004080 | K39: =SUM(K37:K38) -> -54309880 | ... N39: =SUM(N37:N38) -> -54309880
A40: Sub total - stock funds | D40: =D35+D39 -> 64096887206 | E40: =E35+E39 -> 525150395 | F40: =F35+F39 -> 63571736811 | G40: =G35+G39 -> 63756544855 | H40: =H35+H39 -> 866311 | I40: =I35+I39 -> 2.241801e+08 | J40: =J35+J39 -> 1238317121 | K40: =K35+K39 -> -1014137018 | ... N40: =N35+N39 -> -1014137018
A41: Balanced Funds
A42: Primarily invested in Peso Securities (shares)
B43: =1+B38 -> 27 | C43: ATRAM Philippine Balanced Fund, Inc. | D43: 5.0901746e+08 | E43: 20310423 | F43: =D43-E43 -> 4.8870704e+08 | G43: 2.9181271e+08 | H43: 2360 | I43: 694300.78 | J43: 5482668.2 | K43: =I43-J43 -> -4788367.4 | L43: =I43 -> 694300.78 | M43: =J43 -> 5482668.2 | N43: =L43-M43 -> -4788367.4
B44: =1+B43 -> 28 | C44: ATRAM Unicapital Diversified Growth Fund, Inc. | D44: 1.2134157e+08 | E44: 95295.18 | F44: =D44-E44 -> 1.2124627e+08 | G44: 49650782 | H44: 705 | I44: 407405.34 | J44: 592892.9 | K44: =I44-J44 -> -185487.56 | L44: =I44 -> 407405.34 | M44: =J44 -> 592892.9 | N44: =L44-M44 -> -185487.56
B45: =1+B44 -> 29 | C45: First Metro Save and Learn Balanced Fund, Inc. | D45: 994292212 | E45: 40094161 | F45: =D45-E45 -> 954198051 | G45: 578347588 | H45: 4415 | I45: 1459383 | J45: 10707460 | K45: =I45-J45 -> -9248077 | L45: =I45 -> 1459383 | M45: =J45 -> 10707460 | N45: =L45-M45 -> -9248077
...

Sheet Jan UPDATED
A1: PHILIPPINE INVESTMENT FUNDS ASSOCIATION, INC.
A2: MUTUAL FUNDS STATISTICAL REPORT
A3: Month of January 2024
A4: (Amounts in Peso)
I5: F O R - T H E - M O N T H | L5: Y E A R - T O - D A T E
A6: Fund Category | C6: Fund Name | D6: ASSETS | E6: LIABILITIES | F6: NET ASSETS | G6: EQUITY INV. | H6: NO. OF A/C | I6: SALES | J6: REDEMPTIONS | K6: NET SALES | L6: TOTAL SALES | M6: TOTAL REDEMPTIONS | N6: TOTAL NET SALES
A7: Stock Funds
A8: Primarily invested in Peso Securities (shares)
B9: 1 | C9: ALFM Growth Fund, Inc. | D9: 4.3886259e+09 | E9: 25251041 | F9: =D9-E9 -> 4363374893 | G9: 4170172547 | H9: 6647 | I9: 5246522 | J9: 59052402 | K9: =I9-J9 -> -53805880 | L9: =I9 -> 5246522 | M9: =J9 -> 59052402 | N9: =L9-M9 -> -53805880
B10: =1+B9 -> 2 | C10: ATRAM Alpha Opportunity Fund, Inc. | D10: 7.7679695e+08 | E10: 4549367 | F10: =D10-E10 -> 772247588 | G10: 7.2461709e+08 | H10: 4097 | I10: 2767579.5 | J10: 18155947 | K10: =I10-J10 -> -15388367 | L10: =I10 -> 2767579.5 | M10: =J10 -> 18155947 | N10: =L10-M10 -> -15388367
B11: =1+B10 -> 3 | C11: ATRAM Phil. Equity Opportunity Fund, Inc. | D11: 1.3863369e+09 | E11: 20532353 | F11: =D11-E11 -> 1365804545 | G11: 1.2929364e+09 | H11: 2694 | I11: 18300741 | J11: 10969605 | K11: =I11-J11 -> 7331135.8 | L11: =I11 -> 18300741 | M11: =J11 -> 10969605 | N11: =L11-M11 -> 7331135.8
B12: =1+B11 -> 4 | C12: Climbs Share Capital Equity Investment Fund Corp. | D12: 3.5333195e+08 | E12: 4843605.6 | F12: =D12-E12 -> 3.4848835e+08 | G12: 2.1089339e+08 | H12: 1773 | I12: 527670.76 | J12: 7339206.8 | K12: =I12-J12 -> -6811536 | L12: =I12 -> 527670.76 | M12: =J12 -> 7339206.8 | N12: =L12-M12 -> -6811536
B13: =1+B12 -> 5 | C13: First Metro Consumer Fund, Inc. | D13: 470095998 | E13: 10696373 | F13: =D13-E13 -> 459399625 | G13: 383056795 | H13: 1322 | I13: 1482636 | J13: 4852537 | K13: =I13-J13 -> -3369901 | L13: =I13 -> 1482636 | M13: =J13 -> 4852537 | N13: =L13-M13 -> -3369901
B14: =1+B13 -> 6 | C14: First Metro Save and Learn Equity Fund, Inc. | D14: 4387782585 | E14: 149266345 | F14: =D14-E14 -> 4238516240 | G14: 4039857719 | H14: 15399 | I14: 4098336 | J14: 214609288 | K14: =I14-J14 -> -210510952 | L14: =I14 -> 4098336 | M14: =J14 -> 214609288 | N14: =L14-M14 -> -210510952
B15: =1+B14 -> 7 | C15: First Metro Save and Learn Phil. Index Fund, Inc. | D15: 101862188 | E15: 439965 | F15: =D15-E15 -> 101422223 | G15: 99758532 | H15: 512 | I15: 263908 | J15: 2310554 | K15: =I15-J15 -> -2046646 | L15: =I15 -> 263908 | M15: =J15 -> 2310554 | N15: =L15-M15 -> -2046646
B16: =1+B15 -> 8 | C16: MBG Equity Investment Fund, Inc. | D16: 126198350 | E16: 887102 | F16: =D16-E16 -> 125311248 | G16: 119327669 | H16: 49 | I16: 0 | J16: 1946420 | K16: =I16-J16 -> -1946420 | L16: =I16 -> 0 | M16: =J16 -> 1946420 | N16: =L16-M16 -> -1946420
B17: =1+B16 -> 9 | C17: PAMI Equity Index Fund, Inc. | D17: 1226771013 | E17: 39110074 | F17: =D17-E17 -> 1187660939 | G17: 1206090296 | H17: 11637 | I17: 0 | J17: 23899895 | K17: =I17-J17 -> -23899895 | L17: =I17 -> 0 | M17: =J17 -> 23899895 | N17: =L17-M17 -> -23899895
B18: =1+B17 -> 10 | C18: Philam Strategic Growth Fund, Inc. | D18: 3567912442 | E18: 37673568 | F18: =D18-E18 -> 3530238874 | G18: 3377488242 | H18: 11557 | I18: 5622689 | J18: 26906601 | K18: =I18-J18 -> -21283912 | L18: =I18 -> 5622689 | M18: =J18 -> 26906601 | N18: =L18-M18 -> -21283912
B19: =1+B18 -> 11 | C19: Philequity Dividend Yield Fund, Inc. | D19: 2.2366069e+09 | E19: 3269549.4 | F19: =D19-E19 -> 2233337400 | G19: 2.1104744e+09 | H19: 5014 | I19: 1455818.5 | J19: 5231460.5 | K19: =I19-J19 -> -3775642 | L19: =I19 -> 1455818.5 | M19: =J19 -> 5231460.5 | N19: =L19-M19 -> -3775642
B20: =1+B19 -> 12 | C20: Philequity Fund, Inc. | D20: 9.5676448e+09 | E20: 45360648 | F20: =D20-E20 -> 9522284162 | G20: 8.9689223e+09 | H20: 34177 | I20: 11795600 | J20: 63364290 | K20: =I20-J20 -> -51568690 | L20: =I20 -> 11795600 | M20: =J20 -> 63364290 | N20: =L20-M20 -> -51568690
B21: =1+B20 -> 13 | C21: Philequity MSCI Phil. Index Fund, Inc. | D21: 3.2164396e+08 | E21: 1024021.8 | F21: =D21-E21 -> 3.2061994e+08 | G21: 3.1891805e+08 | H21: 950 | I21: 670425.85 | J21: 504660.13 | K21: =I21-J21 -> 165765.72 | L21: =I21 -> 670425.85 | M21: =J21 -> 504660.13 | N21: =L21-M21 -> 165765.72
... B27: =1+B26 -> 19 | C27: United Fund, Inc. | D27: 6.0499976e+08 | E27: 2313657.1 | F27: =D27-E27 -> 6.0268611e+08 | G27: 5.2266307e+08 | H27: 1246 | I27: 69775.75 | J27: 1178611.1 | K27: =I27-J27 -> -1108835.3 | L27: =I27 -> 69775.75 | M27: =J27 -> 1178611.1 | N27: =L27-M27 -> -1108835.3
A28: Primarily invested in Peso Securities (units)
B29: =1+B27 -> 20 | C29: COL Equity Index Unitized Mutual Fund, Inc. | D29: 2.358269e+08 | E29: 5529640.7 | F29: =D29-E29 -> 230297255 | G29: 2.2761921e+08 | H29: 2971 | I29: 6397829.8 | J29: 11528172 | K29: =I29-J29 -> -5130341.8 | L29: =I29 -> 6397829.8 | M29: =J29 -> 11528172 | N29: =L29-M29 -> -5130341.8
B30: =1+B29 -> 21 | C30: COL Strategic Growth Equity Unitized Mutual Fund, Inc. | D30: 1.3320932e+08 | E30: 643619.95 | F30: =D30-E30 -> 1.325657e+08 | G30: 66740681 | H30: 1928 | I30: 28375881 | J30: 6871653.6 | K30: =I30-J30 -> 21504227 | L30: =I30 -> 28375881 | M30: =J30 -> 6871653.6 | N30: =L30-M30 -> 21504227
B31: =1+B30 -> 22 | C31: Philequity Alpha One Fund, Inc. | D31: 3.1721867e+08 | E31: 5821552.2 | F31: =D31-E31 -> 3.1139712e+08 | G31: 292544795 | H31: 1284 | I31: 808356.87 | J31: 5488814.9 | K31: =I31-J31 -> -4680458 | L31: =I31 -> 808356.87 | M31: =J31 -> 5488814.9 | N31: =L31-M31 -> -4680458
B32: =1+B31 -> 23 | C32: Philippine Stock Index Fund Corp. | D32: 622283336 | E32: 1895742 | F32: =D32-E32 -> 620387594 | G32: 615642340 | H32: 580880 | I32: 12415949 | J32: 26551720 | K32: =I32-J32 -> -14135771 | L32: =I32 -> 12415949 | M32: =J32 -> 26551720 | N32: =L32-M32 -> -14135771
A33: Exchange Traded Fund
B34: =1+B32 -> 24 | C34: First Metro Phil. Equity Exchange Traded Fund, Inc. | D34: 2202380827 | E34: 1752195 | F34: =D34-E34 -> 2200628632 | G34: 2197606516 | H34: 3266 | I34: 6181440 | J34: 8442016 | K34: =I34-J34 -> -2260576 | L34: =I34 -> 6181440 | M34: =J34 -> 8442016 | N34: =L34-M34 -> -2260576
A35: Sub total - Peso Currency | D35: =SUM(D9:D34) -> 66452838461 | E35: =SUM(E9:E34) -> 535854964 | F35: =SUM(F9:F34) -> 65916983497 | G35: =SUM(G9:G34) -> 63733764266 | H35: =SUM(H9:H34) -> 863311 | I35: =SUM(I9:I34) -> 2.064859e+08 | J35: =SUM(J9:J34) -> 1166313041 | K35: =SUM(K9:K34) -> -9.5982714e+08 | ... N35: =SUM(N9:N34) -> -9.5982714e+08
A36: Primarily invested in foreign currency securities (shares)
B37: =1+B34 -> 25 | C37: ATRAM AsiaPlus Equity Fund, Inc. | D37: 24541947 | E37: 60919.38 | F37: =D37-E37 -> 24481027 | G37: 22780589 | H37: 52 | I37: 92758.65 | J37: 11209.42 | K37: =I37-J37 -> 81549.23 | L37: =I37 -> 92758.65 | M37: =J37 -> 11209.42 | N37: =L37-M37 -> 81549.23
B38: =1+B37 -> 26 | C38: Sun Life Prosperity World Voyager Fund, Inc. | D38: 1992280284 | E38: 13992408 | F38: =D38-E38 -> 1978287876 | G38: 0 | H38: 2948 | I38: 17601442 | J38: 71992871 | K38: =I38-J38 -> -54391429 | L38: =I38 -> 17601442 | M38: =J38 -> 71992871 | N38: =L38-M38 -> -54391429
A39: Sub total - US Currency | D39: =SUM(D37:D38) -> 2016822231 | E39: =SUM(E37:E38) -> 14053327 | F39: =SUM(F37:F38) -> 2002768903 | G39: =SUM(G37:G38) -> 22780589 | H39: =SUM(H37:H38) -> 3000 | I39: =SUM(I37:I38) -> 17694201 | J39: =SUM(J37:J38) -> 72004080 | K39: =SUM(K37:K38) -> -54309880 | ... N39: =SUM(N37:N38) -> -54309880
A40: Sub total - stock funds | D40: =D35+D39 -> 68469660692 | E40: =E35+E39 -> 5.4990829e+08 | F40: =F35+F39 -> 67919752401 | G40: =G35+G39 -> 63756544855 | H40: =H35+H39 -> 866311 | I40: =I35+I39 -> 2.241801e+08 | J40: =J35+J39 -> 1238317121 | K40: =K35+K39 -> -1014137018 | ... N40: =N35+N39 -> -1014137018
A41: Balanced Funds
A42: Primarily invested in Peso Securities (shares)
B43: =1+B38 -> 27 | C43: ATRAM Philippine Balanced Fund, Inc. | D43: 5.0901746e+08 | E43: 20310423 | F43: =D43-E43 -> 4.8870704e+08 | G43: 2.9181271e+08 | H43: 2360 | I43: 694300.78 | J43: 5482668.2 | K43: =I43-J43 -> -4788367.4 | L43: =I43 -> 694300.78 | M43: =J43 -> 5482668.2 | N43: =L43-M43 -> -4788367.4
B44: =1+B43 -> 28 | C44: ATRAM Unicapital Diversified Growth Fund, Inc. | D44: 1.2134157e+08 | E44: 95295.18 | F44: =D44-E44 -> 1.2124627e+08 | G44: 49650782 | H44: 705 | I44: 407405.34 | J44: 592892.9 | K44: =I44-J44 -> -185487.56 | L44: =I44 -> 407405.34 | M44: =J44 -> 592892.9 | N44: =L44-M44 -> -185487.56
B45: =1+B44 -> 29 | C45: First Metro Save and Learn Balanced Fund, Inc. | D45: 994292212 | E45: 40094161 | F45: =D45-E45 -> 954198051 | G45: 578347588 | H45: 4415 | I45: 1459383 | J45: 10707460 | K45: =I45-J45 -> -9248077 | L45: =I45 -> 1459383 | M45: =J45 -> 10707460 | N45: =L45-M45 -> -9248077
...

Sheet Feb
A1: PHILIPPINE INVESTMENT FUNDS ASSOCIATION, INC.
A2: MUTUAL FUNDS STATISTICAL REPORT
A3: Month of February 2024
A4: (Amounts in Peso)
I5: F O R - T H E - M O N T H | L5: Y E A R - T O - D A T E
A6: Fund Category | C6: Fund Name | D6: ASSETS | E6: LIABILITIES | F6: NET ASSETS | G6: EQUITY INV. | H6: NO. OF A/C | I6: SALES | J6: REDEMPTIONS | K6: NET SALES | L6: TOTAL SALES | M6: TOTAL REDEMPTIONS | N6: TOTAL NET SALES
A7: Stock Funds
A8: Primarily invested in Peso Securities (shares)
B9: 1 | C9: ALFM Growth Fund, Inc. | D9: 4537893336 | E9: 25764830 | F9: =D9-E9 -> 4512128506 | G9: 4318682817 | H9: 6542 | I9: 2563558 | J9: 56906144 | K9: =I9-J9 -> -54342586 | L9: =I9+'Jan UPDATED'!L9 -> 7810080 | M9: =J9+'Jan UPDATED'!M9 -> 115958546 | N9: =L9-M9 -> -108148466
B10: =1+B9 -> 2 | C10: ATRAM Alpha Opportunity Fund, Inc. | D10: 7.7947833e+08 | E10: 7522486.7 | F10: =D10-E10 -> 7.7195584e+08 | G10: 7.3126179e+08 | H10: 4075 | I10: 1872432.5 | J10: 13189805 | K10: =I10-J10 -> -11317372 | L10: =I10+Jan!L10 -> 4640012 | M10: =J10+Jan!M10 -> 31345751 | N10: =L10-M10 -> -26705739
B11: =1+B10 -> 3 | C11: ATRAM Phil. Equity Opportunity Fund, Inc. | D11: 1.4188661e+09 | E11: 7983030.2 | F11: =D11-E11 -> 1410883056 | G11: 1.3258309e+09 | H11: 2676 | I11: 5755161.2 | J11: 36631886 | K11: =I11-J11 -> -30876725 | L11: =I11+Jan!L11 -> 24055902 | M11: =J11+Jan!M11 -> 47601492 | N11: =L11-M11 -> -23545590
B12: =1+B11 -> 4 | C12: Climbs Share Capital Equity Investment Fund Corp. | D12: 4.0184556e+08 | E12: 12279326 | F12: =D12-E12 -> 389566232 | G12: 2.2312001e+08 | H12: 1783 | I12: 42693995 | J12: 965467.03 | K12: =I12-J12 -> 41728528 | L12: =I12+Jan!L12 -> 43221666 | M12: =J12+Jan!M12 -> 8304673.8 | N12: =L12-M12 -> 34916992
B13: =1+B12 -> 5 | C13: First Metro Consumer Fund, Inc. | D13: 481665173 | E13: 11752609 | F13: =D13-E13 -> 469912564 | G13: 450628587 | H13: 1311 | I13: 31492395 | J13: 32197132 | K13: =I13-J13 -> -704737 | L13: =I13+Jan!L13 -> 32975031 | M13: =J13+Jan!M13 -> 37049669 | N13: =L13-M13 -> -4074638
B14: =1+B13 -> 6 | C14: First Metro Save and Learn Equity Fund, Inc. | D14: 4110224484 | E14: 41164477 | F14: =D14-E14 -> 4069060007 | G14: 3965059614 | H14: 15300 | I14: 267007353 | J14: 602967795 | K14: =I14-J14 -> -335960442 | L14: =I14+Jan!L14 -> 271105689 | M14: =J14+Jan!M14 -> 817577083 | N14: =L14-M14 -> -546471394
B15: =1+B14 -> 7 | C15: First Metro Save and Learn Phil. Index Fund, Inc. | D15: 105470622 | E15: 451506 | F15: =D15-E15 -> 105019116 | G15: 104245833 | H15: 509 | I15: 351501 | J15: 1075524 | K15: =I15-J15 -> -724023 | L15: =I15+Jan!L15 -> 615409 | M15: =J15+Jan!M15 -> 3386078 | N15: =L15-M15 -> -2770669
B16: =1+B15 -> 8 | C16: MBG Equity Investment Fund, Inc. | D16: 123800115 | E16: 1007085 | F16: =D16-E16 -> 122793030 | G16: 112054432 | H16: 49 | I16: 0 | J16: 0 | K16: =I16-J16 -> 0 | L16: =I16+Jan!L16 -> 0 | M16: =J16+Jan!M16 -> 1946420 | N16: =L16-M16 -> -1946420
B17: =1+B16 -> 9 | C17: PAMI Equity Index Fund, Inc. | D17: 1260431593 | E17: 38562522 | F17: =D17-E17 -> 1221869071 | G17: 1239720234 | H17: 11580 | I17: 0 | J17: 17923616 | K17: =I17-J17 -> -17923616 | L17: =I17+Jan!L17 -> 0 | M17: =J17+Jan!M17 -> 41823511 | N17: =L17-M17 -> -41823511
B18: =1+B17 -> 10 | C18: Philam Strategic Growth Fund, Inc. | D18: 3713496352 | E18: 46037315 | F18: =D18-E18 -> 3667459037 | G18: 3507936237 | H18: 11487 | I18: 7278270 | J18: 37850465 | K18: =I18-J18 -> -30572195 | L18: =I18+Jan!L18 -> 12900959 | M18: =J18+Jan!M18 -> 64757066 | N18: =L18-M18 -> -51856107
B19: =1+B18 -> 11 | C19: Philequity Dividend Yield Fund, Inc. | D19: 2.3143928e+09 | E19: 2939147.1 | F19: =D19-E19 -> 2311453640 | G19: 2.1900991e+09 | H19: 4976 | I19: 1347007.7 | J19: 4123676.2 | K19: =I19-J19 -> -2776668.4 | L19: =I19+Jan!L19 -> 2802826.2 | M19: =J19+Jan!M19 -> 9355136.6 | N19: =L19-M19 -> -6552310.4
B20: =1+B19 -> 12 | C20: Philequity Fund, Inc. | D20: 9.9420787e+09 | E20: 36569566 | F20: =D20-E20 -> 9905509178 | G20: 9.236565e+09 | H20: 33975 | I20: 8033646.3 | J20: 42419727 | K20: =I20-J20 -> -34386080 | L20: =I20+Jan!L20 -> 19829246 | M20: =J20+Jan!M20 -> 1.0578402e+08 | N20: =L20-M20 -> -85954771
B21: =1+B20 -> 13 | C21: Philequity MSCI Phil. Index Fund, Inc. | D21: 3.3645196e+08 | E21: 783171.4 | F21: =D21-E21 -> 3.3566879e+08 | G21: 3.3332276e+08 | H21: 938 | I21: 181299 | J21: 1399624.1 | K21: =I21-J21 -> -1218325.1 | L21: =I21+Jan!L21 -> 851724.85 | M21: =J21+Jan!M21 -> 1904284.2 | N21: =L21-M21 -> -1052559.4
... B27: =1+B26 -> 19 | C27: United Fund, Inc. | D27: 6.2069875e+08 | E27: 5402879.9 | F27: =D27-E27 -> 6.1529587e+08 | G27: 5.194373e+08 | H27: 1241 | I27: 784953.5 | J27: 3063940.6 | K27: =I27-J27 -> -2278987.1 | L27: =I27+Jan!L27 -> 854729.25 | M27: =J27+Jan!M27 -> 4242551.7 | N27: =L27-M27 -> -3387822.5
A28: Primarily invested in Peso Securities (units)
B29: =1+B27 -> 20 | C29: COL Equity Index Unitized Mutual Fund, Inc. | D29: 2.3785871e+08 | E29: 4970811.2 | F29: =D29-E29 -> 2.328879e+08 | G29: 2.3067381e+08 | H29: 3136 | I29: 6418630.1 | J29: 13847818 | K29: =I29-J29 -> -7429188.3 | L29: =I29+Jan!L29 -> 12816460 | M29: =J29+Jan!M29 -> 25375990 | N29: =L29-M29 -> -12559530
B30: =1+B29 -> 21 | C30: COL Strategic Growth Equity Unitized Mutual Fund, Inc. | D30: 2.4338453e+08 | E30: 5688384.3 | F30: =D30-E30 -> 2.3769615e+08 | G30: 1.3959825e+08 | H30: 2322 | I30: 1.0400048e+08 | J30: 1319415.5 | K30: =I30-J30 -> 1.0268107e+08 | L30: =I30+Jan!L30 -> 1.3237636e+08 | M30: =J30+Jan!M30 -> 8191069 | N30: =L30-M30 -> 1.2418529e+08
B31: =1+B30 -> 22 | C31: Philequity Alpha One Fund, Inc. | D31: 3.1588606e+08 | E31: 3404000.6 | F31: =D31-E31 -> 312482057 | G31: 2.8684164e+08 | H31: 1250 | I31: 693735.02 | J31: 9527958 | K31: =I31-J31 -> -8834223 | L31: =I31+Jan!L31 -> 1502091.9 | M31: =J31+Jan!M31 -> 15016773 | N31: =L31-M31 -> -13514681
B32: =1+B31 -> 23 | C32: Philippine Stock Index Fund Corp. | D32: 639917212 | E32: 3883445 | F32: =D32-E32 -> 636033767 | G32: 632086498 | H32: 627401 | I32: 18963149 | J32: 30219075 | K32: =I32-J32 -> -11255926 | L32: =I32+Jan!L32 -> 31379098 | M32: =J32+Jan!M32 -> 56770795 | N32: =L32-M32 -> -25391697
A33: Exchange Traded Fund
B34: =1+B32 -> 24 | C34: First Metro Phil. Equity Exchange Traded Fund, Inc. | D34: 2259839759 | E34: 1757382 | F34: =D34-E34 -> 2258082377 | G34: 2256006861 | H34: 3223 | I34: 2154855 | J34: 41653113 | K34: =I34-J34 -> -39498258 | L34: =I34+Jan!L34 -> 8336295 | M34: =J34+Jan!M34 -> 50095129 | N34: =L34-M34 -> -41758834
A35: Sub total - Peso Currency | D35: =SUM(D9:D34) -> 68183803326 | E35: =SUM(E9:E34) -> 3.870149e+08 | F35: =SUM(F9:F34) -> 67796788424 | G35: =SUM(G9:G34) -> 65572794434 | H35: =SUM(H9:H34) -> 909066 | I35: =SUM(I9:I34) -> 591596146 | J35: =SUM(J9:J34) -> 1536649575 | K35: =SUM(K9:K34) -> -9.4505343e+08 | ... N35: =SUM(N9:N34) -> -1904880567
A36: Primarily invested in foreign currency securities (shares)
B37: =1+B34 -> 25 | C37: ATRAM AsiaPlus Equity Fund, Inc. | D37: 25686145 | E37: 60860.67 | F37: =D37-E37 -> 25625285 | G37: 23847897 | H37: 52 | I37: 179724.23 | J37: 0 | K37: =I37-J37 -> 179724.23 | L37: =I37+Jan!L37 -> 272482.88 | M37: =J37+Jan!M37 -> 11209.42 | N37: =L37-M37 -> 261273.46
B38: =1+B37 -> 26 | C38: Sun Life Prosperity World Voyager Fund, Inc. | D38: 2078110359 | E38: 33126415 | F38: =D38-E38 -> 2044983944 | G38: 0 | H38: 2963 | I38: 17576578 | J38: 11364242 | K38: =I38-J38 -> 6212336 | L38: =I38+Jan!L38 -> 35178020 | M38: =J38+Jan!M38 -> 83357113 | N38: =L38-M38 -> -48179093
A39: Sub total - US Currency | D39: =SUM(D37:D38) -> 2103796504 | E39: =SUM(E37:E38) -> 33187276 | F39: =SUM(F37:F38) -> 2070609229 | G39: =SUM(G37:G38) -> 23847897 | H39: =SUM(H37:H38) -> 3015 | I39: =SUM(I37:I38) -> 17756302 | J39: =SUM(J37:J38) -> 11364242 | K39: =SUM(K37:K38) -> 6392060.2 | ... N39: =SUM(N37:N38) -> -47917820
A40: Sub total - stock funds | D40: =D35+D39 -> 70287599830 | E40: =E35+E39 -> 4.2020218e+08 | F40: =F35+F39 -> 69867397653 | G40: =G35+G39 -> 65596642331 | H40: =H35+H39 -> 912081 | I40: =I35+I39 -> 6.0935245e+08 | J40: =J35+J39 -> 1548013817 | K40: =K35+K39 -> -9.3866137e+08 | ... N40: =N35+N39 -> -1952798386
A41: Balanced Funds
A42: Primarily invested in Peso Securities (shares)
B43: =1+B38 -> 27 | C43: ATRAM Philippine Balanced Fund, Inc. | D43: 5.2701244e+08 | E43: 48138802 | F43: =D43-E43 -> 4.7887363e+08 | G43: 300042871 | H43: 2354 | I43: 915834.42 | J43: 12695508 | K43: =I43-J43 -> -11779673 | L43: =I43+Jan!L43 -> 1610135.2 | M43: =J43+Jan!M43 -> 18178176 | N43: =L43-M43 -> -16568041
B44: =1+B43 -> 28 | C44: ATRAM Unicapital Diversified Growth Fund, Inc. | D44: 1.2291743e+08 | E44: 4061715.2 | F44: =D44-E44 -> 1.1885572e+08 | G44: 49683979 | H44: 706 | I44: 375966.52 | J44: 2339667 | K44: =I44-J44 -> -1963700.5 | L44: =I44+Jan!L44 -> 783371.86 | M44: =J44+Jan!M44 -> 2932559.9 | N44: =L44-M44 -> -2149188
B45: =1+B44 -> 29 | C45: First Metro Save and Learn Balanced Fund, Inc. | D45: 877618660 | E45: 5813840 | F45: =D45-E45 -> 871804820 | G45: 561372118 | H45: 4386 | I45: 895961 | J45: 107049944 | K45: =I45-J45 -> -106153983 | L45: =I45+Jan!L45 -> 2355344 | M45: =J45+Jan!M45 -> 117757404 | N45: =L45-M45 -> -115402060
...

Sheet Mar
A1: PHILIPPINE INVESTMENT FUNDS ASSOCIATION, INC.
A2: MUTUAL FUNDS STATISTICAL REPORT
A3: Month of March 2024
A4: (Amounts in Peso)
I5: F O R - T H E - M O N T H | L5: Y E A R - T O - D A T E
A6: Fund Category | C6: Fund Name | D6: ASSETS | E6: LIABILITIES | F6: NET ASSETS | G6: EQUITY INV. | H6: NO. OF A/C | I6: SALES | J6: REDEMPTIONS | K6: NET SALES | L6: TOTAL SALES | M6: TOTAL REDEMPTIONS | N6: TOTAL NET SALES
A7: Stock Funds
A8: Primarily invested in Peso Securities (shares)
B9: 1 | C9: ALFM Growth Fund, Inc. | D9: 4483880182 | E9: 24760270 | F9: =D9-E9 -> 4459119912 | G9: 4279876512 | H9: 6452 | I9: 4311324 | J9: 63633150 | K9: =I9-J9 -> -59321826 | L9: =I9+Feb!L9 -> 12121404 | M9: =J9+Feb!M9 -> 179591696 | N9: =L9-M9 -> -167470292
B10: =1+B9 -> 2 | C10: ATRAM Alpha Opportunity Fund, Inc. | D10: 8.0051861e+08 | E10: 257503.58 | F10: =D10-E10 -> 800261106 | G10: 7.5358229e+08 | H10: 4050 | I10: 1804163.6 | J10: 8684311.5 | K10: =I10-J10 -> -6880147.9 | L10: =I10+Feb!L10 -> 6444175.6 | M10: =J10+Feb!M10 -> 40030063 | N10: =L10-M10 -> -33585887
B11: =1+B10 -> 3 | C11: ATRAM Phil. Equity Opportunity Fund, Inc. | D11: 1.3586972e+09 | E11: 1237636 | F11: =D11-E11 -> 1357459559 | G11: 1.2486355e+09 | H11: 2711 | I11: 8349734.5 | J11: 58456640 | K11: =I11-J11 -> -50106905 | L11: =I11+Feb!L11 -> 32405637 | M11: =J11+Feb!M11 -> 1.0605813e+08 | N11: =L11-M11 -> -73652495
B12: =1+B11 -> 4 | C12: Climbs Share Capital Equity Investment Fund Corp. | D12: 4.0394648e+08 | E12: 7201648.5 | F12: =D12-E12 -> 3.9674483e+08 | G12: 2.3503542e+08 | H12: 1770 | I12: 8509497.4 | J12: 688828.72 | K12: =I12-J12 -> 7820668.7 | L12: =I12+Feb!L12 -> 51731163 | M12: =J12+Feb!M12 -> 8993502.6 | N12: =L12-M12 -> 42737661
B13: =1+B12 -> 5 | C13: First Metro Consumer Fund, Inc. | D13: 474934315 | E13: 1372196 | F13: =D13-E13 -> 473562119 | G13: 408743942 | H13: 1297 | I13: 235156 | J13: 1160298 | K13: =I13-J13 -> -925142 | L13: =I13+Feb!L13 -> 33210187 | M13: =J13+Feb!M13 -> 38209967 | N13: =L13-M13 -> -4999780
B14: =1+B13 -> 6 | C14: First Metro Save and Learn Equity Fund, Inc. | D14: 4107170056 | E14: 107166362 | F14: =D14-E14 -> 4000003694 | G14: 3953133772 | H14: 15221 | I14: 10570282 | J14: 75380451 | K14: =I14-J14 -> -64810169 | L14: =I14+Feb!L14 -> 281675971 | M14: =J14+Feb!M14 -> 892957534 | N14: =L14-M14 -> -611281563
B15: =1+B14 -> 7 | C15: First Metro Save and Learn Phil. Index Fund, Inc. | D15: 104824830 | E15: 368554 | F15: =D15-E15 -> 104456276 | G15: 102257134 | H15: 507 | I15: 312196 | J15: 962960 | K15: =I15-J15 -> -650764 | L15: =I15+Feb!L15 -> 927605 | M15: =J15+Feb!M15 -> 4349038 | N15: =L15-M15 -> -3421433
B16: =1+B15 -> 8 | C16: MBG Equity Investment Fund, Inc. | D16: 136476488 | E16: 818611 | F16: =D16-E16 -> 135657877 | G16: 120686665 | H16: 48 | I16: 20000000 | J16: 5282425 | K16: =I16-J16 -> 14717575 | L16: =I16+Feb!L16 -> 20000000 | M16: =J16+Feb!M16 -> 7228845 | N16: =L16-M16 -> 12771155
B17: =1+B16 -> 9 | C17: PAMI Equity Index Fund, Inc. | D17: 1255565234 | E17: 45895664 | F17: =D17-E17 -> 1209669570 | G17: 1231270634 | H17: 11530 | I17: 0 | J17: 7267094 | K17: =I17-J17 -> -7267094 | L17: =I17+Feb!L17 -> 0 | M17: =J17+Feb!M17 -> 49090605 | N17: =L17-M17 -> -49090605
B18: =1+B17 -> 10 | C18: Philam Strategic Growth Fund, Inc. | D18: 3660635386 | E18: 34638252 | F18: =D18-E18 -> 3625997134 | G18: 3479893417 | H18: 11434 | I18: 7092987 | J18: 45919508 | K18: =I18-J18 -> -38826521 | L18: =I18+Feb!L18 -> 19993946 | M18: =J18+Feb!M18 -> 110676574 | N18: =L18-M18 -> -90682628
B19: =1+B18 -> 11 | C19: Philequity Dividend Yield Fund, Inc. | D19: 2.3688486e+09 | E19: 6250197.9 | F19: =D19-E19 -> 2362598414 | G19: 2.1862566e+09 | H19: 4930 | I19: 4169868.2 | J19: 3629097.8 | K19: =I19-J19 -> 540770.4 | L19: =I19+Feb!L19 -> 6972694.4 | M19: =J19+Feb!M19 -> 12984234 | N19: =L19-M19 -> -6011540
B20: =1+B19 -> 12 | C20: Philequity Fund, Inc. | D20: 9.9454505e+09 | E20: 44508162 | F20: =D20-E20 -> 9900942311 | G20: 9.1746985e+09 | H20: 33793 | I20: 8475106.3 | J20: 48156529 | K20: =I20-J20 -> -39681422 | L20: =I20+Feb!L20 -> 28304353 | M20: =J20+Feb!M20 -> 1.5394055e+08 | N20: =L20-M20 -> -125636193
B21: =1+B20 -> 13 | C21: Philequity MSCI Phil. Index Fund, Inc. | D21: 3.3202565e+08 | E21: 769105.37 | F21: =D21-E21 -> 3.3125655e+08 | G21: 3.2467583e+08 | H21: 933 | I21: 218923.87 | J21: 3955790.4 | K21: =I21-J21 -> -3736866.5 | L21: =I21+Feb!L21 -> 1070648.7 | M21: =J21+Feb!M21 -> 5860074.7 | N21: =L21-M21 -> -4789425.9
... B27: =1+B26 -> 19 | C27: United Fund, Inc. | D27: 6.2017586e+08 | E27: 4592568.1 | F27: =D27-E27 -> 6.155833e+08 | G27: 5.3441245e+08 | H27: 1237 | I27: 1788635.6 | J27: 495371.89 | K27: =I27-J27 -> 1293263.7 | L27: =I27+Feb!L27 -> 2643364.8 | M27: =J27+Feb!M27 -> 4737923.6 | N27: =L27-M27 -> -2094558.8
A28: Primarily invested in Peso Securities (units)
B29: =1+B27 -> 20 | C29: COL Equity Index Unitized Mutual Fund, Inc. | D29: 2.3225626e+08 | E29: 1808934.6 | F29: =D29-E29 -> 2.3044733e+08 | G29: 2.2771641e+08 | H29: 3298 | I29: 5136368.2 | J29: 7889440.5 | K29: =I29-J29 -> -2753072.3 | L29: =I29+Feb!L29 -> 17952828 | M29: =J29+Feb!M29 -> 33265430 | N29: =L29-M29 -> -15312602
B30: =1+B29 -> 21 | C30: COL Strategic Growth Equity Unitized Mutual Fund, Inc. | D30: 2.5495943e+08 | E30: 1548984.6 | F30: =D30-E30 -> 2.5341044e+08 | G30: 1.4247344e+08 | H30: 2756 | I30: 19567449 | J30: 6717379.6 | K30: =I30-J30 -> 12850070 | L30: =I30+Feb!L30 -> 151943812 | M30: =J30+Feb!M30 -> 14908449 | N30: =L30-M30 -> 1.3703536e+08
B31: =1+B30 -> 22 | C31: Philequity Alpha One Fund, Inc. | D31: 3.1407579e+08 | E31: 2116146.9 | F31: =D31-E31 -> 3.1195964e+08 | G31: 2.7664281e+08 | H31: 1235 | I31: 433154.2 | J31: 1373893.6 | K31: =I31-J31 -> -940739.35 | L31: =I31+Feb!L31 -> 1935246.1 | M31: =J31+Feb!M31 -> 16390666 | N31: =L31-M31 -> -14455420
B32: =1+B31 -> 23 | C32: Philippine Stock Index Fund Corp. | D32: 634834115 | E32: 9852473 | F32: =D32-E32 -> 624981642 | G32: 618773532 | H32: 652918 | I32: 19301863 | J32: 31460608 | K32: =I32-J32 -> -12158745 | L32: =I32+Feb!L32 -> 50680961 | M32: =J32+Feb!M32 -> 88231403 | N32: =L32-M32 -> -37550442
A33: Exchange Traded Fund
B34: =1+B32 -> 24 | C34: First Metro Phil. Equity Exchange Traded Fund, Inc. | D34: 2237964469 | E34: 1890662 | F34: =D34-E34 -> 2236073807 | G34: 2211932497 | H34: 3209 | I34: 0 | J34: 27517230 | K34: =I34-J34 -> -27517230 | L34: =I34+Feb!L34 -> 8336295 | M34: =J34+Feb!M34 -> 77612359 | N34: =L34-M34 -> -69276064
A35: Sub total - Peso Currency | D35: =SUM(D9:D34) -> 67863075101 | E35: =SUM(E9:E34) -> 4.4184464e+08 | F35: =SUM(F9:F34) -> 67421230465 | G35: =SUM(G9:G34) -> 65138272502 | H35: =SUM(H9:H34) -> 934721 | I35: =SUM(I9:I34) -> 2.593522e+08 | J35: =SUM(J9:J34) -> 8.8743059e+08 | K35: =SUM(K9:K34) -> -628078395 | ... N35: =SUM(N9:N34) -> -2532958962
A36: Primarily invested in foreign currency securities (shares)
B37: =1+B34 -> 25 | C37: ATRAM AsiaPlus Equity Fund, Inc. | D37: 26205148 | E37: 60742.01 | F37: =D37-E37 -> 26144406 | G37: 24858777 | H37: 51 | I37: 33714.19 | J37: 21556.23 | K37: =I37-J37 -> 12157.96 | L37: =I37+Feb!L37 -> 306197.07 | M37: =J37+Feb!M37 -> 32765.65 | N37: =L37-M37 -> 273431.42
B38: =1+B37 -> 26 | C38: Sun Life Prosperity World Voyager Fund, Inc. | D38: 2111913039 | E38: 9289520 | F38: =D38-E38 -> 2102623519 | G38: 0 | H38: 2972 | I38: 10927273 | J38: 15841522 | K38: =I38-J38 -> -4914249 | L38: =I38+Feb!L38 -> 46105293 | M38: =J38+Feb!M38 -> 99198635 | N38: =L38-M38 -> -53093342
A39: Sub total - US Currency | D39: =SUM(D37:D38) -> 2138118187 | E39: =SUM(E37:E38) -> 9350262 | F39: =SUM(F37:F38) -> 2128767925 | G39: =SUM(G37:G38) -> 24858777 | H39: =SUM(H37:H38) -> 3023 | I39: =SUM(I37:I38) -> 10960987 | J39: =SUM(J37:J38) -> 15863078 | K39: =SUM(K37:K38) -> -4902091 | ... N39: =SUM(N37:N38) -> -52819911
A40: Sub total - stock funds | D40: =D35+D39 -> 70001193288 | E40: =E35+E39 -> 4.511949e+08 | F40: =F35+F39 -> 69549998390 | G40: =G35+G39 -> 65163131278 | H40: =H35+H39 -> 937744 | I40: =I35+I39 -> 2.7031319e+08 | J40: =J35+J39 -> 9.0329367e+08 | K40: =K35+K39 -> -6.3298049e+08 | ... N40: =N35+N39 -> -2585778872
A41: Balanced Funds
A42: Primarily invested in Peso Securities (shares)
B43: =1+B38 -> 27 | C43: ATRAM Philippine Balanced Fund, Inc. | D43: 4.641075e+08 | E43: 311279.24 | F43: =D43-E43 -> 4.6379622e+08 | G43: 2.7540604e+08 | H43: 2345 | I43: 576961.65 | J43: 5889286.7 | K43: =I43-J43 -> -5312325 | L43: =I43+Feb!L43 -> 2187096.9 | M43: =J43+Feb!M43 -> 24067463 | N43: =L43-M43 -> -21880366
B44: =1+B43 -> 28 | C44: ATRAM Unicapital Diversified Growth Fund, Inc. | D44: 1.1814101e+08 | E44: 13122.93 | F44: =D44-E44 -> 1.1812789e+08 | G44: 45273972 | H44: 697 | I44: 227512.69 | J44: 409061.65 | K44: =I44-J44 -> -181548.96 | L44: =I44+Feb!L44 -> 1010884.6 | M44: =J44+Feb!M44 -> 3341621.5 | N44: =L44-M44 -> -2330737
B45: =1+B44 -> 29 | C45: First Metro Save and Learn Balanced Fund, Inc. | D45: 839590805 | E45: 13763593 | F45: =D45-E45 -> 825827212 | G45: 532334445 | H45: 4350 | I45: 5797527 | J45: 51213538 | K45: =I45-J45 -> -45416011 | L45: =I45+Feb!L45 -> 8152871 | M45: =J45+Feb!M45 -> 168970942 | N45: =L45-M45 -> -160818071
...

Sheet Q1
A1: PHILIPPINE INVESTMENT FUNDS ASSOCIATION, INC.
A2: MUTUAL FUNDS STATISTICAL REPORT
A3: As of the First Quarter of 2024
A4: (Amounts in Philippine Peso)
A6: Fund Category | C6: Fund Name | D6: NET ASSETS | E6: TOTAL SALES | F6: TOTAL REDEMPTIONS | G6: NET SALES
A7: Stock Funds
A8: Primarily invested in Peso Securities (shares)
B9: 1 | C9: ALFM Growth Fund, Inc. | D9: =Mar!F9 -> 4459119912 | E9: ='Jan UPDATED'!I9+Feb!I9+Mar!I9 -> 12121404 | F9: ='Jan UPDATED'!J9+Feb!J9+Mar!J9 -> 179591696 | G9: =E9-F9 -> -167470292
B10: =1+B9 -> 2 | C10: ATRAM Alpha Opportunity Fund, Inc. | D10: =Mar!F10 -> 800261106 | E10: ='Jan UPDATED'!I10+Feb!I10+Mar!I10 -> 6444175.6 | F10: ='Jan UPDATED'!J10+Feb!J10+Mar!J10 -> 40030063 | G10: =E10-F10 -> -33585887
B11: =1+B10 -> 3 | C11: ATRAM Phil. Equity Opportunity Fund, Inc. | D11: =Mar!F11 -> 1357459559 | E11: ='Jan UPDATED'!I11+Feb!I11+Mar!I11 -> 32405637 | F11: ='Jan UPDATED'!J11+Feb!J11+Mar!J11 -> 1.0605813e+08 | G11: =E11-F11 -> -73652495
B12: =1+B11 -> 4 | C12: Climbs Share Capital Equity Investment Fund Corp. | D12: =Mar!F12 -> 3.9674483e+08 | E12: ='Jan UPDATED'!I12+Feb!I12+Mar!I12 -> 51731163 | F12: ='Jan UPDATED'!J12+Feb!J12+Mar!J12 -> 8993502.6 | G12: =E12-F12 -> 42737661
B13: =1+B12 -> 5 | C13: First Metro Consumer Fund, Inc. | D13: =Mar!F13 -> 473562119 | E13: ='Jan UPDATED'!I13+Feb!I13+Mar!I13 -> 33210187 | F13: ='Jan UPDATED'!J13+Feb!J13+Mar!J13 -> 38209967 | G13: =E13-F13 -> -4999780
B14: =1+B13 -> 6 | C14: First Metro Save and Learn Equity Fund, Inc. | D14: =Mar!F14 -> 4000003694 | E14: ='Jan UPDATED'!I14+Feb!I14+Mar!I14 -> 281675971 | F14: ='Jan UPDATED'!J14+Feb!J14+Mar!J14 -> 892957534 | G14: =E14-F14 -> -611281563
B15: =1+B14 -> 7 | C15: First Metro Save and Learn Phil. Index Fund, Inc. | D15: =Mar!F15 -> 104456276 | E15: ='Jan UPDATED'!I15+Feb!I15+Mar!I15 -> 927605 | F15: ='Jan UPDATED'!J15+Feb!J15+Mar!J15 -> 4349038 | G15: =E15-F15 -> -3421433
B16: =1+B15 -> 8 | C16: MBG Equity Investment Fund, Inc. | D16: =Mar!F16 -> 135657877 | E16: ='Jan UPDATED'!I16+Feb!I16+Mar!I16 -> 20000000 | F16: ='Jan UPDATED'!J16+Feb!J16+Mar!J16 -> 7228845 | G16: =E16-F16 -> 12771155
B17: =1+B16 -> 9 | C17: PAMI Equity Index Fund, Inc. | D17: =Mar!F17 -> 1209669570 | E17: ='Jan UPDATED'!I17+Feb!I17+Mar!I17 -> 0 | F17: ='Jan UPDATED'!J17+Feb!J17+Mar!J17 -> 49090605 | G17: =E17-F17 -> -49090605
B18: =1+B17 -> 10 | C18: Philam Strategic Growth Fund, Inc. | D18: =Mar!F18 -> 3625997134 | E18: ='Jan UPDATED'!I18+Feb!I18+Mar!I18 -> 19993946 | F18: ='Jan UPDATED'!J18+Feb!J18+Mar!J18 -> 110676574 | G18: =E18-F18 -> -90682628
B19: =1+B18 -> 11 | C19: Philequity Dividend Yield Fund, Inc. | D19: =Mar!F19 -> 2362598414 | E19: ='Jan UPDATED'!I19+Feb!I19+Mar!I19 -> 6972694.4 | F19: ='Jan UPDATED'!J19+Feb!J19+Mar!J19 -> 12984234 | G19: =E19-F19 -> -6011540
B20: =1+B19 -> 12 | C20: Philequity Fund, Inc. | D20: =Mar!F20 -> 9900942311 | E20: ='Jan UPDATED'!I20+Feb!I20+Mar!I20 -> 28304353 | F20: ='Jan UPDATED'!J20+Feb!J20+Mar!J20 -> 1.5394055e+08 | G20: =E20-F20 -> -125636193
B21: =1+B20 -> 13 | C21: Philequity MSCI Phils. Index Fund, Inc. | D21: =Mar!F21 -> 3.3125655e+08 | E21: ='Jan UPDATED'!I21+Feb!I21+Mar!I21 -> 1070648.7 | F21: ='Jan UPDATED'!J21+Feb!J21+Mar!J21 -> 5860074.7 | G21: =E21-F21 -> -4789425.9
... B27: =1+B26 -> 19 | C27: United Fund, Inc. | D27: =Mar!F27 -> 6.155833e+08 | E27: ='Jan UPDATED'!I27+Feb!I27+Mar!I27 -> 2643364.8 | F27: ='Jan UPDATED'!J27+Feb!J27+Mar!J27 -> 4737923.6 | G27: =E27-F27 -> -2094558.8
A28: Primarily invested in Peso Securities (units) | D28: =Mar!F28 | E28: ='Jan UPDATED'!I28+Feb!I28+Mar!I28 -> 0 | F28: ='Jan UPDATED'!J28+Feb!J28+Mar!J28 -> 0
B29: =1+B27 -> 20 | C29: COL Equity Index Unitized Mutual Fund, Inc. | D29: =Mar!F29 -> 2.3044733e+08 | E29: ='Jan UPDATED'!I29+Feb!I29+Mar!I29 -> 17952828 | F29: ='Jan UPDATED'!J29+Feb!J29+Mar!J29 -> 33265430 | G29: =E29-F29 -> -15312602
B30: =1+B29 -> 21 | C30: COL Strategic Growth Equity Unitized Mutual Fund, Inc. | D30: =Mar!F30 -> 2.5341044e+08 | E30: ='Jan UPDATED'!I30+Feb!I30+Mar!I30 -> 151943812 | F30: ='Jan UPDATED'!J30+Feb!J30+Mar!J30 -> 14908449 | G30: =E30-F30 -> 1.3703536e+08
B31: =1+B30 -> 22 | C31: Philequity Alpha One Fund, Inc. | D31: =Mar!F31 -> 3.1195964e+08 | E31: ='Jan UPDATED'!I31+Feb!I31+Mar!I31 -> 1935246.1 | F31: ='Jan UPDATED'!J31+Feb!J31+Mar!J31 -> 16390666 | G31: =E31-F31 -> -14455420
B32: =1+B31 -> 23 | C32: Philippine Stock Index Fund Corp. | D32: =Mar!F32 -> 624981642 | E32: ='Jan UPDATED'!I32+Feb!I32+Mar!I32 -> 50680961 | F32: ='Jan UPDATED'!J32+Feb!J32+Mar!J32 -> 88231403 | G32: =E32-F32 -> -37550442
A33: Exchange Traded Fund | D33: =Mar!F33 | E33: ='Jan UPDATED'!I33+Feb!I33+Mar!I33 -> 0 | F33: ='Jan UPDATED'!J33+Feb!J33+Mar!J33 -> 0
B34: =1+B32 -> 24 | C34: First Metro Phil. Equity Exchange Traded Fund, Inc. | D34: =Mar!F34 -> 2236073807 | E34: ='Jan UPDATED'!I34+Feb!I34+Mar!I34 -> 8336295 | F34: ='Jan UPDATED'!J34+Feb!J34+Mar!J34 -> 77612359 | G34: =E34-F34 -> -69276064
A35: Sub total - Peso Currency | D35: =SUM(D9:D34) -> 67421230465 | E35: =SUM(E9:E34) -> 1057434248 | F35: =SUM(F9:F34) -> 3590393209 | G35: =SUM(G9:G34) -> -2532958962
A36: Primarily invested in foreign currency securities (shares)
B37: =1+B34 -> 25 | C37: ATRAM AsiaPlus Equity Fund, Inc. | D37: =Mar!F37 -> 26144406 | E37: ='Jan UPDATED'!I37+Feb!I37+Mar!I37 -> 306197.07 | F37: ='Jan UPDATED'!J37+Feb!J37+Mar!J37 -> 32765.65 | G37: =E37-F37 -> 273431.42
B38: =1+B37 -> 26 | C38: Sun Life Prosperity World Voyager Fund, Inc. | D38: =Mar!F38 -> 2102623519 | E38: ='Jan UPDATED'!I38+Feb!I38+Mar!I38 -> 46105293 | F38: ='Jan UPDATED'!J38+Feb!J38+Mar!J38 -> 99198635 | G38: =E38-F38 -> -53093342
A39: Sub total - US Currency | D39: =SUM(D37:D38) -> 2128767925 | E39: =SUM(E37:E38) -> 46411490 | F39: =SUM(F37:F38) -> 99231401 | G39: =SUM(G37:G38) -> -52819911
A40: Sub total - stock funds | D40: =D35+D39 -> 69549998390 | E40: =E35+E39 -> 1103845738 | F40: =F35+F39 -> 3689624610 | G40: =G35+G39 -> -2585778872
A41: Balanced Funds
A42: Primarily invested in Peso Securities (shares)
B43: =B38+1 -> 27 | C43: ATRAM Philippine Balanced Fund, Inc. | D43: =Mar!F43 -> 4.6379622e+08 | E43: ='Jan UPDATED'!I43+Feb!I43+Mar!I43 -> 2187096.9 | F43: ='Jan UPDATED'!J43+Feb!J43+Mar!J43 -> 24067463 | G43: =E43-F43 -> -21880366
B44: =B43+1 -> 28 | C44: ATRAM Unicapital Diversified Growth Fund, Inc. | D44: =Mar!F44 -> 1.1812789e+08 | E44: ='Jan UPDATED'!I44+Feb!I44+Mar!I44 -> 1010884.6 | F44: ='Jan UPDATED'!J44+Feb!J44+Mar!J44 -> 3341621.5 | G44: =E44-F44 -> -2330737
B45: =B44+1 -> 29 | C45: First Metro Save and Learn Balanced Fund, Inc. | D45: =Mar!F45 -> 825827212 | E45: ='Jan UPDATED'!I45+Feb!I45+Mar!I45 -> 8152871 | F45: ='Jan UPDATED'!J45+Feb!J45+Mar!J45 -> 168970942 | G45: =E45-F45 -> -160818071
B46: =B45+1 -> 30 | C46: First Metro Save and Learn F.O.C.C.U.S. Dynamic Fund, Inc. | D46: =Mar!F46 -> 303464419 | E46: ='Jan UPDATED'!I46+Feb!I46+Mar!I46 -> 87895884 | F46: ='Jan UPDATED'!J46+Feb!J46+Mar!J46 -> 90615655 | G46: =E46-F46 -> -2719771
...

Sheet Apr
A1: PHILIPPINE INVESTMENT FUNDS ASSOCIATION, INC.
A2: MUTUAL FUNDS STATISTICAL REPORT
A3: Month of April 2024
A4: (Amounts in Peso)
I5: F O R - T H E - M O N T H | L5: Y E A R - T O - D A T E
A6: Fund Category | C6: Fund Name | D6: ASSETS | E6: LIABILITIES | F6: NET ASSETS | G6: EQUITY INV. | H6: NO. OF A/C | I6: SALES | J6: REDEMPTIONS | K6: NET SALES | L6: TOTAL SALES | M6: TOTAL REDEMPTIONS | N6: TOTAL NET SALES
A7: Stock Funds
A8: Primarily invested in Peso Securities (shares)
B9: 1 | C9: ALFM Growth Fund, Inc. | D9: 4324706938 | E9: 12765826 | F9: =D9-E9 -> 4311941112 | G9: 4143331275 | H9: 6398 | I9: 4855576 | J9: 31743228 | K9: =I9-J9 -> -26887652 | L9: =I9+Mar!L9 -> 16976980 | M9: =J9+Mar!M9 -> 211334924 | N9: =L9-M9 -> -194357944
B10: =1+B9 -> 2 | C10: ATRAM Alpha Opportunity Fund, Inc. | D10: 7.8367735e+08 | E10: 210890.79 | F10: =D10-E10 -> 7.8346645e+08 | G10: 7.218737e+08 | H10: 4026 | I10: 3611881.2 | J10: 10167385 | K10: =I10-J10 -> -6555503.4 | L10: =I10+Mar!L10 -> 10056057 | M10: =J10+Mar!M10 -> 50197448 | N10: =L10-M10 -> -40141391
B11: =1+B10 -> 3 | C11: ATRAM Phil. Equity Opportunity Fund, Inc. | D11: 1.3066175e+09 | E11: 946676.02 | F11: =D11-E11 -> 1305670840 | G11: 1.2290593e+09 | H11: 2642 | I11: 6216093.7 | J11: 24945078 | K11: =I11-J11 -> -18728984 | L11: =I11+Mar!L11 -> 38621730 | M11: =J11+Mar!M11 -> 1.3100321e+08 | N11: =L11-M11 -> -92381479
B12: =1+B11 -> 4 | C12: Climbs Share Capital Equity Investment Fund Corp. | D12: 4.1801023e+08 | E12: 6948729.3 | F12: =D12-E12 -> 4.110615e+08 | G12: 3.1772831e+08 | H12: 1760 | I12: 15652857 | J12: 281371.09 | K12: =I12-J12 -> 15371486 | L12: =I12+Mar!L12 -> 67384020 | M12: =J12+Mar!M12 -> 9274873.7 | N12: =L12-M12 -> 58109147
B13: =1+B12 -> 5 | C13: First Metro Consumer Fund, Inc. | D13: 457811351 | E13: 4280116 | F13: =D13-E13 -> 453531235 | G13: 306615119 | H13: 1287 | I13: 31139718 | J13: 35560063 | K13: =I13-J13 -> -4420345 | L13: =I13+Mar!L13 -> 64349905 | M13: =J13+Mar!M13 -> 73770030 | N13: =L13-M13 -> -9420125
B14: =1+B13 -> 6 | C14: First Metro Save and Learn Equity Fund, Inc. | D14: 3832512626 | E14: 78179127 | F14: =D14-E14 -> 3754333499 | G14: 3110046771 | H14: 15133 | I14: 274892935 | J14: 371014043 | K14: =I14-J14 -> -96121108 | L14: =I14+Mar!L14 -> 556568906 | M14: =J14+Mar!M14 -> 1263971577 | N14: =L14-M14 -> -707402671
B15: =1+B14 -> 7 | C15: First Metro Save and Learn Phil. Index Fund, Inc. | D15: 101873353 | E15: 401213 | F15: =D15-E15 -> 101472140 | G15: 99243234 | H15: 506 | I15: 510069 | J15: 493714 | K15: =I15-J15 -> 16355 | L15: =I15+Mar!L15 -> 1437674 | M15: =J15+Mar!M15 -> 4842752 | N15: =L15-M15 -> -3405078
B16: =1+B15 -> 8 | C16: MBG Equity Investment Fund, Inc. | D16: 136784852 | E16: 1540683 | F16: =D16-E16 -> 135244169 | G16: 117944390 | H16: 47 | I16: 3000000 | J16: 313773 | K16: =I16-J16 -> 2686227 | L16: =I16+Mar!L16 -> 23000000 | M16: =J16+Mar!M16 -> 7542618 | N16: =L16-M16 -> 15457382
B17: =1+B16 -> 9 | C17: PAMI Equity Index Fund, Inc. | D17: 1195857998 | E17: 27005919 | F17: =D17-E17 -> 1168852079 | G17: 1178726225 | H17: 11490 | I17: 0 | J17: 7726419 | K17: =I17-J17 -> -7726419 | L17: =I17+Mar!L17 -> 0 | M17: =J17+Mar!M17 -> 56817024 | N17: =L17-M17 -> -56817024
B18: =1+B17 -> 10 | C18: Philam Strategic Growth Fund, Inc. | D18: 3528769287 | E18: 31061967 | F18: =D18-E18 -> 3497707320 | G18: 3374100919 | H18: 11384 | I18: 7501654 | J18: 34851344 | K18: =I18-J18 -> -27349690 | L18: =I18+Mar!L18 -> 27495600 | M18: =J18+Mar!M18 -> 145527918 | N18: =L18-M18 -> -118032318
B19: =1+B18 -> 11 | C19: Philequity Dividend Yield Fund, Inc. | D19: 2.3636668e+09 | E19: 6495743.1 | F19: =D19-E19 -> 2357171034 | G19: 2.1320997e+09 | H19: 4897 | I19: 4854076 | J19: 7765123.8 | K19: =I19-J19 -> -2911047.7 | L19: =I19+Mar!L19 -> 11826770 | M19: =J19+Mar!M19 -> 20749358 | N19: =L19-M19 -> -8922587.8
B20: =1+B19 -> 12 | C20: Philequity Fund, Inc. | D20: 9.6400033e+09 | E20: 39896435 | F20: =D20-E20 -> 9600106884 | G20: 8.7087155e+09 | H20: 33629 | I20: 11819125 | J20: 43435134 | K20: =I20-J20 -> -31616009 | L20: =I20+Mar!L20 -> 40123478 | M20: =J20+Mar!M20 -> 1.9737568e+08 | N20: =L20-M20 -> -1.572522e+08
B21: =1+B20 -> 13 | C21: Philequity MSCI Phil. Index Fund, Inc. | D21: 3.2150242e+08 | E21: 748479.42 | F21: =D21-E21 -> 3.2075394e+08 | G21: 3.1420374e+08 | H21: 932 | I21: 356181.63 | J21: 69213.24 | K21: =I21-J21 -> 286968.39 | L21: =I21+Mar!L21 -> 1426830.4 | M21: =J21+Mar!M21 -> 5929287.9 | N21: =L21-M21 -> -4502457.5
... B27: =1+B26 -> 19 | C27: United Fund, Inc. | D27: 6.2556624e+08 | E27: 20960020 | F27: =D27-E27 -> 604606217 | G27: 5.3967495e+08 | H27: 1233 | I27: 7450782.6 | J27: 1390154.2 | K27: =I27-J27 -> 6060628.4 | L27: =I27+Mar!L27 -> 10094147 | M27: =J27+Mar!M27 -> 6128077.8 | N27: =L27-M27 -> 3966069.6
A28: Primarily invested in Peso Securities (units)
B29: =1+B27 -> 20 | C29: COL Equity Index Unitized Mutual Fund, Inc. | D29: 2.2770206e+08 | E29: 922248.71 | F29: =D29-E29 -> 2.2677981e+08 | G29: 2.2362517e+08 | H29: 3470 | I29: 5963945.1 | J29: 3151445.6 | K29: =I29-J29 -> 2812499.6 | L29: =I29+Mar!L29 -> 23916773 | M29: =J29+Mar!M29 -> 36416876 | N29: =L29-M29 -> -12500103
B30: =1+B29 -> 21 | C30: COL Strategic Growth Equity Unitized Mutual Fund, Inc. | D30: 2.6000024e+08 | E30: 604612.73 | F30: =D30-E30 -> 2.5939562e+08 | G30: 149131269 | H30: 3137 | I30: 13248793 | J30: 2791651.4 | K30: =I30-J30 -> 10457141 | L30: =I30+Mar!L30 -> 1.651926e+08 | M30: =J30+Mar!M30 -> 17700100 | N30: =L30-M30 -> 1.474925e+08
B31: =1+B30 -> 22 | C31: Philequity Alpha One Fund, Inc. | D31: 3.0235854e+08 | E31: 1581879.3 | F31: =D31-E31 -> 3.0077666e+08 | G31: 274822933 | H31: 1219 | I31: 498335.29 | J31: 4336046.9 | K31: =I31-J31 -> -3837711.6 | L31: =I31+Mar!L31 -> 2433581.4 | M31: =J31+Mar!M31 -> 20726713 | N31: =L31-M31 -> -18293132
B32: =1+B31 -> 23 | C32: Philippine Stock Index Fund Corp. | D32: 624420763 | E32: 5502308 | F32: =D32-E32 -> 618918455 | G32: 612947226 | H32: 646399 | I32: 28103494 | J32: 17118746 | K32: =I32-J32 -> 10984748 | L32: =I32+Mar!L32 -> 78784455 | M32: =J32+Mar!M32 -> 105350149 | N32: =L32-M32 -> -26565694
A33: Exchange Traded Fund
B34: =1+B32 -> 24 | C34: First Metro Phil. Equity Exchange Traded Fund, Inc. | D34: 2141987007 | E34: 1932857 | F34: =D34-E34 -> 2140054150 | G34: 2127887775 | H34: 3225 | I34: 6199623 | J34: 41981604 | K34: =I34-J34 -> -35781981 | L34: =I34+Mar!L34 -> 14535918 | M34: =J34+Mar!M34 -> 119593963 | N34: =L34-M34 -> -105058045
A35: Sub total - Peso Currency | D35: =SUM(D9:D34) -> 65421075432 | E35: =SUM(E9:E34) -> 4.0083047e+08 | F35: =SUM(F9:F34) -> 65020244959 | G35: =SUM(G9:G34) -> 61811389174 | H35: =SUM(H9:H34) -> 928043 | I35: =SUM(I9:I34) -> 6.2795297e+08 | J35: =SUM(J9:J34) -> 1156456765 | K35: =SUM(K9:K34) -> -528503795 | ... N35: =SUM(N9:N34) -> -3061462757
A36: Primarily invested in foreign currency securities (shares)
B37: =1+B34 -> 25 | C37: ATRAM AsiaPlus Equity Fund, Inc. | D37: 26983952 | E37: 62379.64 | F37: =D37-E37 -> 26921572 | G37: 0 | H37: 51 | I37: 46170.46 | J37: 7354.58 | K37: =I37-J37 -> 38815.88 | L37: =I37+Mar!L37 -> 352367.53 | M37: =J37+Mar!M37 -> 40120.23 | N37: =L37-M37 -> 312247.3
B38: =1+B37 -> 26 | C38: Sun Life Prosperity World Voyager Fund, Inc. | D38: 1868204040 | E38: 41500208 | F38: =D38-E38 -> 1826703832 | G38: 0 | H38: 2982 | I38: 14579177 | J38: 298337949 | K38: =I38-J38 -> -283758772 | L38: =I38+Mar!L38 -> 60684470 | M38: =J38+Mar!M38 -> 397536584 | N38: =L38-M38 -> -336852114
A39: Sub total - US Currency | D39: =SUM(D37:D38) -> 1895187992 | E39: =SUM(E37:E38) -> 41562588 | F39: =SUM(F37:F38) -> 1853625404 | G39: =SUM(G37:G38) -> 0 | H39: =SUM(H37:H38) -> 3033 | I39: =SUM(I37:I38) -> 14625347 | J39: =SUM(J37:J38) -> 2.983453e+08 | K39: =SUM(K37:K38) -> -2.8371996e+08 | ... N39: =SUM(N37:N38) -> -3.3653987e+08
A40: Sub total - stock funds | D40: =D35+D39 -> 67316263424 | E40: =E35+E39 -> 4.4239306e+08 | F40: =F35+F39 -> 66873870363 | G40: =G35+G39 -> 61811389174 | H40: =H35+H39 -> 931076 | I40: =I35+I39 -> 6.4257832e+08 | J40: =J35+J39 -> 1454802069 | K40: =K35+K39 -> -8.1222375e+08 | ... N40: =N35+N39 -> -3398002623
A41: Balanced Funds
A42: Primarily invested in Peso Securities (shares)
B43: =1+B38 -> 27 | C43: ATRAM Philippine Balanced Fund, Inc. | D43: 4.4481235e+08 | E43: 69146.33 | F43: =D43-E43 -> 4.4474321e+08 | G43: 2.3403218e+08 | H43: 2332 | I43: 492069.9 | J43: 3461082.6 | K43: =I43-J43 -> -2969012.7 | L43: =I43+Mar!L43 -> 2679166.8 | M43: =J43+Mar!M43 -> 27528545 | N43: =L43-M43 -> -24849378
B44: =1+B43 -> 28 | C44: ATRAM Unicapital Diversified Growth Fund, Inc. | D44: 1.2150824e+08 | E44: 5873675.2 | F44: =D44-E44 -> 1.1563456e+08 | G44: 34232023 | H44: 698 | I44: 155535.2 | J44: 327702.35 | K44: =I44-J44 -> -172167.15 | L44: =I44+Mar!L44 -> 1166419.8 | M44: =J44+Mar!M44 -> 3669323.9 | N44: =L44-M44 -> -2502904.1
B45: =1+B44 -> 29 | C45: First Metro Save and Learn Balanced Fund, Inc. | D45: 810734671 | E45: 12426091 | F45: =D45-E45 -> 798308580 | G45: 384981968 | H45: 4320 | I45: 672857 | J45: 5911411 | K45: =I45-J45 -> -5238554 | L45: =I45+Mar!L45 -> 8825728 | M45: =J45+Mar!M45 -> 174882353 | N45: =L45-M45 -> -166056625
...

Sheet May
A1: PHILIPPINE INVESTMENT FUNDS ASSOCIATION, INC.
A2: MUTUAL FUNDS STATISTICAL REPORT
A3: Month of May 2024
A4: (Amounts in Peso)
I5: F O R - T H E - M O N T H | L5: Y E A R - T O - D A T E
A6: Fund Category | C6: Fund Name | D6: ASSETS | E6: LIABILITIES | F6: NET ASSETS | G6: EQUITY INV. | H6: NO. OF A/C | I6: SALES | J6: REDEMPTIONS | K6: NET SALES | L6: TOTAL SALES | M6: TOTAL REDEMPTIONS | N6: TOTAL NET SALES
A7: Stock Funds
A8: Primarily invested in Peso Securities (shares)
B9: 1 | C9: ALFM Growth Fund, Inc. | D9: 4114788301 | E9: 16837865 | F9: =D9-E9 -> 4097950436 | G9: 3918040331 | H9: 6365 | I9: 4301884 | J9: 43398326 | K9: =I9-J9 -> -39096442 | L9: =I9+Apr!L9 -> 21278864 | M9: =J9+Apr!M9 -> 254733250 | N9: =L9-M9 -> -233454386
B10: =1+B9 -> 2 | C10: ATRAM Alpha Opportunity Fund, Inc. | D10: 7.8519195e+08 | E10: 1029848.4 | F10: =D10-E10 -> 7.841621e+08 | G10: 7.3942494e+08 | H10: 4000 | I10: 12157264 | J10: 63510391 | K10: =I10-J10 -> -51353127 | L10: =I10+Apr!L10 -> 22213321 | M10: =J10+Apr!M10 -> 1.1370784e+08 | N10: =L10-M10 -> -91494517
B11: =1+B10 -> 3 | C11: ATRAM Phil. Equity Opportunity Fund, Inc. | D11: 1.2470821e+09 | E11: 1.0661299e+08 | F11: =D11-E11 -> 1140469153 | G11: 1.0686439e+09 | H11: 2626 | I11: 3593981.3 | J11: 1.1190924e+08 | K11: =I11-J11 -> -1.0831526e+08 | L11: =I11+Apr!L11 -> 42215712 | M11: =J11+Apr!M11 -> 2.4291245e+08 | N11: =L11-M11 -> -2.0069674e+08
B12: =1+B11 -> 4 | C12: Climbs Share Capital Equity Investment Fund Corp. | D12: 4.2719516e+08 | E12: 14459284 | F12: =D12-E12 -> 4.1273587e+08 | G12: 3.2724066e+08 | H12: 1764 | I12: 1758548 | J12: 174565.04 | K12: =I12-J12 -> 1583983 | L12: =I12+Apr!L12 -> 69142568 | M12: =J12+Apr!M12 -> 9449438.7 | N12: =L12-M12 -> 59693130
B13: =1+B12 -> 5 | C13: First Metro Consumer Fund, Inc. | D13: 470998960 | E13: 3001073 | F13: =D13-E13 -> 467997887 | G13: 427372598 | H13: 1271 | I13: 281811 | J13: 1625028 | K13: =I13-J13 -> -1343217 | L13: =I13+Apr!L13 -> 64631716 | M13: =J13+Apr!M13 -> 75395058 | N13: =L13-M13 -> -10763342
B14: =1+B13 -> 6 | C14: First Metro Save and Learn Equity Fund, Inc. | D14: 3679149560 | E14: 95646435 | F14: =D14-E14 -> 3583503125 | G14: 3371420641 | H14: 15063 | I14: 9872816 | J14: 44146222 | K14: =I14-J14 -> -34273406 | L14: =I14+Apr!L14 -> 566441722 | M14: =J14+Apr!M14 -> 1308117799 | N14: =L14-M14 -> -741676077
B15: =1+B14 -> 7 | C15: First Metro Save and Learn Phil. Index Fund, Inc. | D15: 118989573 | E15: 5978976 | F15: =D15-E15 -> 113010597 | G15: 100570166 | H15: 506 | I15: 15926426 | J15: 254849 | K15: =I15-J15 -> 15671577 | L15: =I15+Apr!L15 -> 17364100 | M15: =J15+Apr!M15 -> 5097601 | N15: =L15-M15 -> 12266499
B16: =1+B15 -> 8 | C16: MBG Equity Investment Fund, Inc. | D16: 134979483 | E16: 1718998 | F16: =D16-E16 -> 133260485 | G16: 123915955 | H16: 47 | I16: 0 | J16: 0 | K16: =I16-J16 -> 0 | L16: =I16+Apr!L16 -> 23000000 | M16: =J16+Apr!M16 -> 7542618 | N16: =L16-M16 -> 15457382
B17: =1+B16 -> 9 | C17: PAMI Equity Index Fund, Inc. | D17: 1145258534 | E17: 29853423 | F17: =D17-E17 -> 1115405111 | G17: 1127104795 | H17: 11440 | I17: 0 | J17: 9483523 | K17: =I17-J17 -> -9483523 | L17: =I17+Apr!L17 -> 0 | M17: =J17+Apr!M17 -> 66300547 | N17: =L17-M17 -> -66300547
B18: =1+B17 -> 10 | C18: Philam Strategic Growth Fund, Inc. | D18: 3372360836 | E18: 28863147 | F18: =D18-E18 -> 3343497689 | G18: 3208019197 | H18: 11347 | I18: 6598010 | J18: 15263035 | K18: =I18-J18 -> -8665025 | L18: =I18+Apr!L18 -> 34093610 | M18: =J18+Apr!M18 -> 160790953 | N18: =L18-M18 -> -126697343
B19: =1+B18 -> 11 | C19: Philequity Dividend Yield Fund, Inc. | D19: 2.3892951e+09 | E19: 8145658.1 | F19: =D19-E19 -> 2381149456 | G19: 2.1891663e+09 | H19: 4873 | I19: 2771733.6 | J19: 8062768.3 | K19: =I19-J19 -> -5291034.8 | L19: =I19+Apr!L19 -> 14598504 | M19: =J19+Apr!M19 -> 28812126 | N19: =L19-M19 -> -14213623
B20: =1+B19 -> 12 | C20: Philequity Fund, Inc. | D20: 9.2512941e+09 | E20: 49281085 | F20: =D20-E20 -> 9202013043 | G20: 8.4155578e+09 | H20: 33438 | I20: 8118872.5 | J20: 49146025 | K20: =I20-J20 -> -41027152 | L20: =I20+Apr!L20 -> 48242351 | M20: =J20+Apr!M20 -> 2.465217e+08 | N20: =L20-M20 -> -1.9827935e+08
B21: =1+B20 -> 13 | C21: Philequity MSCI Phil. Index Fund, Inc. | D21: 3.0666187e+08 | E21: 964165.84 | F21: =D21-E21 -> 3.0569771e+08 | G21: 2.9927956e+08 | H21: 918 | I21: 673929.16 | J21: 176216.28 | K21: =I21-J21 -> 497712.88 | L21: =I21+Apr!L21 -> 2100759.5 | M21: =J21+Apr!M21 -> 6105504.2 | N21: =L21-M21 -> -4004744.7
... B27: =1+B26 -> 19 | C27: United Fund, Inc. | D27: 6.0377667e+08 | E27: 16176386 | F27: =D27-E27 -> 5.8760029e+08 | G27: 5.3372861e+08 | H27: 1230 | I27: 384084.82 | J27: 552820.07 | K27: =I27-J27 -> -168735.25 | L27: =I27+Apr!L27 -> 10478232 | M27: =J27+Apr!M27 -> 6680897.9 | N27: =L27-M27 -> 3797334.3
A28: Primarily invested in Peso Securities (units)
B29: =1+B27 -> 20 | C29: COL Equity Index Unitized Mutual Fund, Inc. | D29: 2.2485669e+08 | E29: 1411560 | F29: =D29-E29 -> 2.2344513e+08 | G29: 2.1843907e+08 | H29: 3594 | I29: 6595133.9 | J29: 1493387.5 | K29: =I29-J29 -> 5101746.3 | L29: =I29+Apr!L29 -> 30511907 | M29: =J29+Apr!M29 -> 37910264 | N29: =L29-M29 -> -7398356.4
B30: =1+B29 -> 21 | C30: COL Strategic Growth Equity Unitized Mutual Fund, Inc. | D30: 2.7490098e+08 | E30: 6138558 | F30: =D30-E30 -> 2.6876242e+08 | G30: 175221460 | H30: 3368 | I30: 14491781 | J30: 4210310.9 | K30: =I30-J30 -> 10281470 | L30: =I30+Apr!L30 -> 1.7968439e+08 | M30: =J30+Apr!M30 -> 21910411 | N30: =L30-M30 -> 1.5777397e+08
B31: =1+B30 -> 22 | C31: Philequity Alpha One Fund, Inc. | D31: 2.9549599e+08 | E31: 3292576.6 | F31: =D31-E31 -> 2.9220341e+08 | G31: 2.6612999e+08 | H31: 1201 | I31: 210603.36 | J31: 2243687.3 | K31: =I31-J31 -> -2033083.9 | L31: =I31+Apr!L31 -> 2644184.7 | M31: =J31+Apr!M31 -> 22970401 | N31: =L31-M31 -> -20326216
B32: =1+B31 -> 23 | C32: Philippine Stock Index Fund Corp. | D32: 609387098 | E32: 6781623 | F32: =D32-E32 -> 602605475 | G32: 597059392 | H32: 655066 | I32: 19542511 | J32: 13060471 | K32: =I32-J32 -> 6482040 | L32: =I32+Apr!L32 -> 98326966 | M32: =J32+Apr!M32 -> 118410620 | N32: =L32-M32 -> -20083654
A33: Exchange Traded Fund
B34: =1+B32 -> 24 | C34: First Metro Phil. Equity Exchange Traded Fund, Inc. | D34: 1981619812 | E34: 2023313 | F34: =D34-E34 -> 1979596499 | G34: 1960685178 | H34: 3242 | I34: 0 | J34: 84244427 | K34: =I34-J34 -> -84244427 | L34: =I34+Apr!L34 -> 14535918 | M34: =J34+Apr!M34 -> 203838390 | N34: =L34-M34 -> -189302472
A35: Sub total - Peso Currency | D35: =SUM(D9:D34) -> 62485996471 | E35: =SUM(E9:E34) -> 5.8605246e+08 | F35: =SUM(F9:F34) -> 61899944013 | G35: =SUM(G9:G34) -> 59476959768 | H35: =SUM(H9:H34) -> 936364 | I35: =SUM(I9:I34) -> 209184762 | J35: =SUM(J9:J34) -> 1130093881 | K35: =SUM(K9:K34) -> -9.2090912e+08 | ... N35: =SUM(N9:N34) -> -3982371875
A36: Primarily invested in foreign currency securities (shares)
B37: =1+B34 -> 25 | C37: ATRAM AsiaPlus Equity Fund, Inc. | D37: 27817915 | E37: 63193.14 | F37: =D37-E37 -> 27754722 | G37: 0 | H37: 50 | I37: 35069.72 | J37: 41280.56 | K37: =I37-J37 -> -6210.84 | L37: =I37+Apr!L37 -> 387437.25 | M37: =J37+Apr!M37 -> 81400.79 | N37: =L37-M37 -> 306036.46
B38: =1+B37 -> 26 | C38: Sun Life Prosperity World Voyager Fund, Inc. | D38: 1917208482 | E38: 57050271 | F38: =D38-E38 -> 1860158211 | G38: 0 | H38: 2998 | I38: 13945134 | J38: 50383339 | K38: =I38-J38 -> -36438205 | L38: =I38+Apr!L38 -> 74629604 | M38: =J38+Apr!M38 -> 447919923 | N38: =L38-M38 -> -373290319
