Workbook

Sheet Jan
A1: PHILIPPINE INVESTMENT FUNDS ASSOCIATION, INC.
A2: MUTUAL FUNDS STATISTICAL REPORT
A3: Month of January 2025
A4: (Amounts in Peso)
I5: F O R - T H E - M O N T H | L5: Y E A R - T O - D A T E
A6: Fund Category | C6: Fund Name | D6: ASSETS | E6: LIABILITIES | F6: NET ASSETS | G6: EQUITY INV. | H6: NO. OF A/C | I6: SALES | J6: REDEMPTIONS | K6: NET SALES | L6: TOTAL SALES | M6: TOTAL REDEMPTIONS | N6: TOTAL NET SALES
A7: Stock Funds
A8: Primarily invested in Peso Securities (shares)
B9: 1 | C9: ALFM Growth Fund, Inc. | D9: 3579826711 | E9: 60047130 | F9: =D9-E9 -> 3519779581 | G9: 3475227040 | H9: 5846 | I9: 11499302 | J9: 30214575 | K9: =I9-J9 -> -18715273 | L9: =I9 -> 11499302 | M9: =J9 -> 30214575 | N9: =L9-M9 -> -18715273
B10: =1+B9 -> 2 | C10: ATRAM Alpha Opportunity Fund, Inc. | D10: 9.3805794e+08 | E10: 58592991 | F10: =D10-E10 -> 8.7946495e+08 | G10: 5.9089101e+08 | H10: 4061 | I10: 13170545 | J10: 6220592.8 | K10: =I10-J10 -> 6949951.9 | L10: =I10 -> 13170545 | M10: =J10 -> 6220592.8 | N10: =L10-M10 -> 6949951.9
B11: =1+B10 -> 3 | C11: ATRAM Phil. Equity Opportunity Fund, Inc. | D11: 1.0065305e+09 | E11: 17071102 | F11: =D11-E11 -> 9.8945944e+08 | G11: 8.7106506e+08 | H11: 2503 | I11: 5383935.7 | J11: 8624066.5 | K11: =I11-J11 -> -3240130.8 | L11: =I11 -> 5383935.7 | M11: =J11 -> 8624066.5 | N11: =L11-M11 -> -3240130.8
B12: =1+B11 -> 4 | C12: Climbs Share Capital Equity Investment Fund Corp. | D12: 4.2124987e+08 | E12: 19479963 | F12: =D12-E12 -> 4.0176991e+08 | G12: 3.3617052e+08 | H12: 1740 | I12: 20489233 | J12: 276473.35 | K12: =I12-J12 -> 20212760 | L12: =I12 -> 20489233 | M12: =J12 -> 276473.35 | N12: =L12-M12 -> 20212760
B13: =1+B12 -> 5 | C13: First Metro Consumer Fund, Inc. | D13: 341431433 | E13: 884460 | F13: =D13-E13 -> 340546973 | G13: 248281283 | H13: 1161 | I13: 256022 | J13: 6969374 | K13: =I13-J13 -> -6713352 | L13: =I13 -> 256022 | M13: =J13 -> 6969374 | N13: =L13-M13 -> -6713352
B14: =1+B13 -> 6 | C14: First Metro Save and Learn Equity Fund, Inc. | D14: 2952083625 | E14: 17366215 | F14: =D14-E14 -> 2934717410 | G14: 2419813390 | H14: 14472 | I14: 7725106 | J14: 57441139 | K14: =I14-J14 -> -49716033 | L14: =I14 -> 7725106 | M14: =J14 -> 57441139 | N14: =L14-M14 -> -49716033
B15: =1+B14 -> 7 | C15: First Metro Save and Learn Phil. Index Fund, Inc. | D15: 78267694 | E15: 705356 | F15: =D15-E15 -> 77562338 | G15: 76061457 | H15: 482 | I15: 291880 | J15: 693859 | K15: =I15-J15 -> -401979 | L15: =I15 -> 291880 | M15: =J15 -> 693859 | N15: =L15-M15 -> -401979
B16: =1+B15 -> 8 | C16: MBG Equity Investment Fund, Inc. | D16: 119035466 | E16: 1095263 | F16: =D16-E16 -> 117940203 | G16: 106213102 | H16: 43 | I16: 0 | J16: 0 | K16: =I16-J16 -> 0 | L16: =I16 -> 0 | M16: =J16 -> 0 | N16: =L16-M16 -> 0
B17: =1+B16 -> 9 | C17: PAMI Equity Index Fund, Inc. | D17: 1006525465 | E17: 65887982 | F17: =D17-E17 -> 940637483 | G17: 950993002 | H17: 11023 | I17: 0 | J17: 11500602 | K17: =I17-J17 -> -11500602 | L17: =I17 -> 0 | M17: =J17 -> 11500602 | N17: =L17-M17 -> -11500602
B18: =1+B17 -> 10 | C18: Philam Strategic Growth Fund, Inc. | D18: 2989820457 | E18: 54632474 | F18: =D18-E18 -> 2935187983 | G18: 2890363132 | H18: 10798 | I18: 7570471 | J18: 10535783 | K18: =I18-J18 -> -2965312 | L18: =I18 -> 7570471 | M18: =J18 -> 10535783 | N18: =L18-M18 -> -2965312
B19: =1+B18 -> 11 | C19: Philequity Dividend Yield Fund, Inc. | D19: 2.4243623e+09 | E19: 16065153 | F19: =D19-E19 -> 2408297162 | G19: 2.1769677e+09 | H19: 4996 | I19: 5960467.9 | J19: 4335582.7 | K19: =I19-J19 -> 1624885.2 | L19: =I19 -> 5960467.9 | M19: =J19 -> 4335582.7 | N19: =L19-M19 -> 1624885.2
B20: =1+B19 -> 12 | C20: Philequity Fund, Inc. | D20: 8.3221859e+09 | E20: 40501500 | F20: =D20-E20 -> 8281684398 | G20: 7.5329936e+09 | H20: 31941 | I20: 9043925.1 | J20: 33846096 | K20: =I20-J20 -> -24802171 | L20: =I20 -> 9043925.1 | M20: =J20 -> 33846096 | N20: =L20-M20 -> -24802171
B21: =1+B20 -> 13 | C21: Philequity MSCI Phil. Index Fund, Inc. | D21: 2.8477119e+08 | E21: 530690.7 | F21: =D21-E21 -> 2.842405e+08 | G21: 2.7753402e+08 | H21: 889 | I21: 426331.18 | J21: 230967.34 | K21: =I21-J21 -> 195363.84 | L21: =I21 -> 426331.18 | M21: =J21 -> 230967.34 | N21: =L21-M21 -> 195363.84
... B27: =1+B26 -> 19 | C27: United Fund, Inc. | D27: 4.7107537e+08 | E27: 9249195.2 | F27: =D27-E27 -> 4.6182618e+08 | G27: 4.4986876e+08 | H27: 1199 | I27: 383693.8 | J27: 156012.72 | K27: =I27-J27 -> 227681.08 | L27: =I27 -> 383693.8 | M27: =J27 -> 156012.72 | N27: =L27-M27 -> 227681.08
A28: Primarily invested in Peso Securities (units)
B29: =1+B27 -> 20 | C29: COL Equity Index Unitized Mutual Fund, Inc. | D29: 2.1880443e+08 | E29: 1072328.6 | F29: =D29-E29 -> 2.177321e+08 | G29: 2.0383569e+08 | H29: 4535 | I29: 14204655 | J29: 1702977.7 | K29: =I29-J29 -> 12501677 | L29: =I29 -> 14204655 | M29: =J29 -> 1702977.7 | N29: =L29-M29 -> 12501677
B30: =1+B29 -> 21 | C30: COL Strategic Growth Equity Unitized Mutual Fund, Inc. | D30: 3.74349e+08 | E30: 1332236.2 | F30: =D30-E30 -> 3.7301676e+08 | G30: 259592968 | H30: 5777 | I30: 17585486 | J30: 9255197.5 | K30: =I30-J30 -> 8330288.1 | L30: =I30 -> 17585486 | M30: =J30 -> 9255197.5 | N30: =L30-M30 -> 8330288.1
B31: =1+B30 -> 22 | C31: Philequity Alpha One Fund, Inc. | D31: 2.6160626e+08 | E31: 3299887.8 | F31: =D31-E31 -> 2.5830637e+08 | G31: 2.5752204e+08 | H31: 1145 | I31: 392667.96 | J31: 361446.73 | K31: =I31-J31 -> 31221.23 | L31: =I31 -> 392667.96 | M31: =J31 -> 361446.73 | N31: =L31-M31 -> 31221.23
B32: =1+B31 -> 23 | C32: Philippine Stock Index Fund Corp. | D32: 680494522 | E32: 36647664 | F32: =D32-E32 -> 643846858 | G32: 641628933 | H32: 753266 | I32: 65027228 | J32: 45283184 | K32: =I32-J32 -> 19744044 | L32: =I32 -> 65027228 | M32: =J32 -> 45283184 | N32: =L32-M32 -> 19744044
A33: Exchange Traded Fund
B34: =1+B32 -> 24 | C34: First Metro Phil. Equity Exchange Traded Fund, Inc. | D34: 1261499223 | E34: 1633140 | F34: =D34-E34 -> 1259866083 | G34: 1253247378 | H34: 3234 | I34: 13123499 | J34: 0 | K34: =I34-J34 -> 13123499 | L34: =I34 -> 13123499 | M34: =J34 -> 0 | N34: =L34-M34 -> 13123499
A35: Sub total - Peso Currency | D35: =SUM(D9:D34) -> 54154634125 | E35: =SUM(E9:E34) -> 1293236119 | F35: =SUM(F9:F34) -> 52861398006 | G35: =SUM(G9:G34) -> 49955877099 | H35: =SUM(H9:H34) -> 1032356 | I35: =SUM(I9:I34) -> 3.2058945e+08 | J35: =SUM(J9:J34) -> 4.8905661e+08 | K35: =SUM(K9:K34) -> -168467158 | ... N35: =SUM(N9:N34) -> -168467158
A36: Primarily invested in foreign currency securities (shares)
B37: =1+B34 -> 25 | C37: ATRAM AsiaPlus Equity Fund, Inc. | D37: 28047684 | E37: 257491.79 | F37: =D37-E37 -> 27790192 | G37: 0 | H37: 50 | I37: 46669.82 | J37: 98660.78 | K37: =I37-J37 -> -51990.96 | L37: =I37 -> 46669.82 | M37: =J37 -> 98660.78 | N37: =L37-M37 -> -51990.96
B38: =1+B37 -> 26 | C38: Sun Life Prosperity World Voyager Fund, Inc. | D38: 2117078191 | E38: 10072922 | F38: =D38-E38 -> 2107005269 | G38: 0 | H38: 3168 | I38: 24947275 | J38: 12017256 | K38: =I38-J38 -> 12930019 | L38: =I38 -> 24947275 | M38: =J38 -> 12017256 | N38: =L38-M38 -> 12930019
A39: Sub total - US Currency | D39: =SUM(D37:D38) -> 2145125875 | E39: =SUM(E37:E38) -> 10330414 | F39: =SUM(F37:F38) -> 2134795461 | G39: =SUM(G37:G38) -> 0 | H39: =SUM(H37:H38) -> 3218 | I39: =SUM(I37:I38) -> 24993945 | J39: =SUM(J37:J38) -> 12115917 | K39: =SUM(K37:K38) -> 12878028 | ... N39: =SUM(N37:N38) -> 12878028
A40: Sub total - stock funds | D40: =D35+D39 -> 56299759999 | E40: =E35+E39 -> 1303566533 | F40: =F35+F39 -> 54996193467 | G40: =G35+G39 -> 49955877099 | H40: =H35+H39 -> 1035574 | I40: =I35+I39 -> 345583399 | J40: =J35+J39 -> 501172529 | K40: =K35+K39 -> -155589130 | ... N40: =N35+N39 -> -155589130
A41: Balanced Funds
A42: Primarily invested in Peso Securities (shares)
B43: =1+B38 -> 27 | C43: ATRAM Philippine Balanced Fund, Inc. | D43: 4.3817323e+08 | E43: 43482111 | F43: =D43-E43 -> 3.9469112e+08 | G43: 2.0987916e+08 | H43: 2318 | I43: 470306.26 | J43: 6607205.7 | K43: =I43-J43 -> -6136899.4 | L43: =I43 -> 470306.26 | M43: =J43 -> 6607205.7 | N43: =L43-M43 -> -6136899.4
B44: =1+B43 -> 28 | C44: ATRAM Unicapital Diversified Growth Fund, Inc. | D44: 1.1731335e+08 | E44: 5835578.6 | F44: =D44-E44 -> 1.1147777e+08 | G44: 29499292 | H44: 801 | I44: 368040.7 | J44: 464959.65 | K44: =I44-J44 -> -96918.95 | L44: =I44 -> 368040.7 | M44: =J44 -> 464959.65 | N44: =L44-M44 -> -96918.95
B45: =1+B44 -> 29 | C45: First Metro Save and Learn Balanced Fund, Inc. | D45: 637012595 | E45: 2723392 | F45: =D45-E45 -> 634289203 | G45: 267879202 | H45: 4116 | I45: 1150101 | J45: 4973213 | K45: =I45-J45 -> -3823112 | L45: =I45 -> 1150101 | M45: =J45 -> 4973213 | N45: =L45-M45 -> -3823112
...

Sheet Feb
A1: PHILIPPINE INVESTMENT FUNDS ASSOCIATION, INC.
A2: MUTUAL FUNDS STATISTICAL REPORT
A3: Month of February 2025
A4: (Amounts in Peso)
I5: F O R - T H E - M O N T H | L5: Y E A R - T O - D A T E
A6: Fund Category | C6: Fund Name | D6: ASSETS | E6: LIABILITIES | F6: NET ASSETS | G6: EQUITY INV. | H6: NO. OF A/C | I6: SALES | J6: REDEMPTIONS | K6: NET SALES | L6: TOTAL SALES | M6: TOTAL REDEMPTIONS | N6: TOTAL NET SALES
A7: Stock Funds
A8: Primarily invested in Peso Securities (shares)
B9: 1 | C9: ALFM Growth Fund, Inc. | D9: 3614590099 | E9: 9804439 | F9: =D9-E9 -> 3604785660 | G9: 3550553739 | H9: 5820 | I9: 8526054 | J9: 24540198 | K9: =I9-J9 -> -16014144 | L9: =I9+Jan!L9 -> 20025356 | M9: =J9+Jan!M9 -> 54754773 | N9: =L9-M9 -> -34729417
B10: =1+B9 -> 2 | C10: ATRAM Alpha Opportunity Fund, Inc. | D10: 9.7563577e+08 | E10: 58807440 | F10: =D10-E10 -> 9.1682833e+08 | G10: 846930515 | H10: 4101 | I10: 29130413 | J10: 17776753 | K10: =I10-J10 -> 11353659 | L10: =I10+Jan!L10 -> 42300957 | M10: =J10+Jan!M10 -> 23997346 | N10: =L10-M10 -> 18303611
B11: =1+B10 -> 3 | C11: ATRAM Phil. Equity Opportunity Fund, Inc. | D11: 1.0590887e+09 | E11: 41496227 | F11: =D11-E11 -> 1017592443 | G11: 9.6020108e+08 | H11: 2491 | I11: 7391344.5 | J11: 4318041.7 | K11: =I11-J11 -> 3073302.8 | L11: =I11+Jan!L11 -> 12775280 | M11: =J11+Jan!M11 -> 12942108 | N11: =L11-M11 -> -166828.01
B12: =1+B11 -> 4 | C12: Climbs Share Capital Equity Investment Fund Corp. | D12: 4.2146263e+08 | E12: 16453509 | F12: =D12-E12 -> 4.0500912e+08 | G12: 3.6255925e+08 | H12: 1709 | I12: 593070 | J12: 699624.3 | K12: =I12-J12 -> -106554.3 | L12: =I12+Jan!L12 -> 21082303 | M12: =J12+Jan!M12 -> 976097.65 | N12: =L12-M12 -> 20106206
B13: =1+B12 -> 5 | C13: First Metro Consumer Fund, Inc. | D13: 350949757 | E13: 747413 | F13: =D13-E13 -> 350202344 | G13: 254813507 | H13: 1155 | I13: 306037 | J13: 545372 | K13: =I13-J13 -> -239335 | L13: =I13+Jan!L13 -> 562059 | M13: =J13+Jan!M13 -> 7514746 | N13: =L13-M13 -> -6952687
B14: =1+B13 -> 6 | C14: First Metro Save and Learn Equity Fund, Inc. | D14: 2999143112 | E14: 8918826 | F14: =D14-E14 -> 2990224286 | G14: 2442258472 | H14: 14421 | I14: 28260213 | J14: 41238048 | K14: =I14-J14 -> -12977835 | L14: =I14+Jan!L14 -> 35985319 | M14: =J14+Jan!M14 -> 98679187 | N14: =L14-M14 -> -62693868
B15: =1+B14 -> 7 | C15: First Metro Save and Learn Phil. Index Fund, Inc. | D15: 85088943 | E15: 353406 | F15: =D15-E15 -> 84735537 | G15: 77831015 | H15: 477 | I15: 5473707 | J15: 179157 | K15: =I15-J15 -> 5294550 | L15: =I15+Jan!L15 -> 5765587 | M15: =J15+Jan!M15 -> 873016 | N15: =L15-M15 -> 4892571
B16: =1+B15 -> 8 | C16: MBG Equity Investment Fund, Inc. | D16: 117859044 | E16: 1412322 | F16: =D16-E16 -> 116446722 | G16: 108671198 | H16: 43 | I16: 0 | J16: 0 | K16: =I16-J16 -> 0 | L16: =I16+Jan!L16 -> 0 | M16: =J16+Jan!M16 -> 0 | N16: =L16-M16 -> 0
B17: =1+B16 -> 9 | C17: PAMI Equity Index Fund, Inc. | D17: 984401545 | E17: 24592054 | F17: =D17-E17 -> 959809491 | G17: 970682329 | H17: 10897 | I17: 0 | J17: 2577792 | K17: =I17-J17 -> -2577792 | L17: =I17+Jan!L17 -> 0 | M17: =J17+Jan!M17 -> 14078394 | N17: =L17-M17 -> -14078394
B18: =1+B17 -> 10 | C18: Philam Strategic Growth Fund, Inc. | D18: 3023222400 | E18: 44931046 | F18: =D18-E18 -> 2978291354 | G18: 2959270074 | H18: 10760 | I18: 5943949 | J18: 44233057 | K18: =I18-J18 -> -38289108 | L18: =I18+Jan!L18 -> 13514420 | M18: =J18+Jan!M18 -> 54768840 | N18: =L18-M18 -> -41254420
B19: =1+B18 -> 11 | C19: Philequity Dividend Yield Fund, Inc. | D19: 2.482421e+09 | E19: 3733841.7 | F19: =D19-E19 -> 2478687115 | G19: 2.2618273e+09 | H19: 4987 | I19: 10296707 | J19: 2915154.5 | K19: =I19-J19 -> 7381552.7 | L19: =I19+Jan!L19 -> 16257175 | M19: =J19+Jan!M19 -> 7250737.2 | N19: =L19-M19 -> 9006437.8
B20: =1+B19 -> 12 | C20: Philequity Fund, Inc. | D20: 8.7195517e+09 | E20: 1.5736146e+08 | F20: =D20-E20 -> 8562190284 | G20: 8.0222041e+09 | H20: 31851 | I20: 7707527.2 | J20: 17618680 | K20: =I20-J20 -> -9911152.9 | L20: =I20+Jan!L20 -> 16751452 | M20: =J20+Jan!M20 -> 51464776 | N20: =L20-M20 -> -34713324
B21: =1+B20 -> 13 | C21: Philequity MSCI Phil. Index Fund, Inc. | D21: 2.9667971e+08 | E21: 2988299.6 | F21: =D21-E21 -> 2.9369141e+08 | G21: 2.8591525e+08 | H21: 890 | I21: 384397.33 | J21: 53008.27 | K21: =I21-J21 -> 331389.06 | L21: =I21+Jan!L21 -> 810728.51 | M21: =J21+Jan!M21 -> 283975.61 | N21: =L21-M21 -> 526752.9
... B27: =1+B26 -> 19 | C27: United Fund, Inc. | D27: 4.8489152e+08 | E27: 12147024 | F27: =D27-E27 -> 4.727445e+08 | G27: 4.6132164e+08 | H27: 1201 | I27: 488658.88 | J27: 77704.41 | K27: =I27-J27 -> 410954.47 | L27: =I27+Jan!L27 -> 872352.68 | M27: =J27+Jan!M27 -> 233717.13 | N27: =L27-M27 -> 638635.55
A28: Primarily invested in Peso Securities (units)
B29: =1+B27 -> 20 | C29: COL Equity Index Unitized Mutual Fund, Inc. | D29: 2.2057332e+08 | E29: 679642.68 | F29: =D29-E29 -> 2.1989368e+08 | G29: 2.1035685e+08 | H29: 4611 | I29: 7128940.7 | J29: 10780180 | K29: =I29-J29 -> -3651239.4 | L29: =I29+Jan!L29 -> 21333596 | M29: =J29+Jan!M29 -> 12483158 | N29: =L29-M29 -> 8850437.8
B30: =1+B29 -> 21 | C30: COL Strategic Growth Equity Unitized Mutual Fund, Inc. | D30: 3.9513504e+08 | E30: 2678228.1 | F30: =D30-E30 -> 3.9245681e+08 | G30: 314883869 | H30: 6017 | I30: 18418420 | J30: 3195589 | K30: =I30-J30 -> 15222831 | L30: =I30+Jan!L30 -> 36003905 | M30: =J30+Jan!M30 -> 12450786 | N30: =L30-M30 -> 23553119
B31: =1+B30 -> 22 | C31: Philequity Alpha One Fund, Inc. | D31: 2.5394841e+08 | E31: 833338.16 | F31: =D31-E31 -> 2.5311507e+08 | G31: 2.5099544e+08 | H31: 1142 | I31: 2348070.8 | J31: 12035552 | K31: =I31-J31 -> -9687481.2 | L31: =I31+Jan!L31 -> 2740738.8 | M31: =J31+Jan!M31 -> 12396999 | N31: =L31-M31 -> -9656260
B32: =1+B31 -> 23 | C32: Philippine Stock Index Fund Corp. | D32: 673460777 | E32: 8406067 | F32: =D32-E32 -> 665054710 | G32: 664103983 | H32: 755020 | I32: 40951090 | J32: 34020108 | K32: =I32-J32 -> 6930982 | L32: =I32+Jan!L32 -> 105978318 | M32: =J32+Jan!M32 -> 79303292 | N32: =L32-M32 -> 26675026
A33: Exchange Traded Fund
B34: =1+B32 -> 24 | C34: First Metro Phil. Equity Exchange Traded Fund, Inc. | D34: 1317597331 | E34: 1941343 | F34: =D34-E34 -> 1315655988 | G34: 1314949404 | H34: 3278 | I34: 27108889 | J34: 0 | K34: =I34-J34 -> 27108889 | L34: =I34+Jan!L34 -> 40232388 | M34: =J34+Jan!M34 -> 0 | N34: =L34-M34 -> 40232388
A35: Sub total - Peso Currency | D35: =SUM(D9:D34) -> 54802113405 | E35: =SUM(E9:E34) -> 6.7922424e+08 | F35: =SUM(F9:F34) -> 54122889167 | G35: =SUM(G9:G34) -> 51981591359 | H35: =SUM(H9:H34) -> 1034017 | I35: =SUM(I9:I34) -> 327765508 | J35: =SUM(J9:J34) -> 4.9561963e+08 | K35: =SUM(K9:K34) -> -1.6785412e+08 | ... N35: =SUM(N9:N34) -> -3.3632128e+08
A36: Primarily invested in foreign currency securities (shares)
B37: =1+B34 -> 25 | C37: ATRAM AsiaPlus Equity Fund, Inc. | D37: 27883687 | E37: 237825.32 | F37: =D37-E37 -> 27645862 | G37: 0 | H37: 50 | I37: 57972.38 | J37: 25942.32 | K37: =I37-J37 -> 32030.06 | L37: =I37+Jan!L37 -> 104642.2 | M37: =J37+Jan!M37 -> 124603.1 | N37: =L37-M37 -> -19960.9
B38: =1+B37 -> 26 | C38: Sun Life Prosperity World Voyager Fund, Inc. | D38: 2051182309 | E38: 24649862 | F38: =D38-E38 -> 2026532447 | G38: 0 | H38: 3192 | I38: 46285415 | J38: 69993528 | K38: =I38-J38 -> -23708113 | L38: =I38+Jan!L38 -> 71232690 | M38: =J38+Jan!M38 -> 82010784 | N38: =L38-M38 -> -10778094
A39: Sub total - US Currency | D39: =SUM(D37:D38) -> 2079065996 | E39: =SUM(E37:E38) -> 24887687 | F39: =SUM(F37:F38) -> 2054178309 | G39: =SUM(G37:G38) -> 0 | H39: =SUM(H37:H38) -> 3242 | I39: =SUM(I37:I38) -> 46343387 | J39: =SUM(J37:J38) -> 70019470 | K39: =SUM(K37:K38) -> -23676083 | ... N39: =SUM(N37:N38) -> -10798055
A40: Sub total - stock funds | D40: =D35+D39 -> 56881179401 | E40: =E35+E39 -> 7.0411193e+08 | F40: =F35+F39 -> 56177067476 | G40: =G35+G39 -> 51981591359 | H40: =H35+H39 -> 1037259 | I40: =I35+I39 -> 3.741089e+08 | J40: =J35+J39 -> 5.656391e+08 | K40: =K35+K39 -> -1.915302e+08 | ... N40: =N35+N39 -> -3.4711933e+08
A41: Balanced Funds
A42: Primarily invested in Peso Securities (shares)
B43: =1+B38 -> 27 | C43: ATRAM Philippine Balanced Fund, Inc. | D43: 4.1445908e+08 | E43: 22106061 | F43: =D43-E43 -> 3.9235302e+08 | G43: 2.081194e+08 | H43: 2316 | I43: 437016.77 | J43: 10198627 | K43: =I43-J43 -> -9761610.1 | L43: =I43+Jan!L43 -> 907323.03 | M43: =J43+Jan!M43 -> 16805833 | N43: =L43-M43 -> -15898510
B44: =1+B43 -> 28 | C44: ATRAM Unicapital Diversified Growth Fund, Inc. | D44: 1.1474133e+08 | E44: 2717663.1 | F44: =D44-E44 -> 1.1202367e+08 | G44: 29379221 | H44: 811 | I44: 290811.7 | J44: 407410.94 | K44: =I44-J44 -> -116599.24 | L44: =I44+Jan!L44 -> 658852.4 | M44: =J44+Jan!M44 -> 872370.59 | N44: =L44-M44 -> -213518.19
B45: =1+B44 -> 29 | C45: First Metro Save and Learn Balanced Fund, Inc. | D45: 640273113 | E45: 2636848 | F45: =D45-E45 -> 637636265 | G45: 270617654 | H45: 4096 | I45: 647209 | J45: 5537711 | K45: =I45-J45 -> -4890502 | L45: =I45+Jan!L45 -> 1797310 | M45: =J45+Jan!M45 -> 10510924 | N45: =L45-M45 -> -8713614
...

Sheet Feb UPDATED
A1: PHILIPPINE INVESTMENT FUNDS ASSOCIATION, INC.
A2: MUTUAL FUNDS STATISTICAL REPORT
A3: Month of February 2025
A4: (Amounts in Peso)
I5: F O R - T H E - M O N T H | L5: Y E A R - T O - D A T E
A6: Fund Category | C6: Fund Name | D6: ASSETS | E6: LIABILITIES | F6: NET ASSETS | G6: EQUITY INV. | H6: NO. OF A/C | I6: SALES | J6: REDEMPTIONS | K6: NET SALES | L6: TOTAL SALES | M6: TOTAL REDEMPTIONS | N6: TOTAL NET SALES
A7: Stock Funds
A8: Primarily invested in Peso Securities (shares)
B9: 1 | C9: ALFM Growth Fund, Inc. | D9: 3614590099 | E9: 9804439 | F9: =D9-E9 -> 3604785660 | G9: 3550553739 | H9: 5820 | I9: 8526054 | J9: 24540198 | K9: =I9-J9 -> -16014144 | L9: =I9+Jan!L9 -> 20025356 | M9: =J9+Jan!M9 -> 54754773 | N9: =L9-M9 -> -34729417
B10: =1+B9 -> 2 | C10: ATRAM Alpha Opportunity Fund, Inc. | D10: 9.7563577e+08 | E10: 58807440 | F10: =D10-E10 -> 9.1682833e+08 | G10: 846930515 | H10: 4101 | I10: 29130413 | J10: 17776753 | K10: =I10-J10 -> 11353659 | L10: =I10+Jan!L10 -> 42300957 | M10: =J10+Jan!M10 -> 23997346 | N10: =L10-M10 -> 18303611
B11: =1+B10 -> 3 | C11: ATRAM Phil. Equity Opportunity Fund, Inc. | D11: 1.0590887e+09 | E11: 41496227 | F11: =D11-E11 -> 1017592443 | G11: 9.6020108e+08 | H11: 2491 | I11: 7391344.5 | J11: 4318041.7 | K11: =I11-J11 -> 3073302.8 | L11: =I11+Jan!L11 -> 12775280 | M11: =J11+Jan!M11 -> 12942108 | N11: =L11-M11 -> -166828.01
B12: =1+B11 -> 4 | C12: Climbs Share Capital Equity Investment Fund Corp. | D12: 4.2146263e+08 | E12: 16453509 | F12: =D12-E12 -> 4.0500912e+08 | G12: 3.6255925e+08 | H12: 1709 | I12: 593070 | J12: 699624.3 | K12: =I12-J12 -> -106554.3 | L12: =I12+Jan!L12 -> 21082303 | M12: =J12+Jan!M12 -> 976097.65 | N12: =L12-M12 -> 20106206
B13: =1+B12 -> 5 | C13: First Metro Consumer Fund, Inc. | D13: 350949757 | E13: 747413 | F13: =D13-E13 -> 350202344 | G13: 254813507 | H13: 1155 | I13: 306037 | J13: 545372 | K13: =I13-J13 -> -239335 | L13: =I13+Jan!L13 -> 562059 | M13: =J13+Jan!M13 -> 7514746 | N13: =L13-M13 -> -6952687
B14: =1+B13 -> 6 | C14: First Metro Save and Learn Equity Fund, Inc. | D14: 2999143112 | E14: 8918826 | F14: =D14-E14 -> 2990224286 | G14: 2442258472 | H14: 14421 | I14: 28260213 | J14: 41238048 | K14: =I14-J14 -> -12977835 | L14: =I14+Jan!L14 -> 35985319 | M14: =J14+Jan!M14 -> 98679187 | N14: =L14-M14 -> -62693868
B15: =1+B14 -> 7 | C15: First Metro Save and Learn Phil. Index Fund, Inc. | D15: 85088943 | E15: 353406 | F15: =D15-E15 -> 84735537 | G15: 77831015 | H15: 477 | I15: 5473707 | J15: 179157 | K15: =I15-J15 -> 5294550 | L15: =I15+Jan!L15 -> 5765587 | M15: =J15+Jan!M15 -> 873016 | N15: =L15-M15 -> 4892571
B16: =1+B15 -> 8 | C16: MBG Equity Investment Fund, Inc. | D16: 117859044 | E16: 1412322 | F16: =D16-E16 -> 116446722 | G16: 108671198 | H16: 43 | I16: 0 | J16: 0 | K16: =I16-J16 -> 0 | L16: =I16+Jan!L16 -> 0 | M16: =J16+Jan!M16 -> 0 | N16: =L16-M16 -> 0
B17: =1+B16 -> 9 | C17: PAMI Equity Index Fund, Inc. | D17: 984401545 | E17: 24592054 | F17: =D17-E17 -> 959809491 | G17: 970682329 | H17: 10897 | I17: 0 | J17: 2577792 | K17: =I17-J17 -> -2577792 | L17: =I17+Jan!L17 -> 0 | M17: =J17+Jan!M17 -> 14078394 | N17: =L17-M17 -> -14078394
B18: =1+B17 -> 10 | C18: Philam Strategic Growth Fund, Inc. | D18: 3023222400 | E18: 44931046 | F18: =D18-E18 -> 2978291354 | G18: 2959270074 | H18: 10760 | I18: 5943949 | J18: 44233057 | K18: =I18-J18 -> -38289108 | L18: =I18+Jan!L18 -> 13514420 | M18: =J18+Jan!M18 -> 54768840 | N18: =L18-M18 -> -41254420
B19: =1+B18 -> 11 | C19: Philequity Dividend Yield Fund, Inc. | D19: 2.482421e+09 | E19: 3733841.7 | F19: =D19-E19 -> 2478687115 | G19: 2.2618273e+09 | H19: 4987 | I19: 10296707 | J19: 2915154.5 | K19: =I19-J19 -> 7381552.7 | L19: =I19+Jan!L19 -> 16257175 | M19: =J19+Jan!M19 -> 7250737.2 | N19: =L19-M19 -> 9006437.8
B20: =1+B19 -> 12 | C20: Philequity Fund, Inc. | D20: 8.7195517e+09 | E20: 1.5736146e+08 | F20: =D20-E20 -> 8562190284 | G20: 8.0222041e+09 | H20: 31851 | I20: 7707527.2 | J20: 17618680 | K20: =I20-J20 -> -9911152.9 | L20: =I20+Jan!L20 -> 16751452 | M20: =J20+Jan!M20 -> 51464776 | N20: =L20-M20 -> -34713324
B21: =1+B20 -> 13 | C21: Philequity MSCI Phil. Index Fund, Inc. | D21: 2.9667971e+08 | E21: 2988299.6 | F21: =D21-E21 -> 2.9369141e+08 | G21: 2.8591525e+08 | H21: 890 | I21: 384397.33 | J21: 53008.27 | K21: =I21-J21 -> 331389.06 | L21: =I21+Jan!L21 -> 810728.51 | M21: =J21+Jan!M21 -> 283975.61 | N21: =L21-M21 -> 526752.9
... B27: =1+B26 -> 19 | C27: United Fund, Inc. | D27: 4.8489152e+08 | E27: 12147024 | F27: =D27-E27 -> 4.727445e+08 | G27: 4.6132164e+08 | H27: 1201 | I27: 488658.88 | J27: 77704.41 | K27: =I27-J27 -> 410954.47 | L27: =I27+Jan!L27 -> 872352.68 | M27: =J27+Jan!M27 -> 233717.13 | N27: =L27-M27 -> 638635.55
A28: Primarily invested in Peso Securities (units)
B29: =1+B27 -> 20 | C29: COL Equity Index Unitized Mutual Fund, Inc. | D29: 2.2057332e+08 | E29: 679642.68 | F29: =D29-E29 -> 2.1989368e+08 | G29: 2.1035685e+08 | H29: 4611 | I29: 7128940.7 | J29: 10780180 | K29: =I29-J29 -> -3651239.4 | L29: =I29+Jan!L29 -> 21333596 | M29: =J29+Jan!M29 -> 12483158 | N29: =L29-M29 -> 8850437.8
B30: =1+B29 -> 21 | C30: COL Strategic Growth Equity Unitized Mutual Fund, Inc. | D30: 3.9513504e+08 | E30: 2678228.1 | F30: =D30-E30 -> 3.9245681e+08 | G30: 314883869 | H30: 6017 | I30: 18418420 | J30: 3195589 | K30: =I30-J30 -> 15222831 | L30: =I30+Jan!L30 -> 36003905 | M30: =J30+Jan!M30 -> 12450786 | N30: =L30-M30 -> 23553119
B31: =1+B30 -> 22 | C31: Philequity Alpha One Fund, Inc. | D31: 2.5394841e+08 | E31: 833338.16 | F31: =D31-E31 -> 2.5311507e+08 | G31: 2.5099544e+08 | H31: 1142 | I31: 2348070.8 | J31: 12035552 | K31: =I31-J31 -> -9687481.2 | L31: =I31+Jan!L31 -> 2740738.8 | M31: =J31+Jan!M31 -> 12396999 | N31: =L31-M31 -> -9656260
B32: =1+B31 -> 23 | C32: Philippine Stock Index Fund Corp. | D32: 673460777 | E32: 8406067 | F32: =D32-E32 -> 665054710 | G32: 664103983 | H32: 755020 | I32: 40951090 | J32: 34020108 | K32: =I32-J32 -> 6930982 | L32: =I32+Jan!L32 -> 105978318 | M32: =J32+Jan!M32 -> 79303292 | N32: =L32-M32 -> 26675026
A33: Exchange Traded Fund
B34: =1+B32 -> 24 | C34: First Metro Phil. Equity Exchange Traded Fund, Inc. | D34: 1317597331 | E34: 1941343 | F34: =D34-E34 -> 1315655988 | G34: 1314949404 | H34: 3278 | I34: 27108889 | J34: 0 | K34: =I34-J34 -> 27108889 | L34: =I34+Jan!L34 -> 40232388 | M34: =J34+Jan!M34 -> 0 | N34: =L34-M34 -> 40232388
A35: Sub total - Peso Currency | D35: =SUM(D9:D34) -> 54802113405 | E35: =SUM(E9:E34) -> 6.7922424e+08 | F35: =SUM(F9:F34) -> 54122889167 | G35: =SUM(G9:G34) -> 51981591359 | H35: =SUM(H9:H34) -> 1034017 | I35: =SUM(I9:I34) -> 327765508 | J35: =SUM(J9:J34) -> 4.9561963e+08 | K35: =SUM(K9:K34) -> -1.6785412e+08 | ... N35: =SUM(N9:N34) -> -3.3632128e+08
A36: Primarily invested in foreign currency securities (shares)
B37: =1+B34 -> 25 | C37: ATRAM AsiaPlus Equity Fund, Inc. | D37: 27883687 | E37: 237825.32 | F37: =D37-E37 -> 27645862 | G37: 0 | H37: 50 | I37: 57972.38 | J37: 25942.32 | K37: =I37-J37 -> 32030.06 | L37: =I37+Jan!L37 -> 104642.2 | M37: =J37+Jan!M37 -> 124603.1 | N37: =L37-M37 -> -19960.9
B38: =1+B37 -> 26 | C38: Sun Life Prosperity World Voyager Fund, Inc. | D38: 2051182309 | E38: 24649862 | F38: =D38-E38 -> 2026532447 | G38: 0 | H38: 3192 | I38: 46285415 | J38: 69993528 | K38: =I38-J38 -> -23708113 | L38: =I38+Jan!L38 -> 71232690 | M38: =J38+Jan!M38 -> 82010784 | N38: =L38-M38 -> -10778094
A39: Sub total - US Currency | D39: =SUM(D37:D38) -> 2079065996 | E39: =SUM(E37:E38) -> 24887687 | F39: =SUM(F37:F38) -> 2054178309 | G39: =SUM(G37:G38) -> 0 | H39: =SUM(H37:H38) -> 3242 | I39: =SUM(I37:I38) -> 46343387 | J39: =SUM(J37:J38) -> 70019470 | K39: =SUM(K37:K38) -> -23676083 | ... N39: =SUM(N37:N38) -> -10798055
A40: Sub total - stock funds | D40: =D35+D39 -> 56881179401 | E40: =E35+E39 -> 7.0411193e+08 | F40: =F35+F39 -> 56177067476 | G40: =G35+G39 -> 51981591359 | H40: =H35+H39 -> 1037259 | I40: =I35+I39 -> 3.741089e+08 | J40: =J35+J39 -> 5.656391e+08 | K40: =K35+K39 -> -1.915302e+08 | ... N40: =N35+N39 -> -3.4711933e+08
A41: Balanced Funds
A42: Primarily invested in Peso Securities (shares)
B43: =1+B38 -> 27 | C43: ATRAM Philippine Balanced Fund, Inc. | D43: 4.1445908e+08 | E43: 22106061 | F43: =D43-E43 -> 3.9235302e+08 | G43: 2.081194e+08 | H43: 2316 | I43: 437016.77 | J43: 10198627 | K43: =I43-J43 -> -9761610.1 | L43: =I43+Jan!L43 -> 907323.03 | M43: =J43+Jan!M43 -> 16805833 | N43: =L43-M43 -> -15898510
B44: =1+B43 -> 28 | C44: ATRAM Unicapital Diversified Growth Fund, Inc. | D44: 1.1474133e+08 | E44: 2717663.1 | F44: =D44-E44 -> 1.1202367e+08 | G44: 29379221 | H44: 811 | I44: 290811.7 | J44: 407410.94 | K44: =I44-J44 -> -116599.24 | L44: =I44+Jan!L44 -> 658852.4 | M44: =J44+Jan!M44 -> 872370.59 | N44: =L44-M44 -> -213518.19
B45: =1+B44 -> 29 | C45: First Metro Save and Learn Balanced Fund, Inc. | D45: 640273113 | E45: 2636848 | F45: =D45-E45 -> 637636265 | G45: 270617654 | H45: 4096 | I45: 647209 | J45: 5537711 | K45: =I45-J45 -> -4890502 | L45: =I45+Jan!L45 -> 1797310 | M45: =J45+Jan!M45 -> 10510924 | N45: =L45-M45 -> -8713614
...

Sheet Mar
A1: PHILIPPINE INVESTMENT FUNDS ASSOCIATION, INC.
A2: MUTUAL FUNDS STATISTICAL REPORT
A3: Month of March 2025
A4: (Amounts in Peso)
I5: F O R - T H E - M O N T H | L5: Y E A R - T O - D A T E
A6: Fund Category | C6: Fund Name | D6: ASSETS | E6: LIABILITIES | F6: NET ASSETS | G6: EQUITY INV. | H6: NO. OF A/C | I6: SALES | J6: REDEMPTIONS | K6: NET SALES | L6: TOTAL SALES | M6: TOTAL REDEMPTIONS | N6: TOTAL NET SALES
A7: Stock Funds
A8: Primarily invested in Peso Securities (shares)
B9: 1 | C9: ALFM Growth Fund, Inc. | D9: 3727680401 | E9: 16586059 | F9: =D9-E9 -> 3711094342 | G9: 3610766587 | H9: 5787 | I9: 3895709 | J9: 38893467 | K9: =I9-J9 -> -34997758 | L9: =I9+Feb!L9 -> 23921065 | M9: =J9+Feb!M9 -> 93648240 | N9: =L9-M9 -> -69727175
B10: =1+B9 -> 2 | C10: ATRAM Alpha Opportunity Fund, Inc. | D10: 9.9423617e+08 | E10: 5881151.8 | F10: =D10-E10 -> 9.8835502e+08 | G10: 9.0877886e+08 | H10: 4153 | I10: 19453917 | J10: 13827556 | K10: =I10-J10 -> 5626361.1 | L10: =I10+Feb!L10 -> 61754874 | M10: =J10+Feb!M10 -> 37824902 | N10: =L10-M10 -> 23929972
B11: =1+B10 -> 3 | C11: ATRAM Phil. Equity Opportunity Fund, Inc. | D11: 1.0518217e+09 | E11: 5938330.4 | F11: =D11-E11 -> 1045883409 | G11: 9.6679502e+08 | H11: 2475 | I11: 3871055.5 | J11: 16375873 | K11: =I11-J11 -> -12504818 | L11: =I11+Feb!L11 -> 16646336 | M11: =J11+Feb!M11 -> 29317981 | N11: =L11-M11 -> -12671646
B12: =1+B11 -> 4 | C12: Climbs Share Capital Equity Investment Fund Corp. | D12: 4.3695162e+08 | E12: 11777166 | F12: =D12-E12 -> 4.2517445e+08 | G12: 3.7292096e+08 | H12: 1714 | I12: 19950320 | J12: 744807.26 | K12: =I12-J12 -> 19205513 | L12: =I12+Feb!L12 -> 41032623 | M12: =J12+Feb!M12 -> 1720904.9 | N12: =L12-M12 -> 39311718
B13: =1+B12 -> 5 | C13: First Metro Consumer Fund, Inc. | D13: 344433276 | E13: 863871 | F13: =D13-E13 -> 343569405 | G13: 292407742 | H13: 1147 | I13: 232895 | J13: 1582188 | K13: =I13-J13 -> -1349293 | L13: =I13+Feb!L13 -> 794954 | M13: =J13+Feb!M13 -> 9096934 | N13: =L13-M13 -> -8301980
B14: =1+B13 -> 6 | C14: First Metro Save and Learn Equity Fund, Inc. | D14: 3089753006 | E14: 76002487 | F14: =D14-E14 -> 3013750519 | G14: 2727444004 | H14: 14342 | I14: 4949273 | J14: 23436077 | K14: =I14-J14 -> -18486804 | L14: =I14+Feb!L14 -> 40934592 | M14: =J14+Feb!M14 -> 122115264 | N14: =L14-M14 -> -81180672
B15: =1+B14 -> 7 | C15: First Metro Save and Learn Phil. Index Fund, Inc. | D15: 89427281 | E15: 351878 | F15: =D15-E15 -> 89075403 | G15: 83341085 | H15: 477 | I15: 1471042 | J15: 207686 | K15: =I15-J15 -> 1263356 | L15: =I15+Feb!L15 -> 7236629 | M15: =J15+Feb!M15 -> 1080702 | N15: =L15-M15 -> 6155927
B16: =1+B15 -> 8 | C16: MBG Equity Investment Fund, Inc. | D16: 115693364 | E16: 1384500 | F16: =D16-E16 -> 114308864 | G16: 110977560 | H16: 42 | I16: 0 | J16: 4270929 | K16: =I16-J16 -> -4270929 | L16: =I16+Feb!L16 -> 0 | M16: =J16+Feb!M16 -> 4270929 | N16: =L16-M16 -> -4270929
B17: =1+B16 -> 9 | C17: PAMI Equity Index Fund, Inc. | D17: 1019368785 | E17: 26321603 | F17: =D17-E17 -> 993047182 | G17: 1000248093 | H17: 10954 | I17: 0 | J17: 6430162 | K17: =I17-J17 -> -6430162 | L17: =I17+Feb!L17 -> 0 | M17: =J17+Feb!M17 -> 20508556 | N17: =L17-M17 -> -20508556
B18: =1+B17 -> 10 | C18: Philam Strategic Growth Fund, Inc. | D18: 3094232781 | E18: 22477588 | F18: =D18-E18 -> 3071755193 | G18: 3004745015 | H18: 10693 | I18: 6119251 | J18: 29665773 | K18: =I18-J18 -> -23546522 | L18: =I18+Feb!L18 -> 19633671 | M18: =J18+Feb!M18 -> 84434613 | N18: =L18-M18 -> -64800942
B19: =1+B18 -> 11 | C19: Philequity Dividend Yield Fund, Inc. | D19: 2.5359326e+09 | E19: 6843692.3 | F19: =D19-E19 -> 2529088882 | G19: 2.2821337e+09 | H19: 4988 | I19: 31989924 | J19: 38421353 | K19: =I19-J19 -> -6431428.4 | L19: =I19+Feb!L19 -> 48247099 | M19: =J19+Feb!M19 -> 45672090 | N19: =L19-M19 -> 2575009.4
B20: =1+B19 -> 12 | C20: Philequity Fund, Inc. | D20: 8.8235385e+09 | E20: 36790936 | F20: =D20-E20 -> 8786747587 | G20: 8.2239539e+09 | H20: 31681 | I20: 74305031 | J20: 1.267538e+08 | K20: =I20-J20 -> -52448769 | L20: =I20+Feb!L20 -> 91056483 | M20: =J20+Feb!M20 -> 1.7821858e+08 | N20: =L20-M20 -> -87162094
B21: =1+B20 -> 13 | C21: Philequity MSCI Phil. Index Fund, Inc. | D21: 3.0726806e+08 | E21: 487370.37 | F21: =D21-E21 -> 3.0678069e+08 | G21: 3.0049202e+08 | H21: 880 | I21: 275121.22 | J21: 266085.37 | K21: =I21-J21 -> 9035.85 | L21: =I21+Feb!L21 -> 1085849.7 | M21: =J21+Feb!M21 -> 550060.98 | N21: =L21-M21 -> 535788.75
... B27: =1+B26 -> 19 | C27: United Fund, Inc. | D27: 5.3042687e+08 | E27: 13536163 | F27: =D27-E27 -> 516890704 | G27: 4.6848837e+08 | H27: 1194 | I27: 206949.78 | J27: 2849276.1 | K27: =I27-J27 -> -2642326.3 | L27: =I27+Feb!L27 -> 1079302.5 | M27: =J27+Feb!M27 -> 3082993.2 | N27: =L27-M27 -> -2003690.8
A28: Primarily invested in Peso Securities (units) | L28: =I28+Feb!L28 -> 0 | M28: =J28+Feb!M28 -> 0
B29: =1+B27 -> 20 | C29: COL Equity Index Unitized Mutual Fund, Inc. | D29: 2.4543406e+08 | E29: 864167.18 | F29: =D29-E29 -> 2.445699e+08 | G29: 2.3410723e+08 | H29: 4662 | I29: 18132360 | J29: 2549403.9 | K29: =I29-J29 -> 15582956 | L29: =I29+Feb!L29 -> 39465956 | M29: =J29+Feb!M29 -> 15032562 | N29: =L29-M29 -> 24433394
B30: =1+B29 -> 21 | C30: COL Strategic Growth Equity Unitized Mutual Fund, Inc. | D30: 3.9447779e+08 | E30: 1349185 | F30: =D30-E30 -> 3.931286e+08 | G30: 326519805 | H30: 6215 | I30: 7932697.3 | J30: 16842612 | K30: =I30-J30 -> -8909914.5 | L30: =I30+Feb!L30 -> 43936603 | M30: =J30+Feb!M30 -> 29293398 | N30: =L30-M30 -> 14643204
B31: =1+B30 -> 22 | C31: Philequity Alpha One Fund, Inc. | D31: 2.6046398e+08 | E31: 2099576.2 | F31: =D31-E31 -> 2.583644e+08 | G31: 254967084 | H31: 1136 | I31: 219446.22 | J31: 217179.09 | K31: =I31-J31 -> 2267.13 | L31: =I31+Feb!L31 -> 2960185 | M31: =J31+Feb!M31 -> 12614178 | N31: =L31-M31 -> -9653992.9
B32: =1+B31 -> 23 | C32: Philippine Stock Index Fund Corp. | D32: 705683012 | E32: 8613527 | F32: =D32-E32 -> 697069485 | G32: 688515295 | H32: 760660 | I32: 12965953 | J32: 8335050 | K32: =I32-J32 -> 4630903 | L32: =I32+Feb!L32 -> 118944271 | M32: =J32+Feb!M32 -> 87638342 | N32: =L32-M32 -> 31305929
A33: Exchange Traded Fund | L33: =I33+Feb!L33 -> 0 | M33: =J33+Feb!M33 -> 0
B34: =1+B32 -> 24 | C34: First Metro Phil. Equity Exchange Traded Fund, Inc. | D34: 1371676029 | E34: 1307345 | F34: =D34-E34 -> 1370368684 | G34: 1355032660 | H34: 3288 | I34: 0 | J34: 0 | K34: =I34-J34 -> 0 | L34: =I34+Feb!L34 -> 40232388 | M34: =J34+Feb!M34 -> 0 | N34: =L34-M34 -> 40232388
A35: Sub total - Peso Currency | D35: =SUM(D9:D34) -> 56029683910 | E35: =SUM(E9:E34) -> 3.7989204e+08 | F35: =SUM(F9:F34) -> 55649791867 | G35: =SUM(G9:G34) -> 53445377699 | H35: =SUM(H9:H34) -> 1039385 | I35: =SUM(I9:I34) -> 2.7130564e+08 | J35: =SUM(J9:J34) -> 7.1958525e+08 | K35: =SUM(K9:K34) -> -4.4827961e+08 | ... N35: =SUM(N9:N34) -> -7.8460089e+08
A36: Primarily invested in foreign currency securities (shares)
B37: =1+B34 -> 25 | C37: ATRAM AsiaPlus Equity Fund, Inc. | D37: 27486376 | E37: 260731.71 | F37: =D37-E37 -> 27225644 | G37: 0 | H37: 50 | I37: 0 | J37: 28531.77 | K37: =I37-J37 -> -28531.77 | L37: =I37+Feb!L37 -> 104642.2 | M37: =J37+Feb!M37 -> 153134.87 | N37: =L37-M37 -> -48492.67
B38: =1+B37 -> 26 | C38: Sun Life Prosperity World Voyager Fund, Inc. | D38: 1756788232 | E38: 32256146 | F38: =D38-E38 -> 1724532086 | G38: 0 | H38: 3216 | I38: 16360241 | J38: 215287917 | K38: =I38-J38 -> -198927676 | L38: =I38+Feb!L38 -> 87592931 | M38: =J38+Feb!M38 -> 297298701 | N38: =L38-M38 -> -209705770
A39: Sub total - US Currency | D39: =SUM(D37:D38) -> 1784274608 | E39: =SUM(E37:E38) -> 32516878 | F39: =SUM(F37:F38) -> 1751757730 | G39: =SUM(G37:G38) -> 0 | H39: =SUM(H37:H38) -> 3266 | I39: =SUM(I37:I38) -> 16360241 | J39: =SUM(J37:J38) -> 2.1531645e+08 | K39: =SUM(K37:K38) -> -1.9895621e+08 | ... N39: =SUM(N37:N38) -> -2.0975426e+08
A40: Sub total - stock funds | D40: =D35+D39 -> 57813958518 | E40: =E35+E39 -> 4.1240892e+08 | F40: =F35+F39 -> 57401549597 | G40: =G35+G39 -> 53445377699 | H40: =H35+H39 -> 1042651 | I40: =I35+I39 -> 2.8766588e+08 | J40: =J35+J39 -> 9.349017e+08 | K40: =K35+K39 -> -6.4723582e+08 | ... N40: =N35+N39 -> -9.9435515e+08
A41: Balanced Funds
A42: Primarily invested in Peso Securities (shares)
B43: =1+B38 -> 27 | C43: ATRAM Philippine Balanced Fund, Inc. | D43: 4.5410321e+08 | E43: 54254241 | F43: =D43-E43 -> 3.9984897e+08 | G43: 210736819 | H43: 2316 | I43: 716009.53 | J43: 1378680.6 | K43: =I43-J43 -> -662671.11 | L43: =I43+Feb!L43 -> 1623332.6 | M43: =J43+Feb!M43 -> 18184513 | N43: =L43-M43 -> -16561181
B44: =1+B43 -> 28 | C44: ATRAM Unicapital Diversified Growth Fund, Inc. | D44: 1.161206e+08 | E44: 4693809.3 | F44: =D44-E44 -> 1.1142679e+08 | G44: 25667204 | H44: 811 | I44: 284574.8 | J44: 507627.26 | K44: =I44-J44 -> -223052.46 | L44: =I44+Feb!L44 -> 943427.2 | M44: =J44+Feb!M44 -> 1379997.9 | N44: =L44-M44 -> -436570.65
B45: =1+B44 -> 29 | C45: First Metro Save and Learn Balanced Fund, Inc. | D45: 652137686 | E45: 12621540 | F45: =D45-E45 -> 639516146 | G45: 291800977 | H45: 4073 | I45: 565535 | J45: 5023185 | K45: =I45-J45 -> -4457650 | L45: =I45+Feb!L45 -> 2362845 | M45: =J45+Feb!M45 -> 15534109 | N45: =L45-M45 -> -13171264
...

Sheet Mar UPDATED
A1: PHILIPPINE INVESTMENT FUNDS ASSOCIATION, INC.
A2: MUTUAL FUNDS STATISTICAL REPORT
A3: Month of March 2025
A4: (Amounts in Peso)
I5: F O R - T H E - M O N T H | L5: Y E A R - T O - D A T E
A6: Fund Category | C6: Fund Name | D6: ASSETS | E6: LIABILITIES | F6: NET ASSETS | G6: EQUITY INV. | H6: NO. OF A/C | I6: SALES | J6: REDEMPTIONS | K6: NET SALES | L6: TOTAL SALES | M6: TOTAL REDEMPTIONS | N6: TOTAL NET SALES
A7: Stock Funds
A8: Primarily invested in Peso Securities (shares)
B9: 1 | C9: ALFM Growth Fund, Inc. | D9: 3727680401 | E9: 16586059 | F9: =D9-E9 -> 3711094342 | G9: 3610766587 | H9: 5787 | I9: 3895709 | J9: 38893467 | K9: =I9-J9 -> -34997758 | L9: =I9+Feb!L9 -> 23921065 | M9: =J9+Feb!M9 -> 93648240 | N9: =L9-M9 -> -69727175
B10: =1+B9 -> 2 | C10: ATRAM Alpha Opportunity Fund, Inc. | D10: 9.9423617e+08 | E10: 5881151.8 | F10: =D10-E10 -> 9.8835502e+08 | G10: 9.0877886e+08 | H10: 4153 | I10: 19453917 | J10: 13827556 | K10: =I10-J10 -> 5626361.1 | L10: =I10+Feb!L10 -> 61754874 | M10: =J10+Feb!M10 -> 37824902 | N10: =L10-M10 -> 23929972
B11: =1+B10 -> 3 | C11: ATRAM Phil. Equity Opportunity Fund, Inc. | D11: 1.0518217e+09 | E11: 5938330.4 | F11: =D11-E11 -> 1045883409 | G11: 9.6679502e+08 | H11: 2475 | I11: 3871055.5 | J11: 16375873 | K11: =I11-J11 -> -12504818 | L11: =I11+Feb!L11 -> 16646336 | M11: =J11+Feb!M11 -> 29317981 | N11: =L11-M11 -> -12671646
B12: =1+B11 -> 4 | C12: Climbs Share Capital Equity Investment Fund Corp. | D12: 4.3695162e+08 | E12: 11777166 | F12: =D12-E12 -> 4.2517445e+08 | G12: 3.7292096e+08 | H12: 1714 | I12: 19950320 | J12: 744807.26 | K12: =I12-J12 -> 19205513 | L12: =I12+Feb!L12 -> 41032623 | M12: =J12+Feb!M12 -> 1720904.9 | N12: =L12-M12 -> 39311718
B13: =1+B12 -> 5 | C13: First Metro Consumer Fund, Inc. | D13: 344433276 | E13: 863871 | F13: =D13-E13 -> 343569405 | G13: 292407742 | H13: 1147 | I13: 232895 | J13: 1582188 | K13: =I13-J13 -> -1349293 | L13: =I13+Feb!L13 -> 794954 | M13: =J13+Feb!M13 -> 9096934 | N13: =L13-M13 -> -8301980
B14: =1+B13 -> 6 | C14: First Metro Save and Learn Equity Fund, Inc. | D14: 3089753006 | E14: 76002487 | F14: =D14-E14 -> 3013750519 | G14: 2727444004 | H14: 14342 | I14: 4949273 | J14: 23436077 | K14: =I14-J14 -> -18486804 | L14: =I14+Feb!L14 -> 40934592 | M14: =J14+Feb!M14 -> 122115264 | N14: =L14-M14 -> -81180672
B15: =1+B14 -> 7 | C15: First Metro Save and Learn Phil. Index Fund, Inc. | D15: 89427281 | E15: 351878 | F15: =D15-E15 -> 89075403 | G15: 83341085 | H15: 477 | I15: 1471042 | J15: 207686 | K15: =I15-J15 -> 1263356 | L15: =I15+Feb!L15 -> 7236629 | M15: =J15+Feb!M15 -> 1080702 | N15: =L15-M15 -> 6155927
B16: =1+B15 -> 8 | C16: MBG Equity Investment Fund, Inc. | D16: 115693364 | E16: 1384500 | F16: =D16-E16 -> 114308864 | G16: 110977560 | H16: 42 | I16: 0 | J16: 4270929 | K16: =I16-J16 -> -4270929 | L16: =I16+Feb!L16 -> 0 | M16: =J16+Feb!M16 -> 4270929 | N16: =L16-M16 -> -4270929
B17: =1+B16 -> 9 | C17: PAMI Equity Index Fund, Inc. | D17: 1019368785 | E17: 26321603 | F17: =D17-E17 -> 993047182 | G17: 1000248093 | H17: 10954 | I17: 0 | J17: 6430162 | K17: =I17-J17 -> -6430162 | L17: =I17+Feb!L17 -> 0 | M17: =J17+Feb!M17 -> 20508556 | N17: =L17-M17 -> -20508556
B18: =1+B17 -> 10 | C18: Philam Strategic Growth Fund, Inc. | D18: 3094232781 | E18: 22477588 | F18: =D18-E18 -> 3071755193 | G18: 3004745015 | H18: 10693 | I18: 6119251 | J18: 29665773 | K18: =I18-J18 -> -23546522 | L18: =I18+Feb!L18 -> 19633671 | M18: =J18+Feb!M18 -> 84434613 | N18: =L18-M18 -> -64800942
B19: =1+B18 -> 11 | C19: Philequity Dividend Yield Fund, Inc. | D19: 2.5359326e+09 | E19: 6843692.3 | F19: =D19-E19 -> 2529088882 | G19: 2.2821337e+09 | H19: 4988 | I19: 31989924 | J19: 38421353 | K19: =I19-J19 -> -6431428.4 | L19: =I19+Feb!L19 -> 48247099 | M19: =J19+Feb!M19 -> 45672090 | N19: =L19-M19 -> 2575009.4
B20: =1+B19 -> 12 | C20: Philequity Fund, Inc. | D20: 8.8235385e+09 | E20: 36790936 | F20: =D20-E20 -> 8786747587 | G20: 8.2239539e+09 | H20: 31681 | I20: 74305031 | J20: 1.267538e+08 | K20: =I20-J20 -> -52448769 | L20: =I20+Feb!L20 -> 91056483 | M20: =J20+Feb!M20 -> 1.7821858e+08 | N20: =L20-M20 -> -87162094
B21: =1+B20 -> 13 | C21: Philequity MSCI Phil. Index Fund, Inc. | D21: 3.0726806e+08 | E21: 487370.37 | F21: =D21-E21 -> 3.0678069e+08 | G21: 3.0049202e+08 | H21: 880 | I21: 275121.22 | J21: 266085.37 | K21: =I21-J21 -> 9035.85 | L21: =I21+Feb!L21 -> 1085849.7 | M21: =J21+Feb!M21 -> 550060.98 | N21: =L21-M21 -> 535788.75
... B27: =1+B26 -> 19 | C27: United Fund, Inc. | D27: 5.3042687e+08 | E27: 13536163 | F27: =D27-E27 -> 516890704 | G27: 4.6848837e+08 | H27: 1194 | I27: 206949.78 | J27: 2849276.1 | K27: =I27-J27 -> -2642326.3 | L27: =I27+Feb!L27 -> 1079302.5 | M27: =J27+Feb!M27 -> 3082993.2 | N27: =L27-M27 -> -2003690.8
A28: Primarily invested in Peso Securities (units) | L28: =I28+Feb!L28 -> 0 | M28: =J28+Feb!M28 -> 0
B29: =1+B27 -> 20 | C29: COL Equity Index Unitized Mutual Fund, Inc. | D29: 2.4543406e+08 | E29: 864167.18 | F29: =D29-E29 -> 2.445699e+08 | G29: 2.3410723e+08 | H29: 4662 | I29: 18132360 | J29: 2549403.9 | K29: =I29-J29 -> 15582956 | L29: =I29+Feb!L29 -> 39465956 | M29: =J29+Feb!M29 -> 15032562 | N29: =L29-M29 -> 24433394
B30: =1+B29 -> 21 | C30: COL Strategic Growth Equity Unitized Mutual Fund, Inc. | D30: 3.9447779e+08 | E30: 1349185 | F30: =D30-E30 -> 3.931286e+08 | G30: 326519805 | H30: 6215 | I30: 7932697.3 | J30: 16842612 | K30: =I30-J30 -> -8909914.5 | L30: =I30+Feb!L30 -> 43936603 | M30: =J30+Feb!M30 -> 29293398 | N30: =L30-M30 -> 14643204
B31: =1+B30 -> 22 | C31: Philequity Alpha One Fund, Inc. | D31: 2.6046398e+08 | E31: 2099576.2 | F31: =D31-E31 -> 2.583644e+08 | G31: 254967084 | H31: 1136 | I31: 219446.22 | J31: 217179.09 | K31: =I31-J31 -> 2267.13 | L31: =I31+Feb!L31 -> 2960185 | M31: =J31+Feb!M31 -> 12614178 | N31: =L31-M31 -> -9653992.9
B32: =1+B31 -> 23 | C32: Philippine Stock Index Fund Corp. | D32: 705683012 | E32: 8613527 | F32: =D32-E32 -> 697069485 | G32: 688515295 | H32: 760660 | I32: 12965953 | J32: 8335050 | K32: =I32-J32 -> 4630903 | L32: =I32+Feb!L32 -> 118944271 | M32: =J32+Feb!M32 -> 87638342 | N32: =L32-M32 -> 31305929
A33: Exchange Traded Fund | L33: =I33+Feb!L33 -> 0 | M33: =J33+Feb!M33 -> 0
B34: =1+B32 -> 24 | C34: First Metro Phil. Equity Exchange Traded Fund, Inc. | D34: 1371676029 | E34: 1307345 | F34: =D34-E34 -> 1370368684 | G34: 1355032660 | H34: 3288 | I34: 0 | J34: 0 | K34: =I34-J34 -> 0 | L34: =I34+Feb!L34 -> 40232388 | M34: =J34+Feb!M34 -> 0 | N34: =L34-M34 -> 40232388
A35: Sub total - Peso Currency | D35: =SUM(D9:D34) -> 56029683910 | E35: =SUM(E9:E34) -> 3.7989204e+08 | F35: =SUM(F9:F34) -> 55649791867 | G35: =SUM(G9:G34) -> 53445377699 | H35: =SUM(H9:H34) -> 1039385 | I35: =SUM(I9:I34) -> 2.7130564e+08 | J35: =SUM(J9:J34) -> 7.1958525e+08 | K35: =SUM(K9:K34) -> -4.4827961e+08 | ... N35: =SUM(N9:N34) -> -7.8460089e+08
A36: Primarily invested in foreign currency securities (shares)
B37: =1+B34 -> 25 | C37: ATRAM AsiaPlus Equity Fund, Inc. | D37: 27486376 | E37: 260731.71 | F37: =D37-E37 -> 27225644 | G37: 0 | H37: 50 | I37: 0 | J37: 28531.77 | K37: =I37-J37 -> -28531.77 | L37: =I37+Feb!L37 -> 104642.2 | M37: =J37+Feb!M37 -> 153134.87 | N37: =L37-M37 -> -48492.67
B38: =1+B37 -> 26 | C38: Sun Life Prosperity World Voyager Fund, Inc. | D38: 1756788232 | E38: 32256146 | F38: =D38-E38 -> 1724532086 | G38: 0 | H38: 3216 | I38: 16360241 | J38: 215287917 | K38: =I38-J38 -> -198927676 | L38: =I38+Feb!L38 -> 87592931 | M38: =J38+Feb!M38 -> 297298701 | N38: =L38-M38 -> -209705770
A39: Sub total - US Currency | D39: =SUM(D37:D38) -> 1784274608 | E39: =SUM(E37:E38) -> 32516878 | F39: =SUM(F37:F38) -> 1751757730 | G39: =SUM(G37:G38) -> 0 | H39: =SUM(H37:H38) -> 3266 | I39: =SUM(I37:I38) -> 16360241 | J39: =SUM(J37:J38) -> 2.1531645e+08 | K39: =SUM(K37:K38) -> -1.9895621e+08 | ... N39: =SUM(N37:N38) -> -2.0975426e+08
A40: Sub total - stock funds | D40: =D35+D39 -> 57813958518 | E40: =E35+E39 -> 4.1240892e+08 | F40: =F35+F39 -> 57401549597 | G40: =G35+G39 -> 53445377699 | H40: =H35+H39 -> 1042651 | I40: =I35+I39 -> 2.8766588e+08 | J40: =J35+J39 -> 9.349017e+08 | K40: =K35+K39 -> -6.4723582e+08 | ... N40: =N35+N39 -> -9.9435515e+08
A41: Balanced Funds
A42: Primarily invested in Peso Securities (shares)
B43: =1+B38 -> 27 | C43: ATRAM Philippine Balanced Fund, Inc. | D43: 4.5410321e+08 | E43: 54254241 | F43: =D43-E43 -> 3.9984897e+08 | G43: 210736819 | H43: 2316 | I43: 716009.53 | J43: 1378680.6 | K43: =I43-J43 -> -662671.11 | L43: =I43+Feb!L43 -> 1623332.6 | M43: =J43+Feb!M43 -> 18184513 | N43: =L43-M43 -> -16561181
B44: =1+B43 -> 28 | C44: ATRAM Unicapital Diversified Growth Fund, Inc. | D44: 1.161206e+08 | E44: 4693809.3 | F44: =D44-E44 -> 1.1142679e+08 | G44: 25667204 | H44: 811 | I44: 284574.8 | J44: 507627.26 | K44: =I44-J44 -> -223052.46 | L44: =I44+Feb!L44 -> 943427.2 | M44: =J44+Feb!M44 -> 1379997.9 | N44: =L44-M44 -> -436570.65
B45: =1+B44 -> 29 | C45: First Metro Save and Learn Balanced Fund, Inc. | D45: 652137686 | E45: 12621540 | F45: =D45-E45 -> 639516146 | G45: 291800977 | H45: 4073 | I45: 565535 | J45: 5023185 | K45: =I45-J45 -> -4457650 | L45: =I45+Feb!L45 -> 2362845 | M45: =J45+Feb!M45 -> 15534109 | N45: =L45-M45 -> -13171264
...

Sheet Q1
A1: PHILIPPINE INVESTMENT FUNDS ASSOCIATION, INC.
A2: MUTUAL FUNDS STATISTICAL REPORT
A3: As of the First Quarter of 2025
A4: (Amounts in Philippine Peso)
A6: Fund Category | C6: Fund Name | D6: NET ASSETS | E6: TOTAL SALES | F6: TOTAL REDEMPTIONS | G6: NET SALES
A7: Stock Funds
A8: Primarily invested in Peso Securities (shares)
B9: 1 | C9: ALFM Growth Fund, Inc. | D9: =Jan!F9 -> 3519779581 | E9: =Jan!I9+Feb!I9+Mar!I9 -> 23921065 | F9: =Jan!J9+Feb!J9+Mar!J9 -> 93648240 | G9: =E9-F9 -> -69727175
B10: =1+B9 -> 2 | C10: ATRAM Alpha Opportunity Fund, Inc. | D10: =Jan!F10 -> 8.7946495e+08 | E10: =Jan!I10+Feb!I10+Mar!I10 -> 61754874 | F10: =Jan!J10+Feb!J10+Mar!J10 -> 37824902 | G10: =E10-F10 -> 23929972
B11: =1+B10 -> 3 | C11: ATRAM Phil. Equity Opportunity Fund, Inc. | D11: =Jan!F11 -> 9.8945944e+08 | E11: =Jan!I11+Feb!I11+Mar!I11 -> 16646336 | F11: =Jan!J11+Feb!J11+Mar!J11 -> 29317981 | G11: =E11-F11 -> -12671646
B12: =1+B11 -> 4 | C12: Climbs Share Capital Equity Investment Fund Corp. | D12: =Jan!F12 -> 4.0176991e+08 | E12: =Jan!I12+Feb!I12+Mar!I12 -> 41032623 | F12: =Jan!J12+Feb!J12+Mar!J12 -> 1720904.9 | G12: =E12-F12 -> 39311718
B13: =1+B12 -> 5 | C13: First Metro Consumer Fund, Inc. | D13: =Jan!F13 -> 340546973 | E13: =Jan!I13+Feb!I13+Mar!I13 -> 794954 | F13: =Jan!J13+Feb!J13+Mar!J13 -> 9096934 | G13: =E13-F13 -> -8301980
B14: =1+B13 -> 6 | C14: First Metro Save and Learn Equity Fund, Inc. | D14: =Jan!F14 -> 2934717410 | E14: =Jan!I14+Feb!I14+Mar!I14 -> 40934592 | F14: =Jan!J14+Feb!J14+Mar!J14 -> 122115264 | G14: =E14-F14 -> -81180672
B15: =1+B14 -> 7 | C15: First Metro Save and Learn Phil. Index Fund, Inc. | D15: =Jan!F15 -> 77562338 | E15: =Jan!I15+Feb!I15+Mar!I15 -> 7236629 | F15: =Jan!J15+Feb!J15+Mar!J15 -> 1080702 | G15: =E15-F15 -> 6155927
B16: =1+B15 -> 8 | C16: MBG Equity Investment Fund, Inc. | D16: =Jan!F16 -> 117940203 | E16: =Jan!I16+Feb!I16+Mar!I16 -> 0 | F16: =Jan!J16+Feb!J16+Mar!J16 -> 4270929 | G16: =E16-F16 -> -4270929
B17: =1+B16 -> 9 | C17: PAMI Equity Index Fund, Inc. | D17: =Jan!F17 -> 940637483 | E17: =Jan!I17+Feb!I17+Mar!I17 -> 0 | F17: =Jan!J17+Feb!J17+Mar!J17 -> 20508556 | G17: =E17-F17 -> -20508556
B18: =1+B17 -> 10 | C18: Philam Strategic Growth Fund, Inc. | D18: =Jan!F18 -> 2935187983 | E18: =Jan!I18+Feb!I18+Mar!I18 -> 19633671 | F18: =Jan!J18+Feb!J18+Mar!J18 -> 84434613 | G18: =E18-F18 -> -64800942
B19: =1+B18 -> 11 | C19: Philequity Dividend Yield Fund, Inc. | D19: =Jan!F19 -> 2408297162 | E19: =Jan!I19+Feb!I19+Mar!I19 -> 48247099 | F19: =Jan!J19+Feb!J19+Mar!J19 -> 45672090 | G19: =E19-F19 -> 2575009.4
B20: =1+B19 -> 12 | C20: Philequity Fund, Inc. | D20: =Jan!F20 -> 8281684398 | E20: =Jan!I20+Feb!I20+Mar!I20 -> 91056483 | F20: =Jan!J20+Feb!J20+Mar!J20 -> 1.7821858e+08 | G20: =E20-F20 -> -87162094
B21: =1+B20 -> 13 | C21: Philequity MSCI Phil. Index Fund, Inc. | D21: =Jan!F21 -> 2.842405e+08 | E21: =Jan!I21+Feb!I21+Mar!I21 -> 1085849.7 | F21: =Jan!J21+Feb!J21+Mar!J21 -> 550060.98 | G21: =E21-F21 -> 535788.75
... B27: =1+B26 -> 19 | C27: United Fund, Inc. | D27: =Jan!F27 -> 4.6182618e+08 | E27: =Jan!I27+Feb!I27+Mar!I27 -> 1079302.5 | F27: =Jan!J27+Feb!J27+Mar!J27 -> 3082993.2 | G27: =E27-F27 -> -2003690.8
A28: Primarily invested in Peso Securities (units)
B29: =1+B27 -> 20 | C29: COL Equity Index Unitized Mutual Fund, Inc. | D29: =Jan!F29 -> 2.177321e+08 | E29: =Jan!I29+Feb!I29+Mar!I29 -> 39465956 | F29: =Jan!J29+Feb!J29+Mar!J29 -> 15032562 | G29: =E29-F29 -> 24433394
B30: =1+B29 -> 21 | C30: COL Strategic Growth Equity Unitized Mutual Fund, Inc. | D30: =Jan!F30 -> 3.7301676e+08 | E30: =Jan!I30+Feb!I30+Mar!I30 -> 43936603 | F30: =Jan!J30+Feb!J30+Mar!J30 -> 29293398 | G30: =E30-F30 -> 14643204
B31: =1+B30 -> 22 | C31: Philequity Alpha One Fund, Inc. | D31: =Jan!F31 -> 2.5830637e+08 | E31: =Jan!I31+Feb!I31+Mar!I31 -> 2960185 | F31: =Jan!J31+Feb!J31+Mar!J31 -> 12614178 | G31: =E31-F31 -> -9653992.9
B32: =1+B31 -> 23 | C32: Philippine Stock Index Fund Corp. | D32: =Jan!F32 -> 643846858 | E32: =Jan!I32+Feb!I32+Mar!I32 -> 118944271 | F32: =Jan!J32+Feb!J32+Mar!J32 -> 87638342 | G32: =E32-F32 -> 31305929
A33: Exchange Traded Fund
B34: =1+B32 -> 24 | C34: First Metro Phil. Equity Exchange Traded Fund, Inc. | D34: =Jan!F34 -> 1259866083 | E34: =Jan!I34+Feb!I34+Mar!I34 -> 40232388 | F34: =Jan!J34+Feb!J34+Mar!J34 -> 0 | G34: =E34-F34 -> 40232388
A35: Sub total - Peso Currency | D35: =SUM(D9:D34) -> 52861398006 | E35: =SUM(E9:E34) -> 9.196606e+08 | F35: =SUM(F9:F34) -> 1704261488 | G35: =SUM(G9:G34) -> -7.8460089e+08
A36: Primarily invested in foreign currency securities (shares)
B37: =1+B34 -> 25 | C37: ATRAM AsiaPlus Equity Fund, Inc. | D37: =Jan!F37 -> 27790192 | E37: =Jan!I37+Feb!I37+Mar!I37 -> 104642.2 | F37: =Jan!J37+Feb!J37+Mar!J37 -> 153134.87 | G37: =E37-F37 -> -48492.67
B38: =1+B37 -> 26 | C38: Sun Life Prosperity World Voyager Fund, Inc. | D38: =Jan!F38 -> 2107005269 | E38: =Jan!I38+Feb!I38+Mar!I38 -> 87592931 | F38: =Jan!J38+Feb!J38+Mar!J38 -> 297298701 | G38: =E38-F38 -> -209705770
A39: Sub total - US Currency | D39: =SUM(D37:D38) -> 2134795461 | E39: =SUM(E37:E38) -> 87697573 | F39: =SUM(F37:F38) -> 2.9745184e+08 | G39: =SUM(G37:G38) -> -2.0975426e+08
A40: Sub total - stock funds | D40: =D35+D39 -> 54996193467 | E40: =E35+E39 -> 1007358172 | F40: =F35+F39 -> 2001713324 | G40: =G35+G39 -> -9.9435515e+08
A41: Balanced Funds
A42: Primarily invested in Peso Securities (shares)
B43: =B38+1 -> 27 | C43: ATRAM Philippine Balanced Fund, Inc. | D43: =Jan!F43 -> 3.9469112e+08 | E43: =Jan!I43+Feb!I43+Mar!I43 -> 1623332.6 | F43: =Jan!J43+Feb!J43+Mar!J43 -> 18184513 | G43: =E43-F43 -> -16561181
B44: =B43+1 -> 28 | C44: ATRAM Unicapital Diversified Growth Fund, Inc. | D44: =Jan!F44 -> 1.1147777e+08 | E44: =Jan!I44+Feb!I44+Mar!I44 -> 943427.2 | F44: =Jan!J44+Feb!J44+Mar!J44 -> 1379997.9 | G44: =E44-F44 -> -436570.65
B45: =B44+1 -> 29 | C45: First Metro Save and Learn Balanced Fund, Inc. | D45: =Jan!F45 -> 634289203 | E45: =Jan!I45+Feb!I45+Mar!I45 -> 2362845 | F45: =Jan!J45+Feb!J45+Mar!J45 -> 15534109 | G45: =E45-F45 -> -13171264
B46: =B45+1 -> 30 | C46: First Metro Save and Learn F.O.C.C.U.S. Dynamic Fund, Inc. | D46: =Jan!F46 -> 462111116 | E46: =Jan!I46+Feb!I46+Mar!I46 -> 7075076 | F46: =Jan!J46+Feb!J46+Mar!J46 -> 131374204 | G46: =E46-F46 -> -124299128
...

Sheet Q1 Updated
A1: PHILIPPINE INVESTMENT FUNDS ASSOCIATION, INC.
A2: MUTUAL FUNDS STATISTICAL REPORT
A3: As of the First Quarter of 2025
A4: (Amounts in Philippine Peso)
A6: Fund Category | C6: Fund Name | D6: NET ASSETS | E6: TOTAL SALES | F6: TOTAL REDEMPTIONS | G6: NET SALES
A7: Stock Funds
A8: Primarily invested in Peso Securities (shares)
B9: 1 | C9: ALFM Growth Fund, Inc. | D9: =Mar!F9 -> 3711094342 | E9: =Jan!I9+Feb!I9+Mar!I9 -> 23921065 | F9: =Jan!J9+Feb!J9+Mar!J9 -> 93648240 | G9: =E9-F9 -> -69727175
B10: =1+B9 -> 2 | C10: ATRAM Alpha Opportunity Fund, Inc. | D10: =Mar!F10 -> 9.8835502e+08 | E10: =Jan!I10+Feb!I10+Mar!I10 -> 61754874 | F10: =Jan!J10+Feb!J10+Mar!J10 -> 37824902 | G10: =E10-F10 -> 23929972
B11: =1+B10 -> 3 | C11: ATRAM Phil. Equity Opportunity Fund, Inc. | D11: =Mar!F11 -> 1045883409 | E11: =Jan!I11+Feb!I11+Mar!I11 -> 16646336 | F11: =Jan!J11+Feb!J11+Mar!J11 -> 29317981 | G11: =E11-F11 -> -12671646
B12: =1+B11 -> 4 | C12: Climbs Share Capital Equity Investment Fund Corp. | D12: =Mar!F12 -> 4.2517445e+08 | E12: =Jan!I12+Feb!I12+Mar!I12 -> 41032623 | F12: =Jan!J12+Feb!J12+Mar!J12 -> 1720904.9 | G12: =E12-F12 -> 39311718
B13: =1+B12 -> 5 | C13: First Metro Consumer Fund, Inc. | D13: =Mar!F13 -> 343569405 | E13: =Jan!I13+Feb!I13+Mar!I13 -> 794954 | F13: =Jan!J13+Feb!J13+Mar!J13 -> 9096934 | G13: =E13-F13 -> -8301980
B14: =1+B13 -> 6 | C14: First Metro Save and Learn Equity Fund, Inc. | D14: =Mar!F14 -> 3013750519 | E14: =Jan!I14+Feb!I14+Mar!I14 -> 40934592 | F14: =Jan!J14+Feb!J14+Mar!J14 -> 122115264 | G14: =E14-F14 -> -81180672
B15: =1+B14 -> 7 | C15: First Metro Save and Learn Phil. Index Fund, Inc. | D15: =Mar!F15 -> 89075403 | E15: =Jan!I15+Feb!I15+Mar!I15 -> 7236629 | F15: =Jan!J15+Feb!J15+Mar!J15 -> 1080702 | G15: =E15-F15 -> 6155927
B16: =1+B15 -> 8 | C16: MBG Equity Investment Fund, Inc. | D16: =Mar!F16 -> 114308864 | E16: =Jan!I16+Feb!I16+Mar!I16 -> 0 | F16: =Jan!J16+Feb!J16+Mar!J16 -> 4270929 | G16: =E16-F16 -> -4270929
B17: =1+B16 -> 9 | C17: PAMI Equity Index Fund, Inc. | D17: =Mar!F17 -> 993047182 | E17: =Jan!I17+Feb!I17+Mar!I17 -> 0 | F17: =Jan!J17+Feb!J17+Mar!J17 -> 20508556 | G17: =E17-F17 -> -20508556
B18: =1+B17 -> 10 | C18: Philam Strategic Growth Fund, Inc. | D18: =Mar!F18 -> 3071755193 | E18: =Jan!I18+Feb!I18+Mar!I18 -> 19633671 | F18: =Jan!J18+Feb!J18+Mar!J18 -> 84434613 | G18: =E18-F18 -> -64800942
B19: =1+B18 -> 11 | C19: Philequity Dividend Yield Fund, Inc. | D19: =Mar!F19 -> 2529088882 | E19: =Jan!I19+Feb!I19+Mar!I19 -> 48247099 | F19: =Jan!J19+Feb!J19+Mar!J19 -> 45672090 | G19: =E19-F19 -> 2575009.4
B20: =1+B19 -> 12 | C20: Philequity Fund, Inc. | D20: =Mar!F20 -> 8786747587 | E20: =Jan!I20+Feb!I20+Mar!I20 -> 91056483 | F20: =Jan!J20+Feb!J20+Mar!J20 -> 1.7821858e+08 | G20: =E20-F20 -> -87162094
B21: =1+B20 -> 13 | C21: Philequity MSCI Phil. Index Fund, Inc. | D21: =Mar!F21 -> 3.0678069e+08 | E21: =Jan!I21+Feb!I21+Mar!I21 -> 1085849.7 | F21: =Jan!J21+Feb!J21+Mar!J21 -> 550060.98 | G21: =E21-F21 -> 535788.75
... B27: =1+B26 -> 19 | C27: United Fund, Inc. | D27: =Mar!F27 -> 516890704 | E27: =Jan!I27+Feb!I27+Mar!I27 -> 1079302.5 | F27: =Jan!J27+Feb!J27+Mar!J27 -> 3082993.2 | G27: =E27-F27 -> -2003690.8
A28: Primarily invested in Peso Securities (units)
B29: =1+B27 -> 20 | C29: COL Equity Index Unitized Mutual Fund, Inc. | D29: =Mar!F29 -> 2.445699e+08 | E29: =Jan!I29+Feb!I29+Mar!I29 -> 39465956 | F29: =Jan!J29+Feb!J29+Mar!J29 -> 15032562 | G29: =E29-F29 -> 24433394
B30: =1+B29 -> 21 | C30: COL Strategic Growth Equity Unitized Mutual Fund, Inc. | D30: =Mar!F30 -> 3.931286e+08 | E30: =Jan!I30+Feb!I30+Mar!I30 -> 43936603 | F30: =Jan!J30+Feb!J30+Mar!J30 -> 29293398 | G30: =E30-F30 -> 14643204
B31: =1+B30 -> 22 | C31: Philequity Alpha One Fund, Inc. | D31: =Mar!F31 -> 2.583644e+08 | E31: =Jan!I31+Feb!I31+Mar!I31 -> 2960185 | F31: =Jan!J31+Feb!J31+Mar!J31 -> 12614178 | G31: =E31-F31 -> -9653992.9
B32: =1+B31 -> 23 | C32: Philippine Stock Index Fund Corp. | D32: =Mar!F32 -> 697069485 | E32: =Jan!I32+Feb!I32+Mar!I32 -> 118944271 | F32: =Jan!J32+Feb!J32+Mar!J32 -> 87638342 | G32: =E32-F32 -> 31305929
A33: Exchange Traded Fund
B34: =1+B32 -> 24 | C34: First Metro Phil. Equity Exchange Traded Fund, Inc. | D34: =Mar!F34 -> 1370368684 | E34: =Jan!I34+Feb!I34+Mar!I34 -> 40232388 | F34: =Jan!J34+Feb!J34+Mar!J34 -> 0 | G34: =E34-F34 -> 40232388
A35: Sub total - Peso Currency | D35: =SUM(D9:D34) -> 55649791867 | E35: =SUM(E9:E34) -> 9.196606e+08 | F35: =SUM(F9:F34) -> 1704261488 | G35: =SUM(G9:G34) -> -7.8460089e+08
A36: Primarily invested in foreign currency securities (shares)
B37: =1+B34 -> 25 | C37: ATRAM AsiaPlus Equity Fund, Inc. | D37: =Mar!F37 -> 27225644 | E37: =Jan!I37+Feb!I37+Mar!I37 -> 104642.2 | F37: =Jan!J37+Feb!J37+Mar!J37 -> 153134.87 | G37: =E37-F37 -> -48492.67
B38: =1+B37 -> 26 | C38: Sun Life Prosperity World Voyager Fund, Inc. | D38: =Mar!F38 -> 1724532086 | E38: =Jan!I38+Feb!I38+Mar!I38 -> 87592931 | F38: =Jan!J38+Feb!J38+Mar!J38 -> 297298701 | G38: =E38-F38 -> -209705770
A39: Sub total - US Currency | D39: =SUM(D37:D38) -> 1751757730 | E39: =SUM(E37:E38) -> 87697573 | F39: =SUM(F37:F38) -> 2.9745184e+08 | G39: =SUM(G37:G38) -> -2.0975426e+08
A40: Sub total - stock funds | D40: =D35+D39 -> 57401549597 | E40: =E35+E39 -> 1007358172 | F40: =F35+F39 -> 2001713324 | G40: =G35+G39 -> -9.9435515e+08
A41: Balanced Funds
A42: Primarily invested in Peso Securities (shares)
B43: =B38+1 -> 27 | C43: ATRAM Philippine Balanced Fund, Inc. | D43: =Mar!F43 -> 3.9984897e+08 | E43: =Jan!I43+Feb!I43+Mar!I43 -> 1623332.6 | F43: =Jan!J43+Feb!J43+Mar!J43 -> 18184513 | G43: =E43-F43 -> -16561181
B44: =B43+1 -> 28 | C44: ATRAM Unicapital Diversified Growth Fund, Inc. | D44: =Mar!F44 -> 1.1142679e+08 | E44: =Jan!I44+Feb!I44+Mar!I44 -> 943427.2 | F44: =Jan!J44+Feb!J44+Mar!J44 -> 1379997.9 | G44: =E44-F44 -> -436570.65
B45: =B44+1 -> 29 | C45: First Metro Save and Learn Balanced Fund, Inc. | D45: =Mar!F45 -> 639516146 | E45: =Jan!I45+Feb!I45+Mar!I45 -> 2362845 | F45: =Jan!J45+Feb!J45+Mar!J45 -> 15534109 | G45: =E45-F45 -> -13171264
B46: =B45+1 -> 30 | C46: First Metro Save and Learn F.O.C.C.U.S. Dynamic Fund, Inc. | D46: =Mar!F46 -> 350888884 | E46: =Jan!I46+Feb!I46+Mar!I46 -> 7075076 | F46: =Jan!J46+Feb!J46+Mar!J46 -> 131374204 | G46: =E46-F46 -> -124299128
...

Sheet Apr
A1: PHILIPPINE INVESTMENT FUNDS ASSOCIATION, INC.
A2: MUTUAL FUNDS STATISTICAL REPORT
A3: Month of April 2025
A4: (Amounts in Peso)
I5: F O R - T H E - M O N T H | L5: Y E A R - T O - D A T E
A6: Fund Category | C6: Fund Name | D6: ASSETS | E6: LIABILITIES | F6: NET ASSETS | G6: EQUITY INV. | H6: NO. OF A/C | I6: SALES | J6: REDEMPTIONS | K6: NET SALES | L6: TOTAL SALES | M6: TOTAL REDEMPTIONS | N6: TOTAL NET SALES
A7: Stock Funds
A8: Primarily invested in Peso Securities (shares)
B9: 1 | C9: ALFM Growth Fund, Inc. | D9: 3781393446 | E9: 8017652 | F9: =D9-E9 -> 3773375794 | G9: 3681692215 | H9: 5757 | I9: 12733903 | J9: 39496012 | K9: =I9-J9 -> -26762109 | L9: =I9+Mar!L9 -> 36654968 | M9: =J9+Mar!M9 -> 133144252 | N9: =L9-M9 -> -96489284
B10: =1+B9 -> 2 | C10: ATRAM Alpha Opportunity Fund, Inc. | D10: 1.0492816e+09 | E10: 15294192 | F10: =D10-E10 -> 1033987359 | G10: 9.6252545e+08 | H10: 4172 | I10: 35163137 | J10: 13024348 | K10: =I10-J10 -> 22138789 | L10: =I10+Mar!L10 -> 96918012 | M10: =J10+Mar!M10 -> 50849250 | N10: =L10-M10 -> 46068762
B11: =1+B10 -> 3 | C11: ATRAM Phil. Equity Opportunity Fund, Inc. | D11: 1.0857059e+09 | E11: 25301834 | F11: =D11-E11 -> 1060404090 | G11: 1.0069916e+09 | H11: 2465 | I11: 3932979.5 | J11: 18589293 | K11: =I11-J11 -> -14656314 | L11: =I11+Mar!L11 -> 20579315 | M11: =J11+Mar!M11 -> 47907275 | N11: =L11-M11 -> -27327959
B12: =1+B11 -> 4 | C12: Climbs Share Capital Equity Investment Fund Corp. | D12: 4.4922584e+08 | E12: 12031024 | F12: =D12-E12 -> 437194817 | G12: 4.0373036e+08 | H12: 1721 | I12: 4086858.2 | J12: 84571.19 | K12: =I12-J12 -> 4002287.1 | L12: =I12+Mar!L12 -> 45119482 | M12: =J12+Mar!M12 -> 1805476.1 | N12: =L12-M12 -> 43314006
B13: =1+B12 -> 5 | C13: First Metro Consumer Fund, Inc. | D13: 355030859 | E13: 5152327 | F13: =D13-E13 -> 349878532 | G13: 305677623 | H13: 1138 | I13: 569472 | J13: 3121583 | K13: =I13-J13 -> -2552111 | L13: =I13+Mar!L13 -> 1364426 | M13: =J13+Mar!M13 -> 12218517 | N13: =L13-M13 -> -10854091
