Workbook

Sheet Jan
A1: PHILIPPINE INVESTMENT FUNDS ASSOCIATION, INC.
A2: MUTUAL FUNDS STATISTICAL REPORT
A3: Month of January 2026
A4: (Amounts in Peso)
I5: F O R - T H E - M O N T H | L5: Y E A R - T O - D A T E
A6: Fund Category | C6: Fund Name | D6: ASSETS | E6: LIABILITIES | F6: NET ASSETS | G6: EQUITY INV. | H6: NO. OF A/C | I6: SALES | J6: REDEMPTIONS | K6: NET SALES | L6: TOTAL SALES | M6: TOTAL REDEMPTIONS | N6: TOTAL NET SALES
A7: Stock Funds
A8: Primarily invested in Peso Securities (shares)
B9: 1 | C9: ALFM Growth Fund, Inc. | D9: 3566138553 | E9: 17961009 | F9: =D9-E9 -> 3548177544 | G9: 3472418894 | H9: 5367 | I9: 2640307 | J9: 48123098 | K9: =I9-J9 -> -45482791 | L9: =I9 -> 2640307 | M9: =J9 -> 48123098 | N9: =L9-M9 -> -45482791
B10: =1+B9 -> 2 | C10: ATRAM Alpha Opportunity Fund, Inc. | D10: 1.1134106e+09 | E10: 31034235 | F10: =D10-E10 -> 1082376401 | G10: 9.1868494e+08 | H10: 4230 | I10: 11186785 | J10: 89968214 | K10: =I10-J10 -> -78781429 | L10: =I10 -> 11186785 | M10: =J10 -> 89968214 | N10: =L10-M10 -> -78781429
B11: =1+B10 -> 3 | C11: ATRAM Phil. Equity Opportunity Fund, Inc. | D11: 9.624404e+08 | E11: 3514099.3 | F11: =D11-E11 -> 9.5892631e+08 | G11: 9.0628747e+08 | H11: 2354 | I11: 5938717.9 | J11: 46048364 | K11: =I11-J11 -> -40109646 | L11: =I11 -> 5938717.9 | M11: =J11 -> 46048364 | N11: =L11-M11 -> -40109646
B12: =1+B11 -> 4 | C12: Climbs Share Capital Equity Investment Fund Corp. | D12: 5.1005355e+08 | E12: 20594822 | F12: =D12-E12 -> 489458724 | G12: 2.7184791e+08 | H12: 1706 | I12: 63500 | J12: 16442436 | K12: =I12-J12 -> -16378936 | L12: =I12 -> 63500 | M12: =J12 -> 16442436 | N12: =L12-M12 -> -16378936
B13: =1+B12 -> 5 | C13: First Metro Consumer Fund, Inc. | D13: 275598731 | E13: 801995 | F13: =D13-E13 -> 274796736 | G13: 242385987 | H13: 1075 | I13: 148991 | J13: 730052 | K13: =I13-J13 -> -581061 | L13: =I13 -> 148991 | M13: =J13 -> 730052 | N13: =L13-M13 -> -581061
B14: =1+B13 -> 6 | C14: First Metro Save and Learn Equity Fund, Inc. | D14: 2432018800 | E14: 10360781 | F14: =D14-E14 -> 2421658019 | G14: 2268011103 | H14: 15255 | I14: 6409132 | J14: 46378258 | K14: =I14-J14 -> -39969126 | L14: =I14 -> 6409132 | M14: =J14 -> 46378258 | N14: =L14-M14 -> -39969126
B15: =1+B14 -> 7 | C15: First Metro Save and Learn Phil. Index Fund, Inc. | D15: 66587822 | E15: 335772 | F15: =D15-E15 -> 66252050 | G15: 65394638 | H15: 506 | I15: 313220 | J15: 114913 | K15: =I15-J15 -> 198307 | L15: =I15 -> 313220 | M15: =J15 -> 114913 | N15: =L15-M15 -> 198307
B16: =1+B15 -> 8 | C16: MBG Equity Investment Fund, Inc. | D16: 22990822 | E16: 783768 | F16: =D16-E16 -> 22207054 | G16: 19955895 | H16: 35 | I16: 0 | J16: 0 | K16: =I16-J16 -> 0 | L16: =I16 -> 0 | M16: =J16 -> 0 | N16: =L16-M16 -> 0
B17: =1+B16 -> 9 | C17: PAMI Equity Index Fund, Inc. | D17: 933061460 | E17: 38516684 | F17: =D17-E17 -> 894544776 | G17: 906635245 | H17: 10441 | I17: 0 | J17: 15347736 | K17: =I17-J17 -> -15347736 | L17: =I17 -> 0 | M17: =J17 -> 15347736 | N17: =L17-M17 -> -15347736
B18: =1+B17 -> 10 | C18: Philam Strategic Growth Fund, Inc. | D18: 2860346569 | E18: 24485246 | F18: =D18-E18 -> 2835861323 | G18: 2784641521 | H18: 9921 | I18: 0 | J18: 24094015 | K18: =I18-J18 -> -24094015 | L18: =I18 -> 0 | M18: =J18 -> 24094015 | N18: =L18-M18 -> -24094015
B19: =1+B18 -> 11 | C19: Philequity Dividend Yield Fund, Inc. | D19: 2.6415932e+09 | E19: 12607637 | F19: =D19-E19 -> 2628985593 | G19: 2.3965596e+09 | H19: 5131 | I19: 21263667 | J19: 45785337 | K19: =I19-J19 -> -24521670 | L19: =I19 -> 21263667 | M19: =J19 -> 45785337 | N19: =L19-M19 -> -24521670
B20: =1+B19 -> 12 | C20: Philequity Fund, Inc. | D20: 8.293483e+09 | E20: 33130926 | F20: =D20-E20 -> 8260352045 | G20: 7.9557918e+09 | H20: 30275 | I20: 10285233 | J20: 82475086 | K20: =I20-J20 -> -72189853 | L20: =I20 -> 10285233 | M20: =J20 -> 82475086 | N20: =L20-M20 -> -72189853
B21: =1+B20 -> 13 | C21: Philequity MSCI Phil. Index Fund, Inc. | D21: 3.2162002e+08 | E21: 1091529.8 | F21: =D21-E21 -> 3.2052849e+08 | G21: 3.2003943e+08 | H21: 861 | I21: 285074.58 | J21: 2593679 | K21: =I21-J21 -> -2308604.5 | L21: =I21 -> 285074.58 | M21: =J21 -> 2593679 | N21: =L21-M21 -> -2308604.5
... B27: =1+B26 -> 19 | C27: United Fund, Inc. | D27: 5.7953536e+08 | E27: 25579701 | F27: =D27-E27 -> 5.5395566e+08 | G27: 5.1956372e+08 | H27: 1170 | I27: 285318.86 | J27: 470423.67 | K27: =I27-J27 -> -185104.81 | L27: =I27 -> 285318.86 | M27: =J27 -> 470423.67 | N27: =L27-M27 -> -185104.81
A28: Primarily invested in Peso Securities (units)
B29: =1+B27 -> 20 | C29: COL Equity Index Unitized Mutual Fund, Inc. | D29: 2.5048852e+08 | E29: 1360125.8 | F29: =D29-E29 -> 2.4912839e+08 | G29: 2.4678681e+08 | H29: 5154 | I29: 6178380.4 | J29: 30041034 | K29: =I29-J29 -> -23862654 | L29: =I29 -> 6178380.4 | M29: =J29 -> 30041034 | N29: =L29-M29 -> -23862654
B30: =1+B29 -> 21 | C30: COL Strategic Growth Equity Unitized Mutual Fund, Inc. | D30: 3.2727454e+08 | E30: 3848075.7 | F30: =D30-E30 -> 3.2342647e+08 | G30: 2.14631e+08 | H30: 8382 | I30: 4896023.6 | J30: 47996785 | K30: =I30-J30 -> -43100761 | L30: =I30 -> 4896023.6 | M30: =J30 -> 47996785 | N30: =L30-M30 -> -43100761
B31: =1+B30 -> 22 | C31: Philequity Alpha One Fund, Inc. | D31: 2.158626e+08 | E31: 5582137.1 | F31: =D31-E31 -> 2.1028046e+08 | G31: 2.0467063e+08 | H31: 1054 | I31: 146509.33 | J31: 2753696.9 | K31: =I31-J31 -> -2607187.6 | L31: =I31 -> 146509.33 | M31: =J31 -> 2753696.9 | N31: =L31-M31 -> -2607187.6
B32: =1+B31 -> 23 | C32: Philippine Stock Index Fund Corp. | D32: 546972960 | E32: 10112326 | F32: =D32-E32 -> 536860634 | G32: 529827579 | H32: 795947 | I32: 8712309 | J32: 77321355 | K32: =I32-J32 -> -68609046 | L32: =I32 -> 8712309 | M32: =J32 -> 77321355 | N32: =L32-M32 -> -68609046
A33: Exchange Traded Fund
B34: =1+B32 -> 24 | C34: First Metro Phil. Equity Exchange Traded Fund, Inc. | D34: 1341582675 | E34: 2136945 | F34: =D34-E34 -> 1339445730 | G34: 1338437592 | H34: 3263 | I34: 0 | J34: 28553361 | K34: =I34-J34 -> -28553361 | L34: =I34 -> 0 | M34: =J34 -> 28553361 | N34: =L34-M34 -> -28553361
A35: Sub total - Peso Currency | D35: =SUM(D9:D34) -> 51317428461 | E35: =SUM(E9:E34) -> 5.8936543e+08 | F35: =SUM(F9:F34) -> 50728063030 | G35: =SUM(G9:G34) -> 48750469713 | H35: =SUM(H9:H34) -> 1072637 | I35: =SUM(I9:I34) -> 1.1282018e+08 | J35: =SUM(J9:J34) -> 1257421872 | K35: =SUM(K9:K34) -> -1144601691 | ... N35: =SUM(N9:N34) -> -1144601691
A36: Primarily invested in foreign currency securities (shares)
B37: =1+B34 -> 25 | C37: ATRAM AsiaPlus Equity Fund, Inc. | D37: 28712054 | E37: 239289.44 | F37: =D37-E37 -> 28472765 | G37: 0 | H37: 44 | I37: 11731.39 | J37: 4556127.2 | K37: =I37-J37 -> -4544395.8 | L37: =I37 -> 11731.39 | M37: =J37 -> 4556127.2 | N37: =L37-M37 -> -4544395.8
B38: =1+B37 -> 26 | C38: Sun Life Prosperity World Voyager Fund, Inc. | D38: 2454518648 | E38: 114033147 | F38: =D38-E38 -> 2340485501 | G38: 0 | H38: 3342 | I38: 119246734 | J38: 41066033 | K38: =I38-J38 -> 78180701 | L38: =I38 -> 119246734 | M38: =J38 -> 41066033 | N38: =L38-M38 -> 78180701
A39: Sub total - US Currency | D39: =SUM(D37:D38) -> 2483230702 | E39: =SUM(E37:E38) -> 1.1427244e+08 | F39: =SUM(F37:F38) -> 2368958266 | G39: =SUM(G37:G38) -> 0 | H39: =SUM(H37:H38) -> 3386 | I39: =SUM(I37:I38) -> 1.1925847e+08 | J39: =SUM(J37:J38) -> 45622160 | K39: =SUM(K37:K38) -> 73636305 | ... N39: =SUM(N37:N38) -> 73636305
A40: Sub total - stock funds | D40: =D35+D39 -> 53800659163 | E40: =E35+E39 -> 7.0363787e+08 | F40: =F35+F39 -> 53097021296 | G40: =G35+G39 -> 48750469713 | H40: =H35+H39 -> 1076023 | I40: =I35+I39 -> 2.3207865e+08 | J40: =J35+J39 -> 1303044032 | K40: =K35+K39 -> -1070965386 | ... N40: =N35+N39 -> -1070965386
A41: Balanced Funds
A42: Primarily invested in Peso Securities (shares)
B43: =1+B38 -> 27 | C43: ATRAM Philippine Balanced Fund, Inc. | D43: 4.1411202e+08 | E43: 21698969 | F43: =D43-E43 -> 3.9241305e+08 | G43: 1.9453811e+08 | H43: 2316 | I43: 488299.81 | J43: 4979089 | K43: =I43-J43 -> -4490789.2 | L43: =I43 -> 488299.81 | M43: =J43 -> 4979089 | N43: =L43-M43 -> -4490789.2
B44: =1+B43 -> 28 | C44: ATRAM Unicapital Diversified Growth Fund, Inc. | D44: 1.2118598e+08 | E44: 3503422.8 | F44: =D44-E44 -> 1.1768256e+08 | G44: 28732505 | H44: 862 | I44: 631898.87 | J44: 1675298.6 | K44: =I44-J44 -> -1043399.8 | L44: =I44 -> 631898.87 | M44: =J44 -> 1675298.6 | N44: =L44-M44 -> -1043399.8
B45: =1+B44 -> 29 | C45: First Metro Save and Learn Balanced Fund, Inc. | D45: 581092411 | E45: 12434266 | F45: =D45-E45 -> 568658145 | G45: 276274116 | H45: 4546 | I45: 550899 | J45: 8263014 | K45: =I45-J45 -> -7712115 | L45: =I45 -> 550899 | M45: =J45 -> 8263014 | N45: =L45-M45 -> -7712115
...

Sheet Feb
A1: PHILIPPINE INVESTMENT FUNDS ASSOCIATION, INC.
A2: MUTUAL FUNDS STATISTICAL REPORT
A3: Month of February 2026
A4: (Amounts in Peso)
I5: F O R - T H E - M O N T H | L5: Y E A R - T O - D A T E
A6: Fund Category | C6: Fund Name | D6: ASSETS | E6: LIABILITIES | F6: NET ASSETS | G6: EQUITY INV. | H6: NO. OF A/C | I6: SALES | J6: REDEMPTIONS | K6: NET SALES | L6: TOTAL SALES | M6: TOTAL REDEMPTIONS | N6: TOTAL NET SALES
A7: Stock Funds
A8: Primarily invested in Peso Securities (shares)
B9: 1 | C9: ALFM Growth Fund, Inc. | D9: 3678383403 | E9: 29551293 | F9: =D9-E9 -> 3648832110 | G9: 3606659841 | H9: 5290 | I9: 5384497 | J9: 46958163 | K9: =I9-J9 -> -41573666 | L9: =I9+Jan!L9 -> 8024804 | M9: =J9+Jan!M9 -> 95081261 | N9: =L9-M9 -> -87056457
B10: =1+B9 -> 2 | C10: ATRAM Alpha Opportunity Fund, Inc. | D10: 1.1176472e+09 | E10: 10930035 | F10: =D10-E10 -> 1106717117 | G10: 1.0367e+09 | H10: 4210 | I10: 13163391 | J10: 13192961 | K10: =I10-J10 -> -29570.12 | L10: =I10+Jan!L10 -> 24350175 | M10: =J10+Jan!M10 -> 1.0316117e+08 | N10: =L10-M10 -> -78811000
B11: =1+B10 -> 3 | C11: ATRAM Phil. Equity Opportunity Fund, Inc. | D11: 1.07207e+09 | E11: 77750965 | F11: =D11-E11 -> 994319013 | G11: 9.3161594e+08 | H11: 2348 | I11: 2000296 | J11: 7773113.8 | K11: =I11-J11 -> -5772817.9 | L11: =I11+Jan!L11 -> 7939013.9 | M11: =J11+Jan!M11 -> 53821478 | N11: =L11-M11 -> -45882464
B12: =1+B11 -> 4 | C12: Climbs Share Capital Equity Investment Fund Corp. | D12: 5.1885957e+08 | E12: 20165405 | F12: =D12-E12 -> 4.9869416e+08 | G12: 2.7663693e+08 | H12: 1706 | I12: 725792.5 | J12: 564740.09 | K12: =I12-J12 -> 161052.41 | L12: =I12+Jan!L12 -> 789292.5 | M12: =J12+Jan!M12 -> 17007176 | N12: =L12-M12 -> -16217884
B13: =1+B12 -> 5 | C13: First Metro Consumer Fund, Inc. | D13: 279152771 | E13: 10583956 | F13: =D13-E13 -> 268568815 | G13: 263653374 | H13: 1065 | I13: 99185 | J13: 16654032 | K13: =I13-J13 -> -16554847 | L13: =I13+Jan!L13 -> 248176 | M13: =J13+Jan!M13 -> 17384084 | N13: =L13-M13 -> -17135908
B14: =1+B13 -> 6 | C14: First Metro Save and Learn Equity Fund, Inc. | D14: 2648792030 | E14: 156007523 | F14: =D14-E14 -> 2492784507 | G14: 2329860987 | H14: 15162 | I14: 1645204 | J14: 31133161 | K14: =I14-J14 -> -29487957 | L14: =I14+Jan!L14 -> 8054336 | M14: =J14+Jan!M14 -> 77511419 | N14: =L14-M14 -> -69457083
B15: =1+B14 -> 7 | C15: First Metro Save and Learn Phil. Index Fund, Inc. | D15: 69102317 | E15: 403828 | F15: =D15-E15 -> 68698489 | G15: 67798081 | H15: 503 | I15: 137742 | J15: 362141 | K15: =I15-J15 -> -224399 | L15: =I15+Jan!L15 -> 450962 | M15: =J15+Jan!M15 -> 477054 | N15: =L15-M15 -> -26092
B16: =1+B15 -> 8 | C16: MBG Equity Investment Fund, Inc. | D16: 22351116 | E16: 653494 | F16: =D16-E16 -> 21697622 | G16: 19239167 | H16: 35 | I16: 0 | J16: 0 | K16: =I16-J16 -> 0 | L16: =I16+Jan!L16 -> 0 | M16: =J16+Jan!M16 -> 0 | N16: =L16-M16 -> 0
B17: =1+B16 -> 9 | C17: PAMI Equity Index Fund, Inc. | D17: 949293850 | E17: 22894348 | F17: =D17-E17 -> 926399502 | G17: 939380229 | H17: 10374 | I17: 0 | J17: 7489189 | K17: =I17-J17 -> -7489189 | L17: =I17+Jan!L17 -> 0 | M17: =J17+Jan!M17 -> 22836925 | N17: =L17-M17 -> -22836925
B18: =1+B17 -> 10 | C18: Philam Strategic Growth Fund, Inc. | D18: 2952917109 | E18: 43247875 | F18: =D18-E18 -> 2909669234 | G18: 2892320242 | H18: 9863 | I18: 0 | J18: 40639309 | K18: =I18-J18 -> -40639309 | L18: =I18+Jan!L18 -> 0 | M18: =J18+Jan!M18 -> 64733324 | N18: =L18-M18 -> -64733324
B19: =1+B18 -> 11 | C19: Philequity Dividend Yield Fund, Inc. | D19: 2.7067133e+09 | E19: 51127712 | F19: =D19-E19 -> 2655585579 | G19: 2.5908914e+09 | H19: 5155 | I19: 10795622 | J19: 95950687 | K19: =I19-J19 -> -85155065 | L19: =I19+Jan!L19 -> 32059289 | M19: =J19+Jan!M19 -> 1.4173602e+08 | N19: =L19-M19 -> -1.0967673e+08
B20: =1+B19 -> 12 | C20: Philequity Fund, Inc. | D20: 8.6588903e+09 | E20: 1.1530918e+08 | F20: =D20-E20 -> 8543581153 | G20: 8.1371773e+09 | H20: 30091 | I20: 10285233 | J20: 82475086 | K20: =I20-J20 -> -72189853 | L20: =I20+Jan!L20 -> 20570466 | M20: =J20+Jan!M20 -> 1.6495017e+08 | N20: =L20-M20 -> -1.4437971e+08
B21: =1+B20 -> 13 | C21: Philequity MSCI Phil. Index Fund, Inc. | D21: 3.0646961e+08 | E21: 1001407.2 | F21: =D21-E21 -> 3.0546821e+08 | G21: 3.0443688e+08 | H21: 869 | I21: 393524.1 | J21: 29784917 | K21: =I21-J21 -> -29391393 | L21: =I21+Jan!L21 -> 678598.68 | M21: =J21+Jan!M21 -> 32378596 | N21: =L21-M21 -> -31699997
... B27: =1+B26 -> 19 | C27: United Fund, Inc. | D27: 5.6147379e+08 | E27: 2058816.7 | F27: =D27-E27 -> 5.5941498e+08 | G27: 5.0932384e+08 | H27: 1175 | I27: 141976.67 | J27: 301093.29 | K27: =I27-J27 -> -159116.62 | L27: =I27+Jan!L27 -> 427295.53 | M27: =J27+Jan!M27 -> 771516.96 | N27: =L27-M27 -> -344221.43
A28: Primarily invested in Peso Securities (units)
B29: =1+B27 -> 20 | C29: COL Equity Index Unitized Mutual Fund, Inc. | D29: 2.561967e+08 | E29: 2846688 | F29: =D29-E29 -> 2.5335001e+08 | G29: 2.5502866e+08 | H29: 5195 | I29: 4900573 | J29: 11350341 | K29: =I29-J29 -> -6449767.7 | L29: =I29+Jan!L29 -> 11078953 | M29: =J29+Jan!M29 -> 41391375 | N29: =L29-M29 -> -30312421
B30: =1+B29 -> 21 | C30: COL Strategic Growth Equity Unitized Mutual Fund, Inc. | D30: 3.2552876e+08 | E30: 3335942 | F30: =D30-E30 -> 322192821 | G30: 2.4044268e+08 | H30: 8510 | I30: 3451746.9 | J30: 11118657 | K30: =I30-J30 -> -7666910.3 | L30: =I30+Jan!L30 -> 8347770.5 | M30: =J30+Jan!M30 -> 59115442 | N30: =L30-M30 -> -50767671
B31: =1+B30 -> 22 | C31: Philequity Alpha One Fund, Inc. | D31: 2.1490907e+08 | E31: 2990476.1 | F31: =D31-E31 -> 2.1191859e+08 | G31: 2.1030811e+08 | H31: 1045 | I31: 168483.27 | J31: 3699126 | K31: =I31-J31 -> -3530642.7 | L31: =I31+Jan!L31 -> 314992.6 | M31: =J31+Jan!M31 -> 6452822.9 | N31: =L31-M31 -> -6137830.3
B32: =1+B31 -> 23 | C32: Philippine Stock Index Fund Corp. | D32: 558979791 | E32: 4113835 | F32: =D32-E32 -> 554865956 | G32: 549842730 | H32: 799580 | I32: 15068268 | J32: 20407849 | K32: =I32-J32 -> -5339581 | L32: =I32+Jan!L32 -> 23780577 | M32: =J32+Jan!M32 -> 97729204 | N32: =L32-M32 -> -73948627
A33: Exchange Traded Fund
B34: =1+B32 -> 24 | C34: First Metro Phil. Equity Exchange Traded Fund, Inc. | D34: 1365982115 | E34: 2157787 | F34: =D34-E34 -> 1363824328 | G34: 1364289439 | H34: 3234 | I34: 8414744 | J34: 48571714 | K34: =I34-J34 -> -40156970 | L34: =I34+Jan!L34 -> 8414744 | M34: =J34+Jan!M34 -> 77125075 | N34: =L34-M34 -> -68710331
A35: Sub total - Peso Currency | D35: =SUM(D9:D34) -> 52569703204 | E35: =SUM(E9:E34) -> 7.6939971e+08 | F35: =SUM(F9:F34) -> 51800303493 | G35: =SUM(G9:G34) -> 50164847629 | H35: =SUM(H9:H34) -> 1075672 | I35: =SUM(I9:I34) -> 98207906 | J35: =SUM(J9:J34) -> 1095990972 | K35: =SUM(K9:K34) -> -9.9778307e+08 | ... N35: =SUM(N9:N34) -> -2142384757
A36: Primarily invested in foreign currency securities (shares)
B37: =1+B34 -> 25 | C37: ATRAM AsiaPlus Equity Fund, Inc. | D37: 29949336 | E37: 345962.32 | F37: =D37-E37 -> 29603373 | G37: 0 | H37: 43 | I37: 11488.02 | J37: 249258.69 | K37: =I37-J37 -> -237770.67 | L37: =I37+Jan!L37 -> 23219.41 | M37: =J37+Jan!M37 -> 4805385.9 | N37: =L37-M37 -> -4782166.5
B38: =1+B37 -> 26 | C38: Sun Life Prosperity World Voyager Fund, Inc. | D38: 2502584706 | E38: 73412734 | F38: =D38-E38 -> 2429171972 | G38: 0 | H38: 3363 | I38: 112780395 | J38: 11569508 | K38: =I38-J38 -> 101210887 | L38: =I38+Jan!L38 -> 232027129 | M38: =J38+Jan!M38 -> 52635541 | N38: =L38-M38 -> 179391588
A39: Primarily invested in foreign currency securities (units)
B40: =1+B38 -> 27 | C40: Philequity Global Fund, Inc. 3 | D40: 495555.7 | E40: 0 | F40: =D40-E40 -> 495555.7 | G40: 0 | H40: 26 | I40: 495572.14 | J40: 0 | K40: =I40-J40 -> 495572.14 | L40: =I40 -> 495572.14 | M40: =J40 -> 0 | N40: =L40-M40 -> 495572.14
A41: Sub total - US Currency | D41: =SUM(D37:D38)+D40 -> 2533029597 | E41: =SUM(E37:E38)+E40 -> 73758696 | F41: =SUM(F37:F38)+F40 -> 2459270901 | G41: =SUM(G37:G38)+G40 -> 0 | H41: =SUM(H37:H38)+H40 -> 3432 | I41: =SUM(I37:I38)+I40 -> 1.1328746e+08 | J41: =SUM(J37:J38)+J40 -> 11818767 | K41: =SUM(K37:K38)+K40 -> 1.0146869e+08 | ... N41: =SUM(N37:N38)+N40 -> 1.7510499e+08
A42: Sub total - stock funds | D42: =D35+D41 -> 55102732802 | E42: =E35+E41 -> 8.4315841e+08 | F42: =F35+F41 -> 54259574394 | G42: =G35+G41 -> 50164847629 | H42: =H35+H41 -> 1079104 | I42: =I35+I41 -> 2.1149536e+08 | J42: =J35+J41 -> 1107809738 | K42: =K35+K41 -> -8.9631438e+08 | ... N42: =N35+N41 -> -1967279764
A43: Balanced Funds
A44: Primarily invested in Peso Securities (shares)
B45: =1+B40 -> 28 | C45: ATRAM Philippine Balanced Fund, Inc. | D45: 3.9654217e+08 | E45: 1133095.1 | F45: =D45-E45 -> 3.9540907e+08 | G45: 2.0984686e+08 | H45: 2320 | I45: 490945.49 | J45: 5293097.3 | K45: =I45-J45 -> -4802151.8 | L45: =I45+Jan!L43 -> 979245.3 | M45: =J45+Jan!M43 -> 10272186 | N45: =L45-M45 -> -9292941
...

Sheet Feb UPDATED
A1: PHILIPPINE INVESTMENT FUNDS ASSOCIATION, INC.
A2: MUTUAL FUNDS STATISTICAL REPORT
A3: Month of February 2026
A4: (Amounts in Peso)
I5: F O R - T H E - M O N T H | L5: Y E A R - T O - D A T E
A6: Fund Category | C6: Fund Name | D6: ASSETS | E6: LIABILITIES | F6: NET ASSETS | G6: EQUITY INV. | H6: NO. OF A/C | I6: SALES | J6: REDEMPTIONS | K6: NET SALES | L6: TOTAL SALES | M6: TOTAL REDEMPTIONS | N6: TOTAL NET SALES
A7: Stock Funds
A8: Primarily invested in Peso Securities (shares)
B9: 1 | C9: ALFM Growth Fund, Inc. | D9: 3678383403 | E9: 29551293 | F9: =D9-E9 -> 3648832110 | G9: 3606659841 | H9: 5290 | I9: 5384497 | J9: 46958163 | K9: =I9-J9 -> -41573666 | L9: =I9+Jan!L9 -> 8024804 | M9: =J9+Jan!M9 -> 95081261 | N9: =L9-M9 -> -87056457
B10: =1+B9 -> 2 | C10: ATRAM Alpha Opportunity Fund, Inc. | D10: 1.1176472e+09 | E10: 10930035 | F10: =D10-E10 -> 1106717117 | G10: 1.0367e+09 | H10: 4210 | I10: 13163391 | J10: 13192961 | K10: =I10-J10 -> -29570.12 | L10: =I10+Jan!L10 -> 24350175 | M10: =J10+Jan!M10 -> 1.0316117e+08 | N10: =L10-M10 -> -78811000
B11: =1+B10 -> 3 | C11: ATRAM Phil. Equity Opportunity Fund, Inc. | D11: 1.07207e+09 | E11: 77750965 | F11: =D11-E11 -> 994319013 | G11: 9.3161594e+08 | H11: 2348 | I11: 2000296 | J11: 7773113.8 | K11: =I11-J11 -> -5772817.9 | L11: =I11+Jan!L11 -> 7939013.9 | M11: =J11+Jan!M11 -> 53821478 | N11: =L11-M11 -> -45882464
B12: =1+B11 -> 4 | C12: Climbs Share Capital Equity Investment Fund Corp. | D12: 5.1885957e+08 | E12: 20165405 | F12: =D12-E12 -> 4.9869416e+08 | G12: 2.7663693e+08 | H12: 1706 | I12: 725792.5 | J12: 564740.09 | K12: =I12-J12 -> 161052.41 | L12: =I12+Jan!L12 -> 789292.5 | M12: =J12+Jan!M12 -> 17007176 | N12: =L12-M12 -> -16217884
B13: =1+B12 -> 5 | C13: First Metro Consumer Fund, Inc. | D13: 279152771 | E13: 10583956 | F13: =D13-E13 -> 268568815 | G13: 263653374 | H13: 1065 | I13: 99185 | J13: 16654032 | K13: =I13-J13 -> -16554847 | L13: =I13+Jan!L13 -> 248176 | M13: =J13+Jan!M13 -> 17384084 | N13: =L13-M13 -> -17135908
B14: =1+B13 -> 6 | C14: First Metro Save and Learn Equity Fund, Inc. | D14: 2648792030 | E14: 156007523 | F14: =D14-E14 -> 2492784507 | G14: 2329860987 | H14: 15162 | I14: 1645204 | J14: 31133161 | K14: =I14-J14 -> -29487957 | L14: =I14+Jan!L14 -> 8054336 | M14: =J14+Jan!M14 -> 77511419 | N14: =L14-M14 -> -69457083
B15: =1+B14 -> 7 | C15: First Metro Save and Learn Phil. Index Fund, Inc. | D15: 69102317 | E15: 403828 | F15: =D15-E15 -> 68698489 | G15: 67798081 | H15: 503 | I15: 137742 | J15: 362141 | K15: =I15-J15 -> -224399 | L15: =I15+Jan!L15 -> 450962 | M15: =J15+Jan!M15 -> 477054 | N15: =L15-M15 -> -26092
B16: =1+B15 -> 8 | C16: MBG Equity Investment Fund, Inc. | D16: 22351116 | E16: 653494 | F16: =D16-E16 -> 21697622 | G16: 19239167 | H16: 35 | I16: 0 | J16: 0 | K16: =I16-J16 -> 0 | L16: =I16+Jan!L16 -> 0 | M16: =J16+Jan!M16 -> 0 | N16: =L16-M16 -> 0
B17: =1+B16 -> 9 | C17: PAMI Equity Index Fund, Inc. | D17: 949293850 | E17: 22894348 | F17: =D17-E17 -> 926399502 | G17: 939380229 | H17: 10374 | I17: 0 | J17: 7489189 | K17: =I17-J17 -> -7489189 | L17: =I17+Jan!L17 -> 0 | M17: =J17+Jan!M17 -> 22836925 | N17: =L17-M17 -> -22836925
B18: =1+B17 -> 10 | C18: Philam Strategic Growth Fund, Inc. | D18: 2952917109 | E18: 43247875 | F18: =D18-E18 -> 2909669234 | G18: 2892320242 | H18: 9863 | I18: 0 | J18: 40639309 | K18: =I18-J18 -> -40639309 | L18: =I18+Jan!L18 -> 0 | M18: =J18+Jan!M18 -> 64733324 | N18: =L18-M18 -> -64733324
B19: =1+B18 -> 11 | C19: Philequity Dividend Yield Fund, Inc. | D19: 2.7067133e+09 | E19: 51127712 | F19: =D19-E19 -> 2655585579 | G19: 2.5908914e+09 | H19: 5155 | I19: 10795622 | J19: 95950687 | K19: =I19-J19 -> -85155065 | L19: =I19+Jan!L19 -> 32059289 | M19: =J19+Jan!M19 -> 1.4173602e+08 | N19: =L19-M19 -> -1.0967673e+08
B20: =1+B19 -> 12 | C20: Philequity Fund, Inc. | D20: 8.6588903e+09 | E20: 1.1530918e+08 | F20: =D20-E20 -> 8543581153 | G20: 8.1371773e+09 | H20: 30091 | I20: 10285233 | J20: 82475086 | K20: =I20-J20 -> -72189853 | L20: =I20+Jan!L20 -> 20570466 | M20: =J20+Jan!M20 -> 1.6495017e+08 | N20: =L20-M20 -> -1.4437971e+08
B21: =1+B20 -> 13 | C21: Philequity MSCI Phil. Index Fund, Inc. | D21: 3.0646961e+08 | E21: 1001407.2 | F21: =D21-E21 -> 3.0546821e+08 | G21: 3.0443688e+08 | H21: 869 | I21: 393524.1 | J21: 29784917 | K21: =I21-J21 -> -29391393 | L21: =I21+Jan!L21 -> 678598.68 | M21: =J21+Jan!M21 -> 32378596 | N21: =L21-M21 -> -31699997
... B27: =1+B26 -> 19 | C27: United Fund, Inc. | D27: 5.6147379e+08 | E27: 2058816.7 | F27: =D27-E27 -> 5.5941498e+08 | G27: 5.0932384e+08 | H27: 1175 | I27: 141976.67 | J27: 301093.29 | K27: =I27-J27 -> -159116.62 | L27: =I27+Jan!L27 -> 427295.53 | M27: =J27+Jan!M27 -> 771516.96 | N27: =L27-M27 -> -344221.43
A28: Primarily invested in Peso Securities (units)
B29: =1+B27 -> 20 | C29: COL Equity Index Unitized Mutual Fund, Inc. | D29: 2.561967e+08 | E29: 2846688 | F29: =D29-E29 -> 2.5335001e+08 | G29: 2.5502866e+08 | H29: 5195 | I29: 4900573 | J29: 11350341 | K29: =I29-J29 -> -6449767.7 | L29: =I29+Jan!L29 -> 11078953 | M29: =J29+Jan!M29 -> 41391375 | N29: =L29-M29 -> -30312421
B30: =1+B29 -> 21 | C30: COL Strategic Growth Equity Unitized Mutual Fund, Inc. | D30: 3.2552876e+08 | E30: 3335942 | F30: =D30-E30 -> 322192821 | G30: 2.4044268e+08 | H30: 8510 | I30: 3451746.9 | J30: 11118657 | K30: =I30-J30 -> -7666910.3 | L30: =I30+Jan!L30 -> 8347770.5 | M30: =J30+Jan!M30 -> 59115442 | N30: =L30-M30 -> -50767671
B31: =1+B30 -> 22 | C31: Philequity Alpha One Fund, Inc. | D31: 2.1490907e+08 | E31: 2990476.1 | F31: =D31-E31 -> 2.1191859e+08 | G31: 2.1030811e+08 | H31: 1045 | I31: 168483.27 | J31: 3699126 | K31: =I31-J31 -> -3530642.7 | L31: =I31+Jan!L31 -> 314992.6 | M31: =J31+Jan!M31 -> 6452822.9 | N31: =L31-M31 -> -6137830.3
B32: =1+B31 -> 23 | C32: Philippine Stock Index Fund Corp. | D32: 558979791 | E32: 4113835 | F32: =D32-E32 -> 554865956 | G32: 549842730 | H32: 799580 | I32: 15068268 | J32: 20407849 | K32: =I32-J32 -> -5339581 | L32: =I32+Jan!L32 -> 23780577 | M32: =J32+Jan!M32 -> 97729204 | N32: =L32-M32 -> -73948627
A33: Exchange Traded Fund
B34: =1+B32 -> 24 | C34: First Metro Phil. Equity Exchange Traded Fund, Inc. | D34: 1365982115 | E34: 2157787 | F34: =D34-E34 -> 1363824328 | G34: 1364289439 | H34: 3234 | I34: 8414744 | J34: 48571714 | K34: =I34-J34 -> -40156970 | L34: =I34+Jan!L34 -> 8414744 | M34: =J34+Jan!M34 -> 77125075 | N34: =L34-M34 -> -68710331
A35: Sub total - Peso Currency | D35: =SUM(D9:D34) -> 52569703204 | E35: =SUM(E9:E34) -> 7.6939971e+08 | F35: =SUM(F9:F34) -> 51800303493 | G35: =SUM(G9:G34) -> 50164847629 | H35: =SUM(H9:H34) -> 1075672 | I35: =SUM(I9:I34) -> 98207906 | J35: =SUM(J9:J34) -> 1095990972 | K35: =SUM(K9:K34) -> -9.9778307e+08 | ... N35: =SUM(N9:N34) -> -2142384757
A36: Primarily invested in foreign currency securities (shares)
B37: =1+B34 -> 25 | C37: ATRAM AsiaPlus Equity Fund, Inc. | D37: 29949336 | E37: 345962.32 | F37: =D37-E37 -> 29603373 | G37: 0 | H37: 43 | I37: 11488.02 | J37: 249258.69 | K37: =I37-J37 -> -237770.67 | L37: =I37+Jan!L37 -> 23219.41 | M37: =J37+Jan!M37 -> 4805385.9 | N37: =L37-M37 -> -4782166.5
B38: =1+B37 -> 26 | C38: Sun Life Prosperity World Voyager Fund, Inc. | D38: 2502584706 | E38: 73412734 | F38: =D38-E38 -> 2429171972 | G38: 0 | H38: 3363 | I38: 112780395 | J38: 11569508 | K38: =I38-J38 -> 101210887 | L38: =I38+Jan!L38 -> 232027129 | M38: =J38+Jan!M38 -> 52635541 | N38: =L38-M38 -> 179391588
A39: Primarily invested in foreign currency securities (units)
B40: =1+B38 -> 27 | C40: Philequity Global Fund, Inc. 3 | D40: 495555.7 | E40: 0 | F40: =D40-E40 -> 495555.7 | G40: 0 | H40: 26 | I40: 495572.14 | J40: 0 | K40: =I40-J40 -> 495572.14 | L40: =I40 -> 495572.14 | M40: =J40 -> 0 | N40: =L40-M40 -> 495572.14
A41: Sub total - US Currency | D41: =SUM(D37:D38)+D40 -> 2533029597 | E41: =SUM(E37:E38)+E40 -> 73758696 | F41: =SUM(F37:F38)+F40 -> 2459270901 | G41: =SUM(G37:G38)+G40 -> 0 | H41: =SUM(H37:H38)+H40 -> 3432 | I41: =SUM(I37:I38)+I40 -> 1.1328746e+08 | J41: =SUM(J37:J38)+J40 -> 11818767 | K41: =SUM(K37:K38)+K40 -> 1.0146869e+08 | ... N41: =SUM(N37:N38)+N40 -> 1.7510499e+08
A42: Sub total - stock funds | D42: =D35+D41 -> 55102732802 | E42: =E35+E41 -> 8.4315841e+08 | F42: =F35+F41 -> 54259574394 | G42: =G35+G41 -> 50164847629 | H42: =H35+H41 -> 1079104 | I42: =I35+I41 -> 2.1149536e+08 | J42: =J35+J41 -> 1107809738 | K42: =K35+K41 -> -8.9631438e+08 | ... N42: =N35+N41 -> -1967279764
A43: Balanced Funds
A44: Primarily invested in Peso Securities (shares)
B45: =1+B40 -> 28 | C45: ATRAM Philippine Balanced Fund, Inc. | D45: 3.9654217e+08 | E45: 1133095.1 | F45: =D45-E45 -> 3.9540907e+08 | G45: 2.0984686e+08 | H45: 2320 | I45: 490945.49 | J45: 5293097.3 | K45: =I45-J45 -> -4802151.8 | L45: =I45+Jan!L43 -> 979245.3 | M45: =J45+Jan!M43 -> 10272186 | N45: =L45-M45 -> -9292941
...

Sheet Mar
A1: PHILIPPINE INVESTMENT FUNDS ASSOCIATION, INC.
A2: MUTUAL FUNDS STATISTICAL REPORT
A3: Month of March 2026
A4: (Amounts in Peso)
I5: F O R - T H E - M O N T H | L5: Y E A R - T O - D A T E
A6: Fund Category | C6: Fund Name | D6: ASSETS | E6: LIABILITIES | F6: NET ASSETS | G6: EQUITY INV. | H6: NO. OF A/C | I6: SALES | J6: REDEMPTIONS | K6: NET SALES | L6: TOTAL SALES | M6: TOTAL REDEMPTIONS | N6: TOTAL NET SALES
A7: Stock Funds
A8: Primarily invested in Peso Securities (shares)
B9: 1 | C9: ALFM Growth Fund, Inc. | D9: 3272067162 | E9: 8601710 | F9: =D9-E9 -> 3263465452 | G9: 3090206979 | H9: 5226 | I9: 5182504 | J9: 49193407 | K9: =I9-J9 -> -44010903 | L9: =I9+Feb!L9 -> 13207308 | M9: =J9+Feb!M9 -> 144274668 | N9: =L9-M9 -> -131067360
B10: =1+B9 -> 2 | C10: ATRAM Alpha Opportunity Fund, Inc. | D10: 1.0242569e+09 | E10: 51757173 | F10: =D10-E10 -> 9.7249971e+08 | G10: 9.0727828e+08 | H10: 4204 | I10: 6442723.4 | J10: 29923461 | K10: =I10-J10 -> -23480738 | L10: =I10+Feb!L10 -> 30792899 | M10: =J10+Feb!M10 -> 1.3308464e+08 | N10: =L10-M10 -> -1.0229174e+08
B11: =1+B10 -> 3 | C11: ATRAM Phil. Equity Opportunity Fund, Inc. | D11: 8.8737099e+08 | E11: 4613615.1 | F11: =D11-E11 -> 8.8275738e+08 | G11: 8.0465666e+08 | H11: 2337 | I11: 2292414.8 | J11: 14467341 | K11: =I11-J11 -> -12174926 | L11: =I11+Feb!L11 -> 10231429 | M11: =J11+Feb!M11 -> 68288819 | N11: =L11-M11 -> -58057390
B12: =1+B11 -> 4 | C12: Climbs Share Capital Equity Investment Fund Corp. | D12: 5.4060942e+08 | E12: 28160862 | F12: =D12-E12 -> 5.1244855e+08 | G12: 3.2026902e+08 | H12: 1677 | I12: 35836364 | J12: 1070347.2 | K12: =I12-J12 -> 34766016 | L12: =I12+Feb!L12 -> 36625656 | M12: =J12+Feb!M12 -> 18077524 | N12: =L12-M12 -> 18548133
B13: =1+B12 -> 5 | C13: First Metro Consumer Fund, Inc. | D13: 239662407 | E13: 2541170 | F13: =D13-E13 -> 237121237 | G13: 207601062 | H13: 1060 | I13: 119465 | J13: 9609952 | K13: =I13-J13 -> -9490487 | L13: =I13+Feb!L13 -> 367641 | M13: =J13+Feb!M13 -> 26994036 | N13: =L13-M13 -> -26626395
B14: =1+B13 -> 6 | C14: First Metro Save and Learn Equity Fund, Inc. | D14: 2243001265 | E14: 12904872 | F14: =D14-E14 -> 2230096393 | G14: 2010810818 | H14: 15086 | I14: 5206303 | J14: 37191773 | K14: =I14-J14 -> -31985470 | L14: =I14+Feb!L14 -> 13260639 | M14: =J14+Feb!M14 -> 114703192 | N14: =L14-M14 -> -101442553
B15: =1+B14 -> 7 | C15: First Metro Save and Learn Phil. Index Fund, Inc. | D15: 61619808 | E15: 202154 | F15: =D15-E15 -> 61417654 | G15: 59827032 | H15: 496 | I15: 185502 | J15: 1368429 | K15: =I15-J15 -> -1182927 | L15: =I15+Feb!L15 -> 636464 | M15: =J15+Feb!M15 -> 1845483 | N15: =L15-M15 -> -1209019
B16: =1+B15 -> 8 | C16: MBG Equity Investment Fund, Inc. | D16: 19462107 | E16: 672280 | F16: =D16-E16 -> 18789827 | G16: 17178988 | H16: 35 | I16: 0 | J16: 0 | K16: =I16-J16 -> 0 | L16: =I16+Feb!L16 -> 0 | M16: =J16+Feb!M16 -> 0 | N16: =L16-M16 -> 0
B17: =1+B16 -> 9 | C17: PAMI Equity Index Fund, Inc. | D17: 866205842 | E17: 29174958 | F17: =D17-E17 -> 837030884 | G17: 846308665 | H17: 10290 | I17: 0 | J17: 5655258 | K17: =I17-J17 -> -5655258 | L17: =I17+Feb!L17 -> 0 | M17: =J17+Feb!M17 -> 28492183 | N17: =L17-M17 -> -28492183
B18: =1+B17 -> 10 | C18: Philam Strategic Growth Fund, Inc. | D18: 2596188973 | E18: 14886783 | F18: =D18-E18 -> 2581302190 | G18: 2462860640 | H18: 9801 | I18: 0 | J18: 51587153 | K18: =I18-J18 -> -51587153 | L18: =I18+Feb!L18 -> 0 | M18: =J18+Feb!M18 -> 116320477 | N18: =L18-M18 -> -116320477
B19: =1+B18 -> 11 | C19: Philequity Dividend Yield Fund, Inc. | D19: 2.5476708e+09 | E19: 9874725.1 | F19: =D19-E19 -> 2537796058 | G19: 2.4565425e+09 | H19: 5174 | I19: 5004934.9 | J19: 16365208 | K19: =I19-J19 -> -11360273 | L19: =I19+Feb!L19 -> 37064224 | M19: =J19+Feb!M19 -> 158101232 | N19: =L19-M19 -> -121037008
B20: =1+B19 -> 12 | C20: Philequity Fund, Inc. | D20: 7.8154893e+09 | E20: 38277495 | F20: =D20-E20 -> 7777211793 | G20: 7.4103042e+09 | H20: 29927 | I20: 5399760.3 | J20: 49611964 | K20: =I20-J20 -> -44212204 | L20: =I20+Feb!L20 -> 25970226 | M20: =J20+Feb!M20 -> 2.1456214e+08 | N20: =L20-M20 -> -1.8859191e+08
B21: =1+B20 -> 13 | C21: Philequity MSCI Phil. Index Fund, Inc. | D21: 2.7729257e+08 | E21: 842315.71 | F21: =D21-E21 -> 2.7645025e+08 | G21: 2.7313189e+08 | H21: 887 | I21: 1220789.5 | J21: 602287.17 | K21: =I21-J21 -> 618502.31 | L21: =I21+Feb!L21 -> 1899388.2 | M21: =J21+Feb!M21 -> 32980883 | N21: =L21-M21 -> -31081495
... B27: =1+B26 -> 19 | C27: United Fund, Inc. | D27: 5.527678e+08 | E27: 22726476 | F27: =D27-E27 -> 5.3004132e+08 | G27: 4.9581516e+08 | H27: 1171 | I27: 3174479.4 | J27: 514311.56 | K27: =I27-J27 -> 2660167.9 | L27: =I27+Feb!L27 -> 3601775 | M27: =J27+Feb!M27 -> 1285828.5 | N27: =L27-M27 -> 2315946.4
A28: Primarily invested in Peso Securities (units)
B29: =1+B27 -> 20 | C29: COL Equity Index Unitized Mutual Fund, Inc. | D29: 2.3455528e+08 | E29: 426165.63 | F29: =D29-E29 -> 2.3412911e+08 | G29: 2.3063e+08 | H29: 5251 | I29: 6342138.6 | J29: 2830530.5 | K29: =I29-J29 -> 3511608 | L29: =I29+Feb!L29 -> 17421092 | M29: =J29+Feb!M29 -> 44221905 | N29: =L29-M29 -> -26800813
B30: =1+B29 -> 21 | C30: COL Strategic Growth Equity Unitized Mutual Fund, Inc. | D30: 2.949785e+08 | E30: 828623.13 | F30: =D30-E30 -> 2.9414988e+08 | G30: 220243098 | H30: 8633 | I30: 4753871.5 | J30: 13486066 | K30: =I30-J30 -> -8732194.3 | L30: =I30+Feb!L30 -> 13101642 | M30: =J30+Feb!M30 -> 72601508 | N30: =L30-M30 -> -59499866
B31: =1+B30 -> 22 | C31: Philequity Alpha One Fund, Inc. | D31: 1.9403589e+08 | E31: 4665031.5 | F31: =D31-E31 -> 1.8937086e+08 | G31: 1.7701323e+08 | H31: 1045 | I31: 114821.04 | J31: 108858.09 | K31: =I31-J31 -> 5962.95 | L31: =I31+Feb!L31 -> 429813.64 | M31: =J31+Feb!M31 -> 6561681 | N31: =L31-M31 -> -6131867.4
B32: =1+B31 -> 23 | C32: Philippine Stock Index Fund Corp. | D32: 499748138 | E32: 10493480 | F32: =D32-E32 -> 489254658 | G32: 482227460 | H32: 801221 | I32: 16419406 | J32: 34454925 | K32: =I32-J32 -> -18035519 | L32: =I32+Feb!L32 -> 40199983 | M32: =J32+Feb!M32 -> 132184129 | N32: =L32-M32 -> -91984146
A33: Exchange Traded Fund
B34: =1+B32 -> 24 | C34: First Metro Phil. Equity Exchange Traded Fund, Inc. | D34: 1224566977 | E34: 1466889 | F34: =D34-E34 -> 1223100088 | G34: 1208912523 | H34: 3238 | I34: 0 | J34: 15825390 | K34: =I34-J34 -> -15825390 | L34: =I34+Feb!L34 -> 8414744 | M34: =J34+Feb!M34 -> 92950465 | N34: =L34-M34 -> -84535721
A35: Sub total - Peso Currency | D35: =SUM(D9:D34) -> 47070428201 | E35: =SUM(E9:E34) -> 4.4384249e+08 | F35: =SUM(F9:F34) -> 46626585709 | G35: =SUM(G9:G34) -> 44500173666 | H35: =SUM(H9:H34) -> 1076783 | I35: =SUM(I9:I34) -> 1.4579507e+08 | J35: =SUM(J9:J34) -> 7.8694137e+08 | K35: =SUM(K9:K34) -> -6.411463e+08 | ... N35: =SUM(N9:N34) -> -2783531059
A36: Primarily invested in foreign currency securities (shares)
B37: =1+B34 -> 25 | C37: ATRAM AsiaPlus Equity Fund, Inc. | D37: 27510200 | E37: 304498.14 | F37: =D37-E37 -> 27205701 | G37: 0 | H37: 42 | I37: 18209.21 | J37: 448009.82 | K37: =I37-J37 -> -429800.61 | L37: =I37+Feb!L37 -> 41428.62 | M37: =J37+Feb!M37 -> 5253395.7 | N37: =L37-M37 -> -5211967.1
B38: =1+B37 -> 26 | C38: Sun Life Prosperity World Voyager Fund, Inc. | D38: 2256911949 | E38: 41712775 | F38: =D38-E38 -> 2215199174 | G38: 0 | H38: 3375 | I38: 13741678 | J38: 126285511 | K38: =I38-J38 -> -112543833 | L38: =I38+Feb!L38 -> 245768807 | M38: =J38+Feb!M38 -> 178921052 | N38: =L38-M38 -> 66847755
A39: Primarily invested in foreign currency securities (units)
B40: =1+B38 -> 27 | C40: Philequity Global Fund, Inc. 3 | D40: 509686.99 | E40: 0 | F40: =D40-E40 -> 509686.99 | G40: 0 | H40: 32 | I40: 13526.68 | J40: 0 | K40: =I40-J40 -> 13526.68 | L40: =I40+Feb!L40 -> 509098.82 | M40: =J40+Feb!M40 -> 0 | N40: =L40-M40 -> 509098.82
A41: Sub total - US Currency | D41: =SUM(D37:D38)+D40 -> 2284931836 | E41: =SUM(E37:E38)+E40 -> 42017273 | F41: =SUM(F37:F38)+F40 -> 2242914562 | G41: =SUM(G37:G38)+G40 -> 0 | H41: =SUM(H37:H38)+H40 -> 3449 | I41: =SUM(I37:I38)+I40 -> 13773414 | J41: =SUM(J37:J38)+J40 -> 1.2673352e+08 | K41: =SUM(K37:K38)+K40 -> -1.1296011e+08 | ... N41: =SUM(N37:N38)+N40 -> 62144887
A42: Sub total - stock funds | D42: =D35+D41 -> 49355360036 | E42: =E35+E41 -> 4.8585976e+08 | F42: =F35+F41 -> 48869500271 | G42: =G35+G41 -> 44500173666 | H42: =H35+H41 -> 1080232 | I42: =I35+I41 -> 1.5956848e+08 | J42: =J35+J41 -> 913674888 | K42: =K35+K41 -> -7.5410641e+08 | ... N42: =N35+N41 -> -2721386172
A43: Balanced Funds
A44: Primarily invested in Peso Securities (shares)
B45: =1+B40 -> 28 | C45: ATRAM Philippine Balanced Fund, Inc. | D45: 3.7140028e+08 | E45: 3007853.7 | F45: =D45-E45 -> 3.6839243e+08 | G45: 1.867039e+08 | H45: 2323 | I45: 841457.64 | J45: 1641817.8 | K45: =I45-J45 -> -800360.17 | L45: =I45+Feb!L45 -> 1820702.9 | M45: =J45+Feb!M45 -> 11914004 | N45: =L45-M45 -> -10093301
...

Sheet Q1
A1: PHILIPPINE INVESTMENT FUNDS ASSOCIATION, INC.
A2: MUTUAL FUNDS STATISTICAL REPORT
A3: For the First Quarter of 2026
A4: (Amounts in Peso)
E5: Y E A R - T O - D A T E
A6: Fund Category | C6: Fund Name | D6: NET ASSETS | E6: TOTAL SALES | F6: TOTAL REDEMPTIONS | G6: TOTAL NET SALES
A7: Stock Funds
A8: Primarily invested in Peso Securities (shares)
B9: 1 | C9: ALFM Growth Fund, Inc. | D9: =Mar!F9 -> 3263465452 | E9: =Jan!I9+Feb!I9+Mar!I9 -> 13207308 | F9: =Jan!J9+Feb!J9+Mar!J9 -> 144274668 | G9: =E9-F9 -> -131067360
B10: =1+B9 -> 2 | C10: ATRAM Alpha Opportunity Fund, Inc. | D10: =Mar!F10 -> 9.7249971e+08 | E10: =Jan!I10+Feb!I10+Mar!I10 -> 30792899 | F10: =Jan!J10+Feb!J10+Mar!J10 -> 1.3308464e+08 | G10: =E10-F10 -> -1.0229174e+08
B11: =1+B10 -> 3 | C11: ATRAM Phil. Equity Opportunity Fund, Inc. | D11: =Mar!F11 -> 8.8275738e+08 | E11: =Jan!I11+Feb!I11+Mar!I11 -> 10231429 | F11: =Jan!J11+Feb!J11+Mar!J11 -> 68288819 | G11: =E11-F11 -> -58057390
B12: =1+B11 -> 4 | C12: Climbs Share Capital Equity Investment Fund Corp. | D12: =Mar!F12 -> 5.1244855e+08 | E12: =Jan!I12+Feb!I12+Mar!I12 -> 36625656 | F12: =Jan!J12+Feb!J12+Mar!J12 -> 18077524 | G12: =E12-F12 -> 18548133
B13: =1+B12 -> 5 | C13: First Metro Consumer Fund, Inc. | D13: =Mar!F13 -> 237121237 | E13: =Jan!I13+Feb!I13+Mar!I13 -> 367641 | F13: =Jan!J13+Feb!J13+Mar!J13 -> 26994036 | G13: =E13-F13 -> -26626395
B14: =1+B13 -> 6 | C14: First Metro Save and Learn Equity Fund, Inc. | D14: =Mar!F14 -> 2230096393 | E14: =Jan!I14+Feb!I14+Mar!I14 -> 13260639 | F14: =Jan!J14+Feb!J14+Mar!J14 -> 114703192 | G14: =E14-F14 -> -101442553
B15: =1+B14 -> 7 | C15: First Metro Save and Learn Phil. Index Fund, Inc. | D15: =Mar!F15 -> 61417654 | E15: =Jan!I15+Feb!I15+Mar!I15 -> 636464 | F15: =Jan!J15+Feb!J15+Mar!J15 -> 1845483 | G15: =E15-F15 -> -1209019
B16: =1+B15 -> 8 | C16: MBG Equity Investment Fund, Inc. | D16: =Mar!F16 -> 18789827 | E16: =Jan!I16+Feb!I16+Mar!I16 -> 0 | F16: =Jan!J16+Feb!J16+Mar!J16 -> 0 | G16: =E16-F16 -> 0
B17: =1+B16 -> 9 | C17: PAMI Equity Index Fund, Inc. | D17: =Mar!F17 -> 837030884 | E17: =Jan!I17+Feb!I17+Mar!I17 -> 0 | F17: =Jan!J17+Feb!J17+Mar!J17 -> 28492183 | G17: =E17-F17 -> -28492183
B18: =1+B17 -> 10 | C18: Philam Strategic Growth Fund, Inc. | D18: =Mar!F18 -> 2581302190 | E18: =Jan!I18+Feb!I18+Mar!I18 -> 0 | F18: =Jan!J18+Feb!J18+Mar!J18 -> 116320477 | G18: =E18-F18 -> -116320477
B19: =1+B18 -> 11 | C19: Philequity Dividend Yield Fund, Inc. | D19: =Mar!F19 -> 2537796058 | E19: =Jan!I19+Feb!I19+Mar!I19 -> 37064224 | F19: =Jan!J19+Feb!J19+Mar!J19 -> 158101232 | G19: =E19-F19 -> -121037008
B20: =1+B19 -> 12 | C20: Philequity Fund, Inc. | D20: =Mar!F20 -> 7777211793 | E20: =Jan!I20+Feb!I20+Mar!I20 -> 25970226 | F20: =Jan!J20+Feb!J20+Mar!J20 -> 2.1456214e+08 | G20: =E20-F20 -> -1.8859191e+08
B21: =1+B20 -> 13 | C21: Philequity MSCI Phil. Index Fund, Inc. | D21: =Mar!F21 -> 2.7645025e+08 | E21: =Jan!I21+Feb!I21+Mar!I21 -> 1899388.2 | F21: =Jan!J21+Feb!J21+Mar!J21 -> 32980883 | G21: =E21-F21 -> -31081495
... B27: =1+B26 -> 19 | C27: United Fund, Inc. | D27: =Mar!F27 -> 5.3004132e+08 | E27: =Jan!I27+Feb!I27+Mar!I27 -> 3601775 | F27: =Jan!J27+Feb!J27+Mar!J27 -> 1285828.5 | G27: =E27-F27 -> 2315946.4
A28: Primarily invested in Peso Securities (units)
B29: =1+B27 -> 20 | C29: COL Equity Index Unitized Mutual Fund, Inc. | D29: =Mar!F29 -> 2.3412911e+08 | E29: =Jan!I29+Feb!I29+Mar!I29 -> 17421092 | F29: =Jan!J29+Feb!J29+Mar!J29 -> 44221905 | G29: =E29-F29 -> -26800813
B30: =1+B29 -> 21 | C30: COL Strategic Growth Equity Unitized Mutual Fund, Inc. | D30: =Mar!F30 -> 2.9414988e+08 | E30: =Jan!I30+Feb!I30+Mar!I30 -> 13101642 | F30: =Jan!J30+Feb!J30+Mar!J30 -> 72601508 | G30: =E30-F30 -> -59499866
B31: =1+B30 -> 22 | C31: Philequity Alpha One Fund, Inc. | D31: =Mar!F31 -> 1.8937086e+08 | E31: =Jan!I31+Feb!I31+Mar!I31 -> 429813.64 | F31: =Jan!J31+Feb!J31+Mar!J31 -> 6561681 | G31: =E31-F31 -> -6131867.4
B32: =1+B31 -> 23 | C32: Philippine Stock Index Fund Corp. | D32: =Mar!F32 -> 489254658 | E32: =Jan!I32+Feb!I32+Mar!I32 -> 40199983 | F32: =Jan!J32+Feb!J32+Mar!J32 -> 132184129 | G32: =E32-F32 -> -91984146
A33: Exchange Traded Fund
B34: =1+B32 -> 24 | C34: First Metro Phil. Equity Exchange Traded Fund, Inc. | D34: =Mar!F34 -> 1223100088 | E34: =Jan!I34+Feb!I34+Mar!I34 -> 8414744 | F34: =Jan!J34+Feb!J34+Mar!J34 -> 92950465 | G34: =E34-F34 -> -84535721
A35: Sub total - Peso Currency | D35: =SUM(D9:D34) -> 46626585709 | E35: =SUM(E9:E34) -> 3.5682315e+08 | F35: =SUM(F9:F34) -> 3140354210 | G35: =SUM(G9:G34) -> -2783531059
A36: Primarily invested in foreign currency securities (shares)
B37: =1+B34 -> 25 | C37: ATRAM AsiaPlus Equity Fund, Inc. | D37: =Mar!F37 -> 27205701 | E37: =Jan!I37+Feb!I37+Mar!I37 -> 41428.62 | F37: =Jan!J37+Feb!J37+Mar!J37 -> 5253395.7 | G37: =E37-F37 -> -5211967.1
B38: =1+B37 -> 26 | C38: Sun Life Prosperity World Voyager Fund, Inc. | D38: =Mar!F38 -> 2215199174 | E38: =Jan!I38+Feb!I38+Mar!I38 -> 245768807 | F38: =Jan!J38+Feb!J38+Mar!J38 -> 178921052 | G38: =E38-F38 -> 66847755
A39: Primarily invested in foreign currency securities (units)
B40: =1+B38 -> 27 | C40: Philequity Global Fund, Inc. 3 | D40: =Mar!F40 -> 509686.99 | E40: =Feb!I40+Mar!I40 -> 509098.82 | F40: =Feb!J40+Mar!J40 -> 0 | G40: =E40-F40 -> 509098.82
A41: Sub total - US Currency | D41: =SUM(D37:D38)+D40 -> 2242914562 | E41: =SUM(E37:E38)+E40 -> 2.4631933e+08 | F41: =SUM(F37:F38)+F40 -> 1.8417445e+08 | G41: =SUM(G37:G38)+G40 -> 62144887
A42: Sub total - stock funds | D42: =D35+D41 -> 48869500271 | E42: =E35+E41 -> 6.0314249e+08 | F42: =F35+F41 -> 3324528658 | G42: =G35+G41 -> -2721386172
A43: Balanced Funds
A44: Primarily invested in Peso Securities (shares)
B45: =1+B40 -> 28 | C45: ATRAM Philippine Balanced Fund, Inc. | D45: =Mar!F45 -> 3.6839243e+08 | E45: =Jan!I43+Feb!I45+Mar!I45 -> 1820702.9 | F45: =Jan!J43+Feb!J45+Mar!J45 -> 11914004 | G45: =E45-F45 -> -10093301
...

Sheet AUM
A1: PHILIPPINE INVESTMENT FUNDS ASSOCIATION, INC.
A2: ASSET UNDER MANAGEMENT
A4: No. | B4: Company | C4: No. of Funds | D4: January | E4: February | F4: March | G4: April | H4: May | I4: June | J4: July | K4: August | L4: September | M4: October | N4: November | O4: December
A5: 1 | B5: AIB | C5: 1 | D5: =Jan!F96 -> 1.7561621e+08 | E5: =Feb!F98 -> 1.7598153e+08 | F5: =Mar!F98 -> 1.7632803e+08
A6: =1+A5 -> 2 | B6: ATR FAMI | C6: 9 | D6: =Jan!F13+Jan!F14+Jan!F15+Jan!F34+Jan!F45+Jan!F46+Jan!F72+Jan!F85+Jan!F98 -> 8578750652 | E6: =Feb!F13+Feb!F14+Feb!F15+Feb!F34+Feb!F47+Feb!F48+Feb!F74+Feb!F87+Feb!F100 -> 8709800414 | F6: =Mar!F13+Mar!F14+Mar!F15+Mar!F34+Mar!F47+Mar!F48+Mar!F74+Mar!F87+Mar!F100 -> 8211507594
A7: =1+A6 -> 3 | B7: ATRAM | C7: =8+2 -> 10 | D7: =Jan!F10+Jan!F11+Jan!F24+Jan!F37+Jan!F43+Jan!F44+Jan!F69+Jan!F76+Jan!F80+Jan!F84 -> 8508559380 | E7: =Feb!F10+Feb!F11+Feb!F24+Feb!F37+Feb!F45+Feb!F46+Feb!F71+Feb!F78+Feb!F82+Feb!F86 -> 8742017367 | F7: =Mar!F10+Mar!F11+Mar!F24+Mar!F37+Mar!F45+Mar!F46+Mar!F71+Mar!F78+Mar!F82+Mar!F86 -> 8146244554
A8: =1+A7 -> 4 | B8: BPI Wealth | C8: =8+1+9+1+1 -> 20 | D8: =Jan!F9+Jan!F17+Jan!F18+Jan!F23+Jan!F32+Jan!F48+Jan!F49+Jan!F50+Jan!F54+Jan!F61+Jan!F68+Jan!F71+Jan!F73+Jan!F74+Jan!F83+Jan!F86+Jan!F87+Jan!F91+Jan!F97+Jan!F101+Jan!F109+Jan!F114+Jan!F47 -> 119349211086 | E8: =Feb!F9+Feb!F17+Feb!F18+Feb!F23+Feb!F32+Feb!F49+Feb!F50+Feb!F51+Feb!F52+Feb!F56+Feb!F63+Feb!F70+Feb!F73+Feb!F75+Feb!F76+Feb!F85+Feb!F88+Feb!F89+Feb!F93+Feb!F99+Feb!F103+Feb!F111+Feb!F116 -> 120507165837 | F8: =Mar!F9+Mar!F17+Mar!F18+Mar!F23+Mar!F32+Mar!F49+Mar!F50+Mar!F51+Mar!F52+Mar!F56+Mar!F63+Mar!F70+Mar!F73+Mar!F75+Mar!F76+Mar!F85+Mar!F88+Mar!F89+Mar!F93+Mar!F99+Mar!F103+Mar!F111+Mar!F116 -> 118876575764
A9: =1+A8 -> 5 | B9: CAMCI | C9: 3 | D9: =Jan!F27+Jan!F60+Jan!F70 -> 1549506758 | E9: =Feb!F27+Feb!F62+Feb!F72 -> 1548256413 | F9: =Mar!F27+Mar!F62+Mar!F72 -> 1490432867
A10: =1+A9 -> 6 | B10: CIMAC | C10: 1 | D10: =Jan!F12 -> 489458724 | E10: =Feb!F12 -> 4.9869416e+08 | F10: =Mar!F12 -> 5.1244855e+08
A11: =1+A10 -> 7 | B11: CMI | C11: =1+1 -> 2 | D11: =Jan!F29+Jan!F30 -> 5.7255486e+08 | E11: =Feb!F29+Feb!F30 -> 5.7554283e+08 | F11: =Mar!F29+Mar!F30 -> 5.2827899e+08
A12: =1+A11 -> 8 | B12: MBG | C12: 1 | D12: =Jan!F16 -> 22207054 | E12: =Feb!F16 -> 21697622 | F12: =Mar!F16 -> 18789827
A13: =1+A12 -> 9 | B13: PEMI | C13: =7+1 -> 8 | D13: =Jan!F19+Jan!F20+Jan!F21+Jan!F22+Jan!F31+Jan!F75+Jan!F88 -> 15090979264 | E13: =Feb!F19+Feb!F20+Feb!F21+Feb!F22+Feb!F31+Feb!F40+Feb!F77+Feb!F90 -> 15312339812 | F13: =Mar!F19+Mar!F20+Mar!F21+Mar!F22+Mar!F31+Mar!F40+Mar!F77+Mar!F90 -> #REF!
A14: =1+A13 -> 10 | B14: SLAMCI | C14: =15+1+1 -> 17 | D14: =Jan!F25+Jan!F26+Jan!F38+Jan!F51+Jan!F52+Jan!F55+Jan!F56+Jan!F57+Jan!F62+Jan!F63+Jan!F77+Jan!F78+Jan!F89+Jan!F99+Jan!F104+Jan!F110+Jan!F111 -> 51118488558 | E14: =Feb!F25+Feb!F26+Feb!F38+Feb!F53+Feb!F54+Feb!F57+Feb!F58+Feb!F59+Feb!F64+Feb!F65+Feb!F79+Feb!F80+Feb!F91+Feb!F101+Feb!F106+Feb!F112+Feb!F113 -> 51623915010 | F14: =Mar!F25+Mar!F26+Mar!F38+Mar!F53+Mar!F54+Mar!F57+Mar!F58+Mar!F59+Mar!F64+Mar!F65+Mar!F79+Mar!F80+Mar!F91+Mar!F101+Mar!F106+Mar!F112+Mar!F113 -> 49103625646
A16: GRAND TOTALS | C16: =SUM(C5:C14) -> 72 | D16: =SUM(D5:D14) -> 205455332549 | E16: =SUM(E5:E14) -> 207715410994 | F16: =SUM(F5:F14) -> #REF! | G16: =SUM(G5:G14) -> 0 | H16: =SUM(H5:H14) -> 0 | I16: =SUM(I5:I14) -> 0 | J16: =SUM(J5:J14) -> 0 | ... O16: =SUM(O5:O14) -> 0
D17: =D16-Jan!F117 -> 0 | E17: =E16-'Feb UPDATED'!F119 -> 3.0517578e-05 | F17: =F16-Mar!F119 -> #REF! | G17: =G16-#REF! -> #REF! | H17: =H16-#REF! -> #REF! | I17: =I16-#REF! -> #REF! | J17: =J16-#REF! -> #REF! | K17: =K16-#REF! -> #REF! | L17: =L16-#REF! -> #REF! | M17: =M16-#REF! -> #REF! | N17: =N16-#REF! -> #REF! | O17: =O16-Jan!F117 -> -205455332549

Sheet NET SALES
A1: PHILIPPINE INVESTMENT FUNDS ASSOCIATION, INC.
A2: YEAR-TO-DATE NET SALES
A4: No. | B4: Company | C4: No. of Funds | D4: Total Sales | E4: Total Redemptions | F4: NET SALES
A5: 1 | B5: AIB | C5: 1 | D5: =Mar!L98 -> 156000 | E5: =Mar!M98 -> 107291.09 | F5: =D5-E5 -> 48708.91
A6: =1+A5 -> 2 | B6: ATR FAMI | C6: 9 | D6: =Mar!L13+Mar!L14+Mar!L15+Mar!L34+Mar!L47+Mar!L48+Mar!L74+Mar!L87+Mar!L100 -> 399056055 | E6: =Mar!M13+Mar!M14+Mar!M15+Mar!M34+Mar!M47+Mar!M48+Mar!M74+Mar!M87+Mar!M100 -> 671743238 | F6: =D6-E6 -> -272687183
A7: =1+A6 -> 3 | B7: ATRAM | C7: =8+2 -> 10 | D7: =Mar!L10+Mar!L11+Mar!L24+Mar!L37+Mar!L45+Mar!L46+Mar!L71+Mar!L82+Mar!L86+Mar!L78 -> 2.4650284e+08 | E7: =Mar!M10+Mar!M11+Mar!M24+Mar!M37+Mar!M45+Mar!M46+Mar!M71+Mar!M82+Mar!M86+Mar!M78 -> 2.6169687e+08 | F7: =D7-E7 -> -15194021
A8: =1+A7 -> 4 | B8: BPI Wealth | C8: =8+1+9+1+1 -> 20 | D8: =Mar!L9+Mar!L17+Mar!L18+Mar!L23+Mar!L32+Mar!L49+Mar!L50+Mar!L51+Mar!L52+Mar!L56+Mar!L63+Mar!L70+Mar!L73+Mar!L75+Mar!L76+Mar!L85+Mar!L88+Mar!L89+Mar!L93+Mar!L99+Mar!L103+Mar!L111+Mar!L116 -> 7249882178 | E8: =Mar!M9+Mar!M17+Mar!M18+Mar!M23+Mar!M32+Mar!M49+Mar!M50+Mar!M51+Mar!M52+Mar!M56+Mar!M63+Mar!M70+Mar!M73+Mar!M75+Mar!M76+Mar!M85+Mar!M88+Mar!M89+Mar!M93+Mar!M99+Mar!M103+Mar!M111+Mar!M116 -> 7726901040 | F8: =D8-E8 -> -477018862
A9: =1+A8 -> 5 | B9: CAMCI | C9: 3 | D9: =Mar!L27+Mar!L62+Mar!L72 -> 13839097 | E9: =Mar!M27+Mar!M62+Mar!M72 -> 36669154 | F9: =D9-E9 -> -22830057
A10: =1+A9 -> 6 | B10: CIMAC | C10: 1 | D10: =Mar!L12 -> 36625656 | E10: =Mar!M12 -> 18077524 | F10: =D10-E10 -> 18548133
A11: =1+A10 -> 7 | B11: CMI | C11: =1+1 -> 2 | D11: =Mar!L29+Mar!L30 -> 30522734 | E11: =Mar!M29+Mar!M30 -> 1.1682341e+08 | F11: =D11-E11 -> -86300679
A12: =1+A11 -> 8 | B12: MBG | C12: 1 | D12: =Mar!L16 -> 0 | E12: =Mar!M16 -> 0 | F12: =D12-E12 -> 0
A13: =1+A12 -> 9 | B13: PEMI | C13: =7+1 -> 8 | D13: =Mar!L19+Mar!L20+Mar!L21+Mar!L22+Mar!L31+Mar!L40+Mar!L77+Mar!L90 -> #REF! | E13: =Mar!M19+Mar!M20+Mar!M21+Mar!M22+Mar!M31+Mar!M40+Mar!M77+Mar!M90 -> #REF! | F13: =D13-E13 -> #REF!
A14: =1+A13 -> 10 | B14: SLAMCI | C14: =15+1+1 -> 17 | D14: =Mar!L25+Mar!L26+Mar!L38+Mar!L53+Mar!L54+Mar!L57+Mar!L58+Mar!L59+Mar!L64+Mar!L65+Mar!L79+Mar!L80+Mar!L91+Mar!L101+Mar!L106+Mar!L112+Mar!L113 -> 4504929997 | E14: =Mar!M25+Mar!M26+Mar!M38+Mar!M53+Mar!M54+Mar!M57+Mar!M58+Mar!M59+Mar!M64+Mar!M65+Mar!M79+Mar!M80+Mar!M91+Mar!M101+Mar!M106+Mar!M112+Mar!M113 -> 5832351708 | F14: =D14-E14 -> -1327421711
A16: GRAND TOTALS | C16: =SUM(C5:C14) -> 72 | D16: =SUM(D5:D14) -> #REF! | E16: =SUM(E5:E14) -> #REF! | F16: =SUM(F5:F14) -> #REF!
D17: =D16-Mar!L119 -> #REF! | E17: =E16-Mar!M119 -> #REF! | F17: =F16-Mar!N119 -> #REF!
